Workbook

Sheet Lisez-moi
A1: Bilan stock-to-use du café et prix KC1 / DF1 — campagnes 2010/11 à 2026/27
A3: Ce que demande l'analyse
A4: Calculer le stock-to-use (STU) du café, le comparer au prix, et comprendre comment le prix réagit selon son niveau, pour prévoir le prix à partir de la production.
A5: Définitions
A6: STU = stocks de fin ÷ (consommation domestique + exportations), données USDA. Monde = somme des 93 pays du fichier USDA.
A7: STU certifié = stocks certifiés ICE en fin de campagne (fin septembre ; fin août 2026 pour 2025/26) ÷ (consommation domestique + exportations). New York pour l'arabica, Londres pour le robusta, les deux pour le total.
A8: Prix : moyenne de la campagne octobre-septembre de ICE New York (KC) et ICE Londres (DF), moyennes mensuelles publiées par l'ICO (2e-3e positions, proxy de KC1 / DF1). 2025/26 = octobre 2025 → août 2026 (11 mois).
A9: Arabica et robusta : ce que l'USDA publie et comment le STU est calculé
A10: Pour chaque pays, l'USDA publie la production arabica et la production robusta, mais un seul chiffre de stocks de fin, de consommation et d'exportations, toutes espèces confondues (vérifié sur les 19 attributs du fichier : exportations, importations et consommation ne sont ventilées que par forme — vert, torréfié, soluble). Il n'existe donc pas de « stocks de fin arabica » USDA, même pays par pays.
A11: Calcul : pour chacun des 42 pays d'origine (producteurs exportateurs nets), stocks et utilisation sont multipliés par la part de l'espèce dans sa production de l'année, puis additionnés. Pour les pays à une seule espèce (Colombie, Éthiopie, Honduras : 100 % arabica), c'est le chiffre USDA exact ; le Vietnam est à ≈ 96-97 % robusta. La répartition porte sur les pays mixtes : Brésil (60 à 81 % d'arabica selon l'année), Inde, Ouganda, Indonésie, Mexique, etc.
A12: Ces STU arabica / robusta sont ceux des PAYS D'ORIGINE : les stocks des pays consommateurs (UE, États-Unis, Japon : 51 à 77 % des stocks mondiaux, dont les stocks certifiés) ne sont pas répartis par espèce et ne figurent que dans le STU mondial.
A13: Contrôles : les colonnes J-K des onglets 2 et 3 recalculent le STU sans aucune répartition. Espèce majoritaire : même courbe (corrélation 0,99 arabica, 0,94 robusta). Pays purs ≥ 90 % : même forme en robusta (0,88), courbe différente en arabica (0,31) car le Brésil en est exclu.
... A25: 16 campagnes (15 avec stocks certifiés), très autocorrélées (≈ 4 à 7 observations indépendantes) : des ordres de grandeur, pas des lois. Le lien STU mondial / prix repose surtout sur 2023/24-2025/26. Campagnes USDA locales (Brésil juillet-juin) contre prix octobre-septembre. Prix non corrigés de l'inflation ni du real brésilien. Les stocks USDA sont en partie estimés, pour tous les pays (États-Unis figés à 5,7 M sacs depuis 2022/23).

Sheet 1_Monde
A1: 1 — Monde : production, stock-to-use et stock-to-use des stocks certifiés, avec KC1 et DF1
A2: STU = stocks de fin ÷ (consommation domestique + exportations), somme des 93 pays USDA. STU certifié = (stocks certifiés New York + Londres, fin de campagne) ÷ (consommation + exportations).
A3: Prix : moyenne octobre-septembre, KC1 et DF1 en US c/lb pour partager l'axe (DF1 en US$/t dans la colonne M).
A4: Campagne | B4: Production monde (1000 sacs) | C4: Production (M sacs) | D4: Stocks de fin monde | E4: Consommation domestique monde | F4: Exportations monde | G4: STU = stocks ÷ (conso + export) | H4: Certifiés NY (M sacs) | I4: Certifiés Londres (M sacs) | J4: STU certifié = (NY + Londres) ÷ (conso + export) | K4: KC1 (US c/lb) | L4: DF1 (US c/lb) | M4: DF1 (US$/t) | N4: Info : STU = stocks ÷ conso (déf. USDA/ICO)
A5: 2010/11 | B5: ='Donnees_USDA'!C102 -> 141409 | C5: =B5/1000 -> 141.409 | D5: ='Donnees_USDA'!C408 -> 28640 | E5: ='Donnees_USDA'!C510 -> 135508 | F5: ='Donnees_USDA'!C612 -> 116972 | G5: =D5/(E5+F5) -> 0.11343473 | K5: ='Prix_ICE'!I5 -> 249.66 | L5: ='Prix_ICE'!J5 -> 100.65583 | M5: ='Prix_ICE'!K5 -> 2219.0813 | N5: =D5/E5 -> 0.21135284
A6: 2011/12 | B6: ='Donnees_USDA'!D102 -> 144837 | C6: =B6/1000 -> 144.837 | D6: ='Donnees_USDA'!D408 -> 25748 | E6: ='Donnees_USDA'!D510 -> 142831 | F6: ='Donnees_USDA'!D612 -> 118031 | G6: =D6/(E6+F6) -> 0.098703529 | H6: ='Stocks_certifies'!H6 -> 2.43 | I6: ='Stocks_certifies'!I6 -> 2.17 | J6: =(H6+I6)*1000/(E6+F6) -> 0.017633845 | K6: ='Prix_ICE'!I6 -> 197.84167 | L6: ='Prix_ICE'!J6 -> 91.384167 | M6: ='Prix_ICE'!K6 -> 2014.676 | N6: =D6/E6 -> 0.18026899
A7: 2012/13 | B7: ='Donnees_USDA'!E102 -> 158018 | C7: =B7/1000 -> 158.018 | D7: ='Donnees_USDA'!E408 -> 35365 | E7: ='Donnees_USDA'!E510 -> 143400 | F7: ='Donnees_USDA'!E612 -> 123239 | G7: =D7/(E7+F7) -> 0.13263251 | H7: ='Stocks_certifies'!H7 -> 3.13 | I7: ='Stocks_certifies'!I7 -> 1.01 | J7: =(H7+I7)*1000/(E7+F7) -> 0.015526611 | K7: ='Prix_ICE'!I7 -> 140.69833 | L7: ='Prix_ICE'!J7 -> 88.480833 | M7: ='Prix_ICE'!K7 -> 1950.6685 | N7: =D7/E7 -> 0.24661785
A8: 2013/14 | B8: ='Donnees_USDA'!F102 -> 160054 | C8: =B8/1000 -> 160.054 | D8: ='Donnees_USDA'!F408 -> 41184 | E8: ='Donnees_USDA'!F510 -> 143877 | F8: ='Donnees_USDA'!F612 -> 129260 | G8: =D8/(E8+F8) -> 0.15078148 | H8: ='Stocks_certifies'!H8 -> 2.68 | I8: ='Stocks_certifies'!I8 -> 1.88 | J8: =(H8+I8)*1000/(E8+F8) -> 0.016694919 | K8: ='Prix_ICE'!I8 -> 161.4675 | L8: ='Prix_ICE'!J8 -> 85.874167 | M8: ='Prix_ICE'!K8 -> 1893.2013 | N8: =D8/E8 -> 0.2862445
A9: 2014/15 | B9: ='Donnees_USDA'!G102 -> 153796 | C9: =B9/1000 -> 153.796 | D9: ='Donnees_USDA'!G408 -> 43132 | E9: ='Donnees_USDA'!G510 -> 147163 | F9: ='Donnees_USDA'!G612 -> 124027 | G9: =D9/(E9+F9) -> 0.15904716 | H9: ='Stocks_certifies'!H9 -> 2.28 | I9: ='Stocks_certifies'!I9 -> 3.43 | J9: =(H9+I9)*1000/(E9+F9) -> 0.021055349 | K9: ='Prix_ICE'!I9 -> 154.02083 | L9: ='Prix_ICE'!J9 -> 83.910833 | M9: ='Prix_ICE'!K9 -> 1849.9172 | N9: =D9/E9 -> 0.29308998
A10: 2015/16 | B10: ='Donnees_USDA'!H102 -> 152429 | C10: =B10/1000 -> 152.429 | D10: ='Donnees_USDA'!H408 -> 34951 | E10: ='Donnees_USDA'!H510 -> 153186 | F10: ='Donnees_USDA'!H612 -> 133845 | G10: =D10/(E10+F10) -> 0.12176734 | H10: ='Stocks_certifies'!H10 -> 1.42 | I10: ='Stocks_certifies'!I10 -> 2.32 | J10: =(H10+I10)*1000/(E10+F10) -> 0.013029951 | K10: ='Prix_ICE'!I10 -> 131.8325 | L10: ='Prix_ICE'!J10 -> 74.068333 | M10: ='Prix_ICE'!K10 -> 1632.9272 | N10: =D10/E10 -> 0.22816054
A11: 2016/17 | B11: ='Donnees_USDA'!I102 -> 161079 | C11: =B11/1000 -> 161.079 | D11: ='Donnees_USDA'!I408 -> 36453 | E11: ='Donnees_USDA'!I510 -> 155104 | F11: ='Donnees_USDA'!I612 -> 133606 | G11: =D11/(E11+F11) -> 0.12626165 | H11: ='Stocks_certifies'!H11 -> 2.03 | I11: ='Stocks_certifies'!I11 -> 2.52 | J11: =(H11+I11)*1000/(E11+F11) -> 0.015759759 | K11: ='Prix_ICE'!I11 -> 143.77167 | L11: ='Prix_ICE'!J11 -> 95.123333 | M11: ='Prix_ICE'!K11 -> 2097.1105 | N11: =D11/E11 -> 0.23502295
A12: 2017/18 | B12: ='Donnees_USDA'!J102 -> 159814 | C12: =B12/1000 -> 159.814 | D12: ='Donnees_USDA'!J408 -> 31951 | E12: ='Donnees_USDA'!J510 -> 160627 | F12: ='Donnees_USDA'!J612 -> 134174 | G12: =D12/(E12+F12) -> 0.10838159 | H12: ='Stocks_certifies'!H12 -> 2.7 | I12: ='Stocks_certifies'!I12 -> 1.51 | J12: =(H12+I12)*1000/(E12+F12) -> 0.01428082 | K12: ='Prix_ICE'!I12 -> 120.60083 | L12: ='Prix_ICE'!J12 -> 78.285 | M12: ='Prix_ICE'!K12 -> 1725.8888 | N12: =D12/E12 -> 0.19891425
A13: 2018/19 | B13: ='Donnees_USDA'!K102 -> 175856 | C13: =B13/1000 -> 175.856 | D13: ='Donnees_USDA'!K408 -> 36946 | E13: ='Donnees_USDA'!K510 -> 166003 | F13: ='Donnees_USDA'!K612 -> 143364 | G13: =D13/(E13+F13) -> 0.1194245 | H13: ='Stocks_certifies'!H13 -> 2.6 | I13: ='Stocks_certifies'!I13 -> 2.62 | J13: =(H13+I13)*1000/(E13+F13) -> 0.016873164 | K13: ='Prix_ICE'!I13 -> 104.98083 | L13: ='Prix_ICE'!J13 -> 67.5325 | M13: ='Prix_ICE'!K13 -> 1488.8368 | N13: =D13/E13 -> 0.22256224
A14: 2019/20 | B14: ='Donnees_USDA'!L102 -> 169030 | C14: =B14/1000 -> 169.03 | D14: ='Donnees_USDA'!L408 -> 35808 | E14: ='Donnees_USDA'!L510 -> 162355 | F14: ='Donnees_USDA'!L612 -> 139001 | G14: =D14/(E14+F14) -> 0.11882292 | H14: ='Stocks_certifies'!H14 -> 1.26 | I14: ='Stocks_certifies'!I14 -> 1.85 | J14: =(H14+I14)*1000/(E14+F14) -> 0.01032002 | K14: ='Prix_ICE'!I14 -> 113.23667 | L14: ='Prix_ICE'!J14 -> 59.220833 | M14: ='Prix_ICE'!K14 -> 1305.5959 | N14: =D14/E14 -> 0.22055372
A15: 2020/21 | B15: ='Donnees_USDA'!M102 -> 176594 | C15: =B15/1000 -> 176.594 | D15: ='Donnees_USDA'!M408 -> 37494 | E15: ='Donnees_USDA'!M510 -> 162093 | F15: ='Donnees_USDA'!M612 -> 144941 | G15: =D15/(E15+F15) -> 0.12211677 | H15: ='Stocks_certifies'!H15 -> 2.27 | I15: ='Stocks_certifies'!I15 -> 2.1 | J15: =(H15+I15)*1000/(E15+F15) -> 0.014232951 | K15: ='Prix_ICE'!I15 -> 143.75333 | L15: ='Prix_ICE'!J15 -> 69.895833 | M15: ='Prix_ICE'!K15 -> 1540.9394 | N15: =D15/E15 -> 0.23131165
A16: 2021/22 | B16: ='Donnees_USDA'!N102 -> 165044 | C16: =B16/1000 -> 165.044 | D16: ='Donnees_USDA'!N408 -> 31940 | E16: ='Donnees_USDA'!N510 -> 167876 | F16: ='Donnees_USDA'!N612 -> 143583 | G16: =D16/(E16+F16) -> 0.10254961 | H16: ='Stocks_certifies'!H16 -> 0.45 | I16: ='Stocks_certifies'!I16 -> 1.59 | J16: =(H16+I16)*1000/(E16+F16) -> 0.0065498188 | K16: ='Prix_ICE'!I16 -> 224.0875 | L16: ='Prix_ICE'!J16 -> 97.529167 | M16: ='Prix_ICE'!K16 -> 2150.1501 | N16: =D16/E16 -> 0.19025948
A17: 2022/23 | B17: ='Donnees_USDA'!O102 -> 164529 | C17: =B17/1000 -> 164.529 | D17: ='Donnees_USDA'!O408 -> 26934 | E17: ='Donnees_USDA'!O510 -> 168754 | F17: ='Donnees_USDA'!O612 -> 134699 | G17: =D17/(E17+F17) -> 0.088758391 | H17: ='Stocks_certifies'!H17 -> 0.49 | I17: ='Stocks_certifies'!I17 -> 0.73 | J17: =(H17+I17)*1000/(E17+F17) -> 0.004020392 | K17: ='Prix_ICE'!I17 -> 171.19 | L17: ='Prix_ICE'!J17 -> 100.565 | M17: ='Prix_ICE'!K17 -> 2217.0787 | N17: =D17/E17 -> 0.15960511
A18: 2023/24 | B18: ='Donnees_USDA'!P102 -> 169335 | C18: =B18/1000 -> 169.335 | D18: ='Donnees_USDA'!P408 -> 23121 | E18: ='Donnees_USDA'!P510 -> 163944 | F18: ='Donnees_USDA'!P612 -> 143474 | G18: =D18/(E18+F18) -> 0.0752103 | H18: ='Stocks_certifies'!H18 -> 0.87 | I18: ='Stocks_certifies'!I18 -> 0.74 | J18: =(H18+I18)*1000/(E18+F18) -> 0.0052371689 | K18: ='Prix_ICE'!I18 -> 204.00167 | L18: ='Prix_ICE'!J18 -> 158.95 | M18: ='Prix_ICE'!K18 -> 3504.2477 | N18: =D18/E18 -> 0.14102986
A19: 2024/25 | B19: ='Donnees_USDA'!Q102 -> 176816 | C19: =B19/1000 -> 176.816 | D19: ='Donnees_USDA'!Q408 -> 22010 | E19: ='Donnees_USDA'!Q510 -> 171761 | F19: ='Donnees_USDA'!Q612 -> 147746 | G19: =D19/(E19+F19) -> 0.06888738 | H19: ='Stocks_certifies'!H19 -> 0.62 | I19: ='Stocks_certifies'!I19 -> 1.08 | J19: =(H19+I19)*1000/(E19+F19) -> 0.0053206972 | K19: ='Prix_ICE'!I19 -> 333.06 | L19: ='Prix_ICE'!J19 -> 213.2675 | M19: ='Prix_ICE'!K19 -> 4701.7435 | N19: =D19/E19 -> 0.12814318
A20: 2025/26 | B20: ='Donnees_USDA'!R102 -> 178830 | C20: =B20/1000 -> 178.83 | D20: ='Donnees_USDA'!R408 -> 24370 | E20: ='Donnees_USDA'!R510 -> 173459 | F20: ='Donnees_USDA'!R612 -> 145942 | G20: =D20/(E20+F20) -> 0.076299072 | H20: ='Stocks_certifies'!H20 -> 0.24 | I20: ='Stocks_certifies'!I20 -> 0.83 | J20: =(H20+I20)*1000/(E20+F20) -> 0.0033500208 | K20: ='Prix_ICE'!I20 -> 312.21 | L20: ='Prix_ICE'!J20 -> 171.84182 | M20: ='Prix_ICE'!K20 -> 3788.4636 | N20: =D20/E20 -> 0.1404943
A21: 2026/27 (prév.) | B21: ='Donnees_USDA'!S102 -> 189667 | C21: =B21/1000 -> 189.667 | D21: ='Donnees_USDA'!S408 -> 26283 | E21: ='Donnees_USDA'!S510 -> 179736 | F21: ='Donnees_USDA'!S612 -> 158874 | G21: =D21/(E21+F21) -> 0.077620271 | N21: =D21/E21 -> 0.14623114
A23: Lecture : la production mondiale monte de 141 à 190 M sacs sans lien avec le niveau des prix. Le STU mondial suit le prix à l'envers (corrélation -0,63 avec le KC, -0,72 avec le DF, sur le logarithme des prix, 16 campagnes). Ce lien repose surtout sur 2023/24-2025/26 (STU < 8 %) : sans ces trois campagnes, -0,26 et -0,21. Définition USDA/ICO (stocks ÷ conso) en colonne N : même forme, niveau plus haut.

Sheet 2_Arabica
A1: 2 — Arabica : production, stock-to-use (stocks de fin) et stock-to-use des stocks certifiés New York, avec KC1
A2: STU des PAYS D'ORIGINE. L'USDA ne publie les stocks, la consommation et les exportations que tous cafés confondus, pays par pays. Méthode : pour chaque pays d'origine (42 exportateurs nets), stocks et utilisation sont multipliés par la part de l'espèce dans sa production de l'année, puis additionnés. Les stocks des pays consommateurs (UE, États-Unis, Japon : 51 à 77 % des stocks mondiaux, dont les stocks certifiés) ne sont pas répartis par espèce : ils ne sont que dans le STU mondial (onglet 1).
A3: Colonnes J-K : tests sans répartition. Espèce majoritaire (100 %) : même courbe que la méthode (corrélation 0,99). Pays « purs » ≥ 90 % : 0,31 — courbe différente, car le Brésil (60 à 81 % d'arabica) en est exclu.
A4: Campagne | B4: Production arabica monde (1000 sacs) | C4: Production arabica (M sacs) | D4: Stocks de fin arabica (pays d'origine) | E4: Conso + export arabica (pays d'origine) | F4: STU arabica = stocks ÷ (conso + export) | G4: Certifiés New York (M sacs, fin de campagne) | H4: STU certifié = certifiés ÷ (conso + export) | I4: KC1 (US c/lb) | J4: Test : STU espèce majoritaire (100 %) | K4: Test : STU pays purs (≥ 90 %)
A5: 2010/11 | B5: ='Donnees_USDA'!C204 -> 87943 | C5: =B5/1000 -> 87.943 | D5: =SUMPRODUCT('Donnees_USDA'!C312:C353,'Donnees_USDA'!C720:C761) -> 4474.3687 | E5: =SUMPRODUCT('Donnees_USDA'!C414:C455,'Donnees_USDA'!C720:C761)+SUMPRODUCT('Donnees_USDA'!C516:C557,'Donnees_USDA'!C720:C761) -> 90468.29 | F5: =D5/E5 -> 0.049457868 | I5: ='Prix_ICE'!I5 -> 249.66 | J5: =SUMPRODUCT('Donnees_USDA'!C312:C353,'Donnees_USDA'!C924:C965)/(SUMPRODUCT('Donnees_USDA'!C414:C455,'Donnees_USDA'!C924:C965)+SUMPRODUCT('Donnees_USDA'!C516:C557,'Donnees_USDA'!C924:C965)) -> 0.045543955 | K5: =SUMPRODUCT('Donnees_USDA'!C312:C353,'Donnees_USDA'!C1128:C1169)/(SUMPRODUCT('Donnees_USDA'!C414:C455,'Donnees_USDA'!C1128:C1169)+SUMPRODUCT('Donnees_USDA'!C516:C557,'Donnees_USDA'!C1128:C1169)) -> 0.033546553
A6: 2011/12 | B6: ='Donnees_USDA'!D204 -> 84542 | C6: =B6/1000 -> 84.542 | D6: =SUMPRODUCT('Donnees_USDA'!D312:D353,'Donnees_USDA'!D720:D761) -> 4373.0747 | E6: =SUMPRODUCT('Donnees_USDA'!D414:D455,'Donnees_USDA'!D720:D761)+SUMPRODUCT('Donnees_USDA'!D516:D557,'Donnees_USDA'!D720:D761) -> 86770.502 | F6: =D6/E6 -> 0.050398172 | G6: ='Stocks_certifies'!H6 -> 2.43 | H6: =G6*1000/E6 -> 0.028004909 | I6: ='Prix_ICE'!I6 -> 197.84167 | J6: =SUMPRODUCT('Donnees_USDA'!D312:D353,'Donnees_USDA'!D924:D965)/(SUMPRODUCT('Donnees_USDA'!D414:D455,'Donnees_USDA'!D924:D965)+SUMPRODUCT('Donnees_USDA'!D516:D557,'Donnees_USDA'!D924:D965)) -> 0.045761927 | K6: =SUMPRODUCT('Donnees_USDA'!D312:D353,'Donnees_USDA'!D1128:D1169)/(SUMPRODUCT('Donnees_USDA'!D414:D455,'Donnees_USDA'!D1128:D1169)+SUMPRODUCT('Donnees_USDA'!D516:D557,'Donnees_USDA'!D1128:D1169)) -> 0.043491809
A7: 2012/13 | B7: ='Donnees_USDA'!E204 -> 92872 | C7: =B7/1000 -> 92.872 | D7: =SUMPRODUCT('Donnees_USDA'!E312:E353,'Donnees_USDA'!E720:E761) -> 9514.9917 | E7: =SUMPRODUCT('Donnees_USDA'!E414:E455,'Donnees_USDA'!E720:E761)+SUMPRODUCT('Donnees_USDA'!E516:E557,'Donnees_USDA'!E720:E761) -> 89074.254 | F7: =D7/E7 -> 0.1068209 | G7: ='Stocks_certifies'!H7 -> 3.13 | H7: =G7*1000/E7 -> 0.035139222 | I7: ='Prix_ICE'!I7 -> 140.69833 | J7: =SUMPRODUCT('Donnees_USDA'!E312:E353,'Donnees_USDA'!E924:E965)/(SUMPRODUCT('Donnees_USDA'!E414:E455,'Donnees_USDA'!E924:E965)+SUMPRODUCT('Donnees_USDA'!E516:E557,'Donnees_USDA'!E924:E965)) -> 0.11615704 | K7: =SUMPRODUCT('Donnees_USDA'!E312:E353,'Donnees_USDA'!E1128:E1169)/(SUMPRODUCT('Donnees_USDA'!E414:E455,'Donnees_USDA'!E1128:E1169)+SUMPRODUCT('Donnees_USDA'!E516:E557,'Donnees_USDA'!E1128:E1169)) -> 0.039625263
A8: 2013/14 | B8: ='Donnees_USDA'!F204 -> 92465 | C8: =B8/1000 -> 92.465 | D8: =SUMPRODUCT('Donnees_USDA'!F312:F353,'Donnees_USDA'!F720:F761) -> 12077.864 | E8: =SUMPRODUCT('Donnees_USDA'!F414:F455,'Donnees_USDA'!F720:F761)+SUMPRODUCT('Donnees_USDA'!F516:F557,'Donnees_USDA'!F720:F761) -> 91093.228 | F8: =D8/E8 -> 0.13258795 | G8: ='Stocks_certifies'!H8 -> 2.68 | H8: =G8*1000/E8 -> 0.029420409 | I8: ='Prix_ICE'!I8 -> 161.4675 | J8: =SUMPRODUCT('Donnees_USDA'!F312:F353,'Donnees_USDA'!F924:F965)/(SUMPRODUCT('Donnees_USDA'!F414:F455,'Donnees_USDA'!F924:F965)+SUMPRODUCT('Donnees_USDA'!F516:F557,'Donnees_USDA'!F924:F965)) -> 0.14601268 | K8: =SUMPRODUCT('Donnees_USDA'!F312:F353,'Donnees_USDA'!F1128:F1169)/(SUMPRODUCT('Donnees_USDA'!F414:F455,'Donnees_USDA'!F1128:F1169)+SUMPRODUCT('Donnees_USDA'!F516:F557,'Donnees_USDA'!F1128:F1169)) -> 0.048254457
A9: 2014/15 | B9: ='Donnees_USDA'!G204 -> 86688 | C9: =B9/1000 -> 86.688 | D9: =SUMPRODUCT('Donnees_USDA'!G312:G353,'Donnees_USDA'!G720:G761) -> 9532.9157 | E9: =SUMPRODUCT('Donnees_USDA'!G414:G455,'Donnees_USDA'!G720:G761)+SUMPRODUCT('Donnees_USDA'!G516:G557,'Donnees_USDA'!G720:G761) -> 89143.069 | F9: =D9/E9 -> 0.10693951 | G9: ='Stocks_certifies'!H9 -> 2.28 | H9: =G9*1000/E9 -> 0.025576862 | I9: ='Prix_ICE'!I9 -> 154.02083 | J9: =SUMPRODUCT('Donnees_USDA'!G312:G353,'Donnees_USDA'!G924:G965)/(SUMPRODUCT('Donnees_USDA'!G414:G455,'Donnees_USDA'!G924:G965)+SUMPRODUCT('Donnees_USDA'!G516:G557,'Donnees_USDA'!G924:G965)) -> 0.11069829 | K9: =SUMPRODUCT('Donnees_USDA'!G312:G353,'Donnees_USDA'!G1128:G1169)/(SUMPRODUCT('Donnees_USDA'!G414:G455,'Donnees_USDA'!G1128:G1169)+SUMPRODUCT('Donnees_USDA'!G516:G557,'Donnees_USDA'!G1128:G1169)) -> 0.038300757
A10: 2015/16 | B10: ='Donnees_USDA'!H204 -> 86135 | C10: =B10/1000 -> 86.135 | D10: =SUMPRODUCT('Donnees_USDA'!H312:H353,'Donnees_USDA'!H720:H761) -> 5330.1739 | E10: =SUMPRODUCT('Donnees_USDA'!H414:H455,'Donnees_USDA'!H720:H761)+SUMPRODUCT('Donnees_USDA'!H516:H557,'Donnees_USDA'!H720:H761) -> 92159.87 | F10: =D10/E10 -> 0.057836169 | G10: ='Stocks_certifies'!H10 -> 1.42 | H10: =G10*1000/E10 -> 0.015408008 | I10: ='Prix_ICE'!I10 -> 131.8325 | J10: =SUMPRODUCT('Donnees_USDA'!H312:H353,'Donnees_USDA'!H924:H965)/(SUMPRODUCT('Donnees_USDA'!H414:H455,'Donnees_USDA'!H924:H965)+SUMPRODUCT('Donnees_USDA'!H516:H557,'Donnees_USDA'!H924:H965)) -> 0.048712343 | K10: =SUMPRODUCT('Donnees_USDA'!H312:H353,'Donnees_USDA'!H1128:H1169)/(SUMPRODUCT('Donnees_USDA'!H414:H455,'Donnees_USDA'!H1128:H1169)+SUMPRODUCT('Donnees_USDA'!H516:H557,'Donnees_USDA'!H1128:H1169)) -> 0.052816347
A11: 2016/17 | B11: ='Donnees_USDA'!I204 -> 101136 | C11: =B11/1000 -> 101.136 | D11: =SUMPRODUCT('Donnees_USDA'!I312:I353,'Donnees_USDA'!I720:I761) -> 6145.9664 | E11: =SUMPRODUCT('Donnees_USDA'!I414:I455,'Donnees_USDA'!I720:I761)+SUMPRODUCT('Donnees_USDA'!I516:I557,'Donnees_USDA'!I720:I761) -> 101254.66 | F11: =D11/E11 -> 0.060698111 | G11: ='Stocks_certifies'!H11 -> 2.03 | H11: =G11*1000/E11 -> 0.020048461 | I11: ='Prix_ICE'!I11 -> 143.77167 | J11: =SUMPRODUCT('Donnees_USDA'!I312:I353,'Donnees_USDA'!I924:I965)/(SUMPRODUCT('Donnees_USDA'!I414:I455,'Donnees_USDA'!I924:I965)+SUMPRODUCT('Donnees_USDA'!I516:I557,'Donnees_USDA'!I924:I965)) -> 0.057640498 | K11: =SUMPRODUCT('Donnees_USDA'!I312:I353,'Donnees_USDA'!I1128:I1169)/(SUMPRODUCT('Donnees_USDA'!I414:I455,'Donnees_USDA'!I1128:I1169)+SUMPRODUCT('Donnees_USDA'!I516:I557,'Donnees_USDA'!I1128:I1169)) -> 0.041114111
A12: 2017/18 | B12: ='Donnees_USDA'!J204 -> 95224 | C12: =B12/1000 -> 95.224 | D12: =SUMPRODUCT('Donnees_USDA'!J312:J353,'Donnees_USDA'!J720:J761) -> 5673.6869 | E12: =SUMPRODUCT('Donnees_USDA'!J414:J455,'Donnees_USDA'!J720:J761)+SUMPRODUCT('Donnees_USDA'!J516:J557,'Donnees_USDA'!J720:J761) -> 96715.596 | F12: =D12/E12 -> 0.058663619 | G12: ='Stocks_certifies'!H12 -> 2.7 | H12: =G12*1000/E12 -> 0.027916904 | I12: ='Prix_ICE'!I12 -> 120.60083 | J12: =SUMPRODUCT('Donnees_USDA'!J312:J353,'Donnees_USDA'!J924:J965)/(SUMPRODUCT('Donnees_USDA'!J414:J455,'Donnees_USDA'!J924:J965)+SUMPRODUCT('Donnees_USDA'!J516:J557,'Donnees_USDA'!J924:J965)) -> 0.056923195 | K12: =SUMPRODUCT('Donnees_USDA'!J312:J353,'Donnees_USDA'!J1128:J1169)/(SUMPRODUCT('Donnees_USDA'!J414:J455,'Donnees_USDA'!J1128:J1169)+SUMPRODUCT('Donnees_USDA'!J516:J557,'Donnees_USDA'!J1128:J1169)) -> 0.050295858
A13: 2018/19 | B13: ='Donnees_USDA'!K204 -> 104926 | C13: =B13/1000 -> 104.926 | D13: =SUMPRODUCT('Donnees_USDA'!K312:K353,'Donnees_USDA'!K720:K761) -> 6096.1861 | E13: =SUMPRODUCT('Donnees_USDA'!K414:K455,'Donnees_USDA'!K720:K761)+SUMPRODUCT('Donnees_USDA'!K516:K557,'Donnees_USDA'!K720:K761) -> 106143.21 | F13: =D13/E13 -> 0.057433592 | G13: ='Stocks_certifies'!H13 -> 2.6 | H13: =G13*1000/E13 -> 0.024495207 | I13: ='Prix_ICE'!I13 -> 104.98083 | J13: =SUMPRODUCT('Donnees_USDA'!K312:K353,'Donnees_USDA'!K924:K965)/(SUMPRODUCT('Donnees_USDA'!K414:K455,'Donnees_USDA'!K924:K965)+SUMPRODUCT('Donnees_USDA'!K516:K557,'Donnees_USDA'!K924:K965)) -> 0.058197052 | K13: =SUMPRODUCT('Donnees_USDA'!K312:K353,'Donnees_USDA'!K1128:K1169)/(SUMPRODUCT('Donnees_USDA'!K414:K455,'Donnees_USDA'!K1128:K1169)+SUMPRODUCT('Donnees_USDA'!K516:K557,'Donnees_USDA'!K1128:K1169)) -> 0.030557694
A14: 2019/20 | B14: ='Donnees_USDA'!L204 -> 94921 | C14: =B14/1000 -> 94.921 | D14: =SUMPRODUCT('Donnees_USDA'!L312:L353,'Donnees_USDA'!L720:L761) -> 4625.7279 | E14: =SUMPRODUCT('Donnees_USDA'!L414:L455,'Donnees_USDA'!L720:L761)+SUMPRODUCT('Donnees_USDA'!L516:L557,'Donnees_USDA'!L720:L761) -> 97936.031 | F14: =D14/E14 -> 0.047232135 | G14: ='Stocks_certifies'!H14 -> 1.26 | H14: =G14*1000/E14 -> 0.012865541 | I14: ='Prix_ICE'!I14 -> 113.23667 | J14: =SUMPRODUCT('Donnees_USDA'!L312:L353,'Donnees_USDA'!L924:L965)/(SUMPRODUCT('Donnees_USDA'!L414:L455,'Donnees_USDA'!L924:L965)+SUMPRODUCT('Donnees_USDA'!L516:L557,'Donnees_USDA'!L924:L965)) -> 0.042434468 | K14: =SUMPRODUCT('Donnees_USDA'!L312:L353,'Donnees_USDA'!L1128:L1169)/(SUMPRODUCT('Donnees_USDA'!L414:L455,'Donnees_USDA'!L1128:L1169)+SUMPRODUCT('Donnees_USDA'!L516:L557,'Donnees_USDA'!L1128:L1169)) -> 0.046951745
A15: 2020/21 | B15: ='Donnees_USDA'!M204 -> 102155 | C15: =B15/1000 -> 102.155 | D15: =SUMPRODUCT('Donnees_USDA'!M312:M353,'Donnees_USDA'!M720:M761) -> 6273.5205 | E15: =SUMPRODUCT('Donnees_USDA'!M414:M455,'Donnees_USDA'!M720:M761)+SUMPRODUCT('Donnees_USDA'!M516:M557,'Donnees_USDA'!M720:M761) -> 103161.87 | F15: =D15/E15 -> 0.060812395 | G15: ='Stocks_certifies'!H15 -> 2.27 | H15: =G15*1000/E15 -> 0.022004254 | I15: ='Prix_ICE'!I15 -> 143.75333 | J15: =SUMPRODUCT('Donnees_USDA'!M312:M353,'Donnees_USDA'!M924:M965)/(SUMPRODUCT('Donnees_USDA'!M414:M455,'Donnees_USDA'!M924:M965)+SUMPRODUCT('Donnees_USDA'!M516:M557,'Donnees_USDA'!M924:M965)) -> 0.058215662 | K15: =SUMPRODUCT('Donnees_USDA'!M312:M353,'Donnees_USDA'!M1128:M1169)/(SUMPRODUCT('Donnees_USDA'!M414:M455,'Donnees_USDA'!M1128:M1169)+SUMPRODUCT('Donnees_USDA'!M516:M557,'Donnees_USDA'!M1128:M1169)) -> 0.053951213
A16: 2021/22 | B16: ='Donnees_USDA'!N204 -> 87089 | C16: =B16/1000 -> 87.089 | D16: =SUMPRODUCT('Donnees_USDA'!N312:N353,'Donnees_USDA'!N720:N761) -> 2451.9278 | E16: =SUMPRODUCT('Donnees_USDA'!N414:N455,'Donnees_USDA'!N720:N761)+SUMPRODUCT('Donnees_USDA'!N516:N557,'Donnees_USDA'!N720:N761) -> 93909.889 | F16: =D16/E16 -> 0.026109367 | G16: ='Stocks_certifies'!H16 -> 0.45 | H16: =G16*1000/E16 -> 0.0047918276 | I16: ='Prix_ICE'!I16 -> 224.0875 | J16: =SUMPRODUCT('Donnees_USDA'!N312:N353,'Donnees_USDA'!N924:N965)/(SUMPRODUCT('Donnees_USDA'!N414:N455,'Donnees_USDA'!N924:N965)+SUMPRODUCT('Donnees_USDA'!N516:N557,'Donnees_USDA'!N924:N965)) -> 0.020110274 | K16: =SUMPRODUCT('Donnees_USDA'!N312:N353,'Donnees_USDA'!N1128:N1169)/(SUMPRODUCT('Donnees_USDA'!N414:N455,'Donnees_USDA'!N1128:N1169)+SUMPRODUCT('Donnees_USDA'!N516:N557,'Donnees_USDA'!N1128:N1169)) -> 0.036178619
A17: 2022/23 | B17: ='Donnees_USDA'!O204 -> 87908 | C17: =B17/1000 -> 87.908 | D17: =SUMPRODUCT('Donnees_USDA'!O312:O353,'Donnees_USDA'!O720:O761) -> 4817.1311 | E17: =SUMPRODUCT('Donnees_USDA'!O414:O455,'Donnees_USDA'!O720:O761)+SUMPRODUCT('Donnees_USDA'!O516:O557,'Donnees_USDA'!O720:O761) -> 88807.386 | F17: =D17/E17 -> 0.05424246 | G17: ='Stocks_certifies'!H17 -> 0.49 | H17: =G17*1000/E17 -> 0.0055175591 | I17: ='Prix_ICE'!I17 -> 171.19 | J17: =SUMPRODUCT('Donnees_USDA'!O312:O353,'Donnees_USDA'!O924:O965)/(SUMPRODUCT('Donnees_USDA'!O414:O455,'Donnees_USDA'!O924:O965)+SUMPRODUCT('Donnees_USDA'!O516:O557,'Donnees_USDA'!O924:O965)) -> 0.058545245 | K17: =SUMPRODUCT('Donnees_USDA'!O312:O353,'Donnees_USDA'!O1128:O1169)/(SUMPRODUCT('Donnees_USDA'!O414:O455,'Donnees_USDA'!O1128:O1169)+SUMPRODUCT('Donnees_USDA'!O516:O557,'Donnees_USDA'!O1128:O1169)) -> 0.036544686
A18: 2023/24 | B18: ='Donnees_USDA'!P204 -> 97160 | C18: =B18/1000 -> 97.16 | D18: =SUMPRODUCT('Donnees_USDA'!P312:P353,'Donnees_USDA'!P720:P761) -> 3083.2351 | E18: =SUMPRODUCT('Donnees_USDA'!P414:P455,'Donnees_USDA'!P720:P761)+SUMPRODUCT('Donnees_USDA'!P516:P557,'Donnees_USDA'!P720:P761) -> 101400.76 | F18: =D18/E18 -> 0.030406431 | G18: ='Stocks_certifies'!H18 -> 0.87 | H18: =G18*1000/E18 -> 0.0085798177 | I18: ='Prix_ICE'!I18 -> 204.00167 | J18: =SUMPRODUCT('Donnees_USDA'!P312:P353,'Donnees_USDA'!P924:P965)/(SUMPRODUCT('Donnees_USDA'!P414:P455,'Donnees_USDA'!P924:P965)+SUMPRODUCT('Donnees_USDA'!P516:P557,'Donnees_USDA'!P924:P965)) -> 0.029703717 | K18: =SUMPRODUCT('Donnees_USDA'!P312:P353,'Donnees_USDA'!P1128:P1169)/(SUMPRODUCT('Donnees_USDA'!P414:P455,'Donnees_USDA'!P1128:P1169)+SUMPRODUCT('Donnees_USDA'!P516:P557,'Donnees_USDA'!P1128:P1169)) -> 0.032614717
A19: 2024/25 | B19: ='Donnees_USDA'!Q204 -> 102276 | C19: =B19/1000 -> 102.276 | D19: =SUMPRODUCT('Donnees_USDA'!Q312:Q353,'Donnees_USDA'!Q720:Q761) -> 2712.5481 | E19: =SUMPRODUCT('Donnees_USDA'!Q414:Q455,'Donnees_USDA'!Q720:Q761)+SUMPRODUCT('Donnees_USDA'!Q516:Q557,'Donnees_USDA'!Q720:Q761) -> 105510.21 | F19: =D19/E19 -> 0.025708868 | G19: ='Stocks_certifies'!H19 -> 0.62 | H19: =G19*1000/E19 -> 0.0058762083 | I19: ='Prix_ICE'!I19 -> 333.06 | J19: =SUMPRODUCT('Donnees_USDA'!Q312:Q353,'Donnees_USDA'!Q924:Q965)/(SUMPRODUCT('Donnees_USDA'!Q414:Q455,'Donnees_USDA'!Q924:Q965)+SUMPRODUCT('Donnees_USDA'!Q516:Q557,'Donnees_USDA'!Q924:Q965)) -> 0.022630314 | K19: =SUMPRODUCT('Donnees_USDA'!Q312:Q353,'Donnees_USDA'!Q1128:Q1169)/(SUMPRODUCT('Donnees_USDA'!Q414:Q455,'Donnees_USDA'!Q1128:Q1169)+SUMPRODUCT('Donnees_USDA'!Q516:Q557,'Donnees_USDA'!Q1128:Q1169)) -> 0.03248559
A20: 2025/26 | B20: ='Donnees_USDA'!R204 -> 94440 | C20: =B20/1000 -> 94.44 | D20: =SUMPRODUCT('Donnees_USDA'!R312:R353,'Donnees_USDA'!R720:R761) -> 4672.9401 | E20: =SUMPRODUCT('Donnees_USDA'!R414:R455,'Donnees_USDA'!R720:R761)+SUMPRODUCT('Donnees_USDA'!R516:R557,'Donnees_USDA'!R720:R761) -> 96609.532 | F20: =D20/E20 -> 0.048369348 | G20: ='Stocks_certifies'!H20 -> 0.24 | H20: =G20*1000/E20 -> 0.0024842269 | I20: ='Prix_ICE'!I20 -> 312.21 | J20: =SUMPRODUCT('Donnees_USDA'!R312:R353,'Donnees_USDA'!R924:R965)/(SUMPRODUCT('Donnees_USDA'!R414:R455,'Donnees_USDA'!R924:R965)+SUMPRODUCT('Donnees_USDA'!R516:R557,'Donnees_USDA'!R924:R965)) -> 0.051171404 | K20: =SUMPRODUCT('Donnees_USDA'!R312:R353,'Donnees_USDA'!R1128:R1169)/(SUMPRODUCT('Donnees_USDA'!R414:R455,'Donnees_USDA'!R1128:R1169)+SUMPRODUCT('Donnees_USDA'!R516:R557,'Donnees_USDA'!R1128:R1169)) -> 0.041244649
A21: 2026/27 (prév.) | B21: ='Donnees_USDA'!S204 -> 105867 | C21: =B21/1000 -> 105.867 | D21: =SUMPRODUCT('Donnees_USDA'!S312:S353,'Donnees_USDA'!S720:S761) -> 5169.044 | E21: =SUMPRODUCT('Donnees_USDA'!S414:S455,'Donnees_USDA'!S720:S761)+SUMPRODUCT('Donnees_USDA'!S516:S557,'Donnees_USDA'!S720:S761) -> 109453.09 | F21: =D21/E21 -> 0.047226115 | J21: =SUMPRODUCT('Donnees_USDA'!S312:S353,'Donnees_USDA'!S924:S965)/(SUMPRODUCT('Donnees_USDA'!S414:S455,'Donnees_USDA'!S924:S965)+SUMPRODUCT('Donnees_USDA'!S516:S557,'Donnees_USDA'!S924:S965)) -> 0.050486097 | K21: =SUMPRODUCT('Donnees_USDA'!S312:S353,'Donnees_USDA'!S1128:S1169)/(SUMPRODUCT('Donnees_USDA'!S414:S455,'Donnees_USDA'!S1128:S1169)+SUMPRODUCT('Donnees_USDA'!S516:S557,'Donnees_USDA'!S1128:S1169)) -> 0.039105249
A23: Corrélations avec le logarithme du KC (16 campagnes ; 15 pour les certifiés) : production -0,14, STU stocks de fin -0,39, STU certifié -0,61. Le lien certifiés / KC vient surtout de la tendance commune (sans tendance -0,34), un peu du point 2025/26 (sans lui -0,51, toujours le plus fort). Le KC réagit à la récolte arabica de la campagne suivante (-0,49), pas à celle en cours (-0,08).

Sheet 3_Robusta
A1: 3 — Robusta : production, stock-to-use (stocks de fin) et stock-to-use des stocks certifiés Londres, avec DF1
A2: STU des PAYS D'ORIGINE. L'USDA ne publie les stocks, la consommation et les exportations que tous cafés confondus, pays par pays. Méthode : pour chaque pays d'origine (42 exportateurs nets), stocks et utilisation sont multipliés par la part de l'espèce dans sa production de l'année, puis additionnés. Les stocks des pays consommateurs (UE, États-Unis, Japon : 51 à 77 % des stocks mondiaux, dont les stocks certifiés) ne sont pas répartis par espèce : ils ne sont que dans le STU mondial (onglet 1).
A3: Colonnes J-K : tests sans répartition. Espèce majoritaire (100 %) : même courbe que la méthode (corrélation 0,94). Pays « purs » ≥ 90 % : 0,88 — même forme.
A4: Campagne | B4: Production robusta monde (1000 sacs) | C4: Production robusta (M sacs) | D4: Stocks de fin robusta (pays d'origine) | E4: Conso + export robusta (pays d'origine) | F4: STU robusta = stocks ÷ (conso + export) | G4: Certifiés Londres (M sacs, fin de campagne) | H4: STU certifié = certifiés ÷ (conso + export) | I4: DF1 (US$/t) | J4: Test : STU espèce majoritaire (100 %) | K4: Test : STU pays purs (≥ 90 %)
A5: 2010/11 | B5: ='Donnees_USDA'!C306 -> 53466 | C5: =B5/1000 -> 53.466 | D5: =SUMPRODUCT('Donnees_USDA'!C312:C353,'Donnees_USDA'!C822:C863) -> 3853.6313 | E5: =SUMPRODUCT('Donnees_USDA'!C414:C455,'Donnees_USDA'!C822:C863)+SUMPRODUCT('Donnees_USDA'!C516:C557,'Donnees_USDA'!C822:C863) -> 58714.71 | F5: =D5/E5 -> 0.065633149 | I5: ='Prix_ICE'!K5 -> 2219.0813 | J5: =SUMPRODUCT('Donnees_USDA'!C312:C353,'Donnees_USDA'!C1026:C1067)/(SUMPRODUCT('Donnees_USDA'!C414:C455,'Donnees_USDA'!C1026:C1067)+SUMPRODUCT('Donnees_USDA'!C516:C557,'Donnees_USDA'!C1026:C1067)) -> 0.076186861 | K5: =SUMPRODUCT('Donnees_USDA'!C312:C353,'Donnees_USDA'!C1230:C1271)/(SUMPRODUCT('Donnees_USDA'!C414:C455,'Donnees_USDA'!C1230:C1271)+SUMPRODUCT('Donnees_USDA'!C516:C557,'Donnees_USDA'!C1230:C1271)) -> 0.047679386
A6: 2011/12 | B6: ='Donnees_USDA'!D306 -> 60295 | C6: =B6/1000 -> 60.295 | D6: =SUMPRODUCT('Donnees_USDA'!D312:D353,'Donnees_USDA'!D822:D863) -> 3466.9253 | E6: =SUMPRODUCT('Donnees_USDA'!D414:D455,'Donnees_USDA'!D822:D863)+SUMPRODUCT('Donnees_USDA'!D516:D557,'Donnees_USDA'!D822:D863) -> 64830.498 | F6: =D6/E6 -> 0.053476765 | G6: ='Stocks_certifies'!I6 -> 2.17 | H6: =G6*1000/E6 -> 0.033471901 | I6: ='Prix_ICE'!K6 -> 2014.676 | J6: =SUMPRODUCT('Donnees_USDA'!D312:D353,'Donnees_USDA'!D1026:D1067)/(SUMPRODUCT('Donnees_USDA'!D414:D455,'Donnees_USDA'!D1026:D1067)+SUMPRODUCT('Donnees_USDA'!D516:D557,'Donnees_USDA'!D1026:D1067)) -> 0.062336994 | K6: =SUMPRODUCT('Donnees_USDA'!D312:D353,'Donnees_USDA'!D1230:D1271)/(SUMPRODUCT('Donnees_USDA'!D414:D455,'Donnees_USDA'!D1230:D1271)+SUMPRODUCT('Donnees_USDA'!D516:D557,'Donnees_USDA'!D1230:D1271)) -> 0.03642298
A7: 2012/13 | B7: ='Donnees_USDA'!E306 -> 65146 | C7: =B7/1000 -> 65.146 | D7: =SUMPRODUCT('Donnees_USDA'!E312:E353,'Donnees_USDA'!E822:E863) -> 6411.0083 | E7: =SUMPRODUCT('Donnees_USDA'!E414:E455,'Donnees_USDA'!E822:E863)+SUMPRODUCT('Donnees_USDA'!E516:E557,'Donnees_USDA'!E822:E863) -> 67498.746 | F7: =D7/E7 -> 0.094979666 | G7: ='Stocks_certifies'!I7 -> 1.01 | H7: =G7*1000/E7 -> 0.014963241 | I7: ='Prix_ICE'!K7 -> 1950.6685 | J7: =SUMPRODUCT('Donnees_USDA'!E312:E353,'Donnees_USDA'!E1026:E1067)/(SUMPRODUCT('Donnees_USDA'!E414:E455,'Donnees_USDA'!E1026:E1067)+SUMPRODUCT('Donnees_USDA'!E516:E557,'Donnees_USDA'!E1026:E1067)) -> 0.077460209 | K7: =SUMPRODUCT('Donnees_USDA'!E312:E353,'Donnees_USDA'!E1230:E1271)/(SUMPRODUCT('Donnees_USDA'!E414:E455,'Donnees_USDA'!E1230:E1271)+SUMPRODUCT('Donnees_USDA'!E516:E557,'Donnees_USDA'!E1230:E1271)) -> 0.058680329
A8: 2013/14 | B8: ='Donnees_USDA'!F306 -> 67589 | C8: =B8/1000 -> 67.589 | D8: =SUMPRODUCT('Donnees_USDA'!F312:F353,'Donnees_USDA'!F822:F863) -> 7326.1359 | E8: =SUMPRODUCT('Donnees_USDA'!F414:F455,'Donnees_USDA'!F822:F863)+SUMPRODUCT('Donnees_USDA'!F516:F557,'Donnees_USDA'!F822:F863) -> 71812.772 | F8: =D8/E8 -> 0.10201717 | G8: ='Stocks_certifies'!I8 -> 1.88 | H8: =G8*1000/E8 -> 0.026179187 | I8: ='Prix_ICE'!K8 -> 1893.2013 | J8: =SUMPRODUCT('Donnees_USDA'!F312:F353,'Donnees_USDA'!F1026:F1067)/(SUMPRODUCT('Donnees_USDA'!F414:F455,'Donnees_USDA'!F1026:F1067)+SUMPRODUCT('Donnees_USDA'!F516:F557,'Donnees_USDA'!F1026:F1067)) -> 0.075683656 | K8: =SUMPRODUCT('Donnees_USDA'!F312:F353,'Donnees_USDA'!F1230:F1271)/(SUMPRODUCT('Donnees_USDA'!F414:F455,'Donnees_USDA'!F1230:F1271)+SUMPRODUCT('Donnees_USDA'!F516:F557,'Donnees_USDA'!F1230:F1271)) -> 0.057172369
A9: 2014/15 | B9: ='Donnees_USDA'!G306 -> 67108 | C9: =B9/1000 -> 67.108 | D9: =SUMPRODUCT('Donnees_USDA'!G312:G353,'Donnees_USDA'!G822:G863) -> 11561.084 | E9: =SUMPRODUCT('Donnees_USDA'!G414:G455,'Donnees_USDA'!G822:G863)+SUMPRODUCT('Donnees_USDA'!G516:G557,'Donnees_USDA'!G822:G863) -> 68976.931 | F9: =D9/E9 -> 0.16760798 | G9: ='Stocks_certifies'!I9 -> 3.43 | H9: =G9*1000/E9 -> 0.04972677 | I9: ='Prix_ICE'!K9 -> 1849.9172 | J9: =SUMPRODUCT('Donnees_USDA'!G312:G353,'Donnees_USDA'!G1026:G1067)/(SUMPRODUCT('Donnees_USDA'!G414:G455,'Donnees_USDA'!G1026:G1067)+SUMPRODUCT('Donnees_USDA'!G516:G557,'Donnees_USDA'!G1026:G1067)) -> 0.17499373 | K9: =SUMPRODUCT('Donnees_USDA'!G312:G353,'Donnees_USDA'!G1230:G1271)/(SUMPRODUCT('Donnees_USDA'!G414:G455,'Donnees_USDA'!G1230:G1271)+SUMPRODUCT('Donnees_USDA'!G516:G557,'Donnees_USDA'!G1230:G1271)) -> 0.19317702
A10: 2015/16 | B10: ='Donnees_USDA'!H306 -> 66294 | C10: =B10/1000 -> 66.294 | D10: =SUMPRODUCT('Donnees_USDA'!H312:H353,'Donnees_USDA'!H822:H863) -> 7121.8261 | E10: =SUMPRODUCT('Donnees_USDA'!H414:H455,'Donnees_USDA'!H822:H863)+SUMPRODUCT('Donnees_USDA'!H516:H557,'Donnees_USDA'!H822:H863) -> 75076.13 | F10: =D10/E10 -> 0.094861392 | G10: ='Stocks_certifies'!I10 -> 2.32 | H10: =G10*1000/E10 -> 0.030901966 | I10: ='Prix_ICE'!K10 -> 1632.9272 | J10: =SUMPRODUCT('Donnees_USDA'!H312:H353,'Donnees_USDA'!H1026:H1067)/(SUMPRODUCT('Donnees_USDA'!H414:H455,'Donnees_USDA'!H1026:H1067)+SUMPRODUCT('Donnees_USDA'!H516:H557,'Donnees_USDA'!H1026:H1067)) -> 0.11471891 | K10: =SUMPRODUCT('Donnees_USDA'!H312:H353,'Donnees_USDA'!H1230:H1271)/(SUMPRODUCT('Donnees_USDA'!H414:H455,'Donnees_USDA'!H1230:H1271)+SUMPRODUCT('Donnees_USDA'!H516:H557,'Donnees_USDA'!H1230:H1271)) -> 0.10572775
A11: 2016/17 | B11: ='Donnees_USDA'!I306 -> 59943 | C11: =B11/1000 -> 59.943 | D11: =SUMPRODUCT('Donnees_USDA'!I312:I353,'Donnees_USDA'!I822:I863) -> 5186.0336 | E11: =SUMPRODUCT('Donnees_USDA'!I414:I455,'Donnees_USDA'!I822:I863)+SUMPRODUCT('Donnees_USDA'!I516:I557,'Donnees_USDA'!I822:I863) -> 66386.343 | F11: =D11/E11 -> 0.078118984 | G11: ='Stocks_certifies'!I11 -> 2.52 | H11: =G11*1000/E11 -> 0.037959615 | I11: ='Prix_ICE'!K11 -> 2097.1105 | J11: =SUMPRODUCT('Donnees_USDA'!I312:I353,'Donnees_USDA'!I1026:I1067)/(SUMPRODUCT('Donnees_USDA'!I414:I455,'Donnees_USDA'!I1026:I1067)+SUMPRODUCT('Donnees_USDA'!I516:I557,'Donnees_USDA'!I1026:I1067)) -> 0.084787665 | K11: =SUMPRODUCT('Donnees_USDA'!I312:I353,'Donnees_USDA'!I1230:I1271)/(SUMPRODUCT('Donnees_USDA'!I414:I455,'Donnees_USDA'!I1230:I1271)+SUMPRODUCT('Donnees_USDA'!I516:I557,'Donnees_USDA'!I1230:I1271)) -> 0.074517992
A12: 2017/18 | B12: ='Donnees_USDA'!J306 -> 64590 | C12: =B12/1000 -> 64.59 | D12: =SUMPRODUCT('Donnees_USDA'!J312:J353,'Donnees_USDA'!J822:J863) -> 3035.3131 | E12: =SUMPRODUCT('Donnees_USDA'!J414:J455,'Donnees_USDA'!J822:J863)+SUMPRODUCT('Donnees_USDA'!J516:J557,'Donnees_USDA'!J822:J863) -> 72802.404 | F12: =D12/E12 -> 0.041692485 | G12: ='Stocks_certifies'!I12 -> 1.51 | H12: =G12*1000/E12 -> 0.020741073 | I12: ='Prix_ICE'!K12 -> 1725.8888 | J12: =SUMPRODUCT('Donnees_USDA'!J312:J353,'Donnees_USDA'!J1026:J1067)/(SUMPRODUCT('Donnees_USDA'!J414:J455,'Donnees_USDA'!J1026:J1067)+SUMPRODUCT('Donnees_USDA'!J516:J557,'Donnees_USDA'!J1026:J1067)) -> 0.042498696 | K12: =SUMPRODUCT('Donnees_USDA'!J312:J353,'Donnees_USDA'!J1230:J1271)/(SUMPRODUCT('Donnees_USDA'!J414:J455,'Donnees_USDA'!J1230:J1271)+SUMPRODUCT('Donnees_USDA'!J516:J557,'Donnees_USDA'!J1230:J1271)) -> 0.017069206
A13: 2018/19 | B13: ='Donnees_USDA'!K306 -> 70930 | C13: =B13/1000 -> 70.93 | D13: =SUMPRODUCT('Donnees_USDA'!K312:K353,'Donnees_USDA'!K822:K863) -> 5115.8139 | E13: =SUMPRODUCT('Donnees_USDA'!K414:K455,'Donnees_USDA'!K822:K863)+SUMPRODUCT('Donnees_USDA'!K516:K557,'Donnees_USDA'!K822:K863) -> 75251.786 | F13: =D13/E13 -> 0.067982625 | G13: ='Stocks_certifies'!I13 -> 2.62 | H13: =G13*1000/E13 -> 0.034816449 | I13: ='Prix_ICE'!K13 -> 1488.8368 | J13: =SUMPRODUCT('Donnees_USDA'!K312:K353,'Donnees_USDA'!K1026:K1067)/(SUMPRODUCT('Donnees_USDA'!K414:K455,'Donnees_USDA'!K1026:K1067)+SUMPRODUCT('Donnees_USDA'!K516:K557,'Donnees_USDA'!K1026:K1067)) -> 0.068678726 | K13: =SUMPRODUCT('Donnees_USDA'!K312:K353,'Donnees_USDA'!K1230:K1271)/(SUMPRODUCT('Donnees_USDA'!K414:K455,'Donnees_USDA'!K1230:K1271)+SUMPRODUCT('Donnees_USDA'!K516:K557,'Donnees_USDA'!K1230:K1271)) -> 0.014505271
A14: 2019/20 | B14: ='Donnees_USDA'!L306 -> 74109 | C14: =B14/1000 -> 74.109 | D14: =SUMPRODUCT('Donnees_USDA'!L312:L353,'Donnees_USDA'!L822:L863) -> 5997.2721 | E14: =SUMPRODUCT('Donnees_USDA'!L414:L455,'Donnees_USDA'!L822:L863)+SUMPRODUCT('Donnees_USDA'!L516:L557,'Donnees_USDA'!L822:L863) -> 79117.969 | F14: =D14/E14 -> 0.075801644 | G14: ='Stocks_certifies'!I14 -> 1.85 | H14: =G14*1000/E14 -> 0.023382805 | I14: ='Prix_ICE'!K14 -> 1305.5959 | J14: =SUMPRODUCT('Donnees_USDA'!L312:L353,'Donnees_USDA'!L1026:L1067)/(SUMPRODUCT('Donnees_USDA'!L414:L455,'Donnees_USDA'!L1026:L1067)+SUMPRODUCT('Donnees_USDA'!L516:L557,'Donnees_USDA'!L1026:L1067)) -> 0.091597502 | K14: =SUMPRODUCT('Donnees_USDA'!L312:L353,'Donnees_USDA'!L1230:L1271)/(SUMPRODUCT('Donnees_USDA'!L414:L455,'Donnees_USDA'!L1230:L1271)+SUMPRODUCT('Donnees_USDA'!L516:L557,'Donnees_USDA'!L1230:L1271)) -> 0.055091431
A15: 2020/21 | B15: ='Donnees_USDA'!M306 -> 74439 | C15: =B15/1000 -> 74.439 | D15: =SUMPRODUCT('Donnees_USDA'!M312:M353,'Donnees_USDA'!M822:M863) -> 7449.4795 | E15: =SUMPRODUCT('Donnees_USDA'!M414:M455,'Donnees_USDA'!M822:M863)+SUMPRODUCT('Donnees_USDA'!M516:M557,'Donnees_USDA'!M822:M863) -> 78096.128 | F15: =D15/E15 -> 0.09538859 | G15: ='Stocks_certifies'!I15 -> 2.1 | H15: =G15*1000/E15 -> 0.026889937 | I15: ='Prix_ICE'!K15 -> 1540.9394 | J15: =SUMPRODUCT('Donnees_USDA'!M312:M353,'Donnees_USDA'!M1026:M1067)/(SUMPRODUCT('Donnees_USDA'!M414:M455,'Donnees_USDA'!M1026:M1067)+SUMPRODUCT('Donnees_USDA'!M516:M557,'Donnees_USDA'!M1026:M1067)) -> 0.10901256 | K15: =SUMPRODUCT('Donnees_USDA'!M312:M353,'Donnees_USDA'!M1230:M1271)/(SUMPRODUCT('Donnees_USDA'!M414:M455,'Donnees_USDA'!M1230:M1271)+SUMPRODUCT('Donnees_USDA'!M516:M557,'Donnees_USDA'!M1230:M1271)) -> 0.10422896
A16: 2021/22 | B16: ='Donnees_USDA'!N306 -> 77955 | C16: =B16/1000 -> 77.955 | D16: =SUMPRODUCT('Donnees_USDA'!N312:N353,'Donnees_USDA'!N822:N863) -> 5254.0722 | E16: =SUMPRODUCT('Donnees_USDA'!N414:N455,'Donnees_USDA'!N822:N863)+SUMPRODUCT('Donnees_USDA'!N516:N557,'Donnees_USDA'!N822:N863) -> 86121.111 | F16: =D16/E16 -> 0.061007948 | G16: ='Stocks_certifies'!I16 -> 1.59 | H16: =G16*1000/E16 -> 0.018462372 | I16: ='Prix_ICE'!K16 -> 2150.1501 | J16: =SUMPRODUCT('Donnees_USDA'!N312:N353,'Donnees_USDA'!N1026:N1067)/(SUMPRODUCT('Donnees_USDA'!N414:N455,'Donnees_USDA'!N1026:N1067)+SUMPRODUCT('Donnees_USDA'!N516:N557,'Donnees_USDA'!N1026:N1067)) -> 0.080724608 | K16: =SUMPRODUCT('Donnees_USDA'!N312:N353,'Donnees_USDA'!N1230:N1271)/(SUMPRODUCT('Donnees_USDA'!N414:N455,'Donnees_USDA'!N1230:N1271)+SUMPRODUCT('Donnees_USDA'!N516:N557,'Donnees_USDA'!N1230:N1271)) -> 0.089770407
A17: 2022/23 | B17: ='Donnees_USDA'!O306 -> 76621 | C17: =B17/1000 -> 76.621 | D17: =SUMPRODUCT('Donnees_USDA'!O312:O353,'Donnees_USDA'!O822:O863) -> 3783.8689 | E17: =SUMPRODUCT('Donnees_USDA'!O414:O455,'Donnees_USDA'!O822:O863)+SUMPRODUCT('Donnees_USDA'!O516:O557,'Donnees_USDA'!O822:O863) -> 83350.614 | F17: =D17/E17 -> 0.045397013 | G17: ='Stocks_certifies'!I17 -> 0.73 | H17: =G17*1000/E17 -> 0.0087581838 | I17: ='Prix_ICE'!K17 -> 2217.0787 | J17: =SUMPRODUCT('Donnees_USDA'!O312:O353,'Donnees_USDA'!O1026:O1067)/(SUMPRODUCT('Donnees_USDA'!O414:O455,'Donnees_USDA'!O1026:O1067)+SUMPRODUCT('Donnees_USDA'!O516:O557,'Donnees_USDA'!O1026:O1067)) -> 0.036237681 | K17: =SUMPRODUCT('Donnees_USDA'!O312:O353,'Donnees_USDA'!O1230:O1271)/(SUMPRODUCT('Donnees_USDA'!O414:O455,'Donnees_USDA'!O1230:O1271)+SUMPRODUCT('Donnees_USDA'!O516:O557,'Donnees_USDA'!O1230:O1271)) -> 0.021848958
A18: 2023/24 | B18: ='Donnees_USDA'!P306 -> 72175 | C18: =B18/1000 -> 72.175 | D18: =SUMPRODUCT('Donnees_USDA'!P312:P353,'Donnees_USDA'!P822:P863) -> 2427.7649 | E18: =SUMPRODUCT('Donnees_USDA'!P414:P455,'Donnees_USDA'!P822:P863)+SUMPRODUCT('Donnees_USDA'!P516:P557,'Donnees_USDA'!P822:P863) -> 79542.244 | F18: =D18/E18 -> 0.030521705 | G18: ='Stocks_certifies'!I18 -> 0.74 | H18: =G18*1000/E18 -> 0.0093032326 | I18: ='Prix_ICE'!K18 -> 3504.2477 | J18: =SUMPRODUCT('Donnees_USDA'!P312:P353,'Donnees_USDA'!P1026:P1067)/(SUMPRODUCT('Donnees_USDA'!P414:P455,'Donnees_USDA'!P1026:P1067)+SUMPRODUCT('Donnees_USDA'!P516:P557,'Donnees_USDA'!P1026:P1067)) -> 0.031918004 | K18: =SUMPRODUCT('Donnees_USDA'!P312:P353,'Donnees_USDA'!P1230:P1271)/(SUMPRODUCT('Donnees_USDA'!P414:P455,'Donnees_USDA'!P1230:P1271)+SUMPRODUCT('Donnees_USDA'!P516:P557,'Donnees_USDA'!P1230:P1271)) -> 0.025105902
A19: 2024/25 | B19: ='Donnees_USDA'!Q306 -> 74540 | C19: =B19/1000 -> 74.54 | D19: =SUMPRODUCT('Donnees_USDA'!Q312:Q353,'Donnees_USDA'!Q822:Q863) -> 2459.4519 | E19: =SUMPRODUCT('Donnees_USDA'!Q414:Q455,'Donnees_USDA'!Q822:Q863)+SUMPRODUCT('Donnees_USDA'!Q516:Q557,'Donnees_USDA'!Q822:Q863) -> 80313.786 | F19: =D19/E19 -> 0.030623035 | G19: ='Stocks_certifies'!I19 -> 1.08 | H19: =G19*1000/E19 -> 0.013447256 | I19: ='Prix_ICE'!K19 -> 4701.7435 | J19: =SUMPRODUCT('Donnees_USDA'!Q312:Q353,'Donnees_USDA'!Q1026:Q1067)/(SUMPRODUCT('Donnees_USDA'!Q414:Q455,'Donnees_USDA'!Q1026:Q1067)+SUMPRODUCT('Donnees_USDA'!Q516:Q557,'Donnees_USDA'!Q1026:Q1067)) -> 0.037862793 | K19: =SUMPRODUCT('Donnees_USDA'!Q312:Q353,'Donnees_USDA'!Q1230:Q1271)/(SUMPRODUCT('Donnees_USDA'!Q414:Q455,'Donnees_USDA'!Q1230:Q1271)+SUMPRODUCT('Donnees_USDA'!Q516:Q557,'Donnees_USDA'!Q1230:Q1271)) -> 0.030121982
A20: 2025/26 | B20: ='Donnees_USDA'!R306 -> 84390 | C20: =B20/1000 -> 84.39 | D20: =SUMPRODUCT('Donnees_USDA'!R312:R353,'Donnees_USDA'!R822:R863) -> 3597.0599 | E20: =SUMPRODUCT('Donnees_USDA'!R414:R455,'Donnees_USDA'!R822:R863)+SUMPRODUCT('Donnees_USDA'!R516:R557,'Donnees_USDA'!R822:R863) -> 89103.468 | F20: =D20/E20 -> 0.040369471 | G20: ='Stocks_certifies'!I20 -> 0.83 | H20: =G20*1000/E20 -> 0.0093150134 | I20: ='Prix_ICE'!K20 -> 3788.4636 | J20: =SUMPRODUCT('Donnees_USDA'!R312:R353,'Donnees_USDA'!R1026:R1067)/(SUMPRODUCT('Donnees_USDA'!R414:R455,'Donnees_USDA'!R1026:R1067)+SUMPRODUCT('Donnees_USDA'!R516:R557,'Donnees_USDA'!R1026:R1067)) -> 0.033456395 | K20: =SUMPRODUCT('Donnees_USDA'!R312:R353,'Donnees_USDA'!R1230:R1271)/(SUMPRODUCT('Donnees_USDA'!R414:R455,'Donnees_USDA'!R1230:R1271)+SUMPRODUCT('Donnees_USDA'!R516:R557,'Donnees_USDA'!R1230:R1271)) -> 0.017164923
A21: 2026/27 (prév.) | B21: ='Donnees_USDA'!S306 -> 83800 | C21: =B21/1000 -> 83.8 | D21: =SUMPRODUCT('Donnees_USDA'!S312:S353,'Donnees_USDA'!S822:S863) -> 3113.956 | E21: =SUMPRODUCT('Donnees_USDA'!S414:S455,'Donnees_USDA'!S822:S863)+SUMPRODUCT('Donnees_USDA'!S516:S557,'Donnees_USDA'!S822:S863) -> 90236.914 | F21: =D21/E21 -> 0.034508671 | J21: =SUMPRODUCT('Donnees_USDA'!S312:S353,'Donnees_USDA'!S1026:S1067)/(SUMPRODUCT('Donnees_USDA'!S414:S455,'Donnees_USDA'!S1026:S1067)+SUMPRODUCT('Donnees_USDA'!S516:S557,'Donnees_USDA'!S1026:S1067)) -> 0.024861446 | K21: =SUMPRODUCT('Donnees_USDA'!S312:S353,'Donnees_USDA'!S1230:S1271)/(SUMPRODUCT('Donnees_USDA'!S414:S455,'Donnees_USDA'!S1230:S1271)+SUMPRODUCT('Donnees_USDA'!S516:S557,'Donnees_USDA'!S1230:S1271)) -> 0.011879023
A23: Corrélations avec le logarithme du DF (16 campagnes ; 15 pour les certifiés) : production (niveau) 0,31, STU stocks de fin -0,54, STU certifié -0,56. En variations d'une campagne à l'autre, une récolte robusta plus faible fait monter le DF la même campagne (-0,62) (significatif).

Sheet 4_STU_pays
A1: 4 — Stock-to-use de chaque pays d'origine = stocks de fin ÷ (consommation domestique + exportations), USDA
A2: Couleurs par ligne : rouge = bas pour ce pays, vert = haut. Colonnes de droite : ce qui fait l'importance d'un pays pour le prix (taille, chocs, coussin).
A4: Pays | B4: Part arabica 26/27 | C4: 2010/11 | D4: 2011/12 | E4: 2012/13 | F4: 2013/14 | G4: 2014/15 | H4: 2015/16 | I4: 2016/17 | J4: 2017/18 | K4: 2018/19 | L4: 2019/20 | M4: 2020/21 | N4: 2021/22 | O4: 2022/23 | P4: 2023/24 | Q4: 2024/25 | R4: 2025/26 | S4: 2026/27 | T4: STU moyen 2010-26 | U4: Part de la production mondiale 26/27 | V4: Part des exportations mondiales 26/27 | W4: Part des stocks des pays d'origine 26/27 | X4: Stock en semaines d'exportation 26/27 | Y4: Poids dans les chocs de production (2011-26) | Z4: Poids dans les variations de stocks (2011-26) | AA4: r STU / KC | AB4: r STU / DF
A5: Brésil | B5: ='Donnees_USDA'!S720 -> 0.66063978 | C5: =IF(('Donnees_USDA'!C414+'Donnees_USDA'!C516)>0,'Donnees_USDA'!C312/('Donnees_USDA'!C414+'Donnees_USDA'!C516),"") -> 0.053389675 | D5: =IF(('Donnees_USDA'!D414+'Donnees_USDA'!D516)>0,'Donnees_USDA'!D312/('Donnees_USDA'!D414+'Donnees_USDA'!D516),"") -> 0.044878479 | E5: =IF(('Donnees_USDA'!E414+'Donnees_USDA'!E516)>0,'Donnees_USDA'!E312/('Donnees_USDA'!E414+'Donnees_USDA'!E516),"") -> 0.17860942 | F5: =IF(('Donnees_USDA'!F414+'Donnees_USDA'!F516)>0,'Donnees_USDA'!F312/('Donnees_USDA'!F414+'Donnees_USDA'!F516),"") -> 0.21977335 | G5: =IF(('Donnees_USDA'!G414+'Donnees_USDA'!G516)>0,'Donnees_USDA'!G312/('Donnees_USDA'!G414+'Donnees_USDA'!G516),"") -> 0.16326566 | H5: =IF(('Donnees_USDA'!H414+'Donnees_USDA'!H516)>0,'Donnees_USDA'!H312/('Donnees_USDA'!H414+'Donnees_USDA'!H516),"") -> 0.042058229 | I5: =IF(('Donnees_USDA'!I414+'Donnees_USDA'!I516)>0,'Donnees_USDA'!I312/('Donnees_USDA'!I414+'Donnees_USDA'!I516),"") -> 0.069974043 | J5: =IF(('Donnees_USDA'!J414+'Donnees_USDA'!J516)>0,'Donnees_USDA'!J312/('Donnees_USDA'!J414+'Donnees_USDA'!J516),"") -> 0.058913644 | ... S5: =IF(('Donnees_USDA'!S414+'Donnees_USDA'!S516)>0,'Donnees_USDA'!S312/('Donnees_USDA'!S414+'Donnees_USDA'!S516),"") -> 0.061922754 | T5: =AVERAGE(C5:S5) -> 0.074706885 | U5: ='Donnees_USDA'!S6/'Donnees_USDA'!S102 -> 0.37908545 | V5: ='Donnees_USDA'!S516/'Donnees_USDA'!S612 -> 0.30886111 | W5: ='Donnees_USDA'!S312/'Donnees_USDA'!S405 -> 0.53422673 | X5: =IF('Donnees_USDA'!S516>0,'Donnees_USDA'!S312/'Donnees_USDA'!S516*52,"") -> 4.6892195 | Y5: 0.82547521 | Z5: 0.75503449 | AA5: -0.2965362 | AB5: -0.25921205
A6: Vietnam | B6: ='Donnees_USDA'!S721 -> 0.033846154 | C6: =IF(('Donnees_USDA'!C415+'Donnees_USDA'!C517)>0,'Donnees_USDA'!C313/('Donnees_USDA'!C415+'Donnees_USDA'!C517),"") -> 0.040046053 | D6: =IF(('Donnees_USDA'!D415+'Donnees_USDA'!D517)>0,'Donnees_USDA'!D313/('Donnees_USDA'!D415+'Donnees_USDA'!D517),"") -> 0.041666667 | E6: =IF(('Donnees_USDA'!E415+'Donnees_USDA'!E517)>0,'Donnees_USDA'!E313/('Donnees_USDA'!E415+'Donnees_USDA'!E517),"") -> 0.073522744 | F6: =IF(('Donnees_USDA'!F415+'Donnees_USDA'!F517)>0,'Donnees_USDA'!F313/('Donnees_USDA'!F415+'Donnees_USDA'!F517),"") -> 0.07030399 | G6: =IF(('Donnees_USDA'!G415+'Donnees_USDA'!G517)>0,'Donnees_USDA'!G313/('Donnees_USDA'!G415+'Donnees_USDA'!G517),"") -> 0.26639758 | H6: =IF(('Donnees_USDA'!H415+'Donnees_USDA'!H517)>0,'Donnees_USDA'!H313/('Donnees_USDA'!H415+'Donnees_USDA'!H517),"") -> 0.13254457 | I6: =IF(('Donnees_USDA'!I415+'Donnees_USDA'!I517)>0,'Donnees_USDA'!I313/('Donnees_USDA'!I415+'Donnees_USDA'!I517),"") -> 0.091752225 | J6: =IF(('Donnees_USDA'!J415+'Donnees_USDA'!J517)>0,'Donnees_USDA'!J313/('Donnees_USDA'!J415+'Donnees_USDA'!J517),"") -> 0.0077469729 | ... S6: =IF(('Donnees_USDA'!S415+'Donnees_USDA'!S517)>0,'Donnees_USDA'!S313/('Donnees_USDA'!S415+'Donnees_USDA'!S517),"") -> 0.014403535 | T6: =AVERAGE(C6:S6) -> 0.069581623 | U6: ='Donnees_USDA'!S7/'Donnees_USDA'!S102 -> 0.17135295 | V6: ='Donnees_USDA'!S517/'Donnees_USDA'!S612 -> 0.18221987 | W6: ='Donnees_USDA'!S313/'Donnees_USDA'!S405 -> 0.059036581 | X6: =IF('Donnees_USDA'!S517>0,'Donnees_USDA'!S313/'Donnees_USDA'!S517*52,"") -> 0.87834197 | Y6: -0.029891137 | Z6: 0.17882889 | AA6: -0.20225458 | AB6: -0.31546639
A7: Colombie | B7: ='Donnees_USDA'!S722 -> 1 | C7: =IF(('Donnees_USDA'!C416+'Donnees_USDA'!C518)>0,'Donnees_USDA'!C314/('Donnees_USDA'!C416+'Donnees_USDA'!C518),"") -> 0.010415571 | D7: =IF(('Donnees_USDA'!D416+'Donnees_USDA'!D518)>0,'Donnees_USDA'!D314/('Donnees_USDA'!D416+'Donnees_USDA'!D518),"") -> 0.028886311 | E7: =IF(('Donnees_USDA'!E416+'Donnees_USDA'!E518)>0,'Donnees_USDA'!E314/('Donnees_USDA'!E416+'Donnees_USDA'!E518),"") -> 0.07667827 | F7: =IF(('Donnees_USDA'!F416+'Donnees_USDA'!F518)>0,'Donnees_USDA'!F314/('Donnees_USDA'!F416+'Donnees_USDA'!F518),"") -> 0.077876823 | G7: =IF(('Donnees_USDA'!G416+'Donnees_USDA'!G518)>0,'Donnees_USDA'!G314/('Donnees_USDA'!G416+'Donnees_USDA'!G518),"") -> 0.048552822 | H7: =IF(('Donnees_USDA'!H416+'Donnees_USDA'!H518)>0,'Donnees_USDA'!H314/('Donnees_USDA'!H416+'Donnees_USDA'!H518),"") -> 0.081926838 | I7: =IF(('Donnees_USDA'!I416+'Donnees_USDA'!I518)>0,'Donnees_USDA'!I314/('Donnees_USDA'!I416+'Donnees_USDA'!I518),"") -> 0.058270306 | J7: =IF(('Donnees_USDA'!J416+'Donnees_USDA'!J518)>0,'Donnees_USDA'!J314/('Donnees_USDA'!J416+'Donnees_USDA'!J518),"") -> 0.077286957 | ... S7: =IF(('Donnees_USDA'!S416+'Donnees_USDA'!S518)>0,'Donnees_USDA'!S314/('Donnees_USDA'!S416+'Donnees_USDA'!S518),"") -> 0.042948718 | T7: =AVERAGE(C7:S7) -> 0.056811993 | U7: ='Donnees_USDA'!S8/'Donnees_USDA'!S102 -> 0.070650139 | V7: ='Donnees_USDA'!S518/'Donnees_USDA'!S612 -> 0.084343568 | W7: ='Donnees_USDA'!S314/'Donnees_USDA'!S405 -> 0.080888567 | X7: =IF('Donnees_USDA'!S518>0,'Donnees_USDA'!S314/'Donnees_USDA'!S518*52,"") -> 2.6 | Y7: 0.066947222 | Z7: 0.012797501 | AA7: -0.3290299 | AB7: -0.15949983
A8: Éthiopie | B8: ='Donnees_USDA'!S723 -> 1 | C8: =IF(('Donnees_USDA'!C417+'Donnees_USDA'!C519)>0,'Donnees_USDA'!C315/('Donnees_USDA'!C417+'Donnees_USDA'!C519),"") -> 0.016406891 | D8: =IF(('Donnees_USDA'!D417+'Donnees_USDA'!D519)>0,'Donnees_USDA'!D315/('Donnees_USDA'!D417+'Donnees_USDA'!D519),"") -> 0.037156704 | E8: =IF(('Donnees_USDA'!E417+'Donnees_USDA'!E519)>0,'Donnees_USDA'!E315/('Donnees_USDA'!E417+'Donnees_USDA'!E519),"") -> 0.015082956 | F8: =IF(('Donnees_USDA'!F417+'Donnees_USDA'!F519)>0,'Donnees_USDA'!F315/('Donnees_USDA'!F417+'Donnees_USDA'!F519),"") -> 0.006245121 | G8: =IF(('Donnees_USDA'!G417+'Donnees_USDA'!G519)>0,'Donnees_USDA'!G315/('Donnees_USDA'!G417+'Donnees_USDA'!G519),"") -> 0.0046260601 | H8: =IF(('Donnees_USDA'!H417+'Donnees_USDA'!H519)>0,'Donnees_USDA'!H315/('Donnees_USDA'!H417+'Donnees_USDA'!H519),"") -> 0.0038372985 | I8: =IF(('Donnees_USDA'!I417+'Donnees_USDA'!I519)>0,'Donnees_USDA'!I315/('Donnees_USDA'!I417+'Donnees_USDA'!I519),"") -> 0.0021573422 | J8: =IF(('Donnees_USDA'!J417+'Donnees_USDA'!J519)>0,'Donnees_USDA'!J315/('Donnees_USDA'!J417+'Donnees_USDA'!J519),"") -> 0.0038335936 | ... S8: =IF(('Donnees_USDA'!S417+'Donnees_USDA'!S519)>0,'Donnees_USDA'!S315/('Donnees_USDA'!S417+'Donnees_USDA'!S519),"") -> 0.011953833 | T8: =AVERAGE(C8:S8) -> 0.011449793 | U8: ='Donnees_USDA'!S9/'Donnees_USDA'!S102 -> 0.063796021 | V8: ='Donnees_USDA'!S519/'Donnees_USDA'!S612 -> 0.044878331 | W8: ='Donnees_USDA'!S315/'Donnees_USDA'!S405 -> 0.017505735 | X8: =IF('Donnees_USDA'!S519>0,'Donnees_USDA'!S315/'Donnees_USDA'!S519*52,"") -> 1.0575035 | Y8: 0.021747079 | Z8: -0.0050503297 | AA8: 0.13490134 | AB8: -0.14407753
A9: Indonésie | B9: ='Donnees_USDA'!S724 -> 0.12126538 | C9: =IF(('Donnees_USDA'!C418+'Donnees_USDA'!C520)>0,'Donnees_USDA'!C316/('Donnees_USDA'!C418+'Donnees_USDA'!C520),"") -> 0.0072934974 | D9: =IF(('Donnees_USDA'!D418+'Donnees_USDA'!D520)>0,'Donnees_USDA'!D316/('Donnees_USDA'!D418+'Donnees_USDA'!D520),"") -> 0.0094929881 | E9: =IF(('Donnees_USDA'!E418+'Donnees_USDA'!E520)>0,'Donnees_USDA'!E316/('Donnees_USDA'!E418+'Donnees_USDA'!E520),"") -> 0.0074581431 | F9: =IF(('Donnees_USDA'!F418+'Donnees_USDA'!F520)>0,'Donnees_USDA'!F316/('Donnees_USDA'!F418+'Donnees_USDA'!F520),"") -> 0.0037151703 | G9: =IF(('Donnees_USDA'!G418+'Donnees_USDA'!G520)>0,'Donnees_USDA'!G316/('Donnees_USDA'!G418+'Donnees_USDA'!G520),"") -> 0.0045611015 | H9: =IF(('Donnees_USDA'!H418+'Donnees_USDA'!H520)>0,'Donnees_USDA'!H316/('Donnees_USDA'!H418+'Donnees_USDA'!H520),"") -> 0.0035192411 | I9: =IF(('Donnees_USDA'!I418+'Donnees_USDA'!I520)>0,'Donnees_USDA'!I316/('Donnees_USDA'!I418+'Donnees_USDA'!I520),"") -> 0.0010547596 | J9: =IF(('Donnees_USDA'!J418+'Donnees_USDA'!J520)>0,'Donnees_USDA'!J316/('Donnees_USDA'!J418+'Donnees_USDA'!J520),"") -> 0.051253241 | ... S9: =IF(('Donnees_USDA'!S418+'Donnees_USDA'!S520)>0,'Donnees_USDA'!S316/('Donnees_USDA'!S418+'Donnees_USDA'!S520),"") -> 0.052096273 | T9: =AVERAGE(C9:S9) -> 0.057528885 | U9: ='Donnees_USDA'!S10/'Donnees_USDA'!S102 -> 0.059999895 | V9: ='Donnees_USDA'!S520/'Donnees_USDA'!S612 -> 0.050669084 | W9: ='Donnees_USDA'!S316/'Donnees_USDA'!S405 -> 0.081009296 | X9: =IF('Donnees_USDA'!S520>0,'Donnees_USDA'!S316/'Donnees_USDA'!S520*52,"") -> 4.3344099 | Y9: 0.044651825 | Z9: 0.020282059 | AA9: -0.36876234 | AB9: -0.3488393
A10: Ouganda | B10: ='Donnees_USDA'!S725 -> 0.15851955 | C10: =IF(('Donnees_USDA'!C419+'Donnees_USDA'!C521)>0,'Donnees_USDA'!C317/('Donnees_USDA'!C419+'Donnees_USDA'!C521),"") -> 0.18575758 | D10: =IF(('Donnees_USDA'!D419+'Donnees_USDA'!D521)>0,'Donnees_USDA'!D317/('Donnees_USDA'!D419+'Donnees_USDA'!D521),"") -> 0.17079365 | E10: =IF(('Donnees_USDA'!E419+'Donnees_USDA'!E521)>0,'Donnees_USDA'!E317/('Donnees_USDA'!E419+'Donnees_USDA'!E521),"") -> 0.09615894 | F10: =IF(('Donnees_USDA'!F419+'Donnees_USDA'!F521)>0,'Donnees_USDA'!F317/('Donnees_USDA'!F419+'Donnees_USDA'!F521),"") -> 0.10287958 | G10: =IF(('Donnees_USDA'!G419+'Donnees_USDA'!G521)>0,'Donnees_USDA'!G317/('Donnees_USDA'!G419+'Donnees_USDA'!G521),"") -> 0.087430168 | H10: =IF(('Donnees_USDA'!H419+'Donnees_USDA'!H521)>0,'Donnees_USDA'!H317/('Donnees_USDA'!H419+'Donnees_USDA'!H521),"") -> 0.088169014 | I10: =IF(('Donnees_USDA'!I419+'Donnees_USDA'!I521)>0,'Donnees_USDA'!I317/('Donnees_USDA'!I419+'Donnees_USDA'!I521),"") -> 0.069690722 | J10: =IF(('Donnees_USDA'!J419+'Donnees_USDA'!J521)>0,'Donnees_USDA'!J317/('Donnees_USDA'!J419+'Donnees_USDA'!J521),"") -> 0.085274725 | ... S10: =IF(('Donnees_USDA'!S419+'Donnees_USDA'!S521)>0,'Donnees_USDA'!S317/('Donnees_USDA'!S419+'Donnees_USDA'!S521),"") -> 0.045917655 | T10: =AVERAGE(C10:S10) -> 0.082360113 | U10: ='Donnees_USDA'!S11/'Donnees_USDA'!S102 -> 0.037750373 | V10: ='Donnees_USDA'!S521/'Donnees_USDA'!S612 -> 0.042990042 | W10: ='Donnees_USDA'!S317/'Donnees_USDA'!S405 -> 0.039719908 | X10: =IF('Donnees_USDA'!S521>0,'Donnees_USDA'!S317/'Donnees_USDA'!S521*52,"") -> 2.5048316 | Y10: 0.025994173 | Z10: -0.0051267594 | AA10: 0.020536828 | AB10: -0.29420162
A11: Inde | B11: ='Donnees_USDA'!S726 -> 0.25407166 | C11: =IF(('Donnees_USDA'!C420+'Donnees_USDA'!C522)>0,'Donnees_USDA'!C318/('Donnees_USDA'!C420+'Donnees_USDA'!C522),"") -> 0.2582271 | D11: =IF(('Donnees_USDA'!D420+'Donnees_USDA'!D522)>0,'Donnees_USDA'!D318/('Donnees_USDA'!D420+'Donnees_USDA'!D522),"") -> 0.23048036 | E11: =IF(('Donnees_USDA'!E420+'Donnees_USDA'!E522)>0,'Donnees_USDA'!E318/('Donnees_USDA'!E420+'Donnees_USDA'!E522),"") -> 0.33266197 | F11: =IF(('Donnees_USDA'!F420+'Donnees_USDA'!F522)>0,'Donnees_USDA'!F318/('Donnees_USDA'!F420+'Donnees_USDA'!F522),"") -> 0.32767265 | G11: =IF(('Donnees_USDA'!G420+'Donnees_USDA'!G522)>0,'Donnees_USDA'!G318/('Donnees_USDA'!G420+'Donnees_USDA'!G522),"") -> 0.42497946 | H11: =IF(('Donnees_USDA'!H420+'Donnees_USDA'!H522)>0,'Donnees_USDA'!H318/('Donnees_USDA'!H420+'Donnees_USDA'!H522),"") -> 0.38095924 | I11: =IF(('Donnees_USDA'!I420+'Donnees_USDA'!I522)>0,'Donnees_USDA'!I318/('Donnees_USDA'!I420+'Donnees_USDA'!I522),"") -> 0.25455287 | J11: =IF(('Donnees_USDA'!J420+'Donnees_USDA'!J522)>0,'Donnees_USDA'!J318/('Donnees_USDA'!J420+'Donnees_USDA'!J522),"") -> 0.16949613 | ... S11: =IF(('Donnees_USDA'!S420+'Donnees_USDA'!S522)>0,'Donnees_USDA'!S318/('Donnees_USDA'!S420+'Donnees_USDA'!S522),"") -> 0.027695858 | T11: =AVERAGE(C11:S11) -> 0.17918315 | U11: ='Donnees_USDA'!S12/'Donnees_USDA'!S102 -> 0.032372527 | V11: ='Donnees_USDA'!S522/'Donnees_USDA'!S612 -> 0.039144228 | W11: ='Donnees_USDA'!S318/'Donnees_USDA'!S405 -> 0.026077508 | X11: =IF('Donnees_USDA'!S522>0,'Donnees_USDA'!S318/'Donnees_USDA'!S522*52,"") -> 1.8060781 | Y11: -0.0078451565 | Z11: 0.051984832 | AA11: -0.40735047 | AB11: -0.47312094
A12: Honduras | B12: ='Donnees_USDA'!S727 -> 1 | C12: =IF(('Donnees_USDA'!C421+'Donnees_USDA'!C523)>0,'Donnees_USDA'!C319/('Donnees_USDA'!C421+'Donnees_USDA'!C523),"") -> 0.0071667463 | D12: =IF(('Donnees_USDA'!D421+'Donnees_USDA'!D523)>0,'Donnees_USDA'!D319/('Donnees_USDA'!D421+'Donnees_USDA'!D523),"") -> 0.01620162 | E12: =IF(('Donnees_USDA'!E421+'Donnees_USDA'!E523)>0,'Donnees_USDA'!E319/('Donnees_USDA'!E421+'Donnees_USDA'!E523),"") -> 0.029850746 | F12: =IF(('Donnees_USDA'!F421+'Donnees_USDA'!F523)>0,'Donnees_USDA'!F319/('Donnees_USDA'!F421+'Donnees_USDA'!F523),"") -> 0.070505288 | G12: =IF(('Donnees_USDA'!G421+'Donnees_USDA'!G523)>0,'Donnees_USDA'!G319/('Donnees_USDA'!G421+'Donnees_USDA'!G523),"") -> 0.066929134 | H12: =IF(('Donnees_USDA'!H421+'Donnees_USDA'!H523)>0,'Donnees_USDA'!H319/('Donnees_USDA'!H421+'Donnees_USDA'!H523),"") -> 0.058933583 | I12: =IF(('Donnees_USDA'!I421+'Donnees_USDA'!I523)>0,'Donnees_USDA'!I319/('Donnees_USDA'!I421+'Donnees_USDA'!I523),"") -> 0.039735099 | J12: =IF(('Donnees_USDA'!J421+'Donnees_USDA'!J523)>0,'Donnees_USDA'!J319/('Donnees_USDA'!J421+'Donnees_USDA'!J523),"") -> 0.042763158 | ... S12: =IF(('Donnees_USDA'!S421+'Donnees_USDA'!S523)>0,'Donnees_USDA'!S319/('Donnees_USDA'!S421+'Donnees_USDA'!S523),"") -> 0.11946604 | T12: =AVERAGE(C12:S12) -> 0.042052885 | U12: ='Donnees_USDA'!S13/'Donnees_USDA'!S102 -> 0.031792563 | V12: ='Donnees_USDA'!S523/'Donnees_USDA'!S612 -> 0.034637511 | W12: ='Donnees_USDA'!S319/'Donnees_USDA'!S405 -> 0.085355548 | X12: =IF('Donnees_USDA'!S523>0,'Donnees_USDA'!S319/'Donnees_USDA'!S523*52,"") -> 6.6807196 | Y12: 0.046165884 | Z12: 0.013481169 | AA12: 0.013933495 | AB12: 0.10949043
