Workbook

Sheet Lisez-moi
A1: Café — stock-to-use (USDA) vs prix KC1 / DF1, campagnes 2010/11 → 2026/27
A3: Ce que contient ce classeur
A4: 1_Monde — STU mondial en colonnes (%) avec KC1 et DF1 en courbes sur l'axe secondaire.
A5: 2_Arabica_Robusta — STU arabica et STU robusta (tous les pays producteurs), avec KC1 pour l'arabica et DF1 pour le robusta.
A6: 3_Groupes_pays — même chose en additionnant les pays demandés : arabica = Brésil, Colombie, Honduras, Éthiopie, Pérou, Mexique, Guatemala, Costa Rica ; robusta = Brésil, Vietnam, Indonésie, Ouganda.
A7: 4_Deux_pays — deux colonnes par an : Brésil + Colombie (avec KC1) et Vietnam + Brésil (avec DF1).
A8: 5_Bresil_Vietnam — un seul pays : Brésil (KC1) et Vietnam (DF1).
A9: 6_Surplus — le « surplus » à la place des stocks USDA : Brésil seul, arabica 6 pays (Brésil, Colombie, Honduras, Mexique, Pérou, Nicaragua), Vietnam seul, robusta 4 pays (Vietnam, Brésil, Ouganda, Indonésie).
A10: Tableau_STU — années en colonnes, pays en lignes, avec couleurs (rouge = tendu, vert = confortable).
A11: Analyse — corrélations, courbe prix = f(STU), application à 2026/27, régimes de prix, pays qui font bouger l'offre, conclusions.
A12: Prix_ICE — les 191 moyennes mensuelles (oct. 2010 → août 2026) et les moyennes de campagne. Donnees_USDA — toutes les données pays par pays (93 pays).
A13: Réponse : stock-to-use = stocks ÷ consommation, ou stocks ÷ (consommation + exportations) ?
... A24: 16 campagnes seulement : les corrélations donnent des ordres de grandeur. Les stocks USDA des pays producteurs sont des estimations résiduelles (le Brésil en particulier). Les prix ne sont pas corrigés de l'inflation ni du real brésilien (BRL), qui pèse lourd (≈1,7 R$/US$ en 2011, ≈5,2 depuis 2020). Toutes les formules sont vivantes : modifiez Donnees_USDA et les graphiques se mettent à jour.

Sheet 1_Monde
A1: 1 — Stock-to-use MONDE (USDA) vs prix KC1 et DF1
A2: STU monde = stocks de fin mondiaux ÷ consommation mondiale (définition USDA/ICO). Colonne F = stocks ÷ (conso + exportations), pour comparaison.
A3: Barres = STU (axe gauche) ; courbes = KC et robusta Londres en US cents/lb (axe droit), moyennes de campagne oct.–sept.
A4: Campagne | B4: Stocks de fin monde (1000 sacs) | C4: Consommation monde | D4: Exportations monde | E4: STU monde (stocks ÷ conso) | F4: STU (stocks ÷ (conso + export)) | G4: KC1 NY (US c/lb) | H4: DF1 Londres (US c/lb) | I4: DF1 Londres (US$/t)
A5: 2010/11 | B5: ='Donnees_USDA'!C801 -> 28640 | C5: ='Donnees_USDA'!C601 -> 135508 | D5: ='Donnees_USDA'!C701 -> 116972 | E5: =B5/C5 -> 0.21135284 | F5: =B5/(C5+D5) -> 0.11343473 | G5: ='Prix_ICE'!J5 -> 249.66 | H5: ='Prix_ICE'!K5 -> 100.65583 | I5: ='Prix_ICE'!L5 -> 2219.0813
A6: 2011/12 | B6: ='Donnees_USDA'!D801 -> 25748 | C6: ='Donnees_USDA'!D601 -> 142831 | D6: ='Donnees_USDA'!D701 -> 118031 | E6: =B6/C6 -> 0.18026899 | F6: =B6/(C6+D6) -> 0.098703529 | G6: ='Prix_ICE'!J6 -> 197.84167 | H6: ='Prix_ICE'!K6 -> 91.384167 | I6: ='Prix_ICE'!L6 -> 2014.676
A7: 2012/13 | B7: ='Donnees_USDA'!E801 -> 35365 | C7: ='Donnees_USDA'!E601 -> 143400 | D7: ='Donnees_USDA'!E701 -> 123239 | E7: =B7/C7 -> 0.24661785 | F7: =B7/(C7+D7) -> 0.13263251 | G7: ='Prix_ICE'!J7 -> 140.69833 | H7: ='Prix_ICE'!K7 -> 88.480833 | I7: ='Prix_ICE'!L7 -> 1950.6685
A8: 2013/14 | B8: ='Donnees_USDA'!F801 -> 41184 | C8: ='Donnees_USDA'!F601 -> 143877 | D8: ='Donnees_USDA'!F701 -> 129260 | E8: =B8/C8 -> 0.2862445 | F8: =B8/(C8+D8) -> 0.15078148 | G8: ='Prix_ICE'!J8 -> 161.4675 | H8: ='Prix_ICE'!K8 -> 85.874167 | I8: ='Prix_ICE'!L8 -> 1893.2013
A9: 2014/15 | B9: ='Donnees_USDA'!G801 -> 43132 | C9: ='Donnees_USDA'!G601 -> 147163 | D9: ='Donnees_USDA'!G701 -> 124027 | E9: =B9/C9 -> 0.29308998 | F9: =B9/(C9+D9) -> 0.15904716 | G9: ='Prix_ICE'!J9 -> 154.02083 | H9: ='Prix_ICE'!K9 -> 83.910833 | I9: ='Prix_ICE'!L9 -> 1849.9172
A10: 2015/16 | B10: ='Donnees_USDA'!H801 -> 34951 | C10: ='Donnees_USDA'!H601 -> 153186 | D10: ='Donnees_USDA'!H701 -> 133845 | E10: =B10/C10 -> 0.22816054 | F10: =B10/(C10+D10) -> 0.12176734 | G10: ='Prix_ICE'!J10 -> 131.8325 | H10: ='Prix_ICE'!K10 -> 74.068333 | I10: ='Prix_ICE'!L10 -> 1632.9272
A11: 2016/17 | B11: ='Donnees_USDA'!I801 -> 36453 | C11: ='Donnees_USDA'!I601 -> 155104 | D11: ='Donnees_USDA'!I701 -> 133606 | E11: =B11/C11 -> 0.23502295 | F11: =B11/(C11+D11) -> 0.12626165 | G11: ='Prix_ICE'!J11 -> 143.77167 | H11: ='Prix_ICE'!K11 -> 95.123333 | I11: ='Prix_ICE'!L11 -> 2097.1105
A12: 2017/18 | B12: ='Donnees_USDA'!J801 -> 31951 | C12: ='Donnees_USDA'!J601 -> 160627 | D12: ='Donnees_USDA'!J701 -> 134174 | E12: =B12/C12 -> 0.19891425 | F12: =B12/(C12+D12) -> 0.10838159 | G12: ='Prix_ICE'!J12 -> 120.60083 | H12: ='Prix_ICE'!K12 -> 78.285 | I12: ='Prix_ICE'!L12 -> 1725.8888
A13: 2018/19 | B13: ='Donnees_USDA'!K801 -> 36946 | C13: ='Donnees_USDA'!K601 -> 166003 | D13: ='Donnees_USDA'!K701 -> 143364 | E13: =B13/C13 -> 0.22256224 | F13: =B13/(C13+D13) -> 0.1194245 | G13: ='Prix_ICE'!J13 -> 104.98083 | H13: ='Prix_ICE'!K13 -> 67.5325 | I13: ='Prix_ICE'!L13 -> 1488.8368
A14: 2019/20 | B14: ='Donnees_USDA'!L801 -> 35808 | C14: ='Donnees_USDA'!L601 -> 162355 | D14: ='Donnees_USDA'!L701 -> 139001 | E14: =B14/C14 -> 0.22055372 | F14: =B14/(C14+D14) -> 0.11882292 | G14: ='Prix_ICE'!J14 -> 113.23667 | H14: ='Prix_ICE'!K14 -> 59.220833 | I14: ='Prix_ICE'!L14 -> 1305.5959
A15: 2020/21 | B15: ='Donnees_USDA'!M801 -> 37494 | C15: ='Donnees_USDA'!M601 -> 162093 | D15: ='Donnees_USDA'!M701 -> 144941 | E15: =B15/C15 -> 0.23131165 | F15: =B15/(C15+D15) -> 0.12211677 | G15: ='Prix_ICE'!J15 -> 143.75333 | H15: ='Prix_ICE'!K15 -> 69.895833 | I15: ='Prix_ICE'!L15 -> 1540.9394
A16: 2021/22 | B16: ='Donnees_USDA'!N801 -> 31940 | C16: ='Donnees_USDA'!N601 -> 167876 | D16: ='Donnees_USDA'!N701 -> 143583 | E16: =B16/C16 -> 0.19025948 | F16: =B16/(C16+D16) -> 0.10254961 | G16: ='Prix_ICE'!J16 -> 224.0875 | H16: ='Prix_ICE'!K16 -> 97.529167 | I16: ='Prix_ICE'!L16 -> 2150.1501
A17: 2022/23 | B17: ='Donnees_USDA'!O801 -> 26934 | C17: ='Donnees_USDA'!O601 -> 168754 | D17: ='Donnees_USDA'!O701 -> 134699 | E17: =B17/C17 -> 0.15960511 | F17: =B17/(C17+D17) -> 0.088758391 | G17: ='Prix_ICE'!J17 -> 171.19 | H17: ='Prix_ICE'!K17 -> 100.565 | I17: ='Prix_ICE'!L17 -> 2217.0787
A18: 2023/24 | B18: ='Donnees_USDA'!P801 -> 23121 | C18: ='Donnees_USDA'!P601 -> 163944 | D18: ='Donnees_USDA'!P701 -> 143474 | E18: =B18/C18 -> 0.14102986 | F18: =B18/(C18+D18) -> 0.0752103 | G18: ='Prix_ICE'!J18 -> 204.00167 | H18: ='Prix_ICE'!K18 -> 158.95 | I18: ='Prix_ICE'!L18 -> 3504.2477
A19: 2024/25 | B19: ='Donnees_USDA'!Q801 -> 22010 | C19: ='Donnees_USDA'!Q601 -> 171761 | D19: ='Donnees_USDA'!Q701 -> 147746 | E19: =B19/C19 -> 0.12814318 | F19: =B19/(C19+D19) -> 0.06888738 | G19: ='Prix_ICE'!J19 -> 333.06 | H19: ='Prix_ICE'!K19 -> 213.2675 | I19: ='Prix_ICE'!L19 -> 4701.7435
A20: 2025/26 | B20: ='Donnees_USDA'!R801 -> 24370 | C20: ='Donnees_USDA'!R601 -> 173459 | D20: ='Donnees_USDA'!R701 -> 145942 | E20: =B20/C20 -> 0.1404943 | F20: =B20/(C20+D20) -> 0.076299072 | G20: ='Prix_ICE'!J20 -> 312.21 | H20: ='Prix_ICE'!K20 -> 171.84182 | I20: ='Prix_ICE'!L20 -> 3788.4636
A21: 2026/27 (prév.) | B21: ='Donnees_USDA'!S801 -> 26283 | C21: ='Donnees_USDA'!S601 -> 179736 | D21: ='Donnees_USDA'!S701 -> 158874 | E21: =B21/C21 -> 0.14623114 | F21: =B21/(C21+D21) -> 0.077620271
A24: Lecture : quand le STU mondial passe sous ~16 %, les prix changent de régime (2023/24-2025/26) ; au-dessus de ~20 %, ils restent bas (2015/16-2020/21). Les deux définitions ont exactement la même forme (corrélation 0,99).
A28: Pourquoi diviser par la consommation seule au niveau mondial : les exportations d'un pays sont les importations d'un autre ; les ajouter compterait deux fois les mêmes sacs. Pour un pays exportateur, on divise par conso + exportations.

Sheet 2_Arabica_Robusta
A1: 2 — Stock-to-use ARABICA et ROBUSTA (total des 47 pays producteurs) vs KC1 / DF1
A2: L'USDA ne publie ni stocks ni consommation par espèce : chaque pays producteur est pondéré par la part arabica (ou robusta) de sa production de l'année.
A3: STU espèce = Σ(stocks × part) ÷ Σ((conso + export) × part). Les stocks des pays importateurs (UE, É.-U., Japon…) ne sont pas ventilables : ils sont exclus ici (voir onglet 1).
A4: Campagne | B4: Stocks arabica (1000 sacs, pondérés) | C4: Conso + export arabica (pondérés) | D4: STU ARABICA | E4: Stocks robusta (pondérés) | F4: Conso + export robusta (pondérés) | G4: STU ROBUSTA | H4: KC1 NY (US c/lb) | I4: DF1 Londres (US$/t)
A5: 2010/11 | B5: =SUMPRODUCT('Donnees_USDA'!C706:C752,'Donnees_USDA'!C806:C852) -> 9293.2165 | C5: =SUMPRODUCT('Donnees_USDA'!C506:C552,'Donnees_USDA'!C806:C852)+SUMPRODUCT('Donnees_USDA'!C606:C652,'Donnees_USDA'!C806:C852) -> 116870.24 | D5: =B5/C5 -> 0.079517394 | E5: =SUMPRODUCT('Donnees_USDA'!C706:C752,'Donnees_USDA'!C906:C952) -> 3936.7835 | F5: =SUMPRODUCT('Donnees_USDA'!C506:C552,'Donnees_USDA'!C906:C952)+SUMPRODUCT('Donnees_USDA'!C606:C652,'Donnees_USDA'!C906:C952) -> 61324.764 | G5: =E5/F5 -> 0.064195656 | H5: ='Prix_ICE'!J5 -> 249.66 | I5: ='Prix_ICE'!L5 -> 2219.0813
A6: 2011/12 | B6: =SUMPRODUCT('Donnees_USDA'!D706:D752,'Donnees_USDA'!D806:D852) -> 9586.9538 | C6: =SUMPRODUCT('Donnees_USDA'!D506:D552,'Donnees_USDA'!D806:D852)+SUMPRODUCT('Donnees_USDA'!D606:D652,'Donnees_USDA'!D806:D852) -> 114087.82 | D6: =B6/C6 -> 0.084031352 | E6: =SUMPRODUCT('Donnees_USDA'!D706:D752,'Donnees_USDA'!D906:D952) -> 3621.0462 | F6: =SUMPRODUCT('Donnees_USDA'!D506:D552,'Donnees_USDA'!D906:D952)+SUMPRODUCT('Donnees_USDA'!D606:D652,'Donnees_USDA'!D906:D952) -> 68249.179 | G6: =E6/F6 -> 0.05305626 | H6: ='Prix_ICE'!J6 -> 197.84167 | I6: ='Prix_ICE'!L6 -> 2014.676
A7: 2012/13 | B7: =SUMPRODUCT('Donnees_USDA'!E706:E752,'Donnees_USDA'!E806:E852) -> 15040.255 | C7: =SUMPRODUCT('Donnees_USDA'!E506:E552,'Donnees_USDA'!E806:E852)+SUMPRODUCT('Donnees_USDA'!E606:E652,'Donnees_USDA'!E806:E852) -> 117410.69 | D7: =B7/C7 -> 0.12809954 | E7: =SUMPRODUCT('Donnees_USDA'!E706:E752,'Donnees_USDA'!E906:E952) -> 6499.7446 | F7: =SUMPRODUCT('Donnees_USDA'!E506:E552,'Donnees_USDA'!E906:E952)+SUMPRODUCT('Donnees_USDA'!E606:E652,'Donnees_USDA'!E906:E952) -> 71613.307 | G7: =E7/F7 -> 0.090761688 | H7: ='Prix_ICE'!J7 -> 140.69833 | I7: ='Prix_ICE'!L7 -> 1950.6685
A8: 2013/14 | B8: =SUMPRODUCT('Donnees_USDA'!F706:F752,'Donnees_USDA'!F806:F852) -> 18263.42 | C8: =SUMPRODUCT('Donnees_USDA'!F506:F552,'Donnees_USDA'!F806:F852)+SUMPRODUCT('Donnees_USDA'!F606:F652,'Donnees_USDA'!F806:F852) -> 120683.67 | D8: =B8/C8 -> 0.15133298 | E8: =SUMPRODUCT('Donnees_USDA'!F706:F752,'Donnees_USDA'!F906:F952) -> 7420.5803 | F8: =SUMPRODUCT('Donnees_USDA'!F506:F552,'Donnees_USDA'!F906:F952)+SUMPRODUCT('Donnees_USDA'!F606:F652,'Donnees_USDA'!F906:F952) -> 75203.328 | G8: =E8/F8 -> 0.098673563 | H8: ='Prix_ICE'!J8 -> 161.4675 | I8: ='Prix_ICE'!L8 -> 1893.2013
A9: 2014/15 | B9: =SUMPRODUCT('Donnees_USDA'!G706:G752,'Donnees_USDA'!G806:G852) -> 15901.179 | C9: =SUMPRODUCT('Donnees_USDA'!G506:G552,'Donnees_USDA'!G806:G852)+SUMPRODUCT('Donnees_USDA'!G606:G652,'Donnees_USDA'!G806:G852) -> 118555.7 | D9: =B9/C9 -> 0.13412412 | E9: =SUMPRODUCT('Donnees_USDA'!G706:G752,'Donnees_USDA'!G906:G952) -> 11655.821 | F9: =SUMPRODUCT('Donnees_USDA'!G506:G552,'Donnees_USDA'!G906:G952)+SUMPRODUCT('Donnees_USDA'!G606:G652,'Donnees_USDA'!G906:G952) -> 72984.3 | G9: =E9/F9 -> 0.15970313 | H9: ='Prix_ICE'!J9 -> 154.02083 | I9: ='Prix_ICE'!L9 -> 1849.9172
A10: 2015/16 | B10: =SUMPRODUCT('Donnees_USDA'!H706:H752,'Donnees_USDA'!H806:H852) -> 11773.586 | C10: =SUMPRODUCT('Donnees_USDA'!H506:H552,'Donnees_USDA'!H806:H852)+SUMPRODUCT('Donnees_USDA'!H606:H652,'Donnees_USDA'!H806:H852) -> 123881.16 | D10: =B10/C10 -> 0.095039352 | E10: =SUMPRODUCT('Donnees_USDA'!H706:H752,'Donnees_USDA'!H906:H952) -> 7592.4144 | F10: =SUMPRODUCT('Donnees_USDA'!H506:H552,'Donnees_USDA'!H906:H952)+SUMPRODUCT('Donnees_USDA'!H606:H652,'Donnees_USDA'!H906:H952) -> 80920.835 | G10: =E10/F10 -> 0.09382521 | H10: ='Prix_ICE'!J10 -> 131.8325 | I10: ='Prix_ICE'!L10 -> 1632.9272
A11: 2016/17 | B11: =SUMPRODUCT('Donnees_USDA'!I706:I752,'Donnees_USDA'!I806:I852) -> 13683.019 | C11: =SUMPRODUCT('Donnees_USDA'!I506:I552,'Donnees_USDA'!I806:I852)+SUMPRODUCT('Donnees_USDA'!I606:I652,'Donnees_USDA'!I806:I852) -> 132742.82 | D11: =B11/C11 -> 0.10307917 | E11: =SUMPRODUCT('Donnees_USDA'!I706:I752,'Donnees_USDA'!I906:I952) -> 5564.981 | F11: =SUMPRODUCT('Donnees_USDA'!I506:I552,'Donnees_USDA'!I906:I952)+SUMPRODUCT('Donnees_USDA'!I606:I652,'Donnees_USDA'!I906:I952) -> 73013.185 | G11: =E11/F11 -> 0.07621885 | H11: ='Prix_ICE'!J11 -> 143.77167 | I11: ='Prix_ICE'!L11 -> 2097.1105
A12: 2017/18 | B12: =SUMPRODUCT('Donnees_USDA'!J706:J752,'Donnees_USDA'!J806:J852) -> 12243.909 | C12: =SUMPRODUCT('Donnees_USDA'!J506:J552,'Donnees_USDA'!J806:J852)+SUMPRODUCT('Donnees_USDA'!J606:J652,'Donnees_USDA'!J806:J852) -> 128761.49 | D12: =B12/C12 -> 0.095089841 | E12: =SUMPRODUCT('Donnees_USDA'!J706:J752,'Donnees_USDA'!J906:J952) -> 3413.0909 | F12: =SUMPRODUCT('Donnees_USDA'!J506:J552,'Donnees_USDA'!J906:J952)+SUMPRODUCT('Donnees_USDA'!J606:J652,'Donnees_USDA'!J906:J952) -> 78988.515 | G12: =E12/F12 -> 0.043209964 | H12: ='Prix_ICE'!J12 -> 120.60083 | I12: ='Prix_ICE'!L12 -> 1725.8888
A13: 2018/19 | B13: =SUMPRODUCT('Donnees_USDA'!K706:K752,'Donnees_USDA'!K806:K852) -> 13528.245 | C13: =SUMPRODUCT('Donnees_USDA'!K506:K552,'Donnees_USDA'!K806:K852)+SUMPRODUCT('Donnees_USDA'!K606:K652,'Donnees_USDA'!K806:K852) -> 139660.51 | D13: =B13/C13 -> 0.096865213 | E13: =SUMPRODUCT('Donnees_USDA'!K706:K752,'Donnees_USDA'!K906:K952) -> 5868.7551 | F13: =SUMPRODUCT('Donnees_USDA'!K506:K552,'Donnees_USDA'!K906:K952)+SUMPRODUCT('Donnees_USDA'!K606:K652,'Donnees_USDA'!K906:K952) -> 81016.492 | G13: =E13/F13 -> 0.072439018 | H13: ='Prix_ICE'!J13 -> 104.98083 | I13: ='Prix_ICE'!L13 -> 1488.8368
A14: 2019/20 | B14: =SUMPRODUCT('Donnees_USDA'!L706:L752,'Donnees_USDA'!L806:L852) -> 11120.172 | C14: =SUMPRODUCT('Donnees_USDA'!L506:L552,'Donnees_USDA'!L806:L852)+SUMPRODUCT('Donnees_USDA'!L606:L652,'Donnees_USDA'!L806:L852) -> 129910.03 | D14: =B14/C14 -> 0.085599027 | E14: =SUMPRODUCT('Donnees_USDA'!L706:L752,'Donnees_USDA'!L906:L952) -> 6752.8277 | F14: =SUMPRODUCT('Donnees_USDA'!L506:L552,'Donnees_USDA'!L906:L952)+SUMPRODUCT('Donnees_USDA'!L606:L652,'Donnees_USDA'!L906:L952) -> 84897.969 | G14: =E14/F14 -> 0.07954051 | H14: ='Prix_ICE'!J14 -> 113.23667 | I14: ='Prix_ICE'!L14 -> 1305.5959
A15: 2020/21 | B15: =SUMPRODUCT('Donnees_USDA'!M706:M752,'Donnees_USDA'!M806:M852) -> 12831.579 | C15: =SUMPRODUCT('Donnees_USDA'!M506:M552,'Donnees_USDA'!M806:M852)+SUMPRODUCT('Donnees_USDA'!M606:M652,'Donnees_USDA'!M806:M852) -> 135351.22 | D15: =B15/C15 -> 0.094802092 | E15: =SUMPRODUCT('Donnees_USDA'!M706:M752,'Donnees_USDA'!M906:M952) -> 8202.4207 | F15: =SUMPRODUCT('Donnees_USDA'!M506:M552,'Donnees_USDA'!M906:M952)+SUMPRODUCT('Donnees_USDA'!M606:M652,'Donnees_USDA'!M906:M952) -> 84293.775 | G15: =E15/F15 -> 0.097307549 | H15: ='Prix_ICE'!J15 -> 143.75333 | I15: ='Prix_ICE'!L15 -> 1540.9394
A16: 2021/22 | B16: =SUMPRODUCT('Donnees_USDA'!N706:N752,'Donnees_USDA'!N806:N852) -> 9221.2611 | C16: =SUMPRODUCT('Donnees_USDA'!N506:N552,'Donnees_USDA'!N806:N852)+SUMPRODUCT('Donnees_USDA'!N606:N652,'Donnees_USDA'!N806:N852) -> 127772.33 | D16: =B16/C16 -> 0.072169466 | E16: =SUMPRODUCT('Donnees_USDA'!N706:N752,'Donnees_USDA'!N906:N952) -> 5820.7389 | F16: =SUMPRODUCT('Donnees_USDA'!N506:N552,'Donnees_USDA'!N906:N952)+SUMPRODUCT('Donnees_USDA'!N606:N652,'Donnees_USDA'!N906:N952) -> 92911.666 | G16: =E16/F16 -> 0.062648095 | H16: ='Prix_ICE'!J16 -> 224.0875 | I16: ='Prix_ICE'!L16 -> 2150.1501
A17: 2022/23 | B17: =SUMPRODUCT('Donnees_USDA'!O706:O752,'Donnees_USDA'!O806:O852) -> 10846.447 | C17: =SUMPRODUCT('Donnees_USDA'!O506:O552,'Donnees_USDA'!O806:O852)+SUMPRODUCT('Donnees_USDA'!O606:O652,'Donnees_USDA'!O806:O852) -> 120505.65 | D17: =B17/C17 -> 0.090007788 | E17: =SUMPRODUCT('Donnees_USDA'!O706:O752,'Donnees_USDA'!O906:O952) -> 4257.5531 | F17: =SUMPRODUCT('Donnees_USDA'!O506:O552,'Donnees_USDA'!O906:O952)+SUMPRODUCT('Donnees_USDA'!O606:O652,'Donnees_USDA'!O906:O952) -> 89475.351 | G17: =E17/F17 -> 0.047583531 | H17: ='Prix_ICE'!J17 -> 171.19 | I17: ='Prix_ICE'!L17 -> 2217.0787
A18: 2023/24 | B18: =SUMPRODUCT('Donnees_USDA'!P706:P752,'Donnees_USDA'!P806:P852) -> 9357.9018 | C18: =SUMPRODUCT('Donnees_USDA'!P506:P552,'Donnees_USDA'!P806:P852)+SUMPRODUCT('Donnees_USDA'!P606:P652,'Donnees_USDA'!P806:P852) -> 133041.87 | D18: =B18/C18 -> 0.070338022 | E18: =SUMPRODUCT('Donnees_USDA'!P706:P752,'Donnees_USDA'!P906:P952) -> 2711.0982 | F18: =SUMPRODUCT('Donnees_USDA'!P506:P552,'Donnees_USDA'!P906:P952)+SUMPRODUCT('Donnees_USDA'!P606:P652,'Donnees_USDA'!P906:P952) -> 85766.133 | G18: =E18/F18 -> 0.031610359 | H18: ='Prix_ICE'!J18 -> 204.00167 | I18: ='Prix_ICE'!L18 -> 3504.2477
A19: 2024/25 | B19: =SUMPRODUCT('Donnees_USDA'!Q706:Q752,'Donnees_USDA'!Q806:Q852) -> 8829.2148 | C19: =SUMPRODUCT('Donnees_USDA'!Q506:Q552,'Donnees_USDA'!Q806:Q852)+SUMPRODUCT('Donnees_USDA'!Q606:Q652,'Donnees_USDA'!Q806:Q852) -> 140002.1 | D19: =B19/C19 -> 0.063064873 | E19: =SUMPRODUCT('Donnees_USDA'!Q706:Q752,'Donnees_USDA'!Q906:Q952) -> 2742.7852 | F19: =SUMPRODUCT('Donnees_USDA'!Q506:Q552,'Donnees_USDA'!Q906:Q952)+SUMPRODUCT('Donnees_USDA'!Q606:Q652,'Donnees_USDA'!Q906:Q952) -> 86159.897 | G19: =E19/F19 -> 0.031833664 | H19: ='Prix_ICE'!J19 -> 333.06 | I19: ='Prix_ICE'!L19 -> 4701.7435
A20: 2025/26 | B20: =SUMPRODUCT('Donnees_USDA'!R706:R752,'Donnees_USDA'!R806:R852) -> 10789.607 | C20: =SUMPRODUCT('Donnees_USDA'!R506:R552,'Donnees_USDA'!R806:R852)+SUMPRODUCT('Donnees_USDA'!R606:R652,'Donnees_USDA'!R806:R852) -> 130872.03 | D20: =B20/C20 -> 0.082443946 | E20: =SUMPRODUCT('Donnees_USDA'!R706:R752,'Donnees_USDA'!R906:R952) -> 3880.3932 | F20: =SUMPRODUCT('Donnees_USDA'!R506:R552,'Donnees_USDA'!R906:R952)+SUMPRODUCT('Donnees_USDA'!R606:R652,'Donnees_USDA'!R906:R952) -> 95265.968 | G20: =E20/F20 -> 0.040732208 | H20: ='Prix_ICE'!J20 -> 312.21 | I20: ='Prix_ICE'!L20 -> 3788.4636
A21: 2026/27 (prév.) | B21: =SUMPRODUCT('Donnees_USDA'!S706:S752,'Donnees_USDA'!S806:S852) -> 11284.833 | C21: =SUMPRODUCT('Donnees_USDA'!S506:S552,'Donnees_USDA'!S806:S852)+SUMPRODUCT('Donnees_USDA'!S606:S652,'Donnees_USDA'!S806:S852) -> 145437.03 | D21: =B21/C21 -> 0.077592572 | E21: =SUMPRODUCT('Donnees_USDA'!S706:S752,'Donnees_USDA'!S906:S952) -> 3398.1665 | F21: =SUMPRODUCT('Donnees_USDA'!S506:S552,'Donnees_USDA'!S906:S952)+SUMPRODUCT('Donnees_USDA'!S606:S652,'Donnees_USDA'!S906:S952) -> 96607.967 | G21: =E21/F21 -> 0.035174806

Sheet 3_Groupes_pays
A1: 3 — STU par addition des pays : ARABICA (8 pays) et ROBUSTA (4 pays) vs KC1 / DF1
A2: Arabica : Brésil, Colombie, Honduras, Éthiopie, Pérou, Mexique, Guatemala, Costa Rica. Robusta : Brésil, Vietnam, Indonésie, Ouganda.
A3: Chaque pays : stocks de fin USDA et conso + export USDA, additionnés. Le Brésil (présent dans les deux listes) est réparti selon sa part arabica / robusta de l'année ; colonnes J-K = addition brute (Brésil compté à 100 % dans les deux) pour comparaison.
A4: Campagne | B4: Stocks arabica 8 pays | C4: Conso + export arabica 8 pays | D4: STU ARABICA 8 pays | E4: Stocks robusta 4 pays | F4: Conso + export robusta 4 pays | G4: STU ROBUSTA 4 pays | H4: KC1 NY (US c/lb) | I4: DF1 Londres (US$/t) | J4: STU arabica 8 pays — addition brute | K4: STU robusta 4 pays — addition brute
A5: 2010/11 | B5: ='Donnees_USDA'!C706*'Donnees_USDA'!C806+'Donnees_USDA'!C708*'Donnees_USDA'!C808+'Donnees_USDA'!C713*'Donnees_USDA'!C813+'Donnees_USDA'!C709*'Donnees_USDA'!C809+'Donnees_USDA'!C714*'Donnees_USDA'!C814+'Donnees_USDA'!C715*'Donnees_USDA'!C815+'Donnees_USDA'!C716*'Donnees_USDA'!C816+'Donnees_USDA'!C722*'Donnees_USDA'!C822 -> 3102.7735 | C5: =('Donnees_USDA'!C506+'Donnees_USDA'!C606)*'Donnees_USDA'!C806+('Donnees_USDA'!C508+'Donnees_USDA'!C608)*'Donnees_USDA'!C808+('Donnees_USDA'!C513+'Donnees_USDA'!C613)*'Donnees_USDA'!C813+('Donnees_USDA'!C509+'Donnees_USDA'!C609)*'Donnees_USDA'!C809+('Donnees_USDA'!C514+'Donnees_USDA'!C614)*'Donnees_USDA'!C814+('Donnees_USDA'!C515+'Donnees_USDA'!C615)*'Donnees_USDA'!C815+('Donnees_USDA'!C516+'Donnees_USDA'!C616)*'Donnees_USDA'!C816+('Donnees_USDA'!C522+'Donnees_USDA'!C622)*'Donnees_USDA'!C822 -> 76339.832 | D5: =B5/C5 -> 0.040644228 | E5: ='Donnees_USDA'!C706*'Donnees_USDA'!C906+'Donnees_USDA'!C707*'Donnees_USDA'!C907+'Donnees_USDA'!C710*'Donnees_USDA'!C910+'Donnees_USDA'!C711*'Donnees_USDA'!C911 -> 2011.2506 | F5: =('Donnees_USDA'!C506+'Donnees_USDA'!C606)*'Donnees_USDA'!C906+('Donnees_USDA'!C507+'Donnees_USDA'!C607)*'Donnees_USDA'!C907+('Donnees_USDA'!C510+'Donnees_USDA'!C610)*'Donnees_USDA'!C910+('Donnees_USDA'!C511+'Donnees_USDA'!C611)*'Donnees_USDA'!C911 -> 44332.213 | G5: =E5/F5 -> 0.045367702 | H5: ='Prix_ICE'!J5 -> 249.66 | I5: ='Prix_ICE'!L5 -> 2219.0813 | J5: =('Donnees_USDA'!C706+'Donnees_USDA'!C708+'Donnees_USDA'!C713+'Donnees_USDA'!C709+'Donnees_USDA'!C714+'Donnees_USDA'!C715+'Donnees_USDA'!C716+'Donnees_USDA'!C722)/('Donnees_USDA'!C506+'Donnees_USDA'!C606+'Donnees_USDA'!C508+'Donnees_USDA'!C608+'Donnees_USDA'!C513+'Donnees_USDA'!C613+'Donnees_USDA'!C509+'Donnees_USDA'!C609+'Donnees_USDA'!C514+'Donnees_USDA'!C614+'Donnees_USDA'!C515+'Donnees_USDA'!C615+'Donnees_USDA'!C516+'Donnees_USDA'!C616+'Donnees_USDA'!C522+'Donnees_USDA'!C622) -> 0.042388541 | K5: =('Donnees_USDA'!C706+'Donnees_USDA'!C707+'Donnees_USDA'!C710+'Donnees_USDA'!C711)/('Donnees_USDA'!C506+'Donnees_USDA'!C606+'Donnees_USDA'!C507+'Donnees_USDA'!C607+'Donnees_USDA'!C510+'Donnees_USDA'!C610+'Donnees_USDA'!C511+'Donnees_USDA'!C611) -> 0.049412372
A6: 2011/12 | B6: ='Donnees_USDA'!D706*'Donnees_USDA'!D806+'Donnees_USDA'!D708*'Donnees_USDA'!D808+'Donnees_USDA'!D713*'Donnees_USDA'!D813+'Donnees_USDA'!D709*'Donnees_USDA'!D809+'Donnees_USDA'!D714*'Donnees_USDA'!D814+'Donnees_USDA'!D715*'Donnees_USDA'!D815+'Donnees_USDA'!D716*'Donnees_USDA'!D816+'Donnees_USDA'!D722*'Donnees_USDA'!D822 -> 2846.6656 | C6: =('Donnees_USDA'!D506+'Donnees_USDA'!D606)*'Donnees_USDA'!D806+('Donnees_USDA'!D508+'Donnees_USDA'!D608)*'Donnees_USDA'!D808+('Donnees_USDA'!D513+'Donnees_USDA'!D613)*'Donnees_USDA'!D813+('Donnees_USDA'!D509+'Donnees_USDA'!D609)*'Donnees_USDA'!D809+('Donnees_USDA'!D514+'Donnees_USDA'!D614)*'Donnees_USDA'!D814+('Donnees_USDA'!D515+'Donnees_USDA'!D615)*'Donnees_USDA'!D815+('Donnees_USDA'!D516+'Donnees_USDA'!D616)*'Donnees_USDA'!D816+('Donnees_USDA'!D522+'Donnees_USDA'!D622)*'Donnees_USDA'!D822 -> 72489.178 | D6: =B6/C6 -> 0.039270214 | E6: ='Donnees_USDA'!D706*'Donnees_USDA'!D906+'Donnees_USDA'!D707*'Donnees_USDA'!D907+'Donnees_USDA'!D710*'Donnees_USDA'!D910+'Donnees_USDA'!D711*'Donnees_USDA'!D911 -> 2174.5915 | F6: =('Donnees_USDA'!D506+'Donnees_USDA'!D606)*'Donnees_USDA'!D906+('Donnees_USDA'!D507+'Donnees_USDA'!D607)*'Donnees_USDA'!D907+('Donnees_USDA'!D510+'Donnees_USDA'!D610)*'Donnees_USDA'!D910+('Donnees_USDA'!D511+'Donnees_USDA'!D611)*'Donnees_USDA'!D911 -> 50063.56 | G6: =E6/F6 -> 0.043436612 | H6: ='Prix_ICE'!J6 -> 197.84167 | I6: ='Prix_ICE'!L6 -> 2014.676 | J6: =('Donnees_USDA'!D706+'Donnees_USDA'!D708+'Donnees_USDA'!D713+'Donnees_USDA'!D709+'Donnees_USDA'!D714+'Donnees_USDA'!D715+'Donnees_USDA'!D716+'Donnees_USDA'!D722)/('Donnees_USDA'!D506+'Donnees_USDA'!D606+'Donnees_USDA'!D508+'Donnees_USDA'!D608+'Donnees_USDA'!D513+'Donnees_USDA'!D613+'Donnees_USDA'!D509+'Donnees_USDA'!D609+'Donnees_USDA'!D514+'Donnees_USDA'!D614+'Donnees_USDA'!D515+'Donnees_USDA'!D615+'Donnees_USDA'!D516+'Donnees_USDA'!D616+'Donnees_USDA'!D522+'Donnees_USDA'!D622) -> 0.040133091 | K6: =('Donnees_USDA'!D706+'Donnees_USDA'!D707+'Donnees_USDA'!D710+'Donnees_USDA'!D711)/('Donnees_USDA'!D506+'Donnees_USDA'!D606+'Donnees_USDA'!D507+'Donnees_USDA'!D607+'Donnees_USDA'!D510+'Donnees_USDA'!D610+'Donnees_USDA'!D511+'Donnees_USDA'!D611) -> 0.044704233
A7: 2012/13 | B7: ='Donnees_USDA'!E706*'Donnees_USDA'!E806+'Donnees_USDA'!E708*'Donnees_USDA'!E808+'Donnees_USDA'!E713*'Donnees_USDA'!E813+'Donnees_USDA'!E709*'Donnees_USDA'!E809+'Donnees_USDA'!E714*'Donnees_USDA'!E814+'Donnees_USDA'!E715*'Donnees_USDA'!E815+'Donnees_USDA'!E716*'Donnees_USDA'!E816+'Donnees_USDA'!E722*'Donnees_USDA'!E822 -> 8142.6741 | C7: =('Donnees_USDA'!E506+'Donnees_USDA'!E606)*'Donnees_USDA'!E806+('Donnees_USDA'!E508+'Donnees_USDA'!E608)*'Donnees_USDA'!E808+('Donnees_USDA'!E513+'Donnees_USDA'!E613)*'Donnees_USDA'!E813+('Donnees_USDA'!E509+'Donnees_USDA'!E609)*'Donnees_USDA'!E809+('Donnees_USDA'!E514+'Donnees_USDA'!E614)*'Donnees_USDA'!E814+('Donnees_USDA'!E515+'Donnees_USDA'!E615)*'Donnees_USDA'!E815+('Donnees_USDA'!E516+'Donnees_USDA'!E616)*'Donnees_USDA'!E816+('Donnees_USDA'!E522+'Donnees_USDA'!E622)*'Donnees_USDA'!E822 -> 74429.176 | D7: =B7/C7 -> 0.10940164 | E7: ='Donnees_USDA'!E706*'Donnees_USDA'!E906+'Donnees_USDA'!E707*'Donnees_USDA'!E907+'Donnees_USDA'!E710*'Donnees_USDA'!E910+'Donnees_USDA'!E711*'Donnees_USDA'!E911 -> 4683.9458 | F7: =('Donnees_USDA'!E506+'Donnees_USDA'!E606)*'Donnees_USDA'!E906+('Donnees_USDA'!E507+'Donnees_USDA'!E607)*'Donnees_USDA'!E907+('Donnees_USDA'!E510+'Donnees_USDA'!E610)*'Donnees_USDA'!E910+('Donnees_USDA'!E511+'Donnees_USDA'!E611)*'Donnees_USDA'!E911 -> 53098.861 | G7: =E7/F7 -> 0.088211795 | H7: ='Prix_ICE'!J7 -> 140.69833 | I7: ='Prix_ICE'!L7 -> 1950.6685 | J7: =('Donnees_USDA'!E706+'Donnees_USDA'!E708+'Donnees_USDA'!E713+'Donnees_USDA'!E709+'Donnees_USDA'!E714+'Donnees_USDA'!E715+'Donnees_USDA'!E716+'Donnees_USDA'!E722)/('Donnees_USDA'!E506+'Donnees_USDA'!E606+'Donnees_USDA'!E508+'Donnees_USDA'!E608+'Donnees_USDA'!E513+'Donnees_USDA'!E613+'Donnees_USDA'!E509+'Donnees_USDA'!E609+'Donnees_USDA'!E514+'Donnees_USDA'!E614+'Donnees_USDA'!E515+'Donnees_USDA'!E615+'Donnees_USDA'!E516+'Donnees_USDA'!E616+'Donnees_USDA'!E522+'Donnees_USDA'!E622) -> 0.11981755 | K7: =('Donnees_USDA'!E706+'Donnees_USDA'!E707+'Donnees_USDA'!E710+'Donnees_USDA'!E711)/('Donnees_USDA'!E506+'Donnees_USDA'!E606+'Donnees_USDA'!E507+'Donnees_USDA'!E607+'Donnees_USDA'!E510+'Donnees_USDA'!E610+'Donnees_USDA'!E511+'Donnees_USDA'!E611) -> 0.1218761
A8: 2013/14 | B8: ='Donnees_USDA'!F706*'Donnees_USDA'!F806+'Donnees_USDA'!F708*'Donnees_USDA'!F808+'Donnees_USDA'!F713*'Donnees_USDA'!F813+'Donnees_USDA'!F709*'Donnees_USDA'!F809+'Donnees_USDA'!F714*'Donnees_USDA'!F814+'Donnees_USDA'!F715*'Donnees_USDA'!F815+'Donnees_USDA'!F716*'Donnees_USDA'!F816+'Donnees_USDA'!F722*'Donnees_USDA'!F822 -> 10559.295 | C8: =('Donnees_USDA'!F506+'Donnees_USDA'!F606)*'Donnees_USDA'!F806+('Donnees_USDA'!F508+'Donnees_USDA'!F608)*'Donnees_USDA'!F808+('Donnees_USDA'!F513+'Donnees_USDA'!F613)*'Donnees_USDA'!F813+('Donnees_USDA'!F509+'Donnees_USDA'!F609)*'Donnees_USDA'!F809+('Donnees_USDA'!F514+'Donnees_USDA'!F614)*'Donnees_USDA'!F814+('Donnees_USDA'!F515+'Donnees_USDA'!F615)*'Donnees_USDA'!F815+('Donnees_USDA'!F516+'Donnees_USDA'!F616)*'Donnees_USDA'!F816+('Donnees_USDA'!F522+'Donnees_USDA'!F622)*'Donnees_USDA'!F822 -> 77602.534 | D8: =B8/C8 -> 0.13606894 | E8: ='Donnees_USDA'!F706*'Donnees_USDA'!F906+'Donnees_USDA'!F707*'Donnees_USDA'!F907+'Donnees_USDA'!F710*'Donnees_USDA'!F910+'Donnees_USDA'!F711*'Donnees_USDA'!F911 -> 5608.9087 | F8: =('Donnees_USDA'!F506+'Donnees_USDA'!F606)*'Donnees_USDA'!F906+('Donnees_USDA'!F507+'Donnees_USDA'!F607)*'Donnees_USDA'!F907+('Donnees_USDA'!F510+'Donnees_USDA'!F610)*'Donnees_USDA'!F910+('Donnees_USDA'!F511+'Donnees_USDA'!F611)*'Donnees_USDA'!F911 -> 57571.799 | G8: =E8/F8 -> 0.097424586 | H8: ='Prix_ICE'!J8 -> 161.4675 | I8: ='Prix_ICE'!L8 -> 1893.2013 | J8: =('Donnees_USDA'!F706+'Donnees_USDA'!F708+'Donnees_USDA'!F713+'Donnees_USDA'!F709+'Donnees_USDA'!F714+'Donnees_USDA'!F715+'Donnees_USDA'!F716+'Donnees_USDA'!F722)/('Donnees_USDA'!F506+'Donnees_USDA'!F606+'Donnees_USDA'!F508+'Donnees_USDA'!F608+'Donnees_USDA'!F513+'Donnees_USDA'!F613+'Donnees_USDA'!F509+'Donnees_USDA'!F609+'Donnees_USDA'!F514+'Donnees_USDA'!F614+'Donnees_USDA'!F515+'Donnees_USDA'!F615+'Donnees_USDA'!F516+'Donnees_USDA'!F616+'Donnees_USDA'!F522+'Donnees_USDA'!F622) -> 0.14898032 | K8: =('Donnees_USDA'!F706+'Donnees_USDA'!F707+'Donnees_USDA'!F710+'Donnees_USDA'!F711)/('Donnees_USDA'!F506+'Donnees_USDA'!F606+'Donnees_USDA'!F507+'Donnees_USDA'!F607+'Donnees_USDA'!F510+'Donnees_USDA'!F610+'Donnees_USDA'!F511+'Donnees_USDA'!F611) -> 0.14317556
A9: 2014/15 | B9: ='Donnees_USDA'!G706*'Donnees_USDA'!G806+'Donnees_USDA'!G708*'Donnees_USDA'!G808+'Donnees_USDA'!G713*'Donnees_USDA'!G813+'Donnees_USDA'!G709*'Donnees_USDA'!G809+'Donnees_USDA'!G714*'Donnees_USDA'!G814+'Donnees_USDA'!G715*'Donnees_USDA'!G815+'Donnees_USDA'!G716*'Donnees_USDA'!G816+'Donnees_USDA'!G722*'Donnees_USDA'!G822 -> 7682.6882 | C9: =('Donnees_USDA'!G506+'Donnees_USDA'!G606)*'Donnees_USDA'!G806+('Donnees_USDA'!G508+'Donnees_USDA'!G608)*'Donnees_USDA'!G808+('Donnees_USDA'!G513+'Donnees_USDA'!G613)*'Donnees_USDA'!G813+('Donnees_USDA'!G509+'Donnees_USDA'!G609)*'Donnees_USDA'!G809+('Donnees_USDA'!G514+'Donnees_USDA'!G614)*'Donnees_USDA'!G814+('Donnees_USDA'!G515+'Donnees_USDA'!G615)*'Donnees_USDA'!G815+('Donnees_USDA'!G516+'Donnees_USDA'!G616)*'Donnees_USDA'!G816+('Donnees_USDA'!G522+'Donnees_USDA'!G622)*'Donnees_USDA'!G822 -> 77125.522 | D9: =B9/C9 -> 0.099612787 | E9: ='Donnees_USDA'!G706*'Donnees_USDA'!G906+'Donnees_USDA'!G707*'Donnees_USDA'!G907+'Donnees_USDA'!G710*'Donnees_USDA'!G910+'Donnees_USDA'!G711*'Donnees_USDA'!G911 -> 9294.393 | F9: =('Donnees_USDA'!G506+'Donnees_USDA'!G606)*'Donnees_USDA'!G906+('Donnees_USDA'!G507+'Donnees_USDA'!G607)*'Donnees_USDA'!G907+('Donnees_USDA'!G510+'Donnees_USDA'!G610)*'Donnees_USDA'!G910+('Donnees_USDA'!G511+'Donnees_USDA'!G611)*'Donnees_USDA'!G911 -> 53687.902 | G9: =E9/F9 -> 0.17311894 | H9: ='Prix_ICE'!J9 -> 154.02083 | I9: ='Prix_ICE'!L9 -> 1849.9172 | J9: =('Donnees_USDA'!G706+'Donnees_USDA'!G708+'Donnees_USDA'!G713+'Donnees_USDA'!G709+'Donnees_USDA'!G714+'Donnees_USDA'!G715+'Donnees_USDA'!G716+'Donnees_USDA'!G722)/('Donnees_USDA'!G506+'Donnees_USDA'!G606+'Donnees_USDA'!G508+'Donnees_USDA'!G608+'Donnees_USDA'!G513+'Donnees_USDA'!G613+'Donnees_USDA'!G509+'Donnees_USDA'!G609+'Donnees_USDA'!G514+'Donnees_USDA'!G614+'Donnees_USDA'!G515+'Donnees_USDA'!G615+'Donnees_USDA'!G516+'Donnees_USDA'!G616+'Donnees_USDA'!G522+'Donnees_USDA'!G622) -> 0.11121833 | K9: =('Donnees_USDA'!G706+'Donnees_USDA'!G707+'Donnees_USDA'!G710+'Donnees_USDA'!G711)/('Donnees_USDA'!G506+'Donnees_USDA'!G606+'Donnees_USDA'!G507+'Donnees_USDA'!G607+'Donnees_USDA'!G510+'Donnees_USDA'!G610+'Donnees_USDA'!G511+'Donnees_USDA'!G611) -> 0.16677954
A10: 2015/16 | B10: ='Donnees_USDA'!H706*'Donnees_USDA'!H806+'Donnees_USDA'!H708*'Donnees_USDA'!H808+'Donnees_USDA'!H713*'Donnees_USDA'!H813+'Donnees_USDA'!H709*'Donnees_USDA'!H809+'Donnees_USDA'!H714*'Donnees_USDA'!H814+'Donnees_USDA'!H715*'Donnees_USDA'!H815+'Donnees_USDA'!H716*'Donnees_USDA'!H816+'Donnees_USDA'!H722*'Donnees_USDA'!H822 -> 3783.0649 | C10: =('Donnees_USDA'!H506+'Donnees_USDA'!H606)*'Donnees_USDA'!H806+('Donnees_USDA'!H508+'Donnees_USDA'!H608)*'Donnees_USDA'!H808+('Donnees_USDA'!H513+'Donnees_USDA'!H613)*'Donnees_USDA'!H813+('Donnees_USDA'!H509+'Donnees_USDA'!H609)*'Donnees_USDA'!H809+('Donnees_USDA'!H514+'Donnees_USDA'!H614)*'Donnees_USDA'!H814+('Donnees_USDA'!H515+'Donnees_USDA'!H615)*'Donnees_USDA'!H815+('Donnees_USDA'!H516+'Donnees_USDA'!H616)*'Donnees_USDA'!H816+('Donnees_USDA'!H522+'Donnees_USDA'!H622)*'Donnees_USDA'!H822 -> 79548.742 | D10: =B10/C10 -> 0.047556565 | E10: ='Donnees_USDA'!H706*'Donnees_USDA'!H906+'Donnees_USDA'!H707*'Donnees_USDA'!H907+'Donnees_USDA'!H710*'Donnees_USDA'!H910+'Donnees_USDA'!H711*'Donnees_USDA'!H911 -> 4949.4185 | F10: =('Donnees_USDA'!H506+'Donnees_USDA'!H606)*'Donnees_USDA'!H906+('Donnees_USDA'!H507+'Donnees_USDA'!H607)*'Donnees_USDA'!H907+('Donnees_USDA'!H510+'Donnees_USDA'!H610)*'Donnees_USDA'!H910+('Donnees_USDA'!H511+'Donnees_USDA'!H611)*'Donnees_USDA'!H911 -> 59724.572 | G10: =E10/F10 -> 0.082870724 | H10: ='Prix_ICE'!J10 -> 131.8325 | I10: ='Prix_ICE'!L10 -> 1632.9272 | J10: =('Donnees_USDA'!H706+'Donnees_USDA'!H708+'Donnees_USDA'!H713+'Donnees_USDA'!H709+'Donnees_USDA'!H714+'Donnees_USDA'!H715+'Donnees_USDA'!H716+'Donnees_USDA'!H722)/('Donnees_USDA'!H506+'Donnees_USDA'!H606+'Donnees_USDA'!H508+'Donnees_USDA'!H608+'Donnees_USDA'!H513+'Donnees_USDA'!H613+'Donnees_USDA'!H509+'Donnees_USDA'!H609+'Donnees_USDA'!H514+'Donnees_USDA'!H614+'Donnees_USDA'!H515+'Donnees_USDA'!H615+'Donnees_USDA'!H516+'Donnees_USDA'!H616+'Donnees_USDA'!H522+'Donnees_USDA'!H622) -> 0.046595358 | K10: =('Donnees_USDA'!H706+'Donnees_USDA'!H707+'Donnees_USDA'!H710+'Donnees_USDA'!H711)/('Donnees_USDA'!H506+'Donnees_USDA'!H606+'Donnees_USDA'!H507+'Donnees_USDA'!H607+'Donnees_USDA'!H510+'Donnees_USDA'!H610+'Donnees_USDA'!H511+'Donnees_USDA'!H611) -> 0.066199362
A11: 2016/17 | B11: ='Donnees_USDA'!I706*'Donnees_USDA'!I806+'Donnees_USDA'!I708*'Donnees_USDA'!I808+'Donnees_USDA'!I713*'Donnees_USDA'!I813+'Donnees_USDA'!I709*'Donnees_USDA'!I809+'Donnees_USDA'!I714*'Donnees_USDA'!I814+'Donnees_USDA'!I715*'Donnees_USDA'!I815+'Donnees_USDA'!I716*'Donnees_USDA'!I816+'Donnees_USDA'!I722*'Donnees_USDA'!I822 -> 4791.5424 | C11: =('Donnees_USDA'!I506+'Donnees_USDA'!I606)*'Donnees_USDA'!I806+('Donnees_USDA'!I508+'Donnees_USDA'!I608)*'Donnees_USDA'!I808+('Donnees_USDA'!I513+'Donnees_USDA'!I613)*'Donnees_USDA'!I813+('Donnees_USDA'!I509+'Donnees_USDA'!I609)*'Donnees_USDA'!I809+('Donnees_USDA'!I514+'Donnees_USDA'!I614)*'Donnees_USDA'!I814+('Donnees_USDA'!I515+'Donnees_USDA'!I615)*'Donnees_USDA'!I815+('Donnees_USDA'!I516+'Donnees_USDA'!I616)*'Donnees_USDA'!I816+('Donnees_USDA'!I522+'Donnees_USDA'!I622)*'Donnees_USDA'!I822 -> 88107.368 | D11: =B11/C11 -> 0.054382993 | E11: ='Donnees_USDA'!I706*'Donnees_USDA'!I906+'Donnees_USDA'!I707*'Donnees_USDA'!I907+'Donnees_USDA'!I710*'Donnees_USDA'!I910+'Donnees_USDA'!I711*'Donnees_USDA'!I911 -> 3559.279 | F11: =('Donnees_USDA'!I506+'Donnees_USDA'!I606)*'Donnees_USDA'!I906+('Donnees_USDA'!I507+'Donnees_USDA'!I607)*'Donnees_USDA'!I907+('Donnees_USDA'!I510+'Donnees_USDA'!I610)*'Donnees_USDA'!I910+('Donnees_USDA'!I511+'Donnees_USDA'!I611)*'Donnees_USDA'!I911 -> 51992.619 | G11: =E11/F11 -> 0.068457391 | H11: ='Prix_ICE'!J11 -> 143.77167 | I11: ='Prix_ICE'!L11 -> 2097.1105 | J11: =('Donnees_USDA'!I706+'Donnees_USDA'!I708+'Donnees_USDA'!I713+'Donnees_USDA'!I709+'Donnees_USDA'!I714+'Donnees_USDA'!I715+'Donnees_USDA'!I716+'Donnees_USDA'!I722)/('Donnees_USDA'!I506+'Donnees_USDA'!I606+'Donnees_USDA'!I508+'Donnees_USDA'!I608+'Donnees_USDA'!I513+'Donnees_USDA'!I613+'Donnees_USDA'!I509+'Donnees_USDA'!I609+'Donnees_USDA'!I514+'Donnees_USDA'!I614+'Donnees_USDA'!I515+'Donnees_USDA'!I615+'Donnees_USDA'!I516+'Donnees_USDA'!I616+'Donnees_USDA'!I522+'Donnees_USDA'!I622) -> 0.055846193 | K11: =('Donnees_USDA'!I706+'Donnees_USDA'!I707+'Donnees_USDA'!I710+'Donnees_USDA'!I711)/('Donnees_USDA'!I506+'Donnees_USDA'!I606+'Donnees_USDA'!I507+'Donnees_USDA'!I607+'Donnees_USDA'!I510+'Donnees_USDA'!I610+'Donnees_USDA'!I511+'Donnees_USDA'!I611) -> 0.068485218
A12: 2017/18 | B12: ='Donnees_USDA'!J706*'Donnees_USDA'!J806+'Donnees_USDA'!J708*'Donnees_USDA'!J808+'Donnees_USDA'!J713*'Donnees_USDA'!J813+'Donnees_USDA'!J709*'Donnees_USDA'!J809+'Donnees_USDA'!J714*'Donnees_USDA'!J814+'Donnees_USDA'!J715*'Donnees_USDA'!J815+'Donnees_USDA'!J716*'Donnees_USDA'!J816+'Donnees_USDA'!J722*'Donnees_USDA'!J822 -> 4440.4626 | C12: =('Donnees_USDA'!J506+'Donnees_USDA'!J606)*'Donnees_USDA'!J806+('Donnees_USDA'!J508+'Donnees_USDA'!J608)*'Donnees_USDA'!J808+('Donnees_USDA'!J513+'Donnees_USDA'!J613)*'Donnees_USDA'!J813+('Donnees_USDA'!J509+'Donnees_USDA'!J609)*'Donnees_USDA'!J809+('Donnees_USDA'!J514+'Donnees_USDA'!J614)*'Donnees_USDA'!J814+('Donnees_USDA'!J515+'Donnees_USDA'!J615)*'Donnees_USDA'!J815+('Donnees_USDA'!J516+'Donnees_USDA'!J616)*'Donnees_USDA'!J816+('Donnees_USDA'!J522+'Donnees_USDA'!J622)*'Donnees_USDA'!J822 -> 84057.969 | D12: =B12/C12 -> 0.052826195 | E12: ='Donnees_USDA'!J706*'Donnees_USDA'!J906+'Donnees_USDA'!J707*'Donnees_USDA'!J907+'Donnees_USDA'!J710*'Donnees_USDA'!J910+'Donnees_USDA'!J711*'Donnees_USDA'!J911 -> 1821.2088 | F12: =('Donnees_USDA'!J506+'Donnees_USDA'!J606)*'Donnees_USDA'!J906+('Donnees_USDA'!J507+'Donnees_USDA'!J607)*'Donnees_USDA'!J907+('Donnees_USDA'!J510+'Donnees_USDA'!J610)*'Donnees_USDA'!J910+('Donnees_USDA'!J511+'Donnees_USDA'!J611)*'Donnees_USDA'!J911 -> 58246.625 | G12: =E12/F12 -> 0.031267198 | H12: ='Prix_ICE'!J12 -> 120.60083 | I12: ='Prix_ICE'!L12 -> 1725.8888 | J12: =('Donnees_USDA'!J706+'Donnees_USDA'!J708+'Donnees_USDA'!J713+'Donnees_USDA'!J709+'Donnees_USDA'!J714+'Donnees_USDA'!J715+'Donnees_USDA'!J716+'Donnees_USDA'!J722)/('Donnees_USDA'!J506+'Donnees_USDA'!J606+'Donnees_USDA'!J508+'Donnees_USDA'!J608+'Donnees_USDA'!J513+'Donnees_USDA'!J613+'Donnees_USDA'!J509+'Donnees_USDA'!J609+'Donnees_USDA'!J514+'Donnees_USDA'!J614+'Donnees_USDA'!J515+'Donnees_USDA'!J615+'Donnees_USDA'!J516+'Donnees_USDA'!J616+'Donnees_USDA'!J522+'Donnees_USDA'!J622) -> 0.053520229 | K12: =('Donnees_USDA'!J706+'Donnees_USDA'!J707+'Donnees_USDA'!J710+'Donnees_USDA'!J711)/('Donnees_USDA'!J506+'Donnees_USDA'!J606+'Donnees_USDA'!J507+'Donnees_USDA'!J607+'Donnees_USDA'!J510+'Donnees_USDA'!J610+'Donnees_USDA'!J511+'Donnees_USDA'!J611) -> 0.042738822
A13: 2018/19 | B13: ='Donnees_USDA'!K706*'Donnees_USDA'!K806+'Donnees_USDA'!K708*'Donnees_USDA'!K808+'Donnees_USDA'!K713*'Donnees_USDA'!K813+'Donnees_USDA'!K709*'Donnees_USDA'!K809+'Donnees_USDA'!K714*'Donnees_USDA'!K814+'Donnees_USDA'!K715*'Donnees_USDA'!K815+'Donnees_USDA'!K716*'Donnees_USDA'!K816+'Donnees_USDA'!K722*'Donnees_USDA'!K822 -> 4786.8016 | C13: =('Donnees_USDA'!K506+'Donnees_USDA'!K606)*'Donnees_USDA'!K806+('Donnees_USDA'!K508+'Donnees_USDA'!K608)*'Donnees_USDA'!K808+('Donnees_USDA'!K513+'Donnees_USDA'!K613)*'Donnees_USDA'!K813+('Donnees_USDA'!K509+'Donnees_USDA'!K609)*'Donnees_USDA'!K809+('Donnees_USDA'!K514+'Donnees_USDA'!K614)*'Donnees_USDA'!K814+('Donnees_USDA'!K515+'Donnees_USDA'!K615)*'Donnees_USDA'!K815+('Donnees_USDA'!K516+'Donnees_USDA'!K616)*'Donnees_USDA'!K816+('Donnees_USDA'!K522+'Donnees_USDA'!K622)*'Donnees_USDA'!K822 -> 93063.474 | D13: =B13/C13 -> 0.051435879 | E13: ='Donnees_USDA'!K706*'Donnees_USDA'!K906+'Donnees_USDA'!K707*'Donnees_USDA'!K907+'Donnees_USDA'!K710*'Donnees_USDA'!K910+'Donnees_USDA'!K711*'Donnees_USDA'!K911 -> 4220.6736 | F13: =('Donnees_USDA'!K506+'Donnees_USDA'!K606)*'Donnees_USDA'!K906+('Donnees_USDA'!K507+'Donnees_USDA'!K607)*'Donnees_USDA'!K907+('Donnees_USDA'!K510+'Donnees_USDA'!K610)*'Donnees_USDA'!K910+('Donnees_USDA'!K511+'Donnees_USDA'!K611)*'Donnees_USDA'!K911 -> 59396.229 | G13: =E13/F13 -> 0.071059622 | H13: ='Prix_ICE'!J13 -> 104.98083 | I13: ='Prix_ICE'!L13 -> 1488.8368 | J13: =('Donnees_USDA'!K706+'Donnees_USDA'!K708+'Donnees_USDA'!K713+'Donnees_USDA'!K709+'Donnees_USDA'!K714+'Donnees_USDA'!K715+'Donnees_USDA'!K716+'Donnees_USDA'!K722)/('Donnees_USDA'!K506+'Donnees_USDA'!K606+'Donnees_USDA'!K508+'Donnees_USDA'!K608+'Donnees_USDA'!K513+'Donnees_USDA'!K613+'Donnees_USDA'!K509+'Donnees_USDA'!K609+'Donnees_USDA'!K514+'Donnees_USDA'!K614+'Donnees_USDA'!K515+'Donnees_USDA'!K615+'Donnees_USDA'!K516+'Donnees_USDA'!K616+'Donnees_USDA'!K522+'Donnees_USDA'!K622) -> 0.054994744 | K13: =('Donnees_USDA'!K706+'Donnees_USDA'!K707+'Donnees_USDA'!K710+'Donnees_USDA'!K711)/('Donnees_USDA'!K506+'Donnees_USDA'!K606+'Donnees_USDA'!K507+'Donnees_USDA'!K607+'Donnees_USDA'!K510+'Donnees_USDA'!K610+'Donnees_USDA'!K511+'Donnees_USDA'!K611) -> 0.075373309
A14: 2019/20 | B14: ='Donnees_USDA'!L706*'Donnees_USDA'!L806+'Donnees_USDA'!L708*'Donnees_USDA'!L808+'Donnees_USDA'!L713*'Donnees_USDA'!L813+'Donnees_USDA'!L709*'Donnees_USDA'!L809+'Donnees_USDA'!L714*'Donnees_USDA'!L814+'Donnees_USDA'!L715*'Donnees_USDA'!L815+'Donnees_USDA'!L716*'Donnees_USDA'!L816+'Donnees_USDA'!L722*'Donnees_USDA'!L822 -> 3458.3758 | C14: =('Donnees_USDA'!L506+'Donnees_USDA'!L606)*'Donnees_USDA'!L806+('Donnees_USDA'!L508+'Donnees_USDA'!L608)*'Donnees_USDA'!L808+('Donnees_USDA'!L513+'Donnees_USDA'!L613)*'Donnees_USDA'!L813+('Donnees_USDA'!L509+'Donnees_USDA'!L609)*'Donnees_USDA'!L809+('Donnees_USDA'!L514+'Donnees_USDA'!L614)*'Donnees_USDA'!L814+('Donnees_USDA'!L515+'Donnees_USDA'!L615)*'Donnees_USDA'!L815+('Donnees_USDA'!L516+'Donnees_USDA'!L616)*'Donnees_USDA'!L816+('Donnees_USDA'!L522+'Donnees_USDA'!L622)*'Donnees_USDA'!L822 -> 85253.277 | D14: =B14/C14 -> 0.040565899 | E14: ='Donnees_USDA'!L706*'Donnees_USDA'!L906+'Donnees_USDA'!L707*'Donnees_USDA'!L907+'Donnees_USDA'!L710*'Donnees_USDA'!L910+'Donnees_USDA'!L711*'Donnees_USDA'!L911 -> 5105.355 | F14: =('Donnees_USDA'!L506+'Donnees_USDA'!L606)*'Donnees_USDA'!L906+('Donnees_USDA'!L507+'Donnees_USDA'!L607)*'Donnees_USDA'!L907+('Donnees_USDA'!L510+'Donnees_USDA'!L610)*'Donnees_USDA'!L910+('Donnees_USDA'!L511+'Donnees_USDA'!L611)*'Donnees_USDA'!L911 -> 63771.361 | G14: =E14/F14 -> 0.080057175 | H14: ='Prix_ICE'!J14 -> 113.23667 | I14: ='Prix_ICE'!L14 -> 1305.5959 | J14: =('Donnees_USDA'!L706+'Donnees_USDA'!L708+'Donnees_USDA'!L713+'Donnees_USDA'!L709+'Donnees_USDA'!L714+'Donnees_USDA'!L715+'Donnees_USDA'!L716+'Donnees_USDA'!L722)/('Donnees_USDA'!L506+'Donnees_USDA'!L606+'Donnees_USDA'!L508+'Donnees_USDA'!L608+'Donnees_USDA'!L513+'Donnees_USDA'!L613+'Donnees_USDA'!L509+'Donnees_USDA'!L609+'Donnees_USDA'!L514+'Donnees_USDA'!L614+'Donnees_USDA'!L515+'Donnees_USDA'!L615+'Donnees_USDA'!L516+'Donnees_USDA'!L616+'Donnees_USDA'!L522+'Donnees_USDA'!L622) -> 0.039814332 | K14: =('Donnees_USDA'!L706+'Donnees_USDA'!L707+'Donnees_USDA'!L710+'Donnees_USDA'!L711)/('Donnees_USDA'!L506+'Donnees_USDA'!L606+'Donnees_USDA'!L507+'Donnees_USDA'!L607+'Donnees_USDA'!L510+'Donnees_USDA'!L610+'Donnees_USDA'!L511+'Donnees_USDA'!L611) -> 0.064437209
A15: 2020/21 | B15: ='Donnees_USDA'!M706*'Donnees_USDA'!M806+'Donnees_USDA'!M708*'Donnees_USDA'!M808+'Donnees_USDA'!M713*'Donnees_USDA'!M813+'Donnees_USDA'!M709*'Donnees_USDA'!M809+'Donnees_USDA'!M714*'Donnees_USDA'!M814+'Donnees_USDA'!M715*'Donnees_USDA'!M815+'Donnees_USDA'!M716*'Donnees_USDA'!M816+'Donnees_USDA'!M722*'Donnees_USDA'!M822 -> 5248.4174 | C15: =('Donnees_USDA'!M506+'Donnees_USDA'!M606)*'Donnees_USDA'!M806+('Donnees_USDA'!M508+'Donnees_USDA'!M608)*'Donnees_USDA'!M808+('Donnees_USDA'!M513+'Donnees_USDA'!M613)*'Donnees_USDA'!M813+('Donnees_USDA'!M509+'Donnees_USDA'!M609)*'Donnees_USDA'!M809+('Donnees_USDA'!M514+'Donnees_USDA'!M614)*'Donnees_USDA'!M814+('Donnees_USDA'!M515+'Donnees_USDA'!M615)*'Donnees_USDA'!M815+('Donnees_USDA'!M516+'Donnees_USDA'!M616)*'Donnees_USDA'!M816+('Donnees_USDA'!M522+'Donnees_USDA'!M622)*'Donnees_USDA'!M822 -> 91328.584 | D15: =B15/C15 -> 0.057467412 | E15: ='Donnees_USDA'!M706*'Donnees_USDA'!M906+'Donnees_USDA'!M707*'Donnees_USDA'!M907+'Donnees_USDA'!M710*'Donnees_USDA'!M910+'Donnees_USDA'!M711*'Donnees_USDA'!M911 -> 6612.2386 | F15: =('Donnees_USDA'!M506+'Donnees_USDA'!M606)*'Donnees_USDA'!M906+('Donnees_USDA'!M507+'Donnees_USDA'!M607)*'Donnees_USDA'!M907+('Donnees_USDA'!M510+'Donnees_USDA'!M610)*'Donnees_USDA'!M910+('Donnees_USDA'!M511+'Donnees_USDA'!M611)*'Donnees_USDA'!M911 -> 63450.725 | G15: =E15/F15 -> 0.10421061 | H15: ='Prix_ICE'!J15 -> 143.75333 | I15: ='Prix_ICE'!L15 -> 1540.9394 | J15: =('Donnees_USDA'!M706+'Donnees_USDA'!M708+'Donnees_USDA'!M713+'Donnees_USDA'!M709+'Donnees_USDA'!M714+'Donnees_USDA'!M715+'Donnees_USDA'!M716+'Donnees_USDA'!M722)/('Donnees_USDA'!M506+'Donnees_USDA'!M606+'Donnees_USDA'!M508+'Donnees_USDA'!M608+'Donnees_USDA'!M513+'Donnees_USDA'!M613+'Donnees_USDA'!M509+'Donnees_USDA'!M609+'Donnees_USDA'!M514+'Donnees_USDA'!M614+'Donnees_USDA'!M515+'Donnees_USDA'!M615+'Donnees_USDA'!M516+'Donnees_USDA'!M616+'Donnees_USDA'!M522+'Donnees_USDA'!M622) -> 0.05827333 | K15: =('Donnees_USDA'!M706+'Donnees_USDA'!M707+'Donnees_USDA'!M710+'Donnees_USDA'!M711)/('Donnees_USDA'!M506+'Donnees_USDA'!M606+'Donnees_USDA'!M507+'Donnees_USDA'!M607+'Donnees_USDA'!M510+'Donnees_USDA'!M610+'Donnees_USDA'!M511+'Donnees_USDA'!M611) -> 0.087876705
A16: 2021/22 | B16: ='Donnees_USDA'!N706*'Donnees_USDA'!N806+'Donnees_USDA'!N708*'Donnees_USDA'!N808+'Donnees_USDA'!N713*'Donnees_USDA'!N813+'Donnees_USDA'!N709*'Donnees_USDA'!N809+'Donnees_USDA'!N714*'Donnees_USDA'!N814+'Donnees_USDA'!N715*'Donnees_USDA'!N815+'Donnees_USDA'!N716*'Donnees_USDA'!N816+'Donnees_USDA'!N722*'Donnees_USDA'!N822 -> 1696.2479 | C16: =('Donnees_USDA'!N506+'Donnees_USDA'!N606)*'Donnees_USDA'!N806+('Donnees_USDA'!N508+'Donnees_USDA'!N608)*'Donnees_USDA'!N808+('Donnees_USDA'!N513+'Donnees_USDA'!N613)*'Donnees_USDA'!N813+('Donnees_USDA'!N509+'Donnees_USDA'!N609)*'Donnees_USDA'!N809+('Donnees_USDA'!N514+'Donnees_USDA'!N614)*'Donnees_USDA'!N814+('Donnees_USDA'!N515+'Donnees_USDA'!N615)*'Donnees_USDA'!N815+('Donnees_USDA'!N516+'Donnees_USDA'!N616)*'Donnees_USDA'!N816+('Donnees_USDA'!N522+'Donnees_USDA'!N622)*'Donnees_USDA'!N822 -> 81137.936 | D16: =B16/C16 -> 0.020905732 | E16: ='Donnees_USDA'!N706*'Donnees_USDA'!N906+'Donnees_USDA'!N707*'Donnees_USDA'!N907+'Donnees_USDA'!N710*'Donnees_USDA'!N910+'Donnees_USDA'!N711*'Donnees_USDA'!N911 -> 4964.9386 | F16: =('Donnees_USDA'!N506+'Donnees_USDA'!N606)*'Donnees_USDA'!N906+('Donnees_USDA'!N507+'Donnees_USDA'!N607)*'Donnees_USDA'!N907+('Donnees_USDA'!N510+'Donnees_USDA'!N610)*'Donnees_USDA'!N910+('Donnees_USDA'!N511+'Donnees_USDA'!N611)*'Donnees_USDA'!N911 -> 69955.962 | G16: =E16/F16 -> 0.070972345 | H16: ='Prix_ICE'!J16 -> 224.0875 | I16: ='Prix_ICE'!L16 -> 2150.1501 | J16: =('Donnees_USDA'!N706+'Donnees_USDA'!N708+'Donnees_USDA'!N713+'Donnees_USDA'!N709+'Donnees_USDA'!N714+'Donnees_USDA'!N715+'Donnees_USDA'!N716+'Donnees_USDA'!N722)/('Donnees_USDA'!N506+'Donnees_USDA'!N606+'Donnees_USDA'!N508+'Donnees_USDA'!N608+'Donnees_USDA'!N513+'Donnees_USDA'!N613+'Donnees_USDA'!N509+'Donnees_USDA'!N609+'Donnees_USDA'!N514+'Donnees_USDA'!N614+'Donnees_USDA'!N515+'Donnees_USDA'!N615+'Donnees_USDA'!N516+'Donnees_USDA'!N616+'Donnees_USDA'!N522+'Donnees_USDA'!N622) -> 0.01816973 | K16: =('Donnees_USDA'!N706+'Donnees_USDA'!N707+'Donnees_USDA'!N710+'Donnees_USDA'!N711)/('Donnees_USDA'!N506+'Donnees_USDA'!N606+'Donnees_USDA'!N507+'Donnees_USDA'!N607+'Donnees_USDA'!N510+'Donnees_USDA'!N610+'Donnees_USDA'!N511+'Donnees_USDA'!N611) -> 0.050094316
A17: 2022/23 | B17: ='Donnees_USDA'!O706*'Donnees_USDA'!O806+'Donnees_USDA'!O708*'Donnees_USDA'!O808+'Donnees_USDA'!O713*'Donnees_USDA'!O813+'Donnees_USDA'!O709*'Donnees_USDA'!O809+'Donnees_USDA'!O714*'Donnees_USDA'!O814+'Donnees_USDA'!O715*'Donnees_USDA'!O815+'Donnees_USDA'!O716*'Donnees_USDA'!O816+'Donnees_USDA'!O722*'Donnees_USDA'!O822 -> 4348.3637 | C17: =('Donnees_USDA'!O506+'Donnees_USDA'!O606)*'Donnees_USDA'!O806+('Donnees_USDA'!O508+'Donnees_USDA'!O608)*'Donnees_USDA'!O808+('Donnees_USDA'!O513+'Donnees_USDA'!O613)*'Donnees_USDA'!O813+('Donnees_USDA'!O509+'Donnees_USDA'!O609)*'Donnees_USDA'!O809+('Donnees_USDA'!O514+'Donnees_USDA'!O614)*'Donnees_USDA'!O814+('Donnees_USDA'!O515+'Donnees_USDA'!O615)*'Donnees_USDA'!O815+('Donnees_USDA'!O516+'Donnees_USDA'!O616)*'Donnees_USDA'!O816+('Donnees_USDA'!O522+'Donnees_USDA'!O622)*'Donnees_USDA'!O822 -> 76210.952 | D17: =B17/C17 -> 0.05705694 | E17: ='Donnees_USDA'!O706*'Donnees_USDA'!O906+'Donnees_USDA'!O707*'Donnees_USDA'!O907+'Donnees_USDA'!O710*'Donnees_USDA'!O910+'Donnees_USDA'!O711*'Donnees_USDA'!O911 -> 3334.2372 | F17: =('Donnees_USDA'!O506+'Donnees_USDA'!O606)*'Donnees_USDA'!O906+('Donnees_USDA'!O507+'Donnees_USDA'!O607)*'Donnees_USDA'!O907+('Donnees_USDA'!O510+'Donnees_USDA'!O610)*'Donnees_USDA'!O910+('Donnees_USDA'!O511+'Donnees_USDA'!O611)*'Donnees_USDA'!O911 -> 68518.664 | G17: =E17/F17 -> 0.048661738 | H17: ='Prix_ICE'!J17 -> 171.19 | I17: ='Prix_ICE'!L17 -> 2217.0787 | J17: =('Donnees_USDA'!O706+'Donnees_USDA'!O708+'Donnees_USDA'!O713+'Donnees_USDA'!O709+'Donnees_USDA'!O714+'Donnees_USDA'!O715+'Donnees_USDA'!O716+'Donnees_USDA'!O722)/('Donnees_USDA'!O506+'Donnees_USDA'!O606+'Donnees_USDA'!O508+'Donnees_USDA'!O608+'Donnees_USDA'!O513+'Donnees_USDA'!O613+'Donnees_USDA'!O509+'Donnees_USDA'!O609+'Donnees_USDA'!O514+'Donnees_USDA'!O614+'Donnees_USDA'!O515+'Donnees_USDA'!O615+'Donnees_USDA'!O516+'Donnees_USDA'!O616+'Donnees_USDA'!O522+'Donnees_USDA'!O622) -> 0.061331764 | K17: =('Donnees_USDA'!O706+'Donnees_USDA'!O707+'Donnees_USDA'!O710+'Donnees_USDA'!O711)/('Donnees_USDA'!O506+'Donnees_USDA'!O606+'Donnees_USDA'!O507+'Donnees_USDA'!O607+'Donnees_USDA'!O510+'Donnees_USDA'!O610+'Donnees_USDA'!O511+'Donnees_USDA'!O611) -> 0.05881707
A18: 2023/24 | B18: ='Donnees_USDA'!P706*'Donnees_USDA'!P806+'Donnees_USDA'!P708*'Donnees_USDA'!P808+'Donnees_USDA'!P713*'Donnees_USDA'!P813+'Donnees_USDA'!P709*'Donnees_USDA'!P809+'Donnees_USDA'!P714*'Donnees_USDA'!P814+'Donnees_USDA'!P715*'Donnees_USDA'!P815+'Donnees_USDA'!P716*'Donnees_USDA'!P816+'Donnees_USDA'!P722*'Donnees_USDA'!P822 -> 2497.2471 | C18: =('Donnees_USDA'!P506+'Donnees_USDA'!P606)*'Donnees_USDA'!P806+('Donnees_USDA'!P508+'Donnees_USDA'!P608)*'Donnees_USDA'!P808+('Donnees_USDA'!P513+'Donnees_USDA'!P613)*'Donnees_USDA'!P813+('Donnees_USDA'!P509+'Donnees_USDA'!P609)*'Donnees_USDA'!P809+('Donnees_USDA'!P514+'Donnees_USDA'!P614)*'Donnees_USDA'!P814+('Donnees_USDA'!P515+'Donnees_USDA'!P615)*'Donnees_USDA'!P815+('Donnees_USDA'!P516+'Donnees_USDA'!P616)*'Donnees_USDA'!P816+('Donnees_USDA'!P522+'Donnees_USDA'!P622)*'Donnees_USDA'!P822 -> 89277.803 | D18: =B18/C18 -> 0.027971646 | E18: ='Donnees_USDA'!P706*'Donnees_USDA'!P906+'Donnees_USDA'!P707*'Donnees_USDA'!P907+'Donnees_USDA'!P710*'Donnees_USDA'!P910+'Donnees_USDA'!P711*'Donnees_USDA'!P911 -> 2136.0836 | F18: =('Donnees_USDA'!P506+'Donnees_USDA'!P606)*'Donnees_USDA'!P906+('Donnees_USDA'!P507+'Donnees_USDA'!P607)*'Donnees_USDA'!P907+('Donnees_USDA'!P510+'Donnees_USDA'!P610)*'Donnees_USDA'!P910+('Donnees_USDA'!P511+'Donnees_USDA'!P611)*'Donnees_USDA'!P911 -> 63557.088 | G18: =E18/F18 -> 0.033608897 | H18: ='Prix_ICE'!J18 -> 204.00167 | I18: ='Prix_ICE'!L18 -> 3504.2477 | J18: =('Donnees_USDA'!P706+'Donnees_USDA'!P708+'Donnees_USDA'!P713+'Donnees_USDA'!P709+'Donnees_USDA'!P714+'Donnees_USDA'!P715+'Donnees_USDA'!P716+'Donnees_USDA'!P722)/('Donnees_USDA'!P506+'Donnees_USDA'!P606+'Donnees_USDA'!P508+'Donnees_USDA'!P608+'Donnees_USDA'!P513+'Donnees_USDA'!P613+'Donnees_USDA'!P509+'Donnees_USDA'!P609+'Donnees_USDA'!P514+'Donnees_USDA'!P614+'Donnees_USDA'!P515+'Donnees_USDA'!P615+'Donnees_USDA'!P516+'Donnees_USDA'!P616+'Donnees_USDA'!P522+'Donnees_USDA'!P622) -> 0.028224766 | K18: =('Donnees_USDA'!P706+'Donnees_USDA'!P707+'Donnees_USDA'!P710+'Donnees_USDA'!P711)/('Donnees_USDA'!P506+'Donnees_USDA'!P606+'Donnees_USDA'!P507+'Donnees_USDA'!P607+'Donnees_USDA'!P510+'Donnees_USDA'!P610+'Donnees_USDA'!P511+'Donnees_USDA'!P611) -> 0.032448559
A19: 2024/25 | B19: ='Donnees_USDA'!Q706*'Donnees_USDA'!Q806+'Donnees_USDA'!Q708*'Donnees_USDA'!Q808+'Donnees_USDA'!Q713*'Donnees_USDA'!Q813+'Donnees_USDA'!Q709*'Donnees_USDA'!Q809+'Donnees_USDA'!Q714*'Donnees_USDA'!Q814+'Donnees_USDA'!Q715*'Donnees_USDA'!Q815+'Donnees_USDA'!Q716*'Donnees_USDA'!Q816+'Donnees_USDA'!Q722*'Donnees_USDA'!Q822 -> 2068.8471 | C19: =('Donnees_USDA'!Q506+'Donnees_USDA'!Q606)*'Donnees_USDA'!Q806+('Donnees_USDA'!Q508+'Donnees_USDA'!Q608)*'Donnees_USDA'!Q808+('Donnees_USDA'!Q513+'Donnees_USDA'!Q613)*'Donnees_USDA'!Q813+('Donnees_USDA'!Q509+'Donnees_USDA'!Q609)*'Donnees_USDA'!Q809+('Donnees_USDA'!Q514+'Donnees_USDA'!Q614)*'Donnees_USDA'!Q814+('Donnees_USDA'!Q515+'Donnees_USDA'!Q615)*'Donnees_USDA'!Q815+('Donnees_USDA'!Q516+'Donnees_USDA'!Q616)*'Donnees_USDA'!Q816+('Donnees_USDA'!Q522+'Donnees_USDA'!Q622)*'Donnees_USDA'!Q822 -> 92890.543 | D19: =B19/C19 -> 0.022271881 | E19: ='Donnees_USDA'!Q706*'Donnees_USDA'!Q906+'Donnees_USDA'!Q707*'Donnees_USDA'!Q907+'Donnees_USDA'!Q710*'Donnees_USDA'!Q910+'Donnees_USDA'!Q711*'Donnees_USDA'!Q911 -> 2125.8946 | F19: =('Donnees_USDA'!Q506+'Donnees_USDA'!Q606)*'Donnees_USDA'!Q906+('Donnees_USDA'!Q507+'Donnees_USDA'!Q607)*'Donnees_USDA'!Q907+('Donnees_USDA'!Q510+'Donnees_USDA'!Q610)*'Donnees_USDA'!Q910+('Donnees_USDA'!Q511+'Donnees_USDA'!Q611)*'Donnees_USDA'!Q911 -> 66572.739 | G19: =E19/F19 -> 0.03193341 | H19: ='Prix_ICE'!J19 -> 333.06 | I19: ='Prix_ICE'!L19 -> 4701.7435 | J19: =('Donnees_USDA'!Q706+'Donnees_USDA'!Q708+'Donnees_USDA'!Q713+'Donnees_USDA'!Q709+'Donnees_USDA'!Q714+'Donnees_USDA'!Q715+'Donnees_USDA'!Q716+'Donnees_USDA'!Q722)/('Donnees_USDA'!Q506+'Donnees_USDA'!Q606+'Donnees_USDA'!Q508+'Donnees_USDA'!Q608+'Donnees_USDA'!Q513+'Donnees_USDA'!Q613+'Donnees_USDA'!Q509+'Donnees_USDA'!Q609+'Donnees_USDA'!Q514+'Donnees_USDA'!Q614+'Donnees_USDA'!Q515+'Donnees_USDA'!Q615+'Donnees_USDA'!Q516+'Donnees_USDA'!Q616+'Donnees_USDA'!Q522+'Donnees_USDA'!Q622) -> 0.020669026 | K19: =('Donnees_USDA'!Q706+'Donnees_USDA'!Q707+'Donnees_USDA'!Q710+'Donnees_USDA'!Q711)/('Donnees_USDA'!Q506+'Donnees_USDA'!Q606+'Donnees_USDA'!Q507+'Donnees_USDA'!Q607+'Donnees_USDA'!Q510+'Donnees_USDA'!Q610+'Donnees_USDA'!Q511+'Donnees_USDA'!Q611) -> 0.0253996
A20: 2025/26 | B20: ='Donnees_USDA'!R706*'Donnees_USDA'!R806+'Donnees_USDA'!R708*'Donnees_USDA'!R808+'Donnees_USDA'!R713*'Donnees_USDA'!R813+'Donnees_USDA'!R709*'Donnees_USDA'!R809+'Donnees_USDA'!R714*'Donnees_USDA'!R814+'Donnees_USDA'!R715*'Donnees_USDA'!R815+'Donnees_USDA'!R716*'Donnees_USDA'!R816+'Donnees_USDA'!R722*'Donnees_USDA'!R822 -> 4007.4609 | C20: =('Donnees_USDA'!R506+'Donnees_USDA'!R606)*'Donnees_USDA'!R806+('Donnees_USDA'!R508+'Donnees_USDA'!R608)*'Donnees_USDA'!R808+('Donnees_USDA'!R513+'Donnees_USDA'!R613)*'Donnees_USDA'!R813+('Donnees_USDA'!R509+'Donnees_USDA'!R609)*'Donnees_USDA'!R809+('Donnees_USDA'!R514+'Donnees_USDA'!R614)*'Donnees_USDA'!R814+('Donnees_USDA'!R515+'Donnees_USDA'!R615)*'Donnees_USDA'!R815+('Donnees_USDA'!R516+'Donnees_USDA'!R616)*'Donnees_USDA'!R816+('Donnees_USDA'!R522+'Donnees_USDA'!R622)*'Donnees_USDA'!R822 -> 83848.06 | D20: =B20/C20 -> 0.047794318 | E20: ='Donnees_USDA'!R706*'Donnees_USDA'!R906+'Donnees_USDA'!R707*'Donnees_USDA'!R907+'Donnees_USDA'!R710*'Donnees_USDA'!R910+'Donnees_USDA'!R711*'Donnees_USDA'!R911 -> 3157.6538 | F20: =('Donnees_USDA'!R506+'Donnees_USDA'!R606)*'Donnees_USDA'!R906+('Donnees_USDA'!R507+'Donnees_USDA'!R607)*'Donnees_USDA'!R907+('Donnees_USDA'!R510+'Donnees_USDA'!R610)*'Donnees_USDA'!R910+('Donnees_USDA'!R511+'Donnees_USDA'!R611)*'Donnees_USDA'!R911 -> 74064.971 | G20: =E20/F20 -> 0.042633566 | H20: ='Prix_ICE'!J20 -> 312.21 | I20: ='Prix_ICE'!L20 -> 3788.4636 | J20: =('Donnees_USDA'!R706+'Donnees_USDA'!R708+'Donnees_USDA'!R713+'Donnees_USDA'!R709+'Donnees_USDA'!R714+'Donnees_USDA'!R715+'Donnees_USDA'!R716+'Donnees_USDA'!R722)/('Donnees_USDA'!R506+'Donnees_USDA'!R606+'Donnees_USDA'!R508+'Donnees_USDA'!R608+'Donnees_USDA'!R513+'Donnees_USDA'!R613+'Donnees_USDA'!R509+'Donnees_USDA'!R609+'Donnees_USDA'!R514+'Donnees_USDA'!R614+'Donnees_USDA'!R515+'Donnees_USDA'!R615+'Donnees_USDA'!R516+'Donnees_USDA'!R616+'Donnees_USDA'!R522+'Donnees_USDA'!R622) -> 0.051119739 | K20: =('Donnees_USDA'!R706+'Donnees_USDA'!R707+'Donnees_USDA'!R710+'Donnees_USDA'!R711)/('Donnees_USDA'!R506+'Donnees_USDA'!R606+'Donnees_USDA'!R507+'Donnees_USDA'!R607+'Donnees_USDA'!R510+'Donnees_USDA'!R610+'Donnees_USDA'!R511+'Donnees_USDA'!R611) -> 0.049627075
A21: 2026/27 (prév.) | B21: ='Donnees_USDA'!S706*'Donnees_USDA'!S806+'Donnees_USDA'!S708*'Donnees_USDA'!S808+'Donnees_USDA'!S713*'Donnees_USDA'!S813+'Donnees_USDA'!S709*'Donnees_USDA'!S809+'Donnees_USDA'!S714*'Donnees_USDA'!S814+'Donnees_USDA'!S715*'Donnees_USDA'!S815+'Donnees_USDA'!S716*'Donnees_USDA'!S816+'Donnees_USDA'!S722*'Donnees_USDA'!S822 -> 4559.0158 | C21: =('Donnees_USDA'!S506+'Donnees_USDA'!S606)*'Donnees_USDA'!S806+('Donnees_USDA'!S508+'Donnees_USDA'!S608)*'Donnees_USDA'!S808+('Donnees_USDA'!S513+'Donnees_USDA'!S613)*'Donnees_USDA'!S813+('Donnees_USDA'!S509+'Donnees_USDA'!S609)*'Donnees_USDA'!S809+('Donnees_USDA'!S514+'Donnees_USDA'!S614)*'Donnees_USDA'!S814+('Donnees_USDA'!S515+'Donnees_USDA'!S615)*'Donnees_USDA'!S815+('Donnees_USDA'!S516+'Donnees_USDA'!S616)*'Donnees_USDA'!S816+('Donnees_USDA'!S522+'Donnees_USDA'!S622)*'Donnees_USDA'!S822 -> 96782.217 | D21: =B21/C21 -> 0.047105925 | E21: ='Donnees_USDA'!S706*'Donnees_USDA'!S906+'Donnees_USDA'!S707*'Donnees_USDA'!S907+'Donnees_USDA'!S710*'Donnees_USDA'!S910+'Donnees_USDA'!S711*'Donnees_USDA'!S911 -> 2840.5962 | F21: =('Donnees_USDA'!S506+'Donnees_USDA'!S606)*'Donnees_USDA'!S906+('Donnees_USDA'!S507+'Donnees_USDA'!S607)*'Donnees_USDA'!S907+('Donnees_USDA'!S510+'Donnees_USDA'!S610)*'Donnees_USDA'!S910+('Donnees_USDA'!S511+'Donnees_USDA'!S611)*'Donnees_USDA'!S911 -> 74398.914 | G21: =E21/F21 -> 0.038180614 | J21: =('Donnees_USDA'!S706+'Donnees_USDA'!S708+'Donnees_USDA'!S713+'Donnees_USDA'!S709+'Donnees_USDA'!S714+'Donnees_USDA'!S715+'Donnees_USDA'!S716+'Donnees_USDA'!S722)/('Donnees_USDA'!S506+'Donnees_USDA'!S606+'Donnees_USDA'!S508+'Donnees_USDA'!S608+'Donnees_USDA'!S513+'Donnees_USDA'!S613+'Donnees_USDA'!S509+'Donnees_USDA'!S609+'Donnees_USDA'!S514+'Donnees_USDA'!S614+'Donnees_USDA'!S515+'Donnees_USDA'!S615+'Donnees_USDA'!S516+'Donnees_USDA'!S616+'Donnees_USDA'!S522+'Donnees_USDA'!S622) -> 0.04964905 | K21: =('Donnees_USDA'!S706+'Donnees_USDA'!S707+'Donnees_USDA'!S710+'Donnees_USDA'!S711)/('Donnees_USDA'!S506+'Donnees_USDA'!S606+'Donnees_USDA'!S507+'Donnees_USDA'!S607+'Donnees_USDA'!S510+'Donnees_USDA'!S610+'Donnees_USDA'!S511+'Donnees_USDA'!S611) -> 0.047140409

Sheet 4_Deux_pays
A1: 4 — STU pays par pays (2 colonnes par an) : Brésil + Colombie (arabica) et Vietnam + Brésil (robusta)
A2: STU pays = stocks de fin USDA ÷ (consommation domestique + exportations) — même ratio que la colonne « Stocks / Use » du bilan.
A3: Le ratio d'un pays ne dépend pas de la répartition arabica/robusta (stocks et utilisation sont répartis dans la même proportion).
A4: Campagne | B4: STU Brésil | C4: STU Colombie | D4: STU Vietnam | E4: KC1 NY (US c/lb) | F4: DF1 Londres (US$/t)
A5: 2010/11 | B5: ='Donnees_USDA'!C706/('Donnees_USDA'!C506+'Donnees_USDA'!C606) -> 0.053389675 | C5: ='Donnees_USDA'!C708/('Donnees_USDA'!C508+'Donnees_USDA'!C608) -> 0.010415571 | D5: ='Donnees_USDA'!C707/('Donnees_USDA'!C507+'Donnees_USDA'!C607) -> 0.040046053 | E5: ='Prix_ICE'!J5 -> 249.66 | F5: ='Prix_ICE'!L5 -> 2219.0813
A6: 2011/12 | B6: ='Donnees_USDA'!D706/('Donnees_USDA'!D506+'Donnees_USDA'!D606) -> 0.044878479 | C6: ='Donnees_USDA'!D708/('Donnees_USDA'!D508+'Donnees_USDA'!D608) -> 0.028886311 | D6: ='Donnees_USDA'!D707/('Donnees_USDA'!D507+'Donnees_USDA'!D607) -> 0.041666667 | E6: ='Prix_ICE'!J6 -> 197.84167 | F6: ='Prix_ICE'!L6 -> 2014.676
A7: 2012/13 | B7: ='Donnees_USDA'!E706/('Donnees_USDA'!E506+'Donnees_USDA'!E606) -> 0.17860942 | C7: ='Donnees_USDA'!E708/('Donnees_USDA'!E508+'Donnees_USDA'!E608) -> 0.07667827 | D7: ='Donnees_USDA'!E707/('Donnees_USDA'!E507+'Donnees_USDA'!E607) -> 0.073522744 | E7: ='Prix_ICE'!J7 -> 140.69833 | F7: ='Prix_ICE'!L7 -> 1950.6685
A8: 2013/14 | B8: ='Donnees_USDA'!F706/('Donnees_USDA'!F506+'Donnees_USDA'!F606) -> 0.21977335 | C8: ='Donnees_USDA'!F708/('Donnees_USDA'!F508+'Donnees_USDA'!F608) -> 0.077876823 | D8: ='Donnees_USDA'!F707/('Donnees_USDA'!F507+'Donnees_USDA'!F607) -> 0.07030399 | E8: ='Prix_ICE'!J8 -> 161.4675 | F8: ='Prix_ICE'!L8 -> 1893.2013
A9: 2014/15 | B9: ='Donnees_USDA'!G706/('Donnees_USDA'!G506+'Donnees_USDA'!G606) -> 0.16326566 | C9: ='Donnees_USDA'!G708/('Donnees_USDA'!G508+'Donnees_USDA'!G608) -> 0.048552822 | D9: ='Donnees_USDA'!G707/('Donnees_USDA'!G507+'Donnees_USDA'!G607) -> 0.26639758 | E9: ='Prix_ICE'!J9 -> 154.02083 | F9: ='Prix_ICE'!L9 -> 1849.9172
A10: 2015/16 | B10: ='Donnees_USDA'!H706/('Donnees_USDA'!H506+'Donnees_USDA'!H606) -> 0.042058229 | C10: ='Donnees_USDA'!H708/('Donnees_USDA'!H508+'Donnees_USDA'!H608) -> 0.081926838 | D10: ='Donnees_USDA'!H707/('Donnees_USDA'!H507+'Donnees_USDA'!H607) -> 0.13254457 | E10: ='Prix_ICE'!J10 -> 131.8325 | F10: ='Prix_ICE'!L10 -> 1632.9272
A11: 2016/17 | B11: ='Donnees_USDA'!I706/('Donnees_USDA'!I506+'Donnees_USDA'!I606) -> 0.069974043 | C11: ='Donnees_USDA'!I708/('Donnees_USDA'!I508+'Donnees_USDA'!I608) -> 0.058270306 | D11: ='Donnees_USDA'!I707/('Donnees_USDA'!I507+'Donnees_USDA'!I607) -> 0.091752225 | E11: ='Prix_ICE'!J11 -> 143.77167 | F11: ='Prix_ICE'!L11 -> 2097.1105
