Workbook

Sheet README
A1: Météo des zones caféières du Honduras (Comayagua, Ocotepeque, Copán) par saison ENSO (juillet–juin), pour refaire les graphiques du type « São Mateus »
A2: Même méthode, mêmes saisons, mêmes mois et même classement El Niño / La Niña que le fichier du Sumatra du Sud. Données météo jusqu'au 2026-09-22, ONI jusqu'à JJA 2026.
A4: CE QUE CONTIENT LE FICHIER
A5: Chart_Mean_3 : moyenne des 3 lieux (Comayagua, Ocotepeque, Copán). Chart_Comayagua, Chart_Ocotepeque, Chart_Copan : la même chose lieu par lieu.
A6: Dans chaque feuille Chart : bloc température moyenne (°C) puis bloc pluie mensuelle (mm). Lignes = saisons juillet–juin, colonnes = Jul … Jun, groupées El Niño / La Niña / Neutre, avec la ligne « Average » de chaque groupe (la ligne noire en pointillés du graphique).
A7: Chart_long : les mêmes chiffres en format long (une ligne par lieu × saison × mois), le plus simple pour ChatGPT ou un graphique croisé.
A8: ENSO_seasons et ENSO_monthly : exactement la même table ONI (NOAA CPC) et le même calcul que pour l'Indonésie, donc les mêmes saisons El Niño / La Niña / Neutre.
A9: Monthly : les valeurs mensuelles, calculées par formule à partir de Daily. Daily : les données jour par jour, 3 lieux × 5 variables (pluie des pluviomètres, 3 températures, pluie NASA pour comparaison), 1er juillet 2005 → 2026-09-22.
A10: Checks : les contrôles (jours manquants, totaux, nombre de saisons par phase), et pourquoi la pluie vient des pluviomètres et la température de la NASA.
A11: Rain_anomaly : pluie en % de la normale (moyenne 2005–2019 du même mois), par année civile et par mois, pour les 3 villes et leur moyenne, avec GPCC en comparaison. C'est là qu'on voit les années humides 2008, 2010 et 2011 (La Niña) avant la rouille de 2012–2013 : les graphiques par phase ENSO comparent des années La Niña entre elles et ne les font pas ressortir.
A12: CORRECTION (septembre 2026) : à Copán, la maille CPC perd son pluviomètre en janvier 2024 (49 % puis 41 % de la normale en 2024 et 2025, alors que GPCC donne 92 % et 103 %). De janvier 2024 à août 2026, la pluie de Copán est donc la valeur GPCC ajustée au niveau CPC (cellules bleues sur fond jaune dans Monthly, détail dans Checks). La feuille Daily garde les valeurs CPC brutes.
A14: LES SAISONS : LES MÊMES QUE TA PHOTO ET QUE LE FICHIER INDONÉSIE
... A39: Formules : toutes les feuilles de calcul se recalculent à l'ouverture dans Excel ; les valeurs sont aussi enregistrées dans le fichier, donc lisibles sans recalcul (Python, ChatGPT).

Sheet Chart_Mean_3
A1: Honduras, mean of 3 towns (Comayagua, Ocotepeque, Copán) | Temperature and rainfall by ENSO season
A2: Rain: NOAA CPC gauge analysis (daily, 0.5°). Temperature: NASA POWER daily (grid cell of each town). July–June seasons 2005/06–2024/25 as in the São Mateus chart. Season phase = official NOAA ENSO episode at its Nov–Jan peak (sheet ENSO_seasons). Average rows = mean of the seasons of that phase in the photo window.
A3: Seasons after the photo window are listed below each block, outside the averages. 2026/27: complete months only (data end 2026-09-22).
A5: Mean temperature (°C) — monthly mean of daily T2M
A6: Season | B6: Phase | C6: Jul | D6: Aug | E6: Sep | F6: Oct | G6: Nov | H6: Dec | I6: Jan | J6: Feb | K6: Mar | L6: Apr | M6: May | N6: Jun | O6: Season mean
A7: El Niño (7 seasons)
A8: 2006/07 | B8: El Niño | C8: =INDEX(Monthly!$AF:$AF,MATCH("2006-07",Monthly!$A:$A,0)) -> 22.467849 | D8: =INDEX(Monthly!$AF:$AF,MATCH("2006-08",Monthly!$A:$A,0)) -> 22.804624 | E8: =INDEX(Monthly!$AF:$AF,MATCH("2006-09",Monthly!$A:$A,0)) -> 22.678 | F8: =INDEX(Monthly!$AF:$AF,MATCH("2006-10",Monthly!$A:$A,0)) -> 22.33043 | G8: =INDEX(Monthly!$AF:$AF,MATCH("2006-11",Monthly!$A:$A,0)) -> 19.802556 | H8: =INDEX(Monthly!$AF:$AF,MATCH("2006-12",Monthly!$A:$A,0)) -> 20.177849 | I8: =INDEX(Monthly!$AF:$AF,MATCH("2007-01",Monthly!$A:$A,0)) -> 20.346452 | J8: =INDEX(Monthly!$AF:$AF,MATCH("2007-02",Monthly!$A:$A,0)) -> 21.379881 | K8: =INDEX(Monthly!$AF:$AF,MATCH("2007-03",Monthly!$A:$A,0)) -> 22.161183 | L8: =INDEX(Monthly!$AF:$AF,MATCH("2007-04",Monthly!$A:$A,0)) -> 24.378889 | M8: =INDEX(Monthly!$AF:$AF,MATCH("2007-05",Monthly!$A:$A,0)) -> 24.912796 | N8: =INDEX(Monthly!$AF:$AF,MATCH("2007-06",Monthly!$A:$A,0)) -> 23.184444 | O8: =AVERAGE(C8:N8) -> 22.218746
A9: 2009/10 | B9: El Niño | C9: =INDEX(Monthly!$AF:$AF,MATCH("2009-07",Monthly!$A:$A,0)) -> 22.477634 | D9: =INDEX(Monthly!$AF:$AF,MATCH("2009-08",Monthly!$A:$A,0)) -> 22.400645 | E9: =INDEX(Monthly!$AF:$AF,MATCH("2009-09",Monthly!$A:$A,0)) -> 22.668 | F9: =INDEX(Monthly!$AF:$AF,MATCH("2009-10",Monthly!$A:$A,0)) -> 22.455699 | G9: =INDEX(Monthly!$AF:$AF,MATCH("2009-11",Monthly!$A:$A,0)) -> 20.385889 | H9: =INDEX(Monthly!$AF:$AF,MATCH("2009-12",Monthly!$A:$A,0)) -> 20.372688 | I9: =INDEX(Monthly!$AF:$AF,MATCH("2010-01",Monthly!$A:$A,0)) -> 19.253763 | J9: =INDEX(Monthly!$AF:$AF,MATCH("2010-02",Monthly!$A:$A,0)) -> 21.726429 | K9: =INDEX(Monthly!$AF:$AF,MATCH("2010-03",Monthly!$A:$A,0)) -> 23.028387 | L9: =INDEX(Monthly!$AF:$AF,MATCH("2010-04",Monthly!$A:$A,0)) -> 24.781222 | M9: =INDEX(Monthly!$AF:$AF,MATCH("2010-05",Monthly!$A:$A,0)) -> 24.435269 | N9: =INDEX(Monthly!$AF:$AF,MATCH("2010-06",Monthly!$A:$A,0)) -> 22.939 | O9: =AVERAGE(C9:N9) -> 22.243719
A10: 2014/15 | B10: El Niño | C10: =INDEX(Monthly!$AF:$AF,MATCH("2014-07",Monthly!$A:$A,0)) -> 23.377204 | D10: =INDEX(Monthly!$AF:$AF,MATCH("2014-08",Monthly!$A:$A,0)) -> 22.998495 | E10: =INDEX(Monthly!$AF:$AF,MATCH("2014-09",Monthly!$A:$A,0)) -> 22.18 | F10: =INDEX(Monthly!$AF:$AF,MATCH("2014-10",Monthly!$A:$A,0)) -> 21.477849 | G10: =INDEX(Monthly!$AF:$AF,MATCH("2014-11",Monthly!$A:$A,0)) -> 19.637778 | H10: =INDEX(Monthly!$AF:$AF,MATCH("2014-12",Monthly!$A:$A,0)) -> 18.826237 | I10: =INDEX(Monthly!$AF:$AF,MATCH("2015-01",Monthly!$A:$A,0)) -> 19.009355 | J10: =INDEX(Monthly!$AF:$AF,MATCH("2015-02",Monthly!$A:$A,0)) -> 19.792143 | K10: =INDEX(Monthly!$AF:$AF,MATCH("2015-03",Monthly!$A:$A,0)) -> 21.883871 | L10: =INDEX(Monthly!$AF:$AF,MATCH("2015-04",Monthly!$A:$A,0)) -> 24.867333 | M10: =INDEX(Monthly!$AF:$AF,MATCH("2015-05",Monthly!$A:$A,0)) -> 24.251828 | N10: =INDEX(Monthly!$AF:$AF,MATCH("2015-06",Monthly!$A:$A,0)) -> 22.788 | O10: =AVERAGE(C10:N10) -> 21.757508
A11: 2015/16 | B11: El Niño | C11: =INDEX(Monthly!$AF:$AF,MATCH("2015-07",Monthly!$A:$A,0)) -> 23.66172 | D11: =INDEX(Monthly!$AF:$AF,MATCH("2015-08",Monthly!$A:$A,0)) -> 24.329032 | E11: =INDEX(Monthly!$AF:$AF,MATCH("2015-09",Monthly!$A:$A,0)) -> 22.997667 | F11: =INDEX(Monthly!$AF:$AF,MATCH("2015-10",Monthly!$A:$A,0)) -> 22.336559 | G11: =INDEX(Monthly!$AF:$AF,MATCH("2015-11",Monthly!$A:$A,0)) -> 21.361889 | H11: =INDEX(Monthly!$AF:$AF,MATCH("2015-12",Monthly!$A:$A,0)) -> 21.169677 | I11: =INDEX(Monthly!$AF:$AF,MATCH("2016-01",Monthly!$A:$A,0)) -> 20.159462 | J11: =INDEX(Monthly!$AF:$AF,MATCH("2016-02",Monthly!$A:$A,0)) -> 19.89908 | K11: =INDEX(Monthly!$AF:$AF,MATCH("2016-03",Monthly!$A:$A,0)) -> 24.161613 | L11: =INDEX(Monthly!$AF:$AF,MATCH("2016-04",Monthly!$A:$A,0)) -> 24.951889 | M11: =INDEX(Monthly!$AF:$AF,MATCH("2016-05",Monthly!$A:$A,0)) -> 25.654516 | N11: =INDEX(Monthly!$AF:$AF,MATCH("2016-06",Monthly!$A:$A,0)) -> 23.218 | O11: =AVERAGE(C11:N11) -> 22.825092
A12: 2018/19 | B12: El Niño | C12: =INDEX(Monthly!$AF:$AF,MATCH("2018-07",Monthly!$A:$A,0)) -> 22.746667 | D12: =INDEX(Monthly!$AF:$AF,MATCH("2018-08",Monthly!$A:$A,0)) -> 22.66828 | E12: =INDEX(Monthly!$AF:$AF,MATCH("2018-09",Monthly!$A:$A,0)) -> 22.696 | F12: =INDEX(Monthly!$AF:$AF,MATCH("2018-10",Monthly!$A:$A,0)) -> 21.752796 | G12: =INDEX(Monthly!$AF:$AF,MATCH("2018-11",Monthly!$A:$A,0)) -> 21.827889 | H12: =INDEX(Monthly!$AF:$AF,MATCH("2018-12",Monthly!$A:$A,0)) -> 20.589892 | I12: =INDEX(Monthly!$AF:$AF,MATCH("2019-01",Monthly!$A:$A,0)) -> 20.572258 | J12: =INDEX(Monthly!$AF:$AF,MATCH("2019-02",Monthly!$A:$A,0)) -> 23.290119 | K12: =INDEX(Monthly!$AF:$AF,MATCH("2019-03",Monthly!$A:$A,0)) -> 23.558817 | L12: =INDEX(Monthly!$AF:$AF,MATCH("2019-04",Monthly!$A:$A,0)) -> 25.479889 | M12: =INDEX(Monthly!$AF:$AF,MATCH("2019-05",Monthly!$A:$A,0)) -> 24.57172 | N12: =INDEX(Monthly!$AF:$AF,MATCH("2019-06",Monthly!$A:$A,0)) -> 24.062222 | O12: =AVERAGE(C12:N12) -> 22.818046
A13: 2019/20 | B13: El Niño | C13: =INDEX(Monthly!$AF:$AF,MATCH("2019-07",Monthly!$A:$A,0)) -> 23.843978 | D13: =INDEX(Monthly!$AF:$AF,MATCH("2019-08",Monthly!$A:$A,0)) -> 24.163871 | E13: =INDEX(Monthly!$AF:$AF,MATCH("2019-09",Monthly!$A:$A,0)) -> 23.283 | F13: =INDEX(Monthly!$AF:$AF,MATCH("2019-10",Monthly!$A:$A,0)) -> 22.336022 | G13: =INDEX(Monthly!$AF:$AF,MATCH("2019-11",Monthly!$A:$A,0)) -> 20.827333 | H13: =INDEX(Monthly!$AF:$AF,MATCH("2019-12",Monthly!$A:$A,0)) -> 20.352581 | I13: =INDEX(Monthly!$AF:$AF,MATCH("2020-01",Monthly!$A:$A,0)) -> 21.092151 | J13: =INDEX(Monthly!$AF:$AF,MATCH("2020-02",Monthly!$A:$A,0)) -> 22.304368 | K13: =INDEX(Monthly!$AF:$AF,MATCH("2020-03",Monthly!$A:$A,0)) -> 23.619355 | L13: =INDEX(Monthly!$AF:$AF,MATCH("2020-04",Monthly!$A:$A,0)) -> 27.046667 | M13: =INDEX(Monthly!$AF:$AF,MATCH("2020-05",Monthly!$A:$A,0)) -> 24.679677 | N13: =INDEX(Monthly!$AF:$AF,MATCH("2020-06",Monthly!$A:$A,0)) -> 22.924111 | O13: =AVERAGE(C13:N13) -> 23.039426
A14: 2023/24 | B14: El Niño | C14: =INDEX(Monthly!$AF:$AF,MATCH("2023-07",Monthly!$A:$A,0)) -> 23.477634 | D14: =INDEX(Monthly!$AF:$AF,MATCH("2023-08",Monthly!$A:$A,0)) -> 23.729462 | E14: =INDEX(Monthly!$AF:$AF,MATCH("2023-09",Monthly!$A:$A,0)) -> 23.877444 | F14: =INDEX(Monthly!$AF:$AF,MATCH("2023-10",Monthly!$A:$A,0)) -> 22.688172 | G14: =INDEX(Monthly!$AF:$AF,MATCH("2023-11",Monthly!$A:$A,0)) -> 21.425444 | H14: =INDEX(Monthly!$AF:$AF,MATCH("2023-12",Monthly!$A:$A,0)) -> 20.277957 | I14: =INDEX(Monthly!$AF:$AF,MATCH("2024-01",Monthly!$A:$A,0)) -> 21.044409 | J14: =INDEX(Monthly!$AF:$AF,MATCH("2024-02",Monthly!$A:$A,0)) -> 21.133448 | K14: =INDEX(Monthly!$AF:$AF,MATCH("2024-03",Monthly!$A:$A,0)) -> 25.11086 | L14: =INDEX(Monthly!$AF:$AF,MATCH("2024-04",Monthly!$A:$A,0)) -> 25.641222 | M14: =INDEX(Monthly!$AF:$AF,MATCH("2024-05",Monthly!$A:$A,0)) -> 27.531935 | N14: =INDEX(Monthly!$AF:$AF,MATCH("2024-06",Monthly!$A:$A,0)) -> 24.011556 | O14: =AVERAGE(C14:N14) -> 23.329129
A15: Average El Niño | B15: 7 seasons | C15: =AVERAGE(C8:C14) -> 23.150384 | D15: =AVERAGE(D8:D14) -> 23.299201 | E15: =AVERAGE(E8:E14) -> 22.911444 | F15: =AVERAGE(F8:F14) -> 22.19679 | G15: =AVERAGE(G8:G14) -> 20.752683 | H15: =AVERAGE(H8:H14) -> 20.252412 | I15: =AVERAGE(I8:I14) -> 20.211121 | J15: =AVERAGE(J8:J14) -> 21.360781 | ... N15: =AVERAGE(N8:N14) -> 23.303905 | O15: =AVERAGE(C15:N15) -> 22.604524
A17: La Niña (9 seasons)
A18: 2005/06 | B18: La Niña | C18: =INDEX(Monthly!$AF:$AF,MATCH("2005-07",Monthly!$A:$A,0)) -> 22.663441 | D18: =INDEX(Monthly!$AF:$AF,MATCH("2005-08",Monthly!$A:$A,0)) -> 22.784409 | E18: =INDEX(Monthly!$AF:$AF,MATCH("2005-09",Monthly!$A:$A,0)) -> 22.388111 | F18: =INDEX(Monthly!$AF:$AF,MATCH("2005-10",Monthly!$A:$A,0)) -> 21.018387 | G18: =INDEX(Monthly!$AF:$AF,MATCH("2005-11",Monthly!$A:$A,0)) -> 19.830444 | H18: =INDEX(Monthly!$AF:$AF,MATCH("2005-12",Monthly!$A:$A,0)) -> 20.398172 | I18: =INDEX(Monthly!$AF:$AF,MATCH("2006-01",Monthly!$A:$A,0)) -> 20.128925 | J18: =INDEX(Monthly!$AF:$AF,MATCH("2006-02",Monthly!$A:$A,0)) -> 20.36869 | K18: =INDEX(Monthly!$AF:$AF,MATCH("2006-03",Monthly!$A:$A,0)) -> 22.834731 | L18: =INDEX(Monthly!$AF:$AF,MATCH("2006-04",Monthly!$A:$A,0)) -> 24.139111 | M18: =INDEX(Monthly!$AF:$AF,MATCH("2006-05",Monthly!$A:$A,0)) -> 24.48172 | N18: =INDEX(Monthly!$AF:$AF,MATCH("2006-06",Monthly!$A:$A,0)) -> 22.454222 | O18: =AVERAGE(C18:N18) -> 21.95753
A19: 2007/08 | B19: La Niña | C19: =INDEX(Monthly!$AF:$AF,MATCH("2007-07",Monthly!$A:$A,0)) -> 22.836882 | D19: =INDEX(Monthly!$AF:$AF,MATCH("2007-08",Monthly!$A:$A,0)) -> 22.467204 | E19: =INDEX(Monthly!$AF:$AF,MATCH("2007-09",Monthly!$A:$A,0)) -> 21.802333 | F19: =INDEX(Monthly!$AF:$AF,MATCH("2007-10",Monthly!$A:$A,0)) -> 20.912581 | G19: =INDEX(Monthly!$AF:$AF,MATCH("2007-11",Monthly!$A:$A,0)) -> 19.378 | H19: =INDEX(Monthly!$AF:$AF,MATCH("2007-12",Monthly!$A:$A,0)) -> 19.170108 | I19: =INDEX(Monthly!$AF:$AF,MATCH("2008-01",Monthly!$A:$A,0)) -> 19.251075 | J19: =INDEX(Monthly!$AF:$AF,MATCH("2008-02",Monthly!$A:$A,0)) -> 21.12069 | K19: =INDEX(Monthly!$AF:$AF,MATCH("2008-03",Monthly!$A:$A,0)) -> 22.471075 | L19: =INDEX(Monthly!$AF:$AF,MATCH("2008-04",Monthly!$A:$A,0)) -> 24.000889 | M19: =INDEX(Monthly!$AF:$AF,MATCH("2008-05",Monthly!$A:$A,0)) -> 24.862366 | N19: =INDEX(Monthly!$AF:$AF,MATCH("2008-06",Monthly!$A:$A,0)) -> 22.482556 | O19: =AVERAGE(C19:N19) -> 21.729646
A20: 2008/09 | B20: La Niña | C20: =INDEX(Monthly!$AF:$AF,MATCH("2008-07",Monthly!$A:$A,0)) -> 21.755591 | D20: =INDEX(Monthly!$AF:$AF,MATCH("2008-08",Monthly!$A:$A,0)) -> 22.230645 | E20: =INDEX(Monthly!$AF:$AF,MATCH("2008-09",Monthly!$A:$A,0)) -> 22.268111 | F20: =INDEX(Monthly!$AF:$AF,MATCH("2008-10",Monthly!$A:$A,0)) -> 20.856452 | G20: =INDEX(Monthly!$AF:$AF,MATCH("2008-11",Monthly!$A:$A,0)) -> 18.513 | H20: =INDEX(Monthly!$AF:$AF,MATCH("2008-12",Monthly!$A:$A,0)) -> 18.500108 | I20: =INDEX(Monthly!$AF:$AF,MATCH("2009-01",Monthly!$A:$A,0)) -> 18.497849 | J20: =INDEX(Monthly!$AF:$AF,MATCH("2009-02",Monthly!$A:$A,0)) -> 19.112381 | K20: =INDEX(Monthly!$AF:$AF,MATCH("2009-03",Monthly!$A:$A,0)) -> 20.205484 | L20: =INDEX(Monthly!$AF:$AF,MATCH("2009-04",Monthly!$A:$A,0)) -> 24.052444 | M20: =INDEX(Monthly!$AF:$AF,MATCH("2009-05",Monthly!$A:$A,0)) -> 23.407634 | N20: =INDEX(Monthly!$AF:$AF,MATCH("2009-06",Monthly!$A:$A,0)) -> 22.988111 | O20: =AVERAGE(C20:N20) -> 21.032318
A21: 2010/11 | B21: La Niña | C21: =INDEX(Monthly!$AF:$AF,MATCH("2010-07",Monthly!$A:$A,0)) -> 22.388065 | D21: =INDEX(Monthly!$AF:$AF,MATCH("2010-08",Monthly!$A:$A,0)) -> 22.370108 | E21: =INDEX(Monthly!$AF:$AF,MATCH("2010-09",Monthly!$A:$A,0)) -> 22.046889 | F21: =INDEX(Monthly!$AF:$AF,MATCH("2010-10",Monthly!$A:$A,0)) -> 20.132903 | G21: =INDEX(Monthly!$AF:$AF,MATCH("2010-11",Monthly!$A:$A,0)) -> 19.088111 | H21: =INDEX(Monthly!$AF:$AF,MATCH("2010-12",Monthly!$A:$A,0)) -> 17.203763 | I21: =INDEX(Monthly!$AF:$AF,MATCH("2011-01",Monthly!$A:$A,0)) -> 19.941935 | J21: =INDEX(Monthly!$AF:$AF,MATCH("2011-02",Monthly!$A:$A,0)) -> 21.073452 | K21: =INDEX(Monthly!$AF:$AF,MATCH("2011-03",Monthly!$A:$A,0)) -> 22.02871 | L21: =INDEX(Monthly!$AF:$AF,MATCH("2011-04",Monthly!$A:$A,0)) -> 24.566444 | M21: =INDEX(Monthly!$AF:$AF,MATCH("2011-05",Monthly!$A:$A,0)) -> 24.132581 | N21: =INDEX(Monthly!$AF:$AF,MATCH("2011-06",Monthly!$A:$A,0)) -> 22.866556 | O21: =AVERAGE(C21:N21) -> 21.486626
A22: 2011/12 | B22: La Niña | C22: =INDEX(Monthly!$AF:$AF,MATCH("2011-07",Monthly!$A:$A,0)) -> 22.178387 | D22: =INDEX(Monthly!$AF:$AF,MATCH("2011-08",Monthly!$A:$A,0)) -> 22.64 | E22: =INDEX(Monthly!$AF:$AF,MATCH("2011-09",Monthly!$A:$A,0)) -> 22.123556 | F22: =INDEX(Monthly!$AF:$AF,MATCH("2011-10",Monthly!$A:$A,0)) -> 20.31043 | G22: =INDEX(Monthly!$AF:$AF,MATCH("2011-11",Monthly!$A:$A,0)) -> 19.350111 | H22: =INDEX(Monthly!$AF:$AF,MATCH("2011-12",Monthly!$A:$A,0)) -> 18.605914 | I22: =INDEX(Monthly!$AF:$AF,MATCH("2012-01",Monthly!$A:$A,0)) -> 19.253763 | J22: =INDEX(Monthly!$AF:$AF,MATCH("2012-02",Monthly!$A:$A,0)) -> 20.762759 | K22: =INDEX(Monthly!$AF:$AF,MATCH("2012-03",Monthly!$A:$A,0)) -> 21.863978 | L22: =INDEX(Monthly!$AF:$AF,MATCH("2012-04",Monthly!$A:$A,0)) -> 23.314222 | M22: =INDEX(Monthly!$AF:$AF,MATCH("2012-05",Monthly!$A:$A,0)) -> 23.668817 | N22: =INDEX(Monthly!$AF:$AF,MATCH("2012-06",Monthly!$A:$A,0)) -> 22.933556 | O22: =AVERAGE(C22:N22) -> 21.417124
A23: 2017/18 | B23: La Niña | C23: =INDEX(Monthly!$AF:$AF,MATCH("2017-07",Monthly!$A:$A,0)) -> 22.312366 | D23: =INDEX(Monthly!$AF:$AF,MATCH("2017-08",Monthly!$A:$A,0)) -> 22.653011 | E23: =INDEX(Monthly!$AF:$AF,MATCH("2017-09",Monthly!$A:$A,0)) -> 22.634 | F23: =INDEX(Monthly!$AF:$AF,MATCH("2017-10",Monthly!$A:$A,0)) -> 21.37129 | G23: =INDEX(Monthly!$AF:$AF,MATCH("2017-11",Monthly!$A:$A,0)) -> 19.566444 | H23: =INDEX(Monthly!$AF:$AF,MATCH("2017-12",Monthly!$A:$A,0)) -> 18.707849 | I23: =INDEX(Monthly!$AF:$AF,MATCH("2018-01",Monthly!$A:$A,0)) -> 17.993333 | J23: =INDEX(Monthly!$AF:$AF,MATCH("2018-02",Monthly!$A:$A,0)) -> 20.537738 | K23: =INDEX(Monthly!$AF:$AF,MATCH("2018-03",Monthly!$A:$A,0)) -> 23.067312 | L23: =INDEX(Monthly!$AF:$AF,MATCH("2018-04",Monthly!$A:$A,0)) -> 24.248333 | M23: =INDEX(Monthly!$AF:$AF,MATCH("2018-05",Monthly!$A:$A,0)) -> 24.329785 | N23: =INDEX(Monthly!$AF:$AF,MATCH("2018-06",Monthly!$A:$A,0)) -> 22.491556 | O23: =AVERAGE(C23:N23) -> 21.659418
A24: 2020/21 | B24: La Niña | C24: =INDEX(Monthly!$AF:$AF,MATCH("2020-07",Monthly!$A:$A,0)) -> 22.918925 | D24: =INDEX(Monthly!$AF:$AF,MATCH("2020-08",Monthly!$A:$A,0)) -> 22.626129 | E24: =INDEX(Monthly!$AF:$AF,MATCH("2020-09",Monthly!$A:$A,0)) -> 22.714111 | F24: =INDEX(Monthly!$AF:$AF,MATCH("2020-10",Monthly!$A:$A,0)) -> 21.835806 | G24: =INDEX(Monthly!$AF:$AF,MATCH("2020-11",Monthly!$A:$A,0)) -> 20.896222 | H24: =INDEX(Monthly!$AF:$AF,MATCH("2020-12",Monthly!$A:$A,0)) -> 19.137634 | I24: =INDEX(Monthly!$AF:$AF,MATCH("2021-01",Monthly!$A:$A,0)) -> 19.517312 | J24: =INDEX(Monthly!$AF:$AF,MATCH("2021-02",Monthly!$A:$A,0)) -> 19.907619 | K24: =INDEX(Monthly!$AF:$AF,MATCH("2021-03",Monthly!$A:$A,0)) -> 20.918387 | L24: =INDEX(Monthly!$AF:$AF,MATCH("2021-04",Monthly!$A:$A,0)) -> 22.738889 | M24: =INDEX(Monthly!$AF:$AF,MATCH("2021-05",Monthly!$A:$A,0)) -> 23.60086 | N24: =INDEX(Monthly!$AF:$AF,MATCH("2021-06",Monthly!$A:$A,0)) -> 22.886444 | O24: =AVERAGE(C24:N24) -> 21.641528
A25: 2021/22 | B25: La Niña | C25: =INDEX(Monthly!$AF:$AF,MATCH("2021-07",Monthly!$A:$A,0)) -> 22.559892 | D25: =INDEX(Monthly!$AF:$AF,MATCH("2021-08",Monthly!$A:$A,0)) -> 22.572796 | E25: =INDEX(Monthly!$AF:$AF,MATCH("2021-09",Monthly!$A:$A,0)) -> 22.602667 | F25: =INDEX(Monthly!$AF:$AF,MATCH("2021-10",Monthly!$A:$A,0)) -> 22.37871 | G25: =INDEX(Monthly!$AF:$AF,MATCH("2021-11",Monthly!$A:$A,0)) -> 19.538778 | H25: =INDEX(Monthly!$AF:$AF,MATCH("2021-12",Monthly!$A:$A,0)) -> 19.874301 | I25: =INDEX(Monthly!$AF:$AF,MATCH("2022-01",Monthly!$A:$A,0)) -> 19.243763 | J25: =INDEX(Monthly!$AF:$AF,MATCH("2022-02",Monthly!$A:$A,0)) -> 19.848452 | K25: =INDEX(Monthly!$AF:$AF,MATCH("2022-03",Monthly!$A:$A,0)) -> 21.717204 | L25: =INDEX(Monthly!$AF:$AF,MATCH("2022-04",Monthly!$A:$A,0)) -> 23.678222 | M25: =INDEX(Monthly!$AF:$AF,MATCH("2022-05",Monthly!$A:$A,0)) -> 23.06129 | N25: =INDEX(Monthly!$AF:$AF,MATCH("2022-06",Monthly!$A:$A,0)) -> 21.936889 | O25: =AVERAGE(C25:N25) -> 21.584414
A26: 2022/23 | B26: La Niña | C26: =INDEX(Monthly!$AF:$AF,MATCH("2022-07",Monthly!$A:$A,0)) -> 22.267849 | D26: =INDEX(Monthly!$AF:$AF,MATCH("2022-08",Monthly!$A:$A,0)) -> 22.380968 | E26: =INDEX(Monthly!$AF:$AF,MATCH("2022-09",Monthly!$A:$A,0)) -> 22.176444 | F26: =INDEX(Monthly!$AF:$AF,MATCH("2022-10",Monthly!$A:$A,0)) -> 21.657204 | G26: =INDEX(Monthly!$AF:$AF,MATCH("2022-11",Monthly!$A:$A,0)) -> 21.002 | H26: =INDEX(Monthly!$AF:$AF,MATCH("2022-12",Monthly!$A:$A,0)) -> 19.398495 | I26: =INDEX(Monthly!$AF:$AF,MATCH("2023-01",Monthly!$A:$A,0)) -> 19.470538 | J26: =INDEX(Monthly!$AF:$AF,MATCH("2023-02",Monthly!$A:$A,0)) -> 20.25619 | K26: =INDEX(Monthly!$AF:$AF,MATCH("2023-03",Monthly!$A:$A,0)) -> 22.710215 | L26: =INDEX(Monthly!$AF:$AF,MATCH("2023-04",Monthly!$A:$A,0)) -> 24.570778 | M26: =INDEX(Monthly!$AF:$AF,MATCH("2023-05",Monthly!$A:$A,0)) -> 25.330108 | N26: =INDEX(Monthly!$AF:$AF,MATCH("2023-06",Monthly!$A:$A,0)) -> 24.498333 | O26: =AVERAGE(C26:N26) -> 22.14326
A27: Average La Niña | B27: 9 seasons | C27: =AVERAGE(C18:C26) -> 22.431266 | D27: =AVERAGE(D18:D26) -> 22.52503 | E27: =AVERAGE(E18:E26) -> 22.306247 | F27: =AVERAGE(F18:F26) -> 21.163751 | G27: =AVERAGE(G18:G26) -> 19.68479 | H27: =AVERAGE(H18:H26) -> 18.999594 | I27: =AVERAGE(I18:I26) -> 19.255388 | J27: =AVERAGE(J18:J26) -> 20.331997 | ... N27: =AVERAGE(N18:N26) -> 22.83758 | O27: =AVERAGE(C27:N27) -> 21.627985
A29: Neutral (4 seasons)
A30: 2012/13 | B30: Neutral | C30: =INDEX(Monthly!$AF:$AF,MATCH("2012-07",Monthly!$A:$A,0)) -> 22.448495 | D30: =INDEX(Monthly!$AF:$AF,MATCH("2012-08",Monthly!$A:$A,0)) -> 22.613118 | E30: =INDEX(Monthly!$AF:$AF,MATCH("2012-09",Monthly!$A:$A,0)) -> 22.201444 | F30: =INDEX(Monthly!$AF:$AF,MATCH("2012-10",Monthly!$A:$A,0)) -> 21.085699 | G30: =INDEX(Monthly!$AF:$AF,MATCH("2012-11",Monthly!$A:$A,0)) -> 18.742556 | H30: =INDEX(Monthly!$AF:$AF,MATCH("2012-12",Monthly!$A:$A,0)) -> 19.581075 | I30: =INDEX(Monthly!$AF:$AF,MATCH("2013-01",Monthly!$A:$A,0)) -> 19.901398 | J30: =INDEX(Monthly!$AF:$AF,MATCH("2013-02",Monthly!$A:$A,0)) -> 21.786548 | K30: =INDEX(Monthly!$AF:$AF,MATCH("2013-03",Monthly!$A:$A,0)) -> 21.545269 | L30: =INDEX(Monthly!$AF:$AF,MATCH("2013-04",Monthly!$A:$A,0)) -> 25.417667 | M30: =INDEX(Monthly!$AF:$AF,MATCH("2013-05",Monthly!$A:$A,0)) -> 24.195484 | N30: =INDEX(Monthly!$AF:$AF,MATCH("2013-06",Monthly!$A:$A,0)) -> 22.898222 | O30: =AVERAGE(C30:N30) -> 21.868081
A31: 2013/14 | B31: Neutral | C31: =INDEX(Monthly!$AF:$AF,MATCH("2013-07",Monthly!$A:$A,0)) -> 22.321613 | D31: =INDEX(Monthly!$AF:$AF,MATCH("2013-08",Monthly!$A:$A,0)) -> 22.526882 | E31: =INDEX(Monthly!$AF:$AF,MATCH("2013-09",Monthly!$A:$A,0)) -> 22.221222 | F31: =INDEX(Monthly!$AF:$AF,MATCH("2013-10",Monthly!$A:$A,0)) -> 22.005054 | G31: =INDEX(Monthly!$AF:$AF,MATCH("2013-11",Monthly!$A:$A,0)) -> 20.340667 | H31: =INDEX(Monthly!$AF:$AF,MATCH("2013-12",Monthly!$A:$A,0)) -> 19.780108 | I31: =INDEX(Monthly!$AF:$AF,MATCH("2014-01",Monthly!$A:$A,0)) -> 18.702043 | J31: =INDEX(Monthly!$AF:$AF,MATCH("2014-02",Monthly!$A:$A,0)) -> 21.37119 | K31: =INDEX(Monthly!$AF:$AF,MATCH("2014-03",Monthly!$A:$A,0)) -> 23.257097 | L31: =INDEX(Monthly!$AF:$AF,MATCH("2014-04",Monthly!$A:$A,0)) -> 24.592222 | M31: =INDEX(Monthly!$AF:$AF,MATCH("2014-05",Monthly!$A:$A,0)) -> 23.783656 | N31: =INDEX(Monthly!$AF:$AF,MATCH("2014-06",Monthly!$A:$A,0)) -> 23.074667 | O31: =AVERAGE(C31:N31) -> 21.998035
A32: 2016/17 | B32: Neutral | C32: =INDEX(Monthly!$AF:$AF,MATCH("2016-07",Monthly!$A:$A,0)) -> 23.15129 | D32: =INDEX(Monthly!$AF:$AF,MATCH("2016-08",Monthly!$A:$A,0)) -> 23.013763 | E32: =INDEX(Monthly!$AF:$AF,MATCH("2016-09",Monthly!$A:$A,0)) -> 22.539 | F32: =INDEX(Monthly!$AF:$AF,MATCH("2016-10",Monthly!$A:$A,0)) -> 21.442688 | G32: =INDEX(Monthly!$AF:$AF,MATCH("2016-11",Monthly!$A:$A,0)) -> 20.330444 | H32: =INDEX(Monthly!$AF:$AF,MATCH("2016-12",Monthly!$A:$A,0)) -> 20.915161 | I32: =INDEX(Monthly!$AF:$AF,MATCH("2017-01",Monthly!$A:$A,0)) -> 20.167957 | J32: =INDEX(Monthly!$AF:$AF,MATCH("2017-02",Monthly!$A:$A,0)) -> 22.286429 | K32: =INDEX(Monthly!$AF:$AF,MATCH("2017-03",Monthly!$A:$A,0)) -> 22.065376 | L32: =INDEX(Monthly!$AF:$AF,MATCH("2017-04",Monthly!$A:$A,0)) -> 24.880778 | M32: =INDEX(Monthly!$AF:$AF,MATCH("2017-05",Monthly!$A:$A,0)) -> 24.004839 | N32: =INDEX(Monthly!$AF:$AF,MATCH("2017-06",Monthly!$A:$A,0)) -> 22.894667 | O32: =AVERAGE(C32:N32) -> 22.307699
A33: 2024/25 | B33: Neutral | C33: =INDEX(Monthly!$AF:$AF,MATCH("2024-07",Monthly!$A:$A,0)) -> 23.087527 | D33: =INDEX(Monthly!$AF:$AF,MATCH("2024-08",Monthly!$A:$A,0)) -> 23.20086 | E33: =INDEX(Monthly!$AF:$AF,MATCH("2024-09",Monthly!$A:$A,0)) -> 23.517111 | F33: =INDEX(Monthly!$AF:$AF,MATCH("2024-10",Monthly!$A:$A,0)) -> 22.048387 | G33: =INDEX(Monthly!$AF:$AF,MATCH("2024-11",Monthly!$A:$A,0)) -> 21.084667 | H33: =INDEX(Monthly!$AF:$AF,MATCH("2024-12",Monthly!$A:$A,0)) -> 20.003333 | I33: =INDEX(Monthly!$AF:$AF,MATCH("2025-01",Monthly!$A:$A,0)) -> 20.066022 | J33: =INDEX(Monthly!$AF:$AF,MATCH("2025-02",Monthly!$A:$A,0)) -> 21.454286 | K33: =INDEX(Monthly!$AF:$AF,MATCH("2025-03",Monthly!$A:$A,0)) -> 23.177527 | L33: =INDEX(Monthly!$AF:$AF,MATCH("2025-04",Monthly!$A:$A,0)) -> 23.278 | M33: =INDEX(Monthly!$AF:$AF,MATCH("2025-05",Monthly!$A:$A,0)) -> 25.948602 | N33: =INDEX(Monthly!$AF:$AF,MATCH("2025-06",Monthly!$A:$A,0)) -> 23.154222 | O33: =AVERAGE(C33:N33) -> 22.501712
A34: Average Neutral | B34: 4 seasons | C34: =AVERAGE(C30:C33) -> 22.752231 | D34: =AVERAGE(D30:D33) -> 22.838656 | E34: =AVERAGE(E30:E33) -> 22.619694 | F34: =AVERAGE(F30:F33) -> 21.645457 | G34: =AVERAGE(G30:G33) -> 20.124583 | H34: =AVERAGE(H30:H33) -> 20.069919 | I34: =AVERAGE(I30:I33) -> 19.709355 | J34: =AVERAGE(J30:J33) -> 21.724613 | ... N34: =AVERAGE(N30:N33) -> 23.005444 | O34: =AVERAGE(C34:N34) -> 22.168882
A36: After the photo window (not in the averages)
A37: 2025/26 | B37: Neutral | C37: =INDEX(Monthly!$AF:$AF,MATCH("2025-07",Monthly!$A:$A,0)) -> 22.938065 | D37: =INDEX(Monthly!$AF:$AF,MATCH("2025-08",Monthly!$A:$A,0)) -> 23.591828 | E37: =INDEX(Monthly!$AF:$AF,MATCH("2025-09",Monthly!$A:$A,0)) -> 23.348 | F37: =INDEX(Monthly!$AF:$AF,MATCH("2025-10",Monthly!$A:$A,0)) -> 22.022043 | G37: =INDEX(Monthly!$AF:$AF,MATCH("2025-11",Monthly!$A:$A,0)) -> 20.872111 | H37: =INDEX(Monthly!$AF:$AF,MATCH("2025-12",Monthly!$A:$A,0)) -> 20.927957 | I37: =INDEX(Monthly!$AF:$AF,MATCH("2026-01",Monthly!$A:$A,0)) -> 19.643441 | J37: =INDEX(Monthly!$AF:$AF,MATCH("2026-02",Monthly!$A:$A,0)) -> 19.408214 | K37: =INDEX(Monthly!$AF:$AF,MATCH("2026-03",Monthly!$A:$A,0)) -> 22.11828 | L37: =INDEX(Monthly!$AF:$AF,MATCH("2026-04",Monthly!$A:$A,0)) -> 23.145889 | M37: =INDEX(Monthly!$AF:$AF,MATCH("2026-05",Monthly!$A:$A,0)) -> 25.724301 | N37: =INDEX(Monthly!$AF:$AF,MATCH("2026-06",Monthly!$A:$A,0)) -> 24.292 | O37: =AVERAGE(C37:N37) -> 22.336011
A38: 2026/27 | B38: El Niño (in progress) | C38: =INDEX(Monthly!$AF:$AF,MATCH("2026-07",Monthly!$A:$A,0)) -> 24.61043 | D38: =INDEX(Monthly!$AF:$AF,MATCH("2026-08",Monthly!$A:$A,0)) -> 24.86957
A41: Monthly rainfall (mm) — sum of daily rainfall from rain gauges (NOAA CPC)
A42: Season | B42: Phase | C42: Jul | D42: Aug | E42: Sep | F42: Oct | G42: Nov | H42: Dec | I42: Jan | J42: Feb | K42: Mar | L42: Apr | M42: May | N42: Jun | O42: Season total
A43: El Niño (7 seasons)
A44: 2006/07 | B44: El Niño | C44: =INDEX(Monthly!$AE:$AE,MATCH("2006-07",Monthly!$A:$A,0)) -> 164.15433 | D44: =INDEX(Monthly!$AE:$AE,MATCH("2006-08",Monthly!$A:$A,0)) -> 131.59133 | E44: =INDEX(Monthly!$AE:$AE,MATCH("2006-09",Monthly!$A:$A,0)) -> 160.00633 | F44: =INDEX(Monthly!$AE:$AE,MATCH("2006-10",Monthly!$A:$A,0)) -> 134.13 | G44: =INDEX(Monthly!$AE:$AE,MATCH("2006-11",Monthly!$A:$A,0)) -> 48.461667 | H44: =INDEX(Monthly!$AE:$AE,MATCH("2006-12",Monthly!$A:$A,0)) -> 57.113333 | I44: =INDEX(Monthly!$AE:$AE,MATCH("2007-01",Monthly!$A:$A,0)) -> 21.410333 | J44: =INDEX(Monthly!$AE:$AE,MATCH("2007-02",Monthly!$A:$A,0)) -> 11.01 | K44: =INDEX(Monthly!$AE:$AE,MATCH("2007-03",Monthly!$A:$A,0)) -> 10.826667 | L44: =INDEX(Monthly!$AE:$AE,MATCH("2007-04",Monthly!$A:$A,0)) -> 42.211333 | M44: =INDEX(Monthly!$AE:$AE,MATCH("2007-05",Monthly!$A:$A,0)) -> 96.007333 | N44: =INDEX(Monthly!$AE:$AE,MATCH("2007-06",Monthly!$A:$A,0)) -> 219.43767 | O44: =SUM(C44:N44) -> 1096.3603
A45: 2009/10 | B45: El Niño | C45: =INDEX(Monthly!$AE:$AE,MATCH("2009-07",Monthly!$A:$A,0)) -> 170.408 | D45: =INDEX(Monthly!$AE:$AE,MATCH("2009-08",Monthly!$A:$A,0)) -> 225.11267 | E45: =INDEX(Monthly!$AE:$AE,MATCH("2009-09",Monthly!$A:$A,0)) -> 144.964 | F45: =INDEX(Monthly!$AE:$AE,MATCH("2009-10",Monthly!$A:$A,0)) -> 96.57 | G45: =INDEX(Monthly!$AE:$AE,MATCH("2009-11",Monthly!$A:$A,0)) -> 96.675333 | H45: =INDEX(Monthly!$AE:$AE,MATCH("2009-12",Monthly!$A:$A,0)) -> 39.386 | I45: =INDEX(Monthly!$AE:$AE,MATCH("2010-01",Monthly!$A:$A,0)) -> 23.679 | J45: =INDEX(Monthly!$AE:$AE,MATCH("2010-02",Monthly!$A:$A,0)) -> 15.198667 | K45: =INDEX(Monthly!$AE:$AE,MATCH("2010-03",Monthly!$A:$A,0)) -> 1.2973333 | L45: =INDEX(Monthly!$AE:$AE,MATCH("2010-04",Monthly!$A:$A,0)) -> 105.63133 | M45: =INDEX(Monthly!$AE:$AE,MATCH("2010-05",Monthly!$A:$A,0)) -> 271.56767 | N45: =INDEX(Monthly!$AE:$AE,MATCH("2010-06",Monthly!$A:$A,0)) -> 282.77733 | O45: =SUM(C45:N45) -> 1473.2673
A46: 2014/15 | B46: El Niño | C46: =INDEX(Monthly!$AE:$AE,MATCH("2014-07",Monthly!$A:$A,0)) -> 57.108 | D46: =INDEX(Monthly!$AE:$AE,MATCH("2014-08",Monthly!$A:$A,0)) -> 218.994 | E46: =INDEX(Monthly!$AE:$AE,MATCH("2014-09",Monthly!$A:$A,0)) -> 256.66467 | F46: =INDEX(Monthly!$AE:$AE,MATCH("2014-10",Monthly!$A:$A,0)) -> 224.90167 | G46: =INDEX(Monthly!$AE:$AE,MATCH("2014-11",Monthly!$A:$A,0)) -> 59.056333 | H46: =INDEX(Monthly!$AE:$AE,MATCH("2014-12",Monthly!$A:$A,0)) -> 39.896 | I46: =INDEX(Monthly!$AE:$AE,MATCH("2015-01",Monthly!$A:$A,0)) -> 16.983667 | J46: =INDEX(Monthly!$AE:$AE,MATCH("2015-02",Monthly!$A:$A,0)) -> 15.721 | K46: =INDEX(Monthly!$AE:$AE,MATCH("2015-03",Monthly!$A:$A,0)) -> 23.108 | L46: =INDEX(Monthly!$AE:$AE,MATCH("2015-04",Monthly!$A:$A,0)) -> 25.756333 | M46: =INDEX(Monthly!$AE:$AE,MATCH("2015-05",Monthly!$A:$A,0)) -> 49.325 | N46: =INDEX(Monthly!$AE:$AE,MATCH("2015-06",Monthly!$A:$A,0)) -> 176.20567 | O46: =SUM(C46:N46) -> 1163.7203
...

Sheet Chart_Comayagua
A1: Comayagua — Comayagua department, town of Comayagua | Temperature and rainfall by ENSO season
A2: Rain: NOAA CPC gauge analysis (daily, 0.5°). Temperature: NASA POWER daily (grid cell of each town). July–June seasons 2005/06–2024/25 as in the São Mateus chart. Season phase = official NOAA ENSO episode at its Nov–Jan peak (sheet ENSO_seasons). Average rows = mean of the seasons of that phase in the photo window.
A3: Seasons after the photo window are listed below each block, outside the averages. 2026/27: complete months only (data end 2026-09-22).
A5: Mean temperature (°C) — monthly mean of daily T2M
A6: Season | B6: Phase | C6: Jul | D6: Aug | E6: Sep | F6: Oct | G6: Nov | H6: Dec | I6: Jan | J6: Feb | K6: Mar | L6: Apr | M6: May | N6: Jun | O6: Season mean
A7: El Niño (7 seasons)
A8: 2006/07 | B8: El Niño | C8: =INDEX(Monthly!$Q:$Q,MATCH("2006-07",Monthly!$A:$A,0)) -> 22.176774 | D8: =INDEX(Monthly!$Q:$Q,MATCH("2006-08",Monthly!$A:$A,0)) -> 23.21129 | E8: =INDEX(Monthly!$Q:$Q,MATCH("2006-09",Monthly!$A:$A,0)) -> 22.943333 | F8: =INDEX(Monthly!$Q:$Q,MATCH("2006-10",Monthly!$A:$A,0)) -> 22.402581 | G8: =INDEX(Monthly!$Q:$Q,MATCH("2006-11",Monthly!$A:$A,0)) -> 19.812 | H8: =INDEX(Monthly!$Q:$Q,MATCH("2006-12",Monthly!$A:$A,0)) -> 20.26129 | I8: =INDEX(Monthly!$Q:$Q,MATCH("2007-01",Monthly!$A:$A,0)) -> 20.432903 | J8: =INDEX(Monthly!$Q:$Q,MATCH("2007-02",Monthly!$A:$A,0)) -> 22.0625 | K8: =INDEX(Monthly!$Q:$Q,MATCH("2007-03",Monthly!$A:$A,0)) -> 22.597097 | L8: =INDEX(Monthly!$Q:$Q,MATCH("2007-04",Monthly!$A:$A,0)) -> 24.424333 | M8: =INDEX(Monthly!$Q:$Q,MATCH("2007-05",Monthly!$A:$A,0)) -> 24.415806 | N8: =INDEX(Monthly!$Q:$Q,MATCH("2007-06",Monthly!$A:$A,0)) -> 22.939667 | O8: =AVERAGE(C8:N8) -> 22.306631
A9: 2009/10 | B9: El Niño | C9: =INDEX(Monthly!$Q:$Q,MATCH("2009-07",Monthly!$A:$A,0)) -> 21.751613 | D9: =INDEX(Monthly!$Q:$Q,MATCH("2009-08",Monthly!$A:$A,0)) -> 21.994516 | E9: =INDEX(Monthly!$Q:$Q,MATCH("2009-09",Monthly!$A:$A,0)) -> 22.478333 | F9: =INDEX(Monthly!$Q:$Q,MATCH("2009-10",Monthly!$A:$A,0)) -> 22.285484 | G9: =INDEX(Monthly!$Q:$Q,MATCH("2009-11",Monthly!$A:$A,0)) -> 20.468333 | H9: =INDEX(Monthly!$Q:$Q,MATCH("2009-12",Monthly!$A:$A,0)) -> 20.500645 | I9: =INDEX(Monthly!$Q:$Q,MATCH("2010-01",Monthly!$A:$A,0)) -> 19.630968 | J9: =INDEX(Monthly!$Q:$Q,MATCH("2010-02",Monthly!$A:$A,0)) -> 21.976429 | K9: =INDEX(Monthly!$Q:$Q,MATCH("2010-03",Monthly!$A:$A,0)) -> 23.029677 | L9: =INDEX(Monthly!$Q:$Q,MATCH("2010-04",Monthly!$A:$A,0)) -> 24.217667 | M9: =INDEX(Monthly!$Q:$Q,MATCH("2010-05",Monthly!$A:$A,0)) -> 24.053548 | N9: =INDEX(Monthly!$Q:$Q,MATCH("2010-06",Monthly!$A:$A,0)) -> 22.292 | O9: =AVERAGE(C9:N9) -> 22.056601
A10: 2014/15 | B10: El Niño | C10: =INDEX(Monthly!$Q:$Q,MATCH("2014-07",Monthly!$A:$A,0)) -> 23.799677 | D10: =INDEX(Monthly!$Q:$Q,MATCH("2014-08",Monthly!$A:$A,0)) -> 23.637419 | E10: =INDEX(Monthly!$Q:$Q,MATCH("2014-09",Monthly!$A:$A,0)) -> 21.93 | F10: =INDEX(Monthly!$Q:$Q,MATCH("2014-10",Monthly!$A:$A,0)) -> 21.115161 | G10: =INDEX(Monthly!$Q:$Q,MATCH("2014-11",Monthly!$A:$A,0)) -> 19.474 | H10: =INDEX(Monthly!$Q:$Q,MATCH("2014-12",Monthly!$A:$A,0)) -> 18.653226 | I10: =INDEX(Monthly!$Q:$Q,MATCH("2015-01",Monthly!$A:$A,0)) -> 19.012903 | J10: =INDEX(Monthly!$Q:$Q,MATCH("2015-02",Monthly!$A:$A,0)) -> 20.400714 | K10: =INDEX(Monthly!$Q:$Q,MATCH("2015-03",Monthly!$A:$A,0)) -> 22.555161 | L10: =INDEX(Monthly!$Q:$Q,MATCH("2015-04",Monthly!$A:$A,0)) -> 25.500667 | M10: =INDEX(Monthly!$Q:$Q,MATCH("2015-05",Monthly!$A:$A,0)) -> 24.357742 | N10: =INDEX(Monthly!$Q:$Q,MATCH("2015-06",Monthly!$A:$A,0)) -> 22.342 | O10: =AVERAGE(C10:N10) -> 21.898223
A11: 2015/16 | B11: El Niño | C11: =INDEX(Monthly!$Q:$Q,MATCH("2015-07",Monthly!$A:$A,0)) -> 23.425806 | D11: =INDEX(Monthly!$Q:$Q,MATCH("2015-08",Monthly!$A:$A,0)) -> 24.618065 | E11: =INDEX(Monthly!$Q:$Q,MATCH("2015-09",Monthly!$A:$A,0)) -> 23.135333 | F11: =INDEX(Monthly!$Q:$Q,MATCH("2015-10",Monthly!$A:$A,0)) -> 21.960968 | G11: =INDEX(Monthly!$Q:$Q,MATCH("2015-11",Monthly!$A:$A,0)) -> 20.871 | H11: =INDEX(Monthly!$Q:$Q,MATCH("2015-12",Monthly!$A:$A,0)) -> 20.899032 | I11: =INDEX(Monthly!$Q:$Q,MATCH("2016-01",Monthly!$A:$A,0)) -> 20.61871 | J11: =INDEX(Monthly!$Q:$Q,MATCH("2016-02",Monthly!$A:$A,0)) -> 20.448621 | K11: =INDEX(Monthly!$Q:$Q,MATCH("2016-03",Monthly!$A:$A,0)) -> 24.167742 | L11: =INDEX(Monthly!$Q:$Q,MATCH("2016-04",Monthly!$A:$A,0)) -> 24.814333 | M11: =INDEX(Monthly!$Q:$Q,MATCH("2016-05",Monthly!$A:$A,0)) -> 25.440968 | N11: =INDEX(Monthly!$Q:$Q,MATCH("2016-06",Monthly!$A:$A,0)) -> 22.514667 | O11: =AVERAGE(C11:N11) -> 22.742937
A12: 2018/19 | B12: El Niño | C12: =INDEX(Monthly!$Q:$Q,MATCH("2018-07",Monthly!$A:$A,0)) -> 22.120968 | D12: =INDEX(Monthly!$Q:$Q,MATCH("2018-08",Monthly!$A:$A,0)) -> 22.31871 | E12: =INDEX(Monthly!$Q:$Q,MATCH("2018-09",Monthly!$A:$A,0)) -> 22.388 | F12: =INDEX(Monthly!$Q:$Q,MATCH("2018-10",Monthly!$A:$A,0)) -> 21.297742 | G12: =INDEX(Monthly!$Q:$Q,MATCH("2018-11",Monthly!$A:$A,0)) -> 21.593 | H12: =INDEX(Monthly!$Q:$Q,MATCH("2018-12",Monthly!$A:$A,0)) -> 20.305806 | I12: =INDEX(Monthly!$Q:$Q,MATCH("2019-01",Monthly!$A:$A,0)) -> 20.501613 | J12: =INDEX(Monthly!$Q:$Q,MATCH("2019-02",Monthly!$A:$A,0)) -> 22.9775 | K12: =INDEX(Monthly!$Q:$Q,MATCH("2019-03",Monthly!$A:$A,0)) -> 23.505161 | L12: =INDEX(Monthly!$Q:$Q,MATCH("2019-04",Monthly!$A:$A,0)) -> 25.216 | M12: =INDEX(Monthly!$Q:$Q,MATCH("2019-05",Monthly!$A:$A,0)) -> 24.21 | N12: =INDEX(Monthly!$Q:$Q,MATCH("2019-06",Monthly!$A:$A,0)) -> 23.975333 | O12: =AVERAGE(C12:N12) -> 22.534153
A13: 2019/20 | B13: El Niño | C13: =INDEX(Monthly!$Q:$Q,MATCH("2019-07",Monthly!$A:$A,0)) -> 23.910968 | D13: =INDEX(Monthly!$Q:$Q,MATCH("2019-08",Monthly!$A:$A,0)) -> 24.363548 | E13: =INDEX(Monthly!$Q:$Q,MATCH("2019-09",Monthly!$A:$A,0)) -> 23.420333 | F13: =INDEX(Monthly!$Q:$Q,MATCH("2019-10",Monthly!$A:$A,0)) -> 21.712258 | G13: =INDEX(Monthly!$Q:$Q,MATCH("2019-11",Monthly!$A:$A,0)) -> 20.740667 | H13: =INDEX(Monthly!$Q:$Q,MATCH("2019-12",Monthly!$A:$A,0)) -> 20.9 | I13: =INDEX(Monthly!$Q:$Q,MATCH("2020-01",Monthly!$A:$A,0)) -> 21.342581 | J13: =INDEX(Monthly!$Q:$Q,MATCH("2020-02",Monthly!$A:$A,0)) -> 22.377586 | K13: =INDEX(Monthly!$Q:$Q,MATCH("2020-03",Monthly!$A:$A,0)) -> 23.615806 | L13: =INDEX(Monthly!$Q:$Q,MATCH("2020-04",Monthly!$A:$A,0)) -> 27.101667 | M13: =INDEX(Monthly!$Q:$Q,MATCH("2020-05",Monthly!$A:$A,0)) -> 24.329677 | N13: =INDEX(Monthly!$Q:$Q,MATCH("2020-06",Monthly!$A:$A,0)) -> 21.985 | O13: =AVERAGE(C13:N13) -> 22.983341
A14: 2023/24 | B14: El Niño | C14: =INDEX(Monthly!$Q:$Q,MATCH("2023-07",Monthly!$A:$A,0)) -> 22.586452 | D14: =INDEX(Monthly!$Q:$Q,MATCH("2023-08",Monthly!$A:$A,0)) -> 23.352258 | E14: =INDEX(Monthly!$Q:$Q,MATCH("2023-09",Monthly!$A:$A,0)) -> 23.898 | F14: =INDEX(Monthly!$Q:$Q,MATCH("2023-10",Monthly!$A:$A,0)) -> 22.467742 | G14: =INDEX(Monthly!$Q:$Q,MATCH("2023-11",Monthly!$A:$A,0)) -> 21.122667 | H14: =INDEX(Monthly!$Q:$Q,MATCH("2023-12",Monthly!$A:$A,0)) -> 20.094516 | I14: =INDEX(Monthly!$Q:$Q,MATCH("2024-01",Monthly!$A:$A,0)) -> 20.747419 | J14: =INDEX(Monthly!$Q:$Q,MATCH("2024-02",Monthly!$A:$A,0)) -> 20.962414 | K14: =INDEX(Monthly!$Q:$Q,MATCH("2024-03",Monthly!$A:$A,0)) -> 25.484194 | L14: =INDEX(Monthly!$Q:$Q,MATCH("2024-04",Monthly!$A:$A,0)) -> 26.005667 | M14: =INDEX(Monthly!$Q:$Q,MATCH("2024-05",Monthly!$A:$A,0)) -> 27.280968 | N14: =INDEX(Monthly!$Q:$Q,MATCH("2024-06",Monthly!$A:$A,0)) -> 23.144 | O14: =AVERAGE(C14:N14) -> 23.095525
A15: Average El Niño | B15: 7 seasons | C15: =AVERAGE(C8:C14) -> 22.824608 | D15: =AVERAGE(D8:D14) -> 23.356544 | E15: =AVERAGE(E8:E14) -> 22.884762 | F15: =AVERAGE(F8:F14) -> 21.891705 | G15: =AVERAGE(G8:G14) -> 20.583095 | H15: =AVERAGE(H8:H14) -> 20.230645 | I15: =AVERAGE(I8:I14) -> 20.326728 | J15: =AVERAGE(J8:J14) -> 21.600823 | ... N15: =AVERAGE(N8:N14) -> 22.74181 | O15: =AVERAGE(C15:N15) -> 22.516773
A17: La Niña (9 seasons)
A18: 2005/06 | B18: La Niña | C18: =INDEX(Monthly!$Q:$Q,MATCH("2005-07",Monthly!$A:$A,0)) -> 22.002258 | D18: =INDEX(Monthly!$Q:$Q,MATCH("2005-08",Monthly!$A:$A,0)) -> 22.353871 | E18: =INDEX(Monthly!$Q:$Q,MATCH("2005-09",Monthly!$A:$A,0)) -> 22 | F18: =INDEX(Monthly!$Q:$Q,MATCH("2005-10",Monthly!$A:$A,0)) -> 20.72871 | G18: =INDEX(Monthly!$Q:$Q,MATCH("2005-11",Monthly!$A:$A,0)) -> 19.751333 | H18: =INDEX(Monthly!$Q:$Q,MATCH("2005-12",Monthly!$A:$A,0)) -> 20.613226 | I18: =INDEX(Monthly!$Q:$Q,MATCH("2006-01",Monthly!$A:$A,0)) -> 20.27 | J18: =INDEX(Monthly!$Q:$Q,MATCH("2006-02",Monthly!$A:$A,0)) -> 20.678929 | K18: =INDEX(Monthly!$Q:$Q,MATCH("2006-03",Monthly!$A:$A,0)) -> 23.187097 | L18: =INDEX(Monthly!$Q:$Q,MATCH("2006-04",Monthly!$A:$A,0)) -> 24.347 | M18: =INDEX(Monthly!$Q:$Q,MATCH("2006-05",Monthly!$A:$A,0)) -> 24.822581 | N18: =INDEX(Monthly!$Q:$Q,MATCH("2006-06",Monthly!$A:$A,0)) -> 22.343667 | O18: =AVERAGE(C18:N18) -> 21.924889
A19: 2007/08 | B19: La Niña | C19: =INDEX(Monthly!$Q:$Q,MATCH("2007-07",Monthly!$A:$A,0)) -> 22.554839 | D19: =INDEX(Monthly!$Q:$Q,MATCH("2007-08",Monthly!$A:$A,0)) -> 22.386129 | E19: =INDEX(Monthly!$Q:$Q,MATCH("2007-09",Monthly!$A:$A,0)) -> 21.39 | F19: =INDEX(Monthly!$Q:$Q,MATCH("2007-10",Monthly!$A:$A,0)) -> 20.509032 | G19: =INDEX(Monthly!$Q:$Q,MATCH("2007-11",Monthly!$A:$A,0)) -> 19.098667 | H19: =INDEX(Monthly!$Q:$Q,MATCH("2007-12",Monthly!$A:$A,0)) -> 18.827419 | I19: =INDEX(Monthly!$Q:$Q,MATCH("2008-01",Monthly!$A:$A,0)) -> 19.476774 | J19: =INDEX(Monthly!$Q:$Q,MATCH("2008-02",Monthly!$A:$A,0)) -> 21.523448 | K19: =INDEX(Monthly!$Q:$Q,MATCH("2008-03",Monthly!$A:$A,0)) -> 22.901935 | L19: =INDEX(Monthly!$Q:$Q,MATCH("2008-04",Monthly!$A:$A,0)) -> 24.436667 | M19: =INDEX(Monthly!$Q:$Q,MATCH("2008-05",Monthly!$A:$A,0)) -> 25.066129 | N19: =INDEX(Monthly!$Q:$Q,MATCH("2008-06",Monthly!$A:$A,0)) -> 22.063 | O19: =AVERAGE(C19:N19) -> 21.68617
A20: 2008/09 | B20: La Niña | C20: =INDEX(Monthly!$Q:$Q,MATCH("2008-07",Monthly!$A:$A,0)) -> 20.920323 | D20: =INDEX(Monthly!$Q:$Q,MATCH("2008-08",Monthly!$A:$A,0)) -> 21.499355 | E20: =INDEX(Monthly!$Q:$Q,MATCH("2008-09",Monthly!$A:$A,0)) -> 21.823667 | F20: =INDEX(Monthly!$Q:$Q,MATCH("2008-10",Monthly!$A:$A,0)) -> 20.555484 | G20: =INDEX(Monthly!$Q:$Q,MATCH("2008-11",Monthly!$A:$A,0)) -> 18.329333 | H20: =INDEX(Monthly!$Q:$Q,MATCH("2008-12",Monthly!$A:$A,0)) -> 18.084194 | I20: =INDEX(Monthly!$Q:$Q,MATCH("2009-01",Monthly!$A:$A,0)) -> 18.124839 | J20: =INDEX(Monthly!$Q:$Q,MATCH("2009-02",Monthly!$A:$A,0)) -> 19.190714 | K20: =INDEX(Monthly!$Q:$Q,MATCH("2009-03",Monthly!$A:$A,0)) -> 20.811613 | L20: =INDEX(Monthly!$Q:$Q,MATCH("2009-04",Monthly!$A:$A,0)) -> 24.516 | M20: =INDEX(Monthly!$Q:$Q,MATCH("2009-05",Monthly!$A:$A,0)) -> 23.329032 | N20: =INDEX(Monthly!$Q:$Q,MATCH("2009-06",Monthly!$A:$A,0)) -> 22.431333 | O20: =AVERAGE(C20:N20) -> 20.801324
A21: 2010/11 | B21: La Niña | C21: =INDEX(Monthly!$Q:$Q,MATCH("2010-07",Monthly!$A:$A,0)) -> 21.722903 | D21: =INDEX(Monthly!$Q:$Q,MATCH("2010-08",Monthly!$A:$A,0)) -> 21.827097 | E21: =INDEX(Monthly!$Q:$Q,MATCH("2010-09",Monthly!$A:$A,0)) -> 21.645 | F21: =INDEX(Monthly!$Q:$Q,MATCH("2010-10",Monthly!$A:$A,0)) -> 19.763548 | G21: =INDEX(Monthly!$Q:$Q,MATCH("2010-11",Monthly!$A:$A,0)) -> 18.627667 | H21: =INDEX(Monthly!$Q:$Q,MATCH("2010-12",Monthly!$A:$A,0)) -> 17.037097 | I21: =INDEX(Monthly!$Q:$Q,MATCH("2011-01",Monthly!$A:$A,0)) -> 19.704516 | J21: =INDEX(Monthly!$Q:$Q,MATCH("2011-02",Monthly!$A:$A,0)) -> 20.911071 | K21: =INDEX(Monthly!$Q:$Q,MATCH("2011-03",Monthly!$A:$A,0)) -> 21.889355 | L21: =INDEX(Monthly!$Q:$Q,MATCH("2011-04",Monthly!$A:$A,0)) -> 24.286333 | M21: =INDEX(Monthly!$Q:$Q,MATCH("2011-05",Monthly!$A:$A,0)) -> 24.112581 | N21: =INDEX(Monthly!$Q:$Q,MATCH("2011-06",Monthly!$A:$A,0)) -> 22.604 | O21: =AVERAGE(C21:N21) -> 21.177597
A22: 2011/12 | B22: La Niña | C22: =INDEX(Monthly!$Q:$Q,MATCH("2011-07",Monthly!$A:$A,0)) -> 21.600968 | D22: =INDEX(Monthly!$Q:$Q,MATCH("2011-08",Monthly!$A:$A,0)) -> 22.119355 | E22: =INDEX(Monthly!$Q:$Q,MATCH("2011-09",Monthly!$A:$A,0)) -> 21.698 | F22: =INDEX(Monthly!$Q:$Q,MATCH("2011-10",Monthly!$A:$A,0)) -> 19.907097 | G22: =INDEX(Monthly!$Q:$Q,MATCH("2011-11",Monthly!$A:$A,0)) -> 18.920333 | H22: =INDEX(Monthly!$Q:$Q,MATCH("2011-12",Monthly!$A:$A,0)) -> 18.165806 | I22: =INDEX(Monthly!$Q:$Q,MATCH("2012-01",Monthly!$A:$A,0)) -> 18.992258 | J22: =INDEX(Monthly!$Q:$Q,MATCH("2012-02",Monthly!$A:$A,0)) -> 21.104483 | K22: =INDEX(Monthly!$Q:$Q,MATCH("2012-03",Monthly!$A:$A,0)) -> 22.529677 | L22: =INDEX(Monthly!$Q:$Q,MATCH("2012-04",Monthly!$A:$A,0)) -> 23.510667 | M22: =INDEX(Monthly!$Q:$Q,MATCH("2012-05",Monthly!$A:$A,0)) -> 23.386774 | N22: =INDEX(Monthly!$Q:$Q,MATCH("2012-06",Monthly!$A:$A,0)) -> 22.377 | O22: =AVERAGE(C22:N22) -> 21.192702
A23: 2017/18 | B23: La Niña | C23: =INDEX(Monthly!$Q:$Q,MATCH("2017-07",Monthly!$A:$A,0)) -> 21.605484 | D23: =INDEX(Monthly!$Q:$Q,MATCH("2017-08",Monthly!$A:$A,0)) -> 21.970323 | E23: =INDEX(Monthly!$Q:$Q,MATCH("2017-09",Monthly!$A:$A,0)) -> 21.969 | F23: =INDEX(Monthly!$Q:$Q,MATCH("2017-10",Monthly!$A:$A,0)) -> 21.000645 | G23: =INDEX(Monthly!$Q:$Q,MATCH("2017-11",Monthly!$A:$A,0)) -> 19.259667 | H23: =INDEX(Monthly!$Q:$Q,MATCH("2017-12",Monthly!$A:$A,0)) -> 18.384516 | I23: =INDEX(Monthly!$Q:$Q,MATCH("2018-01",Monthly!$A:$A,0)) -> 17.995161 | J23: =INDEX(Monthly!$Q:$Q,MATCH("2018-02",Monthly!$A:$A,0)) -> 20.155 | K23: =INDEX(Monthly!$Q:$Q,MATCH("2018-03",Monthly!$A:$A,0)) -> 22.891613 | L23: =INDEX(Monthly!$Q:$Q,MATCH("2018-04",Monthly!$A:$A,0)) -> 24.055333 | M23: =INDEX(Monthly!$Q:$Q,MATCH("2018-05",Monthly!$A:$A,0)) -> 23.823226 | N23: =INDEX(Monthly!$Q:$Q,MATCH("2018-06",Monthly!$A:$A,0)) -> 21.637667 | O23: =AVERAGE(C23:N23) -> 21.22897
A24: 2020/21 | B24: La Niña | C24: =INDEX(Monthly!$Q:$Q,MATCH("2020-07",Monthly!$A:$A,0)) -> 22.038065 | D24: =INDEX(Monthly!$Q:$Q,MATCH("2020-08",Monthly!$A:$A,0)) -> 22.056129 | E24: =INDEX(Monthly!$Q:$Q,MATCH("2020-09",Monthly!$A:$A,0)) -> 22.277333 | F24: =INDEX(Monthly!$Q:$Q,MATCH("2020-10",Monthly!$A:$A,0)) -> 21.298387 | G24: =INDEX(Monthly!$Q:$Q,MATCH("2020-11",Monthly!$A:$A,0)) -> 20.58 | H24: =INDEX(Monthly!$Q:$Q,MATCH("2020-12",Monthly!$A:$A,0)) -> 18.617742 | I24: =INDEX(Monthly!$Q:$Q,MATCH("2021-01",Monthly!$A:$A,0)) -> 18.839355 | J24: =INDEX(Monthly!$Q:$Q,MATCH("2021-02",Monthly!$A:$A,0)) -> 19.291786 | K24: =INDEX(Monthly!$Q:$Q,MATCH("2021-03",Monthly!$A:$A,0)) -> 20.167097 | L24: =INDEX(Monthly!$Q:$Q,MATCH("2021-04",Monthly!$A:$A,0)) -> 22.113333 | M24: =INDEX(Monthly!$Q:$Q,MATCH("2021-05",Monthly!$A:$A,0)) -> 23.18871 | N24: =INDEX(Monthly!$Q:$Q,MATCH("2021-06",Monthly!$A:$A,0)) -> 22.597667 | O24: =AVERAGE(C24:N24) -> 21.0888
A25: 2021/22 | B25: La Niña | C25: =INDEX(Monthly!$Q:$Q,MATCH("2021-07",Monthly!$A:$A,0)) -> 22.078387 | D25: =INDEX(Monthly!$Q:$Q,MATCH("2021-08",Monthly!$A:$A,0)) -> 22.102581 | E25: =INDEX(Monthly!$Q:$Q,MATCH("2021-09",Monthly!$A:$A,0)) -> 22.141667 | F25: =INDEX(Monthly!$Q:$Q,MATCH("2021-10",Monthly!$A:$A,0)) -> 21.954839 | G25: =INDEX(Monthly!$Q:$Q,MATCH("2021-11",Monthly!$A:$A,0)) -> 19.435333 | H25: =INDEX(Monthly!$Q:$Q,MATCH("2021-12",Monthly!$A:$A,0)) -> 19.470645 | I25: =INDEX(Monthly!$Q:$Q,MATCH("2022-01",Monthly!$A:$A,0)) -> 19.239355 | J25: =INDEX(Monthly!$Q:$Q,MATCH("2022-02",Monthly!$A:$A,0)) -> 19.7975 | K25: =INDEX(Monthly!$Q:$Q,MATCH("2022-03",Monthly!$A:$A,0)) -> 22.239032 | L25: =INDEX(Monthly!$Q:$Q,MATCH("2022-04",Monthly!$A:$A,0)) -> 24.002 | M25: =INDEX(Monthly!$Q:$Q,MATCH("2022-05",Monthly!$A:$A,0)) -> 23.129355 | N25: =INDEX(Monthly!$Q:$Q,MATCH("2022-06",Monthly!$A:$A,0)) -> 21.362667 | O25: =AVERAGE(C25:N25) -> 21.41278
A26: 2022/23 | B26: La Niña | C26: =INDEX(Monthly!$Q:$Q,MATCH("2022-07",Monthly!$A:$A,0)) -> 21.585484 | D26: =INDEX(Monthly!$Q:$Q,MATCH("2022-08",Monthly!$A:$A,0)) -> 21.689677 | E26: =INDEX(Monthly!$Q:$Q,MATCH("2022-09",Monthly!$A:$A,0)) -> 21.654333 | F26: =INDEX(Monthly!$Q:$Q,MATCH("2022-10",Monthly!$A:$A,0)) -> 21.317097 | G26: =INDEX(Monthly!$Q:$Q,MATCH("2022-11",Monthly!$A:$A,0)) -> 20.48 | H26: =INDEX(Monthly!$Q:$Q,MATCH("2022-12",Monthly!$A:$A,0)) -> 18.74129 | I26: =INDEX(Monthly!$Q:$Q,MATCH("2023-01",Monthly!$A:$A,0)) -> 18.810968 | J26: =INDEX(Monthly!$Q:$Q,MATCH("2023-02",Monthly!$A:$A,0)) -> 19.983571 | K26: =INDEX(Monthly!$Q:$Q,MATCH("2023-03",Monthly!$A:$A,0)) -> 22.793548 | L26: =INDEX(Monthly!$Q:$Q,MATCH("2023-04",Monthly!$A:$A,0)) -> 24.466333 | M26: =INDEX(Monthly!$Q:$Q,MATCH("2023-05",Monthly!$A:$A,0)) -> 24.870968 | N26: =INDEX(Monthly!$Q:$Q,MATCH("2023-06",Monthly!$A:$A,0)) -> 23.17 | O26: =AVERAGE(C26:N26) -> 21.630273
A27: Average La Niña | B27: 9 seasons | C27: =AVERAGE(C18:C26) -> 21.789857 | D27: =AVERAGE(D18:D26) -> 22.000502 | E27: =AVERAGE(E18:E26) -> 21.844333 | F27: =AVERAGE(F18:F26) -> 20.781649 | G27: =AVERAGE(G18:G26) -> 19.386926 | H27: =AVERAGE(H18:H26) -> 18.660215 | I27: =AVERAGE(I18:I26) -> 19.050358 | J27: =AVERAGE(J18:J26) -> 20.292945 | ... N27: =AVERAGE(N18:N26) -> 22.287444 | O27: =AVERAGE(C27:N27) -> 21.349278
A29: Neutral (4 seasons)
A30: 2012/13 | B30: Neutral | C30: =INDEX(Monthly!$Q:$Q,MATCH("2012-07",Monthly!$A:$A,0)) -> 22.291613 | D30: =INDEX(Monthly!$Q:$Q,MATCH("2012-08",Monthly!$A:$A,0)) -> 22.382903 | E30: =INDEX(Monthly!$Q:$Q,MATCH("2012-09",Monthly!$A:$A,0)) -> 21.880333 | F30: =INDEX(Monthly!$Q:$Q,MATCH("2012-10",Monthly!$A:$A,0)) -> 20.74871 | G30: =INDEX(Monthly!$Q:$Q,MATCH("2012-11",Monthly!$A:$A,0)) -> 18.623667 | H30: =INDEX(Monthly!$Q:$Q,MATCH("2012-12",Monthly!$A:$A,0)) -> 19.635161 | I30: =INDEX(Monthly!$Q:$Q,MATCH("2013-01",Monthly!$A:$A,0)) -> 20.003871 | J30: =INDEX(Monthly!$Q:$Q,MATCH("2013-02",Monthly!$A:$A,0)) -> 21.887143 | K30: =INDEX(Monthly!$Q:$Q,MATCH("2013-03",Monthly!$A:$A,0)) -> 21.816774 | L30: =INDEX(Monthly!$Q:$Q,MATCH("2013-04",Monthly!$A:$A,0)) -> 25.029667 | M30: =INDEX(Monthly!$Q:$Q,MATCH("2013-05",Monthly!$A:$A,0)) -> 23.851613 | N30: =INDEX(Monthly!$Q:$Q,MATCH("2013-06",Monthly!$A:$A,0)) -> 22.178333 | O30: =AVERAGE(C30:N30) -> 21.694149
A31: 2013/14 | B31: Neutral | C31: =INDEX(Monthly!$Q:$Q,MATCH("2013-07",Monthly!$A:$A,0)) -> 22.001935 | D31: =INDEX(Monthly!$Q:$Q,MATCH("2013-08",Monthly!$A:$A,0)) -> 22.588065 | E31: =INDEX(Monthly!$Q:$Q,MATCH("2013-09",Monthly!$A:$A,0)) -> 21.831333 | F31: =INDEX(Monthly!$Q:$Q,MATCH("2013-10",Monthly!$A:$A,0)) -> 21.307742 | G31: =INDEX(Monthly!$Q:$Q,MATCH("2013-11",Monthly!$A:$A,0)) -> 19.931333 | H31: =INDEX(Monthly!$Q:$Q,MATCH("2013-12",Monthly!$A:$A,0)) -> 19.253548 | I31: =INDEX(Monthly!$Q:$Q,MATCH("2014-01",Monthly!$A:$A,0)) -> 18.579355 | J31: =INDEX(Monthly!$Q:$Q,MATCH("2014-02",Monthly!$A:$A,0)) -> 21.285 | K31: =INDEX(Monthly!$Q:$Q,MATCH("2014-03",Monthly!$A:$A,0)) -> 23.762258 | L31: =INDEX(Monthly!$Q:$Q,MATCH("2014-04",Monthly!$A:$A,0)) -> 25.248 | M31: =INDEX(Monthly!$Q:$Q,MATCH("2014-05",Monthly!$A:$A,0)) -> 24.043871 | N31: =INDEX(Monthly!$Q:$Q,MATCH("2014-06",Monthly!$A:$A,0)) -> 23.157 | O31: =AVERAGE(C31:N31) -> 21.915787
A32: 2016/17 | B32: Neutral | C32: =INDEX(Monthly!$Q:$Q,MATCH("2016-07",Monthly!$A:$A,0)) -> 22.88871 | D32: =INDEX(Monthly!$Q:$Q,MATCH("2016-08",Monthly!$A:$A,0)) -> 22.986129 | E32: =INDEX(Monthly!$Q:$Q,MATCH("2016-09",Monthly!$A:$A,0)) -> 22.424667 | F32: =INDEX(Monthly!$Q:$Q,MATCH("2016-10",Monthly!$A:$A,0)) -> 21.355161 | G32: =INDEX(Monthly!$Q:$Q,MATCH("2016-11",Monthly!$A:$A,0)) -> 20.351 | H32: =INDEX(Monthly!$Q:$Q,MATCH("2016-12",Monthly!$A:$A,0)) -> 20.567419 | I32: =INDEX(Monthly!$Q:$Q,MATCH("2017-01",Monthly!$A:$A,0)) -> 20.069032 | J32: =INDEX(Monthly!$Q:$Q,MATCH("2017-02",Monthly!$A:$A,0)) -> 22.255357 | K32: =INDEX(Monthly!$Q:$Q,MATCH("2017-03",Monthly!$A:$A,0)) -> 22.44 | L32: =INDEX(Monthly!$Q:$Q,MATCH("2017-04",Monthly!$A:$A,0)) -> 24.981333 | M32: =INDEX(Monthly!$Q:$Q,MATCH("2017-05",Monthly!$A:$A,0)) -> 23.623548 | N32: =INDEX(Monthly!$Q:$Q,MATCH("2017-06",Monthly!$A:$A,0)) -> 22.417 | O32: =AVERAGE(C32:N32) -> 22.196613
A33: 2024/25 | B33: Neutral | C33: =INDEX(Monthly!$Q:$Q,MATCH("2024-07",Monthly!$A:$A,0)) -> 22.366452 | D33: =INDEX(Monthly!$Q:$Q,MATCH("2024-08",Monthly!$A:$A,0)) -> 22.525484 | E33: =INDEX(Monthly!$Q:$Q,MATCH("2024-09",Monthly!$A:$A,0)) -> 22.814 | F33: =INDEX(Monthly!$Q:$Q,MATCH("2024-10",Monthly!$A:$A,0)) -> 21.645484 | G33: =INDEX(Monthly!$Q:$Q,MATCH("2024-11",Monthly!$A:$A,0)) -> 20.538333 | H33: =INDEX(Monthly!$Q:$Q,MATCH("2024-12",Monthly!$A:$A,0)) -> 19.526452 | I33: =INDEX(Monthly!$Q:$Q,MATCH("2025-01",Monthly!$A:$A,0)) -> 19.190323 | J33: =INDEX(Monthly!$Q:$Q,MATCH("2025-02",Monthly!$A:$A,0)) -> 20.02 | K33: =INDEX(Monthly!$Q:$Q,MATCH("2025-03",Monthly!$A:$A,0)) -> 22.072258 | L33: =INDEX(Monthly!$Q:$Q,MATCH("2025-04",Monthly!$A:$A,0)) -> 21.937667 | M33: =INDEX(Monthly!$Q:$Q,MATCH("2025-05",Monthly!$A:$A,0)) -> 24.806452 | N33: =INDEX(Monthly!$Q:$Q,MATCH("2025-06",Monthly!$A:$A,0)) -> 22.262 | O33: =AVERAGE(C33:N33) -> 21.642075
A34: Average Neutral | B34: 4 seasons | C34: =AVERAGE(C30:C33) -> 22.387177 | D34: =AVERAGE(D30:D33) -> 22.620645 | E34: =AVERAGE(E30:E33) -> 22.237583 | F34: =AVERAGE(F30:F33) -> 21.264274 | G34: =AVERAGE(G30:G33) -> 19.861083 | H34: =AVERAGE(H30:H33) -> 19.745645 | I34: =AVERAGE(I30:I33) -> 19.460645 | J34: =AVERAGE(J30:J33) -> 21.361875 | ... N34: =AVERAGE(N30:N33) -> 22.503583 | O34: =AVERAGE(C34:N34) -> 21.862156
A36: After the photo window (not in the averages)
A37: 2025/26 | B37: Neutral | C37: =INDEX(Monthly!$Q:$Q,MATCH("2025-07",Monthly!$A:$A,0)) -> 22.03871 | D37: =INDEX(Monthly!$Q:$Q,MATCH("2025-08",Monthly!$A:$A,0)) -> 22.722581 | E37: =INDEX(Monthly!$Q:$Q,MATCH("2025-09",Monthly!$A:$A,0)) -> 22.457333 | F37: =INDEX(Monthly!$Q:$Q,MATCH("2025-10",Monthly!$A:$A,0)) -> 21.337419 | G37: =INDEX(Monthly!$Q:$Q,MATCH("2025-11",Monthly!$A:$A,0)) -> 20.172 | H37: =INDEX(Monthly!$Q:$Q,MATCH("2025-12",Monthly!$A:$A,0)) -> 19.831613 | I37: =INDEX(Monthly!$Q:$Q,MATCH("2026-01",Monthly!$A:$A,0)) -> 19.039032 | J37: =INDEX(Monthly!$Q:$Q,MATCH("2026-02",Monthly!$A:$A,0)) -> 18.859286 | K37: =INDEX(Monthly!$Q:$Q,MATCH("2026-03",Monthly!$A:$A,0)) -> 21.568387 | L37: =INDEX(Monthly!$Q:$Q,MATCH("2026-04",Monthly!$A:$A,0)) -> 21.735 | M37: =INDEX(Monthly!$Q:$Q,MATCH("2026-05",Monthly!$A:$A,0)) -> 24.451935 | N37: =INDEX(Monthly!$Q:$Q,MATCH("2026-06",Monthly!$A:$A,0)) -> 23.448667 | O37: =AVERAGE(C37:N37) -> 21.47183
A38: 2026/27 | B38: El Niño (in progress) | C38: =INDEX(Monthly!$Q:$Q,MATCH("2026-07",Monthly!$A:$A,0)) -> 23.522581 | D38: =INDEX(Monthly!$Q:$Q,MATCH("2026-08",Monthly!$A:$A,0)) -> 23.580968
A41: Monthly rainfall (mm) — sum of daily rainfall from rain gauges (NOAA CPC)
A42: Season | B42: Phase | C42: Jul | D42: Aug | E42: Sep | F42: Oct | G42: Nov | H42: Dec | I42: Jan | J42: Feb | K42: Mar | L42: Apr | M42: May | N42: Jun | O42: Season total
A43: El Niño (7 seasons)
A44: 2006/07 | B44: El Niño | C44: =INDEX(Monthly!$P:$P,MATCH("2006-07",Monthly!$A:$A,0)) -> 140.11 | D44: =INDEX(Monthly!$P:$P,MATCH("2006-08",Monthly!$A:$A,0)) -> 54.827 | E44: =INDEX(Monthly!$P:$P,MATCH("2006-09",Monthly!$A:$A,0)) -> 183.784 | F44: =INDEX(Monthly!$P:$P,MATCH("2006-10",Monthly!$A:$A,0)) -> 172.228 | G44: =INDEX(Monthly!$P:$P,MATCH("2006-11",Monthly!$A:$A,0)) -> 55.998 | H44: =INDEX(Monthly!$P:$P,MATCH("2006-12",Monthly!$A:$A,0)) -> 32.25 | I44: =INDEX(Monthly!$P:$P,MATCH("2007-01",Monthly!$A:$A,0)) -> 2.74 | J44: =INDEX(Monthly!$P:$P,MATCH("2007-02",Monthly!$A:$A,0)) -> 2.085 | K44: =INDEX(Monthly!$P:$P,MATCH("2007-03",Monthly!$A:$A,0)) -> 5.48 | L44: =INDEX(Monthly!$P:$P,MATCH("2007-04",Monthly!$A:$A,0)) -> 58.081 | M44: =INDEX(Monthly!$P:$P,MATCH("2007-05",Monthly!$A:$A,0)) -> 77.63 | N44: =INDEX(Monthly!$P:$P,MATCH("2007-06",Monthly!$A:$A,0)) -> 191.058 | O44: =SUM(C44:N44) -> 976.271
A45: 2009/10 | B45: El Niño | C45: =INDEX(Monthly!$P:$P,MATCH("2009-07",Monthly!$A:$A,0)) -> 154.351 | D45: =INDEX(Monthly!$P:$P,MATCH("2009-08",Monthly!$A:$A,0)) -> 159.515 | E45: =INDEX(Monthly!$P:$P,MATCH("2009-09",Monthly!$A:$A,0)) -> 157.755 | F45: =INDEX(Monthly!$P:$P,MATCH("2009-10",Monthly!$A:$A,0)) -> 88.816 | G45: =INDEX(Monthly!$P:$P,MATCH("2009-11",Monthly!$A:$A,0)) -> 101.03 | H45: =INDEX(Monthly!$P:$P,MATCH("2009-12",Monthly!$A:$A,0)) -> 34.142 | I45: =INDEX(Monthly!$P:$P,MATCH("2010-01",Monthly!$A:$A,0)) -> 1.428 | J45: =INDEX(Monthly!$P:$P,MATCH("2010-02",Monthly!$A:$A,0)) -> 1.67 | K45: =INDEX(Monthly!$P:$P,MATCH("2010-03",Monthly!$A:$A,0)) -> 0.995 | L45: =INDEX(Monthly!$P:$P,MATCH("2010-04",Monthly!$A:$A,0)) -> 111.742 | M45: =INDEX(Monthly!$P:$P,MATCH("2010-05",Monthly!$A:$A,0)) -> 320.1 | N45: =INDEX(Monthly!$P:$P,MATCH("2010-06",Monthly!$A:$A,0)) -> 250.838 | O45: =SUM(C45:N45) -> 1382.382
A46: 2014/15 | B46: El Niño | C46: =INDEX(Monthly!$P:$P,MATCH("2014-07",Monthly!$A:$A,0)) -> 29.379 | D46: =INDEX(Monthly!$P:$P,MATCH("2014-08",Monthly!$A:$A,0)) -> 164.523 | E46: =INDEX(Monthly!$P:$P,MATCH("2014-09",Monthly!$A:$A,0)) -> 210.235 | F46: =INDEX(Monthly!$P:$P,MATCH("2014-10",Monthly!$A:$A,0)) -> 153.326 | G46: =INDEX(Monthly!$P:$P,MATCH("2014-11",Monthly!$A:$A,0)) -> 33.889 | H46: =INDEX(Monthly!$P:$P,MATCH("2014-12",Monthly!$A:$A,0)) -> 2.653 | I46: =INDEX(Monthly!$P:$P,MATCH("2015-01",Monthly!$A:$A,0)) -> 5.953 | J46: =INDEX(Monthly!$P:$P,MATCH("2015-02",Monthly!$A:$A,0)) -> 3.411 | K46: =INDEX(Monthly!$P:$P,MATCH("2015-03",Monthly!$A:$A,0)) -> 12.708 | L46: =INDEX(Monthly!$P:$P,MATCH("2015-04",Monthly!$A:$A,0)) -> 27.371 | M46: =INDEX(Monthly!$P:$P,MATCH("2015-05",Monthly!$A:$A,0)) -> 37.529 | N46: =INDEX(Monthly!$P:$P,MATCH("2015-06",Monthly!$A:$A,0)) -> 189.803 | O46: =SUM(C46:N46) -> 870.78
...

Sheet Chart_Ocotepeque
A1: Ocotepeque — Ocotepeque department, town of Nueva Ocotepeque | Temperature and rainfall by ENSO season
A2: Rain: NOAA CPC gauge analysis (daily, 0.5°). Temperature: NASA POWER daily (grid cell of each town). July–June seasons 2005/06–2024/25 as in the São Mateus chart. Season phase = official NOAA ENSO episode at its Nov–Jan peak (sheet ENSO_seasons). Average rows = mean of the seasons of that phase in the photo window.
A3: Seasons after the photo window are listed below each block, outside the averages. 2026/27: complete months only (data end 2026-09-22).
A5: Mean temperature (°C) — monthly mean of daily T2M
A6: Season | B6: Phase | C6: Jul | D6: Aug | E6: Sep | F6: Oct | G6: Nov | H6: Dec | I6: Jan | J6: Feb | K6: Mar | L6: Apr | M6: May | N6: Jun | O6: Season mean
A7: El Niño (7 seasons)
A8: 2006/07 | B8: El Niño | C8: =INDEX(Monthly!$V:$V,MATCH("2006-07",Monthly!$A:$A,0)) -> 22.55871 | D8: =INDEX(Monthly!$V:$V,MATCH("2006-08",Monthly!$A:$A,0)) -> 22.464194 | E8: =INDEX(Monthly!$V:$V,MATCH("2006-09",Monthly!$A:$A,0)) -> 22.318667 | F8: =INDEX(Monthly!$V:$V,MATCH("2006-10",Monthly!$A:$A,0)) -> 22.070323 | G8: =INDEX(Monthly!$V:$V,MATCH("2006-11",Monthly!$A:$A,0)) -> 19.708333 | H8: =INDEX(Monthly!$V:$V,MATCH("2006-12",Monthly!$A:$A,0)) -> 20.178387 | I8: =INDEX(Monthly!$V:$V,MATCH("2007-01",Monthly!$A:$A,0)) -> 20.612258 | J8: =INDEX(Monthly!$V:$V,MATCH("2007-02",Monthly!$A:$A,0)) -> 21.628571 | K8: =INDEX(Monthly!$V:$V,MATCH("2007-03",Monthly!$A:$A,0)) -> 22.585161 | L8: =INDEX(Monthly!$V:$V,MATCH("2007-04",Monthly!$A:$A,0)) -> 24.719333 | M8: =INDEX(Monthly!$V:$V,MATCH("2007-05",Monthly!$A:$A,0)) -> 25.443548 | N8: =INDEX(Monthly!$V:$V,MATCH("2007-06",Monthly!$A:$A,0)) -> 23.074667 | O8: =AVERAGE(C8:N8) -> 22.280179
A9: 2009/10 | B9: El Niño | C9: =INDEX(Monthly!$V:$V,MATCH("2009-07",Monthly!$A:$A,0)) -> 22.727097 | D9: =INDEX(Monthly!$V:$V,MATCH("2009-08",Monthly!$A:$A,0)) -> 22.504516 | E9: =INDEX(Monthly!$V:$V,MATCH("2009-09",Monthly!$A:$A,0)) -> 22.546333 | F9: =INDEX(Monthly!$V:$V,MATCH("2009-10",Monthly!$A:$A,0)) -> 22.355484 | G9: =INDEX(Monthly!$V:$V,MATCH("2009-11",Monthly!$A:$A,0)) -> 20.179333 | H9: =INDEX(Monthly!$V:$V,MATCH("2009-12",Monthly!$A:$A,0)) -> 20.12871 | I9: =INDEX(Monthly!$V:$V,MATCH("2010-01",Monthly!$A:$A,0)) -> 19.224516 | J9: =INDEX(Monthly!$V:$V,MATCH("2010-02",Monthly!$A:$A,0)) -> 21.903571 | K9: =INDEX(Monthly!$V:$V,MATCH("2010-03",Monthly!$A:$A,0)) -> 23.350323 | L9: =INDEX(Monthly!$V:$V,MATCH("2010-04",Monthly!$A:$A,0)) -> 25.248667 | M9: =INDEX(Monthly!$V:$V,MATCH("2010-05",Monthly!$A:$A,0)) -> 24.683548 | N9: =INDEX(Monthly!$V:$V,MATCH("2010-06",Monthly!$A:$A,0)) -> 22.954333 | O9: =AVERAGE(C9:N9) -> 22.317203
A10: 2014/15 | B10: El Niño | C10: =INDEX(Monthly!$V:$V,MATCH("2014-07",Monthly!$A:$A,0)) -> 23.339355 | D10: =INDEX(Monthly!$V:$V,MATCH("2014-08",Monthly!$A:$A,0)) -> 22.723871 | E10: =INDEX(Monthly!$V:$V,MATCH("2014-09",Monthly!$A:$A,0)) -> 22.122333 | F10: =INDEX(Monthly!$V:$V,MATCH("2014-10",Monthly!$A:$A,0)) -> 21.504516 | G10: =INDEX(Monthly!$V:$V,MATCH("2014-11",Monthly!$A:$A,0)) -> 19.652667 | H10: =INDEX(Monthly!$V:$V,MATCH("2014-12",Monthly!$A:$A,0)) -> 18.854516 | I10: =INDEX(Monthly!$V:$V,MATCH("2015-01",Monthly!$A:$A,0)) -> 19.139677 | J10: =INDEX(Monthly!$V:$V,MATCH("2015-02",Monthly!$A:$A,0)) -> 20.028214 | K10: =INDEX(Monthly!$V:$V,MATCH("2015-03",Monthly!$A:$A,0)) -> 22.164516 | L10: =INDEX(Monthly!$V:$V,MATCH("2015-04",Monthly!$A:$A,0)) -> 25.233667 | M10: =INDEX(Monthly!$V:$V,MATCH("2015-05",Monthly!$A:$A,0)) -> 24.777097 | N10: =INDEX(Monthly!$V:$V,MATCH("2015-06",Monthly!$A:$A,0)) -> 23.05 | O10: =AVERAGE(C10:N10) -> 21.882536
A11: 2015/16 | B11: El Niño | C11: =INDEX(Monthly!$V:$V,MATCH("2015-07",Monthly!$A:$A,0)) -> 23.824516 | D11: =INDEX(Monthly!$V:$V,MATCH("2015-08",Monthly!$A:$A,0)) -> 24.248065 | E11: =INDEX(Monthly!$V:$V,MATCH("2015-09",Monthly!$A:$A,0)) -> 22.726333 | F11: =INDEX(Monthly!$V:$V,MATCH("2015-10",Monthly!$A:$A,0)) -> 22.353871 | G11: =INDEX(Monthly!$V:$V,MATCH("2015-11",Monthly!$A:$A,0)) -> 21.443667 | H11: =INDEX(Monthly!$V:$V,MATCH("2015-12",Monthly!$A:$A,0)) -> 21.221935 | I11: =INDEX(Monthly!$V:$V,MATCH("2016-01",Monthly!$A:$A,0)) -> 20.035161 | J11: =INDEX(Monthly!$V:$V,MATCH("2016-02",Monthly!$A:$A,0)) -> 19.778276 | K11: =INDEX(Monthly!$V:$V,MATCH("2016-03",Monthly!$A:$A,0)) -> 24.524194 | L11: =INDEX(Monthly!$V:$V,MATCH("2016-04",Monthly!$A:$A,0)) -> 25.309667 | M11: =INDEX(Monthly!$V:$V,MATCH("2016-05",Monthly!$A:$A,0)) -> 25.963548 | N11: =INDEX(Monthly!$V:$V,MATCH("2016-06",Monthly!$A:$A,0)) -> 23.570667 | O11: =AVERAGE(C11:N11) -> 22.916658
A12: 2018/19 | B12: El Niño | C12: =INDEX(Monthly!$V:$V,MATCH("2018-07",Monthly!$A:$A,0)) -> 22.960323 | D12: =INDEX(Monthly!$V:$V,MATCH("2018-08",Monthly!$A:$A,0)) -> 22.73871 | E12: =INDEX(Monthly!$V:$V,MATCH("2018-09",Monthly!$A:$A,0)) -> 22.605333 | F12: =INDEX(Monthly!$V:$V,MATCH("2018-10",Monthly!$A:$A,0)) -> 21.554194 | G12: =INDEX(Monthly!$V:$V,MATCH("2018-11",Monthly!$A:$A,0)) -> 21.411667 | H12: =INDEX(Monthly!$V:$V,MATCH("2018-12",Monthly!$A:$A,0)) -> 20.437419 | I12: =INDEX(Monthly!$V:$V,MATCH("2019-01",Monthly!$A:$A,0)) -> 20.754839 | J12: =INDEX(Monthly!$V:$V,MATCH("2019-02",Monthly!$A:$A,0)) -> 23.534643 | K12: =INDEX(Monthly!$V:$V,MATCH("2019-03",Monthly!$A:$A,0)) -> 23.999032 | L12: =INDEX(Monthly!$V:$V,MATCH("2019-04",Monthly!$A:$A,0)) -> 25.737 | M12: =INDEX(Monthly!$V:$V,MATCH("2019-05",Monthly!$A:$A,0)) -> 24.126452 | N12: =INDEX(Monthly!$V:$V,MATCH("2019-06",Monthly!$A:$A,0)) -> 23.679333 | O12: =AVERAGE(C12:N12) -> 22.794912
