Workbook

Sheet README
A1: Honduras coffee: what drives production and yield, and how to forecast 2026/27
A2: Built 25 Sep 2026 by research/honduras/excel/build_yield_drivers_xlsx.py. Tests run in research/honduras/yield_drivers/analysis.py and robustness.py (Python, standard library).
A4: Answer in one line
A5: Year-to-year output moves with one-off shocks that do not repeat (not an on/off biennial cycle), with fertiliser use (the tightest link: r = +0.75), with heat in Sep-Oct just before the harvest (r = -0.45, exploratory) and with three documented crises (rust 2012/13, price slump 2019/20, rust after hurricanes Eta/Iota 2021/22). ENSO and seasonal rain show no reliable national effect. Some USDA "yield" jumps are bearing-area revisions.
A6: 2026/27: IHCAFE exports put 2025/26 near 6.0 M bags (USDA 5.53). From there, mean reversion and the record September heat point to about 5.5 M bags (range 4.9-6.1) for 2026/27, below USDA 6.03. Without the heat term: about 6.0 M.
A8: Colours
A9: Blue = input read from a file (source given on the sheet). Black = Excel formula. Purple = computed in Python (permutation p-values, regressions, simulated bands): not an Excel formula, re-run the scripts to reproduce.
A11: Crop year
A12: Crop year t = October t to September t+1 (label t/t+1). Harvest Nov t - Mar t+1; flowering Feb - Apr t; fertiliser and fruit fill May - Oct t. World prices, urea and FAO nitrogen use are calendar-year t values, the year the crop t is fertilised and filled.
A14: Sheets
A15: Data: every series by crop year 1970/71 - 2026/27. Changes: year-on-year log changes (formulas). Tests: one driver at a time, Pearson r (Excel CORREL check), permutation p, Holm-corrected p.
A16: Biennial: is there an on/off cycle? Yield_split: yield change = production change - area change. Fertiliser: nitrogen use vs output and what moves nitrogen.
... A25: Press figures for 2025/26 exports and 2026/27 outlooks: see Exports_nowcast and Forecast_2026_27, with status per line.

Sheet Data
A1: Data by crop year (t = October t to September t+1)
A2: Blue = input, black = formula. Rain = total of the window / 1991-2020 normal of the same months (1.00 = normal). ONI = NOAA Oceanic Nino Index of the 3-month season.
A5: Crop year | B5: t | C5: IHCAFE exports (46-kg bags) | D5: IHCAFE export price (US$ / 46 kg) | E5: USDA production (1 000 60-kg bags) | F5: USDA bearing area (kha) | G5: Yield (60-kg bags / bearing ha) | H5: Arabica, calendar t (US$/kg) | I5: Urea, calendar t (US$/t) | J5: kg urea bought by 1 kg coffee | K5: FAO nitrogen use, calendar t (t N) | L5: Rain Dec(t-1)-Mar t / normal (GPCC) | M5: Rain Apr-May t / normal | N5: Rain Jun-Oct t / normal | O5: ONI DJF t | P5: ONI JJA t | Q5: ONI OND t | R5: Coffee-zone max. temperature Sep-Oct, deg C vs 1991-2020 (ERA5-Land)
A6: 1970/71 | B6: 1970 | C6: 493989 | D6: 43.67 | E6: 545 | H6: 1.1475 | I6: 18.3 | J6: =H6*1000/I6 -> 62.704918 | O6: 0.46 | P6: -0.55 | Q6: -0.78
A7: 1971/72 | B7: 1971 | C7: 730349 | D7: 38.29 | E7: 586 | H7: 0.99083333 | I7: 16 | J7: =H7*1000/I7 -> 61.927083 | O7: -1.29 | P7: -0.68 | Q7: -0.86
A8: 1972/73 | B8: 1972 | C8: 894446 | D8: 53.93 | E8: 759 | H8: 1.1108333 | I8: 29.3 | J8: =H8*1000/I8 -> 37.9124 | O8: -0.57 | P8: 1 | Q8: 1.84
A9: 1973/74 | B9: 1973 | C9: 622061 | D9: 66.5 | E9: 689 | H9: 1.3733333 | I9: 64.8 | J9: =H9*1000/I9 -> 21.193416 | O9: 1.55 | P9: -0.99 | Q9: -1.89
A10: 1974/75 | B10: 1974 | C10: 1118404 | D10: 53.6 | E10: 983 | H10: 1.4525 | I10: 285.8 | J10: =H10*1000/I10 -> 5.0822253 | O10: -1.87 | P10: -0.46 | Q10: -0.88
A11: 1975/76 | B11: 1975 | C11: 824865 | D11: 99.99 | E11: 847 | H11: 1.4416667 | I11: 168 | J11: =H11*1000/I11 -> 8.5813492 | O11: -0.56 | P11: -1.08 | Q11: -1.47
A12: 1976/77 | B12: 1976 | C12: 820603 | D12: 206.02 | E12: 691 | H12: 3.1475 | I12: 82 | J12: =H12*1000/I12 -> 38.384146 | O12: -1.49 | P12: 0.23 | Q12: 0.81
A13: 1977/78 | B13: 1977 | C13: 1224716 | D13: 173.12 | E13: 1036 | H13: 5.17 | I13: 120.75833 | J13: =H13*1000/I13 -> 42.81278 | O13: 0.71 | P13: 0.39 | Q13: 0.84
A14: 1978/79 | B14: 1978 | C14: 1370789 | D14: 128.28 | E14: 1132 | H14: 3.5908333 | I14: 136.04167 | J14: =H14*1000/I14 -> 26.3951 | O14: 0.71 | P14: -0.37 | Q14: -0.07
A15: 1979/80 | B15: 1979 | C15: 1274178 | D15: 176.78 | E15: 1137 | H15: 3.825 | I15: 153.01667 | J15: =H15*1000/I15 -> 24.997277 | O15: 0.19 | P15: 0.09 | Q15: 0.5
A16: 1980/81 | B16: 1980 | C16: 1345082 | D16: 108.27 | E16: 1265 | H16: 3.4675 | I16: 200.56667 | J16: =H16*1000/I16 -> 17.288516 | O16: 0.62 | P16: 0.18 | Q16: 0.08
A17: 1981/82 | B17: 1981 | C17: 1188189 | D17: 128.89 | E17: 1200 | H17: 2.8675 | I17: 182.5 | J17: =H17*1000/I17 -> 15.712329 | M17: 0.89554862 | N17: 1.2698115 | O17: -0.27 | P17: -0.28 | Q17: -0.19 | R17: -0.47976667
A18: 1982/83 | B18: 1982 | C18: 1617981 | D18: 93.48 | E18: 1500 | H18: 3.0866667 | I18: 123.95833 | J18: =H18*1000/I18 -> 24.90084 | L18: 1.3359309 | M18: 1.2291387 | N18: 0.86332618 | O18: -0.05 | P18: 0.78 | Q18: 2.03 | R18: -0.75576667
A19: 1983/84 | B19: 1983 | C19: 1364128 | D19: 115.37 | E19: 1310 | H19: 2.9125 | I19: 114.54167 | J19: =H19*1000/I19 -> 25.427428 | L19: 0.89763193 | M19: 0.56760072 | N19: 0.98010663 | O19: 2.14 | P19: 0.25 | Q19: -0.96 | R19: -0.16926667
A20: 1984/85 | B20: 1984 | C20: 1675151 | D20: 110.82 | E20: 1400 | H20: 3.1891667 | I20: 150.16667 | J20: =H20*1000/I20 -> 21.237514 | L20: 1.1486429 | M20: 1.1464117 | N20: 1.0841527 | O20: -0.63 | P20: -0.39 | Q20: -0.95 | R20: -0.61426667
A21: 1985/86 | B21: 1985 | C21: 1931944 | D21: 183.81 | E21: 1062 | H21: 3.2316667 | I21: 111.625 | J21: =H21*1000/I21 -> 28.951101 | L21: 0.73952763 | M21: 0.6542864 | N21: 0.87764911 | O21: -1.01 | P21: -0.44 | Q21: -0.28 | R21: -0.068266667
A22: 1986/87 | B22: 1986 | C22: 1824220 | D22: 108.61 | E22: 1535 | H22: 4.2908333 | I22: 70.75 | J22: =H22*1000/I22 -> 60.647821 | L22: 1.0600439 | M22: 0.79576573 | N22: 0.6999526 | O22: -0.4 | P22: 0.24 | Q22: 1.06 | R22: -0.75376667
A23: 1987/88 | B23: 1987 | C23: 1596725 | D23: 119.75 | E23: 1553 | H23: 2.505 | I23: 82.5 | J23: =H23*1000/I23 -> 30.363636 | L23: 0.83876 | M23: 0.38224207 | N23: 0.89880957 | O23: 1.18 | P23: 1.3 | Q23: 1.2 | R23: -0.59126667
A24: 1988/89 | B24: 1988 | C24: 1910204 | D24: 117.46 | E24: 1635 | H24: 3.0325 | I24: 113.54167 | J24: =H24*1000/I24 -> 26.708257 | L24: 1.0985028 | M24: 0.77932024 | N24: 1.2011304 | O24: 0.63 | P24: -1.3 | Q24: -1.81 | R24: -1.0112667
A25: 1989/90 | B25: 1989 | C25: 2261332 | D25: 69.91 | E25: 1928 | H25: 2.3875 | I25: 102.95833 | J25: =H25*1000/I25 -> 23.188992 | L25: 1.0459566 | M25: 1.3486783 | N25: 1.0606736 | O25: -1.64 | P25: -0.37 | Q25: -0.12 | R25: -0.67126667
A26: 1990/91 | B26: 1990 | C26: 1861302 | D26: 78.39 | E26: 1685 | H26: 1.9733333 | I26: 115.65 | J26: =H26*1000/I26 -> 17.062977 | L26: 1.0554258 | M26: 1.3501768 | N26: 0.90191753 | O26: 0.18 | P26: 0.26 | Q26: 0.31 | R26: 0.15923333
A27: 1991/92 | B27: 1991 | C27: 2348302 | D27: 59.82 | E27: 2255 | H27: 1.8733333 | I27: 138.4 | J27: =H27*1000/I27 -> 13.535645 | L27: 0.82001568 | M27: 0.81025035 | N27: 0.85279857 | O27: 0.35 | P27: 0.77 | Q27: 1.18 | R27: 0.043233333
A28: 1992/93 | B28: 1992 | C28: 2473759 | D28: 54.44 | E28: 1981 | H28: 1.4108333 | I28: 117.60833 | J28: =H28*1000/I28 -> 11.996032 | L28: 1.3505616 | M28: 0.78146611 | N28: 1.0769764 | O28: 1.54 | P28: 0.35 | Q28: -0.24 | R28: 0.091233333
A29: 1993/94 | B29: 1993 | C29: 2166754 | D29: 80.37 | E29: 2060 | H29: 1.56 | I29: 85.541667 | J29: =H29*1000/I29 -> 18.236727 | L29: 1.0758388 | M29: 0.95056425 | N29: 0.97754462 | O29: 0.13 | P29: 0.28 | Q29: 0.2 | R29: -0.65926667
... A39: 2003/04 | B39: 2003 | C39: 3643971 | D39: 67.45 | E39: 2968 | H39: 1.4158333 | I39: 138.18333 | J39: =H39*1000/I39 -> 10.24605 | L39: 1.4746699 | M39: 0.96732422 | N39: 0.98162279 | O39: 0.9 | P39: 0.09 | Q39: 0.29 | R39: 0.50023333
A40: 2004/05 | B40: 2004 | C40: 3126830 | D40: 104.35 | E40: 2575 | H40: 1.7733333 | I40: 174.925 | J40: =H40*1000/I40 -> 10.137678 | K40: 26290 | L40: 1.0168893 | M40: 1.0913406 | N40: 0.82775069 | O40: 0.34 | P40: 0.39 | Q40: 0.64 | R40: 0.81323333
A41: 2005/06 | B41: 2005 | C41: 3817948 | D41: 105.32 | E41: 3204 | F41: 184 | G41: =E41/F41 -> 17.413043 | H41: 2.5325 | I41: 217.35833 | J41: =H41*1000/I41 -> 11.651267 | K41: 41865 | L41: 0.86910796 | M41: 0.87801169 | N41: 1.0302583 | O41: 0.62 | P41: -0.04 | Q41: -0.57 | R41: -0.73076667
A42: 2006/07 | B42: 2006 | C42: 4194523 | D42: 112.03 | E42: 3460 | F42: 230 | G42: =E42/F42 -> 15.043478 | H42: 2.5216667 | I42: 222.14167 | J42: =H42*1000/I42 -> 11.351615 | K42: 66688 | L42: 0.67840483 | M42: 0.73964017 | N42: 0.90287459 | O42: -0.86 | P42: 0.12 | Q42: 0.88 | R42: 0.56173333
A43: 2007/08 | B43: 2007 | C43: 4427991 | D43: 134.24 | E43: 3642 | F43: 230 | G43: =E43/F43 -> 15.834783 | H43: 2.7241667 | I43: 307.11667 | J43: =H43*1000/I43 -> 8.8701362 | K43: 63491 | L43: 1.0717252 | M43: 0.78416694 | N43: 1.1407274 | O43: 0.62 | P43: -0.49 | Q43: -1.57 | R43: -0.73026667
A44: 2008/09 | B44: 2008 | C44: 3940279 | D44: 117.74 | E44: 3225 | F44: 224 | G44: =E44/F44 -> 14.397321 | H44: 3.0808333 | I44: 514.98333 | J44: =H44*1000/I44 -> 5.9823943 | K44: 55554 | L44: 0.92704849 | M44: 0.8859847 | N44: 1.3732228 | O44: -1.76 | P44: -0.33 | Q44: -0.57 | R44: -0.64426667
A45: 2009/10 | B45: 2009 | C45: 4122888 | D45: 146.87 | E45: 3550 | F45: 224 | G45: =E45/F45 -> 15.848214 | H45: 3.1708333 | I45: 251.1 | J45: =H45*1000/I45 -> 12.627771 | K45: 47616 | L45: 0.95227377 | M45: 1.2530947 | N45: 0.93799621 | O45: -0.89 | P45: 0.5 | Q45: 1.31 | R45: 1.1522333
A46: 2010/11 | B46: 2010 | C46: 5042612 | D46: 245.69 | E46: 3975 | F46: 238 | G46: =E46/F46 -> 16.701681 | H46: 4.32 | I46: 288.91667 | J46: =H46*1000/I46 -> 14.952408 | K46: 56041 | L46: 0.9739287 | M46: 1.3520266 | N46: 1.221074 | O46: 1.47 | P46: -0.98 | Q46: -1.57 | R46: -0.81976667
A47: 2011/12 | B47: 2011 | C47: 7139810 | D47: 201.56 | E47: 5600 | F47: 245 | G47: =E47/F47 -> 22.857143 | H47: 5.9766667 | I47: 398.94167 | J47: =H47*1000/I47 -> 14.981305 | K47: 85542 | L47: 1.2710825 | M47: 1.1462268 | N47: 1.3071465 | O47: -1.29 | P47: -0.37 | Q47: -1.02 | R47: -0.82276667
A48: 2012/13 | B48: 2012 | C48: 5660894 | D48: 140.47 | E48: 4725 | F48: 267 | G48: =E48/F48 -> 17.696629 | H48: 4.1116667 | I48: 398.6 | J48: =H48*1000/I48 -> 10.31527 | K48: 75417 | L48: 0.98223364 | M48: 1.697382 | N48: 1.0413286 | O48: -0.71 | P48: 0.28 | Q48: 0.13 | R48: 0.049733333
A49: 2013/14 | B49: 2013 | C49: 5446757 | D49: 145.43 | E49: 4400 | F49: 213 | G49: =E49/F49 -> 20.657277 | H49: 3.0766667 | I49: 339.60833 | J49: =H49*1000/I49 -> 9.0594557 | K49: 74712 | L49: 1.2871103 | M49: 1.1058252 | N49: 1.000481 | O49: -0.24 | P49: -0.45 | Q49: -0.12 | R49: 0.31223333
A50: 2014/15 | B50: 2014 | C50: 6547920 | D50: 155.04 | E50: 5100 | F50: 227 | G50: =E50/F50 -> 22.46696 | H50: 4.425 | I50: 308.44167 | J50: =H50*1000/I50 -> 14.346311 | K50: 74007 | L50: 1.2496604 | M50: 0.88365385 | N50: 0.99939244 | O50: -0.24 | P50: 0.07 | Q50: 0.7 | R50: -0.17226667
A51: 2015/16 | B51: 2015 | C51: 6704360 | D51: 125.6 | E51: 5300 | F51: 240 | G51: =E51/F51 -> 22.083333 | H51: 3.5258333 | I51: 277.94167 | J51: =H51*1000/I51 -> 12.685516 | K51: 75343 | L51: 1.1149186 | M51: 0.58939238 | N51: 0.9007467 | O51: 0.73 | P51: 1.44 | Q51: 2.45 | R51: 0.83923333
...

Sheet Changes
A1: Year-on-year changes (natural log: 0.10 = about +10 %)
A2: All black cells are formulas on the Data sheet. "Last year" columns = the same column one row up (the biennial / mean-reversion test).
A5: Crop year | B5: t | C5: Exports | D5: USDA production | E5: Yield | F5: Bearing area | G5: Arabica price | H5: Coffee/urea ratio | I5: Nitrogen use | J5: Rain Dec-Mar (log of ratio) | K5: Rain Apr-May | L5: Rain Jun-Oct | M5: ONI DJF | N5: ONI JJA | O5: Last year: production change | P5: Last year: exports change | Q5: Coffee-zone max. temperature Sep-Oct (deg C vs normal)
A6: 1970/71 | B6: 1970
A7: 1971/72 | B7: 1971 | C7: =LN(Data!C7/Data!C6) -> 0.39100925 | D7: =LN(Data!E7/Data!E6) -> 0.072533995 | G7: =LN(Data!H7/Data!H6) -> -0.1467946 | H7: =LN(Data!J7/Data!J6) -> -0.012482264 | M7: =Data!O7 -> -1.29 | N7: =Data!P7 -> -0.68
A8: 1972/73 | B8: 1972 | C8: =LN(Data!C8/Data!C7) -> 0.20268203 | D8: =LN(Data!E8/Data!E7) -> 0.25868199 | G8: =LN(Data!H8/Data!H7) -> 0.11431942 | H8: =LN(Data!J8/Data!J7) -> -0.49067937 | M8: =Data!O8 -> -0.57 | N8: =Data!P8 -> 1 | O8: =D7 -> 0.072533995 | P8: =C7 -> 0.39100925
A9: 1973/74 | B9: 1973 | C9: =LN(Data!C9/Data!C8) -> -0.36316637 | D9: =LN(Data!E9/Data!E8) -> -0.096760506 | G9: =LN(Data!H9/Data!H8) -> 0.21213039 | H9: =LN(Data!J9/Data!J8) -> -0.5815877 | M9: =Data!O9 -> 1.55 | N9: =Data!P9 -> -0.99 | O9: =D8 -> 0.25868199 | P9: =C8 -> 0.20268203
A10: 1974/75 | B10: 1974 | C10: =LN(Data!C10/Data!C9) -> 0.58661979 | D10: =LN(Data!E10/Data!E9) -> 0.35536785 | G10: =LN(Data!H10/Data!H9) -> 0.056045335 | H10: =LN(Data!J10/Data!J9) -> -1.4279413 | M10: =Data!O10 -> -1.87 | N10: =Data!P10 -> -0.46 | O10: =D9 -> -0.096760506 | P10: =C9 -> -0.36316637
A11: 1975/76 | B11: 1975 | C11: =LN(Data!C11/Data!C10) -> -0.30443821 | D11: =LN(Data!E11/Data!E10) -> -0.14890843 | G11: =LN(Data!H11/Data!H10) -> -0.007486358 | H11: =LN(Data!J11/Data!J10) -> 0.52384193 | M11: =Data!O11 -> -0.56 | N11: =Data!P11 -> -1.08 | O11: =D10 -> 0.35536785 | P11: =C10 -> 0.58661979
A12: 1976/77 | B12: 1976 | C12: =LN(Data!C12/Data!C11) -> -0.0051803007 | D12: =LN(Data!E12/Data!E11) -> -0.20356087 | G12: =LN(Data!H12/Data!H11) -> 0.78080864 | H12: =LN(Data!J12/Data!J11) -> 1.4980534 | M12: =Data!O12 -> -1.49 | N12: =Data!P12 -> 0.23 | O12: =D11 -> -0.14890843 | P12: =C11 -> -0.30443821
A13: 1977/78 | B13: 1977 | C13: =LN(Data!C13/Data!C12) -> 0.40042482 | D13: =LN(Data!E13/Data!E12) -> 0.4049826 | G13: =LN(Data!H13/Data!H12) -> 0.4962642 | H13: =LN(Data!J13/Data!J12) -> 0.10919215 | M13: =Data!O13 -> 0.71 | N13: =Data!P13 -> 0.39 | O13: =D12 -> -0.20356087 | P13: =C12 -> -0.0051803007
A14: 1978/79 | B14: 1978 | C14: =LN(Data!C14/Data!C13) -> 0.11267751 | D14: =LN(Data!E14/Data!E13) -> 0.088618836 | G14: =LN(Data!H14/Data!H13) -> -0.36448839 | H14: =LN(Data!J14/Data!J13) -> -0.48365829 | M14: =Data!O14 -> 0.71 | N14: =Data!P14 -> -0.37 | O14: =D13 -> 0.4049826 | P14: =C13 -> 0.40042482
A15: 1979/80 | B15: 1979 | C15: =LN(Data!C15/Data!C14) -> -0.073085222 | D15: =LN(Data!E15/Data!E14) -> 0.004407235 | G15: =LN(Data!H15/Data!H14) -> 0.063174165 | H15: =LN(Data!J15/Data!J14) -> -0.054411471 | M15: =Data!O15 -> 0.19 | N15: =Data!P15 -> 0.09 | O15: =D14 -> 0.088618836 | P15: =C14 -> 0.11267751
A16: 1980/81 | B16: 1980 | C16: =LN(Data!C16/Data!C15) -> 0.054153713 | D16: =LN(Data!E16/Data!E15) -> 0.10667891 | G16: =LN(Data!H16/Data!H15) -> -0.098124594 | H16: =LN(Data!J16/Data!J15) -> -0.36872444 | M16: =Data!O16 -> 0.62 | N16: =Data!P16 -> 0.18 | O16: =D15 -> 0.004407235 | P16: =C15 -> -0.073085222
A17: 1981/82 | B17: 1981 | C17: =LN(Data!C17/Data!C16) -> -0.12402468 | D17: =LN(Data!E17/Data!E16) -> -0.052750565 | G17: =LN(Data!H17/Data!H16) -> -0.1899933 | H17: =LN(Data!J17/Data!J16) -> -0.095596783 | K17: =LN(Data!M17) -> -0.11031877 | L17: =LN(Data!N17) -> 0.23886845 | M17: =Data!O17 -> -0.27 | N17: =Data!P17 -> -0.28 | O17: =D16 -> 0.10667891 | P17: =C16 -> 0.054153713 | Q17: =Data!R17 -> -0.47976667
A18: 1982/83 | B18: 1982 | C18: =LN(Data!C18/Data!C17) -> 0.30874878 | D18: =LN(Data!E18/Data!E17) -> 0.22314355 | G18: =LN(Data!H18/Data!H17) -> 0.07365119 | H18: =LN(Data!J18/Data!J17) -> 0.46045588 | J18: =LN(Data!L18) -> 0.28962835 | K18: =LN(Data!M18) -> 0.20631366 | L18: =LN(Data!N18) -> -0.1469627 | M18: =Data!O18 -> -0.05 | N18: =Data!P18 -> 0.78 | O18: =D17 -> -0.052750565 | P18: =C17 -> -0.12402468 | Q18: =Data!R18 -> -0.75576667
A19: 1983/84 | B19: 1983 | C19: =LN(Data!C19/Data!C18) -> -0.17066368 | D19: =LN(Data!E19/Data!E18) -> -0.13543797 | G19: =LN(Data!H19/Data!H18) -> -0.058079941 | H19: =LN(Data!J19/Data!J18) -> 0.020926889 | J19: =LN(Data!L19) -> -0.10799517 | K19: =LN(Data!M19) -> -0.56633707 | L19: =LN(Data!N19) -> -0.020093908 | M19: =Data!O19 -> 2.14 | N19: =Data!P19 -> 0.25 | O19: =D18 -> 0.22314355 | P19: =C18 -> 0.30874878 | Q19: =Data!R19 -> -0.16926667
A20: 1984/85 | B20: 1984 | C20: =LN(Data!C20/Data!C19) -> 0.20538791 | D20: =LN(Data!E20/Data!E19) -> 0.066445099 | G20: =LN(Data!H20/Data!H19) -> 0.090747831 | H20: =LN(Data!J20/Data!J19) -> -0.1800593 | J20: =LN(Data!L20) -> 0.13858114 | K20: =LN(Data!M20) -> 0.13663684 | L20: =LN(Data!N20) -> 0.080798722 | M20: =Data!O20 -> -0.63 | N20: =Data!P20 -> -0.39 | O20: =D19 -> -0.13543797 | P20: =C19 -> -0.17066368 | Q20: =Data!R20 -> -0.61426667
A21: 1985/86 | B21: 1985 | C21: =LN(Data!C21/Data!C20) -> 0.14262344 | D21: =LN(Data!E21/Data!E20) -> -0.27631831 | G21: =LN(Data!H21/Data!H20) -> 0.01323835 | H21: =LN(Data!J21/Data!J20) -> 0.3098391 | J21: =LN(Data!L21) -> -0.30174364 | K21: =LN(Data!M21) -> -0.4242101 | L21: =LN(Data!N21) -> -0.13050841 | M21: =Data!O21 -> -1.01 | N21: =Data!P21 -> -0.44 | O21: =D20 -> 0.066445099 | P21: =C20 -> 0.20538791 | Q21: =Data!R21 -> -0.068266667
A22: 1986/87 | B22: 1986 | C22: =LN(Data!C22/Data!C21) -> -0.057374251 | D22: =LN(Data!E22/Data!E21) -> 0.36837646 | G22: =LN(Data!H22/Data!H21) -> 0.28348296 | H22: =LN(Data!J22/Data!J21) -> 0.73947547 | J22: =LN(Data!L22) -> 0.058310351 | K22: =LN(Data!M22) -> -0.22845044 | L22: =LN(Data!N22) -> -0.35674267 | M22: =Data!O22 -> -0.4 | N22: =Data!P22 -> 0.24 | O22: =D21 -> -0.27631831 | P22: =C21 -> 0.14262344 | Q22: =Data!R22 -> -0.75376667
A23: 1987/88 | B23: 1987 | C23: =LN(Data!C23/Data!C22) -> -0.13319784 | D23: =LN(Data!E23/Data!E22) -> 0.011658163 | G23: =LN(Data!H23/Data!H22) -> -0.53819223 | H23: =LN(Data!J23/Data!J22) -> -0.69183799 | J23: =LN(Data!L23) -> -0.17583066 | K23: =LN(Data!M23) -> -0.96170117 | L23: =LN(Data!N23) -> -0.10668409 | M23: =Data!O23 -> 1.18 | N23: =Data!P23 -> 1.3 | O23: =D22 -> 0.36837646 | P23: =C22 -> -0.057374251 | Q23: =Data!R23 -> -0.59126667
A24: 1988/89 | B24: 1988 | C24: =LN(Data!C24/Data!C23) -> 0.17925539 | D24: =LN(Data!E24/Data!E23) -> 0.05145426 | G24: =LN(Data!H24/Data!H23) -> 0.19109863 | H24: =LN(Data!J24/Data!J23) -> -0.12827296 | J24: =LN(Data!L24) -> 0.093948146 | K24: =LN(Data!M24) -> -0.24933323 | L24: =LN(Data!N24) -> 0.18326315 | M24: =Data!O24 -> 0.63 | N24: =Data!P24 -> -1.3 | O24: =D23 -> 0.011658163 | P24: =C23 -> -0.13319784 | Q24: =Data!R24 -> -1.0112667
A25: 1989/90 | B25: 1989 | C25: =LN(Data!C25/Data!C24) -> 0.16874398 | D25: =LN(Data!E25/Data!E24) -> 0.16484039 | G25: =LN(Data!H25/Data!H24) -> -0.23914057 | H25: =LN(Data!J25/Data!J24) -> -0.14129507 | J25: =LN(Data!L25) -> 0.044931856 | K25: =LN(Data!M25) -> 0.29912511 | L25: =LN(Data!N25) -> 0.058904145 | M25: =Data!O25 -> -1.64 | N25: =Data!P25 -> -0.37 | O25: =D24 -> 0.05145426 | P25: =C24 -> 0.17925539 | Q25: =Data!R25 -> -0.67126667
A26: 1990/91 | B26: 1990 | C26: =LN(Data!C26/Data!C25) -> -0.19467778 | D26: =LN(Data!E26/Data!E25) -> -0.13471763 | G26: =LN(Data!H26/Data!H25) -> -0.19052263 | H26: =LN(Data!J26/Data!J25) -> -0.30676665 | J26: =LN(Data!L26) -> 0.053944253 | K26: =LN(Data!M26) -> 0.30023551 | L26: =LN(Data!N26) -> -0.10323219 | M26: =Data!O26 -> 0.18 | N26: =Data!P26 -> 0.26 | O26: =D25 -> 0.16484039 | P26: =C25 -> 0.16874398 | Q26: =Data!R26 -> 0.15923333
A27: 1991/92 | B27: 1991 | C27: =LN(Data!C27/Data!C26) -> 0.23241627 | D27: =LN(Data!E27/Data!E26) -> 0.29138441 | G27: =LN(Data!H27/Data!H26) -> -0.052004785 | H27: =LN(Data!J27/Data!J26) -> -0.23158444 | J27: =LN(Data!L27) -> -0.19843182 | K27: =LN(Data!M27) -> -0.21041201 | L27: =LN(Data!N27) -> -0.1592319 | M27: =Data!O27 -> 0.35 | N27: =Data!P27 -> 0.77 | O27: =D26 -> -0.13471763 | P27: =C26 -> -0.19467778 | Q27: =Data!R27 -> 0.043233333
A28: 1992/93 | B28: 1992 | C28: =LN(Data!C28/Data!C27) -> 0.052046342 | D28: =LN(Data!E28/Data!E27) -> -0.12954821 | G28: =LN(Data!H28/Data!H27) -> -0.28353883 | H28: =LN(Data!J28/Data!J27) -> -0.12075068 | J28: =LN(Data!L28) -> 0.30052047 | K28: =LN(Data!M28) -> -0.2465835 | L28: =LN(Data!N28) -> 0.074157476 | M28: =Data!O28 -> 1.54 | N28: =Data!P28 -> 0.35 | O28: =D27 -> 0.29138441 | P28: =C27 -> 0.23241627 | Q28: =Data!R28 -> 0.091233333
A29: 1993/94 | B29: 1993 | C29: =LN(Data!C29/Data!C28) -> -0.13250866 | D29: =LN(Data!E29/Data!E28) -> 0.039104215 | G29: =LN(Data!H29/Data!H28) -> 0.10050527 | H29: =LN(Data!J29/Data!J28) -> 0.41886158 | J29: =LN(Data!L29) -> 0.073100671 | K29: =LN(Data!M29) -> -0.050699527 | L29: =LN(Data!N29) -> -0.022711346 | M29: =Data!O29 -> 0.13 | N29: =Data!P29 -> 0.28 | O29: =D28 -> -0.12954821 | P29: =C28 -> 0.052046342 | Q29: =Data!R29 -> -0.65926667
... A40: 2004/05 | B40: 2004 | C40: =LN(Data!C40/Data!C39) -> -0.15305431 | D40: =LN(Data!E40/Data!E39) -> -0.14203879 | G40: =LN(Data!H40/Data!H39) -> 0.22514273 | H40: =LN(Data!J40/Data!J39) -> -0.010633276 | J40: =LN(Data!L40) -> 0.016748258 | K40: =LN(Data!M40) -> 0.087406866 | L40: =LN(Data!N40) -> -0.18904326 | M40: =Data!O40 -> 0.34 | N40: =Data!P40 -> 0.39 | O40: =D39 -> 0.17319887 | P40: =C39 -> 0.13627616 | Q40: =Data!R40 -> 0.81323333
A41: 2005/06 | B41: 2005 | C41: =LN(Data!C41/Data!C40) -> 0.19969339 | D41: =LN(Data!E41/Data!E40) -> 0.2185505 | G41: =LN(Data!H41/Data!H40) -> 0.35634594 | H41: =LN(Data!J41/Data!J40) -> 0.13915596 | I41: =LN(Data!K41/Data!K40) -> 0.46526152 | J41: =LN(Data!L41) -> -0.14028793 | K41: =LN(Data!M41) -> -0.13009537 | L41: =LN(Data!N41) -> 0.029809537 | M41: =Data!O41 -> 0.62 | N41: =Data!P41 -> -0.04 | O41: =D40 -> -0.14203879 | P41: =C40 -> -0.15305431 | Q41: =Data!R41 -> -0.73076667
A42: 2006/07 | B42: 2006 | C42: =LN(Data!C42/Data!C41) -> 0.094066521 | D42: =LN(Data!E42/Data!E41) -> 0.07686856 | E42: =LN(Data!G42/Data!G41) -> -0.14627499 | F42: =LN(Data!F42/Data!F41) -> 0.22314355 | G42: =LN(Data!H42/Data!H41) -> -0.0042868986 | H42: =LN(Data!J42/Data!J41) -> -0.026054918 | I42: =LN(Data!K42/Data!K41) -> 0.46557487 | J42: =LN(Data!L42) -> -0.38801107 | K42: =LN(Data!M42) -> -0.30159146 | L42: =LN(Data!N42) -> -0.10217162 | M42: =Data!O42 -> -0.86 | N42: =Data!P42 -> 0.12 | O42: =D41 -> 0.2185505 | P42: =C41 -> 0.19969339 | Q42: =Data!R42 -> 0.56173333
A43: 2007/08 | B43: 2007 | C43: =LN(Data!C43/Data!C42) -> 0.054166356 | D43: =LN(Data!E43/Data!E42) -> 0.051264392 | E43: =LN(Data!G43/Data!G42) -> 0.051264392 | F43: =LN(Data!F43/Data!F42) -> 0 | G43: =LN(Data!H43/Data!H42) -> 0.077242512 | H43: =LN(Data!J43/Data!J42) -> -0.24666987 | I43: =LN(Data!K43/Data!K42) -> -0.049126863 | J43: =LN(Data!L43) -> 0.069269664 | K43: =LN(Data!M43) -> -0.24313334 | L43: =LN(Data!N43) -> 0.13166616 | M43: =Data!O43 -> 0.62 | N43: =Data!P43 -> -0.49 | O43: =D42 -> 0.07686856 | P43: =C42 -> 0.094066521 | Q43: =Data!R43 -> -0.73026667
A44: 2008/09 | B44: 2008 | C44: =LN(Data!C44/Data!C43) -> -0.11669445 | D44: =LN(Data!E44/Data!E43) -> -0.12160003 | E44: =LN(Data!G44/Data!G43) -> -0.095166774 | F44: =LN(Data!F44/Data!F43) -> -0.026433257 | G44: =LN(Data!H44/Data!H43) -> 0.12303755 | H44: =LN(Data!J44/Data!J43) -> -0.39386929 | I44: =LN(Data!K44/Data!K43) -> -0.13354264 | J44: =LN(Data!L44) -> -0.07574941 | K44: =LN(Data!M44) -> -0.12105559 | L44: =LN(Data!N44) -> 0.31716036 | M44: =Data!O44 -> -1.76 | N44: =Data!P44 -> -0.33 | O44: =D43 -> 0.051264392 | P44: =C43 -> 0.054166356 | Q44: =Data!R44 -> -0.64426667
A45: 2009/10 | B45: 2009 | C45: =LN(Data!C45/Data!C44) -> 0.045302356 | D45: =LN(Data!E45/Data!E44) -> 0.096014653 | E45: =LN(Data!G45/Data!G44) -> 0.096014653 | F45: =LN(Data!F45/Data!F44) -> 0 | G45: =LN(Data!H45/Data!H44) -> 0.028794311 | H45: =LN(Data!J45/Data!J44) -> 0.74707758 | I45: =LN(Data!K45/Data!K44) -> -0.15418668 | J45: =LN(Data!L45) -> -0.048902714 | K45: =LN(Data!M45) -> 0.22561626 | L45: =LN(Data!N45) -> -0.064009376 | M45: =Data!O45 -> -0.89 | N45: =Data!P45 -> 0.5 | O45: =D44 -> -0.12160003 | P45: =C44 -> -0.11669445 | Q45: =Data!R45 -> 1.1522333
A46: 2010/11 | B46: 2010 | C46: =LN(Data!C46/Data!C45) -> 0.20137031 | D46: =LN(Data!E46/Data!E45) -> 0.11307714 | E46: =LN(Data!G46/Data!G45) -> 0.052452523 | F46: =LN(Data!F46/Data!F45) -> 0.060624622 | G46: =LN(Data!H46/Data!H45) -> 0.30926097 | H46: =LN(Data!J46/Data!J45) -> 0.16897394 | I46: =LN(Data!K46/Data!K45) -> 0.16291473 | J46: =LN(Data!L46) -> -0.02641718 | K46: =LN(Data!M46) -> 0.30160468 | L46: =LN(Data!N46) -> 0.19973082 | M46: =Data!O46 -> 1.47 | N46: =Data!P46 -> -0.98 | O46: =D45 -> 0.096014653 | P46: =C45 -> 0.045302356 | Q46: =Data!R46 -> -0.81976667
A47: 2011/12 | B47: 2011 | C47: =LN(Data!C47/Data!C46) -> 0.34776196 | D47: =LN(Data!E47/Data!E46) -> 0.34274185 | E47: =LN(Data!G47/Data!G46) -> 0.31375431 | F47: =LN(Data!F47/Data!F46) -> 0.028987537 | G47: =LN(Data!H47/Data!H46) -> 0.3246076 | H47: =LN(Data!J47/Data!J46) -> 0.0019306852 | I47: =LN(Data!K47/Data!K46) -> 0.42292392 | J47: =LN(Data!L47) -> 0.23986891 | K47: =LN(Data!M47) -> 0.13647547 | L47: =LN(Data!N47) -> 0.26784651 | M47: =Data!O47 -> -1.29 | N47: =Data!P47 -> -0.37 | O47: =D46 -> 0.11307714 | P47: =C46 -> 0.20137031 | Q47: =Data!R47 -> -0.82276667
A48: 2012/13 | B48: 2012 | C48: =LN(Data!C48/Data!C47) -> -0.23210434 | D48: =LN(Data!E48/Data!E47) -> -0.16989904 | E48: =LN(Data!G48/Data!G47) -> -0.25588948 | F48: =LN(Data!F48/Data!F47) -> 0.085990448 | G48: =LN(Data!H48/Data!H47) -> -0.37403454 | H48: =LN(Data!J48/Data!J47) -> -0.37317774 | I48: =LN(Data!K48/Data!K47) -> -0.12597477 | J48: =LN(Data!L48) -> -0.017926076 | K48: =LN(Data!M48) -> 0.52908705 | L48: =LN(Data!N48) -> 0.040497354 | M48: =Data!O48 -> -0.71 | N48: =Data!P48 -> 0.28 | O48: =D47 -> 0.34274185 | P48: =C47 -> 0.34776196 | Q48: =Data!R48 -> 0.049733333
A49: 2013/14 | B49: 2013 | C49: =LN(Data!C49/Data!C48) -> -0.038561445 | D49: =LN(Data!E49/Data!E48) -> -0.07126302 | E49: =LN(Data!G49/Data!G48) -> 0.15469347 | F49: =LN(Data!F49/Data!F48) -> -0.22595649 | G49: =LN(Data!H49/Data!H48) -> -0.2899817 | H49: =LN(Data!J49/Data!J48) -> -0.12981629 | I49: =LN(Data!K49/Data!K48) -> -0.009391992 | J49: =LN(Data!L49) -> 0.2523996 | K49: =LN(Data!M49) -> 0.10059187 | L49: =LN(Data!N49) -> 0.00048093333 | M49: =Data!O49 -> -0.24 | N49: =Data!P49 -> -0.45 | O49: =D48 -> -0.16989904 | P49: =C48 -> -0.23210434 | Q49: =Data!R49 -> 0.31223333
A50: 2014/15 | B50: 2014 | C50: =LN(Data!C50/Data!C49) -> 0.18412706 | D50: =LN(Data!E50/Data!E49) -> 0.147636 | E50: =LN(Data!G50/Data!G49) -> 0.083978147 | F50: =LN(Data!F50/Data!F49) -> 0.063657852 | G50: =LN(Data!H50/Data!H49) -> 0.36342352 | H50: =LN(Data!J50/Data!J49) -> 0.45968377 | I50: =LN(Data!K50/Data!K49) -> -0.0094810385 | J50: =LN(Data!L50) -> 0.22287186 | K50: =LN(Data!M50) -> -0.12368987 | L50: =LN(Data!N50) -> -0.00060774469 | M50: =Data!O50 -> -0.24 | N50: =Data!P50 -> 0.07 | O50: =D49 -> -0.07126302 | P50: =C49 -> -0.038561445 | Q50: =Data!R50 -> -0.17226667
A51: 2015/16 | B51: 2015 | C51: =LN(Data!C51/Data!C50) -> 0.023610619 | D51: =LN(Data!E51/Data!E50) -> 0.038466281 | E51: =LN(Data!G51/Data!G50) -> -0.017222625 | F51: =LN(Data!F51/Data!F50) -> 0.055688906 | G51: =LN(Data!H51/Data!H50) -> -0.22715346 | H51: =LN(Data!J51/Data!J50) -> -0.12303198 | I51: =LN(Data!K51/Data!K50) -> 0.017891338 | J51: =LN(Data!L51) -> 0.10878142 | K51: =LN(Data!M51) -> -0.52866314 | L51: =LN(Data!N51) -> -0.10453119 | M51: =Data!O51 -> 0.73 | N51: =Data!P51 -> 1.44 | O51: =D50 -> 0.147636 | P51: =C50 -> 0.18412706 | Q51: =Data!R51 -> 0.83923333
A52: 2016/17 | B52: 2016 | C52: =LN(Data!C52/Data!C51) -> 0.34957477 | D52: =LN(Data!E52/Data!E51) -> 0.34852865 | E52: =LN(Data!G52/Data!G51) -> 0.19437797 | F52: =LN(Data!F52/Data!F51) -> 0.15415068 | G52: =LN(Data!H52/Data!H51) -> 0.024283238 | H52: =LN(Data!J52/Data!J51) -> 0.38306344 | I52: =LN(Data!K52/Data!K51) -> 0.24171367 | J52: =LN(Data!L52) -> 0.1766993 | K52: =LN(Data!M52) -> -0.53448653 | L52: =LN(Data!N52) -> -0.21473972 | M52: =Data!O52 -> 2.5 | N52: =Data!P52 -> -0.19 | O52: =D51 -> 0.038466281 | P52: =C51 -> 0.023610619 | Q52: =Data!R52 -> 0.13723333
...

Sheet Tests
A1: One driver at a time: does it move with output the same year?
A2: r = Pearson correlation of year-on-year changes. p = share of 5 000 random shuffles giving |r| at least as large (purple, Python). Holm p = corrected for testing 14 drivers on the same sample: below 0.05 = survives. Excel check = the same r recomputed with CORREL where the driver is a column of Changes.
A4: A. USDA production, crop years 1982/83 - 2025/26
A5: Driver | B5: n | C5: r (Python) | D5: p (permutation) | E5: Holm p | F5: Verdict | G5: Excel check r
A6: Nitrogen use change (FAO) | B6: 20 | C6: 0.751 | D6: 0.0004 | E6: 0.0056 | F6: robust | G6: =CORREL(Changes!D18:D61,Changes!I18:I61) -> 0.75098967
A7: Last year's change (biennial / mean reversion) | B7: 44 | C7: -0.521 | D7: 0.0008 | E7: 0.0104 | F7: robust | G7: =CORREL(Changes!D18:D61,Changes!O18:O61) -> -0.52051716
A8: Coffee/urea price ratio change | B8: 44 | C8: 0.369 | D8: 0.015 | E8: 0.18 | F8: weak (p<0.05 alone) | G8: =CORREL(Changes!D18:D61,Changes!H18:H61) -> 0.36902021
A9: Rain Dec-Mar (dry season, before flowering) | B9: 44 | C9: 0.344 | D9: 0.0228 | E9: 0.2508 | F9: weak (p<0.05 alone) | G9: =CORREL(Changes!D18:D61,Changes!J18:J61) -> 0.34422462
A10: World arabica price change, year t | B10: 44 | C10: 0.33 | D10: 0.03 | E10: 0.3 | F10: weak (p<0.05 alone) | G10: =CORREL(Changes!D18:D61,Changes!G18:G61) -> 0.33012893
A11: Coffee/urea ratio vs its 5-year mean | B11: 44 | C11: 0.32 | D11: 0.0358 | E11: 0.3222 | F11: weak (p<0.05 alone)
A12: Max temperature Mar-May (NASA POWER) | B12: 44 | C12: 0.199 | D12: 0.1998 | E12: 1 | F12: no link
A13: Rain Jun-Oct (fruit fill) | B13: 44 | C13: 0.101 | D13: 0.5065 | E13: 1 | F13: no link | G13: =CORREL(Changes!D18:D61,Changes!L18:L61) -> 0.10143212
A14: Rain Apr-May (flowering, fruit set) | B14: 44 | C14: -0.103 | D14: 0.5089 | E14: 1 | F14: no link | G14: =CORREL(Changes!D18:D61,Changes!K18:K61) -> -0.10323981
A15: World arabica price change, year t-1 | B15: 44 | C15: -0.078 | D15: 0.6279 | E15: 1 | F15: no link
A16: Rain May-Oct t-1 (wood for this crop) | B16: 44 | C16: -0.07 | D16: 0.6515 | E16: 1 | F16: no link
A17: Price level t-1 vs its 5-year mean | B17: 44 | C17: -0.028 | D17: 0.8594 | E17: 1 | F17: no link
A18: ENSO: ONI Jun-Aug | B18: 44 | C18: -0.01 | D18: 0.951 | E18: 1 | F18: no link | G18: =CORREL(Changes!D18:D61,Changes!N18:N61) -> -0.010291695
A19: ENSO: ONI Dec-Feb | B19: 44 | C19: -0.009 | D19: 0.955 | E19: 1 | F19: no link | G19: =CORREL(Changes!D18:D61,Changes!M18:M61) -> -0.008555449
A21: B. IHCAFE measured exports, 1982/83 - 2020/21
A22: Driver | B22: n | C22: r (Python) | D22: p (permutation) | E22: Holm p | F22: Verdict | G22: Excel check r
A23: Nitrogen use change (FAO) | B23: 16 | C23: 0.691 | D23: 0.0044 | E23: 0.0616 | F23: weak (p<0.05 alone) | G23: =CORREL(Changes!C18:C56,Changes!I18:I56) -> 0.69104854
A24: Last year's change (biennial / mean reversion) | B24: 39 | C24: -0.411 | D24: 0.0102 | E24: 0.1326 | F24: weak (p<0.05 alone) | G24: =CORREL(Changes!C18:C56,Changes!P18:P56) -> -0.41097456
A25: World arabica price change, year t | B25: 39 | C25: 0.335 | D25: 0.0342 | E25: 0.4104 | F25: weak (p<0.05 alone) | G25: =CORREL(Changes!C18:C56,Changes!G18:G56) -> 0.33549714
A26: Rain Dec-Mar (dry season, before flowering) | B26: 39 | C26: 0.308 | D26: 0.0576 | E26: 0.6336 | F26: hint (p<0.10) | G26: =CORREL(Changes!C18:C56,Changes!J18:J56) -> 0.30777651
A27: Coffee/urea price ratio change | B27: 39 | C27: 0.305 | D27: 0.0616 | E27: 0.6336 | F27: hint (p<0.10) | G27: =CORREL(Changes!C18:C56,Changes!H18:H56) -> 0.30534525
A28: Rain Jun-Oct (fruit fill) | B28: 39 | C28: 0.247 | D28: 0.125 | E28: 1 | F28: no link | G28: =CORREL(Changes!C18:C56,Changes!L18:L56) -> 0.24681084
A29: Coffee/urea ratio vs its 5-year mean | B29: 39 | C29: 0.245 | D29: 0.146 | E29: 1 | F29: no link
A30: ENSO: ONI Jun-Aug | B30: 39 | C30: -0.211 | D30: 0.1964 | E30: 1 | F30: no link | G30: =CORREL(Changes!C18:C56,Changes!N18:N56) -> -0.21148425
A31: Max temperature Mar-May (NASA POWER) | B31: 39 | C31: 0.205 | D31: 0.2046 | E31: 1 | F31: no link
A32: Rain Apr-May (flowering, fruit set) | B32: 39 | C32: -0.204 | D32: 0.2108 | E32: 1 | F32: no link | G32: =CORREL(Changes!C18:C56,Changes!K18:K56) -> -0.2041855
A33: World arabica price change, year t-1 | B33: 39 | C33: -0.046 | D33: 0.7822 | E33: 1 | F33: no link
A34: ENSO: ONI Dec-Feb | B34: 39 | C34: -0.03 | D34: 0.845 | E34: 1 | F34: no link | G34: =CORREL(Changes!C18:C56,Changes!M18:M56) -> -0.030139389
A35: Price level t-1 vs its 5-year mean | B35: 39 | C35: -0.02 | D35: 0.905 | E35: 1 | F35: no link
A36: Rain May-Oct t-1 (wood for this crop) | B36: 39 | C36: 0.014 | D36: 0.9348 | E36: 1 | F36: no link
A38: C. USDA yield per bearing hectare, 2006/07 - 2025/26
A39: Driver | B39: n | C39: r (Python) | D39: p (permutation) | E39: Holm p | F39: Verdict | G39: Excel check r
A40: Last year's change (biennial / mean reversion) | B40: 19 | C40: -0.573 | D40: 0.0124 | E40: 0.1736 | F40: weak (p<0.05 alone) | G40: =CORREL(Changes!E42:E61,Changes!O42:O61) -> -0.54783498
A41: Nitrogen use change (FAO) | B41: 19 | C41: 0.557 | D41: 0.0124 | E41: 0.1736 | F41: weak (p<0.05 alone) | G41: =CORREL(Changes!E42:E61,Changes!I42:I61) -> 0.55656215
A42: Rain Dec-Mar (dry season, before flowering) | B42: 20 | C42: 0.437 | D42: 0.0572 | E42: 0.6864 | F42: hint (p<0.10) | G42: =CORREL(Changes!E42:E61,Changes!J42:J61) -> 0.43663183
A43: Coffee/urea ratio vs its 5-year mean | B43: 20 | C43: 0.407 | D43: 0.0776 | E43: 0.8536 | F43: hint (p<0.10)
...

Sheet Biennial
A1: Is there an on/off (biennial) cycle, or only one-off shocks?
A2: If output = trend + independent yearly shocks, the correlation between this year's change and last year's is -0.50 by construction and the direction flips 2 years in 3. An on/off cycle gives less than -0.50 and more flips; lasting shocks give more than -0.50.
A4: Series | B4: n | C4: r(change t, change t-1) | D4: Implied year-to-year link of the level (phi = 1 + 2r) | E4: 95 % band if shocks are independent (low) | F4: (high) | G4: Direction flips | H4: Verdict
A5: IHCAFE exports 1970/71-2020/21 | B5: 49 | C5: =CORREL(Changes!C8:C56,Changes!P8:P56) -> -0.44701809 | D5: =1+2*C5 -> 0.10596383 | E5: -0.67878115 | F5: -0.27539438 | G5: 0.65306122 | H5: independent shocks, no on/off cycle
A6: USDA production 1980/81-2025/26 | B6: 44 | C6: =CORREL(Changes!D18:D61,Changes!O18:O61) -> -0.52051716 | D6: =1+2*C6 -> -0.041034311 | E6: -0.67393135 | F6: -0.27257376 | G6: 0.65909091 | H6: independent shocks, no on/off cycle
A7: USDA yield per bearing ha 2005/06-2025/26 | B7: 19 | C7: -0.57262165 | D7: =1+2*C7 -> -0.1452433 | E7: -0.76105625 | F7: -0.10577904 | G7: 0.68421053 | H7: independent shocks, no on/off cycle
A9: What it means for a forecast
A10: A big crop is followed by a smaller one and a small crop by a bigger one, but only because the shock is not repeated: the crop goes back to its trend, it does not swing below it. Forecast from the multi-year level (trend), not from last year's number and not from an assumed "on/off" year.
A11: Python checks the exports and production rows over slightly different spans (first change 1971 and 1981); the Excel check uses the rows available in Changes.

Sheet Yield_split
A1: Yield change = production change - bearing-area change
A2: USDA yield = USDA production / attache bearing area. Both are estimates; area revisions move the yield without any change in the trees.
A4: Crop year | B4: Production change | C4: Bearing-area change | D4: Yield change | E4: Check: production - area | F4: Area moved yield by more than 8 points?
A5: 2006/07 | B5: =Changes!D42 -> 0.07686856 | C5: =Changes!F42 -> 0.22314355 | D5: =Changes!E42 -> -0.14627499 | E5: =B5-C5 -> -0.14627499 | F5: =IF(ABS(C5)>0.08,"yes","no") -> yes
A6: 2007/08 | B6: =Changes!D43 -> 0.051264392 | C6: =Changes!F43 -> 0 | D6: =Changes!E43 -> 0.051264392 | E6: =B6-C6 -> 0.051264392 | F6: =IF(ABS(C6)>0.08,"yes","no") -> no
A7: 2008/09 | B7: =Changes!D44 -> -0.12160003 | C7: =Changes!F44 -> -0.026433257 | D7: =Changes!E44 -> -0.095166774 | E7: =B7-C7 -> -0.095166774 | F7: =IF(ABS(C7)>0.08,"yes","no") -> no
A8: 2009/10 | B8: =Changes!D45 -> 0.096014653 | C8: =Changes!F45 -> 0 | D8: =Changes!E45 -> 0.096014653 | E8: =B8-C8 -> 0.096014653 | F8: =IF(ABS(C8)>0.08,"yes","no") -> no
A9: 2010/11 | B9: =Changes!D46 -> 0.11307714 | C9: =Changes!F46 -> 0.060624622 | D9: =Changes!E46 -> 0.052452523 | E9: =B9-C9 -> 0.052452523 | F9: =IF(ABS(C9)>0.08,"yes","no") -> no
A10: 2011/12 | B10: =Changes!D47 -> 0.34274185 | C10: =Changes!F47 -> 0.028987537 | D10: =Changes!E47 -> 0.31375431 | E10: =B10-C10 -> 0.31375431 | F10: =IF(ABS(C10)>0.08,"yes","no") -> no
A11: 2012/13 | B11: =Changes!D48 -> -0.16989904 | C11: =Changes!F48 -> 0.085990448 | D11: =Changes!E48 -> -0.25588948 | E11: =B11-C11 -> -0.25588948 | F11: =IF(ABS(C11)>0.08,"yes","no") -> yes
A12: 2013/14 | B12: =Changes!D49 -> -0.07126302 | C12: =Changes!F49 -> -0.22595649 | D12: =Changes!E49 -> 0.15469347 | E12: =B12-C12 -> 0.15469347 | F12: =IF(ABS(C12)>0.08,"yes","no") -> yes
A13: 2014/15 | B13: =Changes!D50 -> 0.147636 | C13: =Changes!F50 -> 0.063657852 | D13: =Changes!E50 -> 0.083978147 | E13: =B13-C13 -> 0.083978147 | F13: =IF(ABS(C13)>0.08,"yes","no") -> no
A14: 2015/16 | B14: =Changes!D51 -> 0.038466281 | C14: =Changes!F51 -> 0.055688906 | D14: =Changes!E51 -> -0.017222625 | E14: =B14-C14 -> -0.017222625 | F14: =IF(ABS(C14)>0.08,"yes","no") -> no
A15: 2016/17 | B15: =Changes!D52 -> 0.34852865 | C15: =Changes!F52 -> 0.15415068 | D15: =Changes!E52 -> 0.19437797 | E15: =B15-C15 -> 0.19437797 | F15: =IF(ABS(C15)>0.08,"yes","no") -> yes
A16: 2017/18 | B16: =Changes!D53 -> 0.011912782 | C16: =Changes!F53 -> 0.062303883 | D16: =Changes!E53 -> -0.050391102 | E16: =B16-C16 -> -0.050391102 | F16: =IF(ABS(C16)>0.08,"yes","no") -> no
... A24: 2025/26 | B24: =Changes!D61 -> 0.06152919 | C24: =Changes!F61 -> 0.032789823 | D24: =Changes!E61 -> 0.028739367 | E24: =B24-C24 -> 0.028739367 | F24: =IF(ABS(C24)>0.08,"yes","no") -> no
A26: Variance of yield changes | B26: 0.026379562
A27: of production changes | B27: 0.030945717
A28: of area changes | B28: 0.0071749957
A29: -2 x covariance | B29: -0.011741151
A31: Reading (log changes above; in plain %): area revisions of more than 8 % (2006/07 +25 %, 2012/13 +9 %, 2013/14 -20 %, 2016/17 +17 %) move the yield by themselves. The 2013/14 yield rebound (+17 %) is an area cut, not better trees.

Sheet Fertiliser
A1: Nitrogen: the tightest link with output (FAOSTAT, t N, all crops)
A2: Nitrogen bought in calendar year t is spread May-Oct t on the crop harvested from November t. The link is with the same crop year, not the next one.
A4: Crop year | B4: N use (t) | C4: N use change | D4: USDA production change | E4: Arabica (US$/kg) | F4: Urea (US$/t)
A5: 2005/06 | B5: =Data!K41 -> 41865 | C5: =Changes!I41 -> 0.46526152 | D5: =Changes!D41 -> 0.2185505 | E5: =Data!H41 -> 2.5325 | F5: =Data!I41 -> 217.35833
A6: 2006/07 | B6: =Data!K42 -> 66688 | C6: =Changes!I42 -> 0.46557487 | D6: =Changes!D42 -> 0.07686856 | E6: =Data!H42 -> 2.5216667 | F6: =Data!I42 -> 222.14167
A7: 2007/08 | B7: =Data!K43 -> 63491 | C7: =Changes!I43 -> -0.049126863 | D7: =Changes!D43 -> 0.051264392 | E7: =Data!H43 -> 2.7241667 | F7: =Data!I43 -> 307.11667
A8: 2008/09 | B8: =Data!K44 -> 55554 | C8: =Changes!I44 -> -0.13354264 | D8: =Changes!D44 -> -0.12160003 | E8: =Data!H44 -> 3.0808333 | F8: =Data!I44 -> 514.98333
A9: 2009/10 | B9: =Data!K45 -> 47616 | C9: =Changes!I45 -> -0.15418668 | D9: =Changes!D45 -> 0.096014653 | E9: =Data!H45 -> 3.1708333 | F9: =Data!I45 -> 251.1
A10: 2010/11 | B10: =Data!K46 -> 56041 | C10: =Changes!I46 -> 0.16291473 | D10: =Changes!D46 -> 0.11307714 | E10: =Data!H46 -> 4.32 | F10: =Data!I46 -> 288.91667
A11: 2011/12 | B11: =Data!K47 -> 85542 | C11: =Changes!I47 -> 0.42292392 | D11: =Changes!D47 -> 0.34274185 | E11: =Data!H47 -> 5.9766667 | F11: =Data!I47 -> 398.94167
A12: 2012/13 | B12: =Data!K48 -> 75417 | C12: =Changes!I48 -> -0.12597477 | D12: =Changes!D48 -> -0.16989904 | E12: =Data!H48 -> 4.1116667 | F12: =Data!I48 -> 398.6
A13: 2013/14 | B13: =Data!K49 -> 74712 | C13: =Changes!I49 -> -0.009391992 | D13: =Changes!D49 -> -0.07126302 | E13: =Data!H49 -> 3.0766667 | F13: =Data!I49 -> 339.60833
A14: 2014/15 | B14: =Data!K50 -> 74007 | C14: =Changes!I50 -> -0.0094810385 | D14: =Changes!D50 -> 0.147636 | E14: =Data!H50 -> 4.425 | F14: =Data!I50 -> 308.44167
A15: 2015/16 | B15: =Data!K51 -> 75343 | C15: =Changes!I51 -> 0.017891338 | D15: =Changes!D51 -> 0.038466281 | E15: =Data!H51 -> 3.5258333 | F15: =Data!I51 -> 277.94167
A16: 2016/17 | B16: =Data!K52 -> 95944 | C16: =Changes!I52 -> 0.24171367 | D16: =Changes!D52 -> 0.34852865 | E16: =Data!H52 -> 3.6125 | F16: =Data!I52 -> 194.15
... A22: 2022/23 | B22: =Data!K58 -> 104865 | C22: =Changes!I58 -> -2.8607801e-05 | D22: =Changes!D58 -> 0.17185026 | E22: =Data!H58 -> 5.6308333 | F22: =Data!I58 -> 700.03333
A24: r(N use change, production change) | C24: =CORREL(C5:C22,D5:D22) -> 0.75325224
A25: Smallest r when any one year is left out (Python) | C25: 0.6900174
A27: What moves nitrogen use? | B27: n | C27: r | D27: p (permutation) | E27: Verdict
A28: N use change vs output change, same crop year | B28: 18 | C28: 0.75325224 | D28: 0.00039992002 | E28: yes
A29: N use change vs output change of the crop before (income) | B29: 18 | C29: -0.066052957 | D29: 0.79084183 | E29: no
A30: N use change vs world arabica price change, same calendar year | B30: 18 | C30: 0.28037034 | D30: 0.24655069 | E30: no
A31: N use change vs coffee/urea price ratio change | B31: 18 | C31: 0.22692653 | D31: 0.36932613 | E31: no
A32: N use change vs urea price change | B32: 18 | C32: -0.026533683 | D32: 0.91541692 | E32: no
A33: N use change vs IHCAFE export price change of the crop before | B33: 17 | C33: 0.46848609 | D33: 0.056588682 | E33: hint
A35: Reading: nitrogen and output rise and fall together, in plain % (2011 +53 % / +41 %, 2016 +27 % / +42 %, 2019 -30 % / -27 %, 2020 +49 % / +25 %, 2021 -18 % / -26 %).
A36: Nitrogen does not follow the world price of the same year; it follows (weakly) the export price received for the previous crop (cash in hand), and state programmes: Bono Cafetalero 2020 = 25 188 t of fertiliser to 91 778 producers (USDA 2021), the year nitrogen use jumped 49 %.
A37: Caution: part of the link can run the other way - growers fertilise more when flowering promises a big crop. For forecasting both readings point the same way: fertiliser bought Apr-Sep is a leading signal of the crop harvested from November. FAOSTAT stops in 2022: track fertiliser imports and urea prices instead.

Sheet Weather
A1: Weather: El Nino, La Nina and the driest seasons against output
A2: Production change of the crop filled during the event (t) and of the next crop (t+1), flowered in the dry season that follows. USDA production, log change.
A4: El Nino (ONI Oct-Dec >= 1.0) | B4: ONI OND | C4: Change crop t | D4: Change crop t+1
A5: 1982/83 | B5: 2.03 | C5: =Changes!D18 -> 0.22314355 | D5: =Changes!D19 -> -0.13543797
A6: 1986/87 | B6: 1.06 | C6: =Changes!D22 -> 0.36837646 | D6: =Changes!D23 -> 0.011658163
A7: 1987/88 | B7: 1.2 | C7: =Changes!D23 -> 0.011658163 | D7: =Changes!D24 -> 0.05145426
A8: 1991/92 | B8: 1.18 | C8: =Changes!D27 -> 0.29138441 | D8: =Changes!D28 -> -0.12954821
A9: 1997/98 | B9: 2.34 | C9: =Changes!D33 -> 0.24269664 | D9: =Changes!D34 -> -0.15254554
A10: 2002/03 | B10: 1.19 | C10: =Changes!D38 -> -0.21606729 | D10: =Changes!D39 -> 0.17319887
A11: 2009/10 | B11: 1.31 | C11: =Changes!D45 -> 0.096014653 | D11: =Changes!D46 -> 0.11307714
A12: 2015/16 | B12: 2.45 | C12: =Changes!D51 -> 0.038466281 | D12: =Changes!D52 -> 0.34852865
A13: 2018/19 | B13: 1.04 | C13: =Changes!D54 -> -0.068053463 | D13: =Changes!D55 -> -0.31143616
A14: 2023/24 | B14: 1.9 | C14: =Changes!D59 -> -0.12107793 | D14: =Changes!D60 -> 0.029270382
A15: Average | C15: =AVERAGE(C5:C14) -> 0.086654147 | D15: =AVERAGE(D5:D14) -> -0.00017804074
A17: La Nina (ONI Oct-Dec <= -1.0) | B17: ONI OND | C17: Change crop t | D17: Change crop t+1
A18: 1988/89 | B18: -1.81 | C18: =Changes!D24 -> 0.05145426 | D18: =Changes!D25 -> 0.16484039
A19: 1995/96 | B19: -1.05 | C19: =Changes!D31 -> -0.018026428 | D19: =Changes!D32 -> 0.011030335
A20: 1998/99 | B20: -1.31 | C20: =Changes!D34 -> -0.15254554 | D20: =Changes!D35 -> 0.20681204
A21: 1999/00 | B21: -1.35 | C21: =Changes!D35 -> 0.20681204 | D21: =Changes!D36 -> -0.083608453
A22: 2007/08 | B22: -1.57 | C22: =Changes!D43 -> 0.051264392 | D22: =Changes!D44 -> -0.12160003
A23: 2010/11 | B23: -1.57 | C23: =Changes!D46 -> 0.11307714 | D23: =Changes!D47 -> 0.34274185
A24: 2011/12 | B24: -1.02 | C24: =Changes!D47 -> 0.34274185 | D24: =Changes!D48 -> -0.16989904
A25: 2020/21 | B25: -1.11 | C25: =Changes!D56 -> 0.22314355 | D25: =Changes!D57 -> -0.30318626
A26: Average | C26: =AVERAGE(C18:C25) -> 0.10224016 | D26: =AVERAGE(D18:D25) -> 0.0058913543
A28: Driest dry seasons Dec(t-1)-Mar t (GPCC, 3 towns) | B28: Rain vs normal | C28: Change crop t | D28: Change crop t+1
A29: 2024/25 | B29: -0.43572986 | C29: =Changes!D60 -> 0.029270382 | D29: =Changes!D61 -> 0.06152919
A30: 2019/20 | B30: -0.33812743 | C30: =Changes!D55 -> -0.31143616 | D30: =Changes!D56 -> 0.22314355
A31: 1998/99 | B31: -0.33009415 | C31: =Changes!D34 -> -0.15254554 | D31: =Changes!D35 -> 0.20681204
A32: 2006/07 | B32: -0.32159517 | C32: =Changes!D42 -> 0.07686856 | D32: =Changes!D43 -> 0.051264392
A33: 1985/86 | B33: -0.26047237 | C33: =Changes!D21 -> -0.27631831 | D33: =Changes!D22 -> 0.36837646
A34: 1995/96 | B34: -0.24859709 | C34: =Changes!D31 -> -0.018026428 | D34: =Changes!D32 -> 0.011030335
A35: 2002/03 | B35: -0.2458029 | C35: =Changes!D38 -> -0.21606729 | D35: =Changes!D39 -> 0.17319887
A37: Driest rainy seasons Jun-Oct t | B37: Rain vs normal | C37: Change crop t | D37: Change crop t+1
A38: 1986/87 | B38: -0.3000474 | C38: =Changes!D22 -> 0.36837646 | D38: =Changes!D23 -> 0.011658163
A39: 2023/24 | B39: -0.28047217 | C39: =Changes!D59 -> -0.12107793 | D39: =Changes!D60 -> 0.029270382
A40: 2018/19 | B40: -0.25698979 | C40: =Changes!D54 -> -0.068053463 | D40: =Changes!D55 -> -0.31143616
A41: 2001/02 | B41: -0.20649938 | C41: =Changes!D37 -> 0.09366531 | D41: =Changes!D38 -> -0.21606729
A42: 2016/17 | B42: -0.19324861 | C42: =Changes!D52 -> 0.34852865 | D42: =Changes!D53 -> 0.011912782
A43: 1994/95 | B43: -0.19073921 | C43: =Changes!D30 -> 0.10802686 | D43: =Changes!D31 -> -0.018026428
A44: 2004/05 | B44: -0.17224931 | C44: =Changes!D40 -> -0.14203879 | D44: =Changes!D41 -> 0.2185505
...

Sheet Backtest
A1: How well can output be forecast? Errors 2000/01 - 2025/26 (forecast made with data up to the year before)
A2: Actual = USDA production (July 2026 data). Averages and last-year are Excel formulas; the trend and the regressions are refitted each year in Python (purple).
A4: Crop year | B4: Actual | C4: Last year (random walk) | D4: Average of last 2 years | E4: Average of last 3 years | F4: Average of last 4 years | G4: Linear trend, last 8 years | H4: Model: mean reversion + price + dry-season rain | I4: Average of last 4 years + price + dry-season rain | J4: Combination: mean of (last 2 years) and the model | K4: Error: Last year (random walk) | L4: Error: Average of last 2 years | M4: Error: Average of last 3 years | N4: Error: Average of last 4 years | O4: Error: Linear trend, last 8 years | P4: Error: Model: mean reversion + price + dry-season rain | Q4: Error: Average of last 4 years + price + dry-season rain | R4: Error: Combination: mean of (last 2 years) and the model
A5: 2000/01 | B5: =Data!E36 -> 2821 | C5: =Data!E35 -> 3067 | D5: =EXP((LN(Data!E35)+LN(Data!E34))/2) -> 2765.7003 | E5: =EXP((LN(Data!E35)+LN(Data!E34)+LN(Data!E33))/3) -> 2811.3751 | F5: =EXP((LN(Data!E35)+LN(Data!E34)+LN(Data!E33)+LN(Data!E32))/4) -> 2667.6274 | G5: 3081.4667 | H5: 2837.3057 | I5: 3042.1704 | J5: =SQRT(D5*H5) -> 2801.2742 | K5: =ABS(C5/B5-1) -> 0.087203119 | L5: =ABS(D5/B5-1) -> 0.019602881 | M5: =ABS(E5/B5-1) -> 0.0034118907 | N5: =ABS(F5/B5-1) -> 0.054368162 | O5: =ABS(G5/B5-1) -> 0.09233134 | P5: =ABS(H5/B5-1) -> 0.0057801013 | Q5: =ABS(I5/B5-1) -> 0.078401432 | R5: =ABS(J5/B5-1) -> 0.0069924906
A6: 2001/02 | B6: =Data!E37 -> 3098 | C6: =Data!E36 -> 2821 | D6: =EXP((LN(Data!E36)+LN(Data!E35))/2) -> 2941.4294 | E6: =EXP((LN(Data!E36)+LN(Data!E35)+LN(Data!E34))/3) -> 2784.012 | F6: =EXP((LN(Data!E36)+LN(Data!E35)+LN(Data!E34)+LN(Data!E33))/4) -> 2813.7782 | G6: 3129.3537 | H6: 3184.8775 | I6: 3181.3956 | J6: =SQRT(D6*H6) -> 3060.734 | K6: =ABS(C6/B6-1) -> 0.089412524 | L6: =ABS(D6/B6-1) -> 0.050539246 | M6: =ABS(E6/B6-1) -> 0.10135184 | N6: =ABS(F6/B6-1) -> 0.091743638 | O6: =ABS(G6/B6-1) -> 0.010120641 | P6: =ABS(H6/B6-1) -> 0.028043093 | Q6: =ABS(I6/B6-1) -> 0.026919162 | R6: =ABS(J6/B6-1) -> 0.012029064
A7: 2002/03 | B7: =Data!E38 -> 2496 | C7: =Data!E37 -> 3098 | D7: =EXP((LN(Data!E37)+LN(Data!E36))/2) -> 2956.2574 | E7: =EXP((LN(Data!E37)+LN(Data!E36)+LN(Data!E35))/3) -> 2992.72 | F7: =EXP((LN(Data!E37)+LN(Data!E36)+LN(Data!E35)+LN(Data!E34))/4) -> 2859.3919 | G7: 3251.6803 | H7: 3055.7852 | I7: 3245.2423 | J7: =SQRT(D7*H7) -> 3005.6094 | K7: =ABS(C7/B7-1) -> 0.2411859 | L7: =ABS(D7/B7-1) -> 0.18439801 | M7: =ABS(E7/B7-1) -> 0.19900643 | N7: =ABS(F7/B7-1) -> 0.1455897 | O7: =ABS(G7/B7-1) -> 0.30275655 | P7: =ABS(H7/B7-1) -> 0.22427291 | Q7: =ABS(I7/B7-1) -> 0.3001772 | R7: =ABS(J7/B7-1) -> 0.20417042
A8: 2003/04 | B8: =Data!E39 -> 2968 | C8: =Data!E38 -> 2496 | D8: =EXP((LN(Data!E38)+LN(Data!E37))/2) -> 2780.7567 | E8: =EXP((LN(Data!E38)+LN(Data!E37)+LN(Data!E36))/3) -> 2794.107 | F8: =EXP((LN(Data!E38)+LN(Data!E37)+LN(Data!E36)+LN(Data!E35))/4) -> 2859.965 | G8: 3017.2473 | H8: 3253.6006 | I8: 3442.2753 | J8: =SQRT(D8*H8) -> 3007.9016 | K8: =ABS(C8/B8-1) -> 0.15902965 | L8: =ABS(D8/B8-1) -> 0.063087355 | M8: =ABS(E8/B8-1) -> 0.0585893 | N8: =ABS(F8/B8-1) -> 0.036399942 | O8: =ABS(G8/B8-1) -> 0.01659275 | P8: =ABS(H8/B8-1) -> 0.096226627 | Q8: =ABS(I8/B8-1) -> 0.15979628 | R8: =ABS(J8/B8-1) -> 0.013443925
A9: 2004/05 | B9: =Data!E40 -> 2575 | C9: =Data!E39 -> 2968 | D9: =EXP((LN(Data!E39)+LN(Data!E38))/2) -> 2721.7876 | E9: =EXP((LN(Data!E39)+LN(Data!E38)+LN(Data!E37))/3) -> 2841.8204 | F9: =EXP((LN(Data!E39)+LN(Data!E38)+LN(Data!E37)+LN(Data!E36))/4) -> 2836.601 | G9: 3006.2217 | H9: 2859.8329 | I9: 3219.0432 | J9: =SQRT(D9*H9) -> 2789.9566 | K9: =ABS(C9/B9-1) -> 0.15262136 | L9: =ABS(D9/B9-1) -> 0.057004912 | M9: =ABS(E9/B9-1) -> 0.10361958 | N9: =ABS(F9/B9-1) -> 0.1015926 | O9: =ABS(G9/B9-1) -> 0.16746472 | P9: =ABS(H9/B9-1) -> 0.1106147 | Q9: =ABS(I9/B9-1) -> 0.25011386 | R9: =ABS(J9/B9-1) -> 0.083478286
A10: 2005/06 | B10: =Data!E41 -> 3204 | C10: =Data!E40 -> 2575 | D10: =EXP((LN(Data!E40)+LN(Data!E39))/2) -> 2764.5253 | E10: =EXP((LN(Data!E40)+LN(Data!E39)+LN(Data!E38))/3) -> 2671.9515 | F10: =EXP((LN(Data!E40)+LN(Data!E39)+LN(Data!E38)+LN(Data!E37))/4) -> 2772.6291 | G10: 2719.5308 | H10: 2951.8451 | I10: 3050.8135 | J10: =SQRT(D10*H10) -> 2856.6502 | K10: =ABS(C10/B10-1) -> 0.1963171 | L10: =ABS(D10/B10-1) -> 0.1371644 | M10: =ABS(E10/B10-1) -> 0.16605759 | N10: =ABS(F10/B10-1) -> 0.1346351 | O10: =ABS(G10/B10-1) -> 0.15120762 | P10: =ABS(H10/B10-1) -> 0.078700033 | Q10: =ABS(I10/B10-1) -> 0.047811028 | R10: =ABS(J10/B10-1) -> 0.1084113
A11: 2006/07 | B11: =Data!E42 -> 3460 | C11: =Data!E41 -> 3204 | D11: =EXP((LN(Data!E41)+LN(Data!E40))/2) -> 2872.3335 | E11: =EXP((LN(Data!E41)+LN(Data!E40)+LN(Data!E39))/3) -> 2903.8747 | F11: =EXP((LN(Data!E41)+LN(Data!E40)+LN(Data!E39)+LN(Data!E38))/4) -> 2796.0476 | G11: 2953.8335 | H11: 2831.1765 | I11: 3042.9165 | J11: =SQRT(D11*H11) -> 2851.6808 | K11: =ABS(C11/B11-1) -> 0.073988439 | L11: =ABS(D11/B11-1) -> 0.1698458 | M11: =ABS(E11/B11-1) -> 0.16072984 | N11: =ABS(F11/B11-1) -> 0.19189377 | O11: =ABS(G11/B11-1) -> 0.1462909 | P11: =ABS(H11/B11-1) -> 0.1817409 | Q11: =ABS(I11/B11-1) -> 0.12054436 | R11: =ABS(J11/B11-1) -> 0.17581481
A12: 2007/08 | B12: =Data!E43 -> 3642 | C12: =Data!E42 -> 3460 | D12: =EXP((LN(Data!E42)+LN(Data!E41))/2) -> 3329.5405 | E12: =EXP((LN(Data!E42)+LN(Data!E41)+LN(Data!E40))/3) -> 3056.2012 | F12: =EXP((LN(Data!E42)+LN(Data!E41)+LN(Data!E40)+LN(Data!E39))/4) -> 3033.9082 | G12: 3124.2853 | H12: 3523.706 | I12: 3385.2887 | J12: =SQRT(D12*H12) -> 3425.2477 | K12: =ABS(C12/B12-1) -> 0.049972543 | L12: =ABS(D12/B12-1) -> 0.08579338 | M12: =ABS(E12/B12-1) -> 0.16084535 | N12: =ABS(F12/B12-1) -> 0.16696645 | O12: =ABS(G12/B12-1) -> 0.1421512 | P12: =ABS(H12/B12-1) -> 0.032480501 | Q12: =ABS(I12/B12-1) -> 0.070486364 | R12: =ABS(J12/B12-1) -> 0.05951463
A13: 2008/09 | B13: =Data!E44 -> 3225 | C13: =Data!E43 -> 3642 | D13: =EXP((LN(Data!E43)+LN(Data!E42))/2) -> 3549.8338 | E13: =EXP((LN(Data!E43)+LN(Data!E42)+LN(Data!E41))/3) -> 3430.5955 | F13: =EXP((LN(Data!E43)+LN(Data!E42)+LN(Data!E41)+LN(Data!E40))/4) -> 3193.1656 | G13: 3524.4502 | H13: 3764.5539 | I13: 3579.1864 | J13: =SQRT(D13*H13) -> 3655.6177 | K13: =ABS(C13/B13-1) -> 0.12930233 | L13: =ABS(D13/B13-1) -> 0.10072366 | M13: =ABS(E13/B13-1) -> 0.063750548 | N13: =ABS(F13/B13-1) -> 0.0098711243 | O13: =ABS(G13/B13-1) -> 0.092852762 | P13: =ABS(H13/B13-1) -> 0.16730355 | Q13: =ABS(I13/B13-1) -> 0.10982524 | R13: =ABS(J13/B13-1) -> 0.13352487
A14: 2009/10 | B14: =Data!E45 -> 3550 | C14: =Data!E44 -> 3225 | D14: =EXP((LN(Data!E44)+LN(Data!E43))/2) -> 3427.1636 | E14: =EXP((LN(Data!E44)+LN(Data!E43)+LN(Data!E42))/3) -> 3438.0743 | F14: =EXP((LN(Data!E44)+LN(Data!E43)+LN(Data!E42)+LN(Data!E41))/4) -> 3377.9994 | G14: 3565.0299 | H14: 3694.4334 | I14: 3759.7915 | J14: =SQRT(D14*H14) -> 3558.29 | K14: =ABS(C14/B14-1) -> 0.091549296 | L14: =ABS(D14/B14-1) -> 0.034601817 | M14: =ABS(E14/B14-1) -> 0.031528377 | N14: =ABS(F14/B14-1) -> 0.048450876 | O14: =ABS(G14/B14-1) -> 0.0042337875 | P14: =ABS(H14/B14-1) -> 0.040685467 | Q14: =ABS(I14/B14-1) -> 0.059096191 | R14: =ABS(J14/B14-1) -> 0.002335203
A15: 2010/11 | B15: =Data!E46 -> 3975 | C15: =Data!E45 -> 3550 | D15: =EXP((LN(Data!E45)+LN(Data!E44))/2) -> 3383.6002 | E15: =EXP((LN(Data!E45)+LN(Data!E44)+LN(Data!E43))/3) -> 3467.6294 | F15: =EXP((LN(Data!E45)+LN(Data!E44)+LN(Data!E43)+LN(Data!E42))/4) -> 3465.7204 | G15: 3856.4209 | H15: 3559.9808 | I15: 3863.9124 | J15: =SQRT(D15*H15) -> 3470.6702 | K15: =ABS(C15/B15-1) -> 0.10691824 | L15: =ABS(D15/B15-1) -> 0.14877984 | M15: =ABS(E15/B15-1) -> 0.12764041 | N15: =ABS(F15/B15-1) -> 0.12812064 | O15: =ABS(G15/B15-1) -> 0.029831218 | P15: =ABS(H15/B15-1) -> 0.10440734 | Q15: =ABS(I15/B15-1) -> 0.027946555 | R15: =ABS(J15/B15-1) -> 0.12687542
A16: 2011/12 | B16: =Data!E47 -> 5600 | C16: =Data!E46 -> 3975 | D16: =EXP((LN(Data!E46)+LN(Data!E45))/2) -> 3756.4944 | E16: =EXP((LN(Data!E46)+LN(Data!E45)+LN(Data!E44))/3) -> 3570.2481 | F16: =EXP((LN(Data!E46)+LN(Data!E45)+LN(Data!E44)+LN(Data!E43))/4) -> 3588.0525 | G16: 4027.2607 | H16: 4049.6614 | I16: 4026.8401 | J16: =SQRT(D16*H16) -> 3900.3244 | K16: =ABS(C16/B16-1) -> 0.29017857 | L16: =ABS(D16/B16-1) -> 0.32919743 | M16: =ABS(E16/B16-1) -> 0.36245569 | N16: =ABS(F16/B16-1) -> 0.35927634 | O16: =ABS(G16/B16-1) -> 0.28084631 | P16: =ABS(H16/B16-1) -> 0.27684619 | Q16: =ABS(I16/B16-1) -> 0.2809214 | R16: =ABS(J16/B16-1) -> 0.30351351
... A30: 2025/26 | B30: =Data!E61 -> 5530 | C30: =Data!E60 -> 5200 | D30: =EXP((LN(Data!E60)+LN(Data!E59))/2) -> 5124.4512 | E30: =EXP((LN(Data!E60)+LN(Data!E59)+LN(Data!E58))/3) -> 5309.5355 | F30: =EXP((LN(Data!E60)+LN(Data!E59)+LN(Data!E58)+LN(Data!E57))/4) -> 5177.2925 | G30: 4598.2347 | H30: 5895.3662 | I30: 5923.6187 | J30: =SQRT(D30*H30) -> 5496.4094 | K30: =ABS(C30/B30-1) -> 0.059674503 | L30: =ABS(D30/B30-1) -> 0.073336132 | M30: =ABS(E30/B30-1) -> 0.039867005 | N30: =ABS(F30/B30-1) -> 0.063780737 | O30: =ABS(G30/B30-1) -> 0.16849282 | P30: =ABS(H30/B30-1) -> 0.066069831 | Q30: =ABS(I30/B30-1) -> 0.071178795 | R30: =ABS(J30/B30-1) -> 0.0060742519
A31: Mean abs. error | K31: =AVERAGE(K5:K30) -> 0.14511297 | L31: =AVERAGE(L5:L30) -> 0.12134964 | M31: =AVERAGE(M5:M30) -> 0.13103302 | N31: =AVERAGE(N5:N30) -> 0.13371765 | O31: =AVERAGE(O5:O30) -> 0.14057086 | P31: =AVERAGE(P5:P30) -> 0.12464334 | Q31: =AVERAGE(Q5:Q30) -> 0.14757603 | R31: =AVERAGE(R5:R30) -> 0.11327105
A34: USDA attache first forecast of the coming crop (Coffee Annual, May of year t), 1 000 60-kg bags
A35: Crop year | B35: USDA May forecast | C35: Actual | D35: Abs. error | E35: Direction right?
A36: 2011/12 | B36: 3900 | C36: =Data!E47 -> 5600 | D36: =ABS(B36/C36-1) -> 0.30357143 | E36: =IF((B36>Data!E46)=(C36>Data!E46),"yes","no") -> no
A37: 2012/13 | B37: 5000 | C37: =Data!E48 -> 4725 | D37: =ABS(B37/C37-1) -> 0.058201058 | E37: =IF((B37>Data!E47)=(C37>Data!E47),"yes","no") -> yes
A38: 2013/14 | B38: 5100 | C38: =Data!E49 -> 4400 | D38: =ABS(B38/C38-1) -> 0.15909091 | E38: =IF((B38>Data!E48)=(C38>Data!E48),"yes","no") -> no
A39: 2014/15 | B39: 5000 | C39: =Data!E50 -> 5100 | D39: =ABS(B39/C39-1) -> 0.019607843 | E39: =IF((B39>Data!E49)=(C39>Data!E49),"yes","no") -> yes
A40: 2015/16 | B40: 5900 | C40: =Data!E51 -> 5300 | D40: =ABS(B40/C40-1) -> 0.11320755 | E40: =IF((B40>Data!E50)=(C40>Data!E50),"yes","no") -> yes
A41: 2016/17 | B41: 6100 | C41: =Data!E52 -> 7510 | D41: =ABS(B41/C41-1) -> 0.18774967 | E41: =IF((B41>Data!E51)=(C41>Data!E51),"yes","no") -> yes
A42: 2017/18 | B42: 6500 | C42: =Data!E53 -> 7600 | D42: =ABS(B42/C42-1) -> 0.14473684 | E42: =IF((B42>Data!E52)=(C42>Data!E52),"yes","no") -> no
A43: 2018/19 | B43: 7300 | C43: =Data!E54 -> 7100 | D43: =ABS(B43/C43-1) -> 0.028169014 | E43: =IF((B43>Data!E53)=(C43>Data!E53),"yes","no") -> yes
A44: 2020/21 | B44: 6100 | C44: =Data!E56 -> 6500 | D44: =ABS(B44/C44-1) -> 0.061538462 | E44: =IF((B44>Data!E55)=(C44>Data!E55),"yes","no") -> yes
A45: 2021/22 | B45: 5500 | C45: =Data!E57 -> 4800 | D45: =ABS(B45/C45-1) -> 0.14583333 | E45: =IF((B45>Data!E56)=(C45>Data!E56),"yes","no") -> yes
A46: 2025/26 | B46: 5800 | C46: =Data!E61 -> 5530 | D46: =ABS(B46/C46-1) -> 0.048824593 | E46: =IF((B46>Data!E60)=(C46>Data!E60),"yes","no") -> yes
A47: Mean abs. error | D47: =AVERAGE(D36:D46) -> 0.11550279
A48: Same 11 years, best simple method (average of last 2 years) | D48: 0.14575561
A50: Not used: 2019 (report not found); May 2022, 2023, 2024 reports forecast the crop then being harvested, not the next one.
A51: Reading: every method misses by 12-15 % on average; the USDA May forecast (field information: flowering, rust surveys, IHCAFE) does best at 11.6 %. Price and rain add nothing out of sample. The edge is in-season tracking (exports, fertiliser, rust bulletins), not a better formula.

Sheet Exports_nowcast
A1: What the 2025/26 exports say about the 2025/26 crop
A2: Export volumes in quintales (bags of 46 kg), as IHCAFE and the press give them. 1 bag of 60 kg = 60/46 quintales. Crop year from 1 October.
A4: Cumulative exports to | B4: 2025/26 (quintales) | C4: 2024/25 same date | D4: Change | E4: Source (read, raw/coffee_zones/) | F4: Quote
A5: 31 Oct 2025 | B5: 51183.91 | C5: =B5-28603.67 -> 22580.24 | D5: =B5/C5-1 -> 1.2667567 | E5: press/01 La Prensa 5 Nov 2025 | F5: 51,183.91 sacos de 46 kilogramos durante octubre ... alza interanual del 126.7%, equivalente a 28,603.67 sacos más
A6: 3 Mar 2026 | B6: 3023652 | C6: 1918225 | D6: =B6/C6-1 -> 0.57627598 | E6: press/02 La Prensa 4 Mar 2026 | F6: 3,023,652 sacos (de 46 kilogramos) ... 57.6% ... cuando envió al exterior 1,918,225 sacos
A7: 30 Apr 2026 | B7: 4970000 | C7: 3600000 | D7: =B7/C7-1 -> 0.38055556 | E7: press/06 El Heraldo 4 May 2026 | F7: 4.97 millones de sacos de 46 kilogramos ... comparado a los 3.60 millones de sacos registrados durante el período 2024-2025
A8: 1 Jul 2026 | B8: 6663920 | C8: 5773579 | D8: =B8/C8-1 -> 0.15420955 | E8: press/03 La Prensa 3 Jul 2026 | F8: se exportaron 6,663,920 sacos de 46 kilogramos ... cuando se exportaron 5,773,579 sacos
