Workbook

Sheet Brazil
A1: Market Year | B1: Area Harvested (1,000 ha) | C1: Yield (bags/ha) | D1: Beginning Stocks | E1: Production | F1: MY Imports | G1: Total Supply (Official) | H1: Roast & Ground Consumption | I1: Soluble Consumption | J1: Total Consumption | K1: MY Exports | L1: Ending Stocks | M1: Total Distribution (Official) | N1: Stocks / Use Domestic + Exports
A2: 2010/11 | B2: 2159.785 | C2: =IF(N(B2)>0,E2/B2,"") -> 25.233993 | D2: 2836 | E2: 54500 | F2: 0 | G2: =D2+E2+F2 -> 57336 | H2: 18330 | I2: 1090 | J2: =H2+I2 -> 19420 | K2: 35010 | L2: 2906 | M2: =J2+K2+L2 -> 57336 | N2: =IF((J2+K2)>0,L2/(J2+K2),"") -> 0.053389675
A3: 2011/12 | B3: 2148.775 | C3: =IF(N(B3)>0,E3/B3,"") -> 22.896767 | D3: 2906 | E3: 49200 | F3: 0 | G3: =D3+E3+F3 -> 52106 | H3: 18905 | I3: 1120 | J3: =H3+I3 -> 20025 | K3: 29843 | L3: 2238 | M3: =J3+K3+L3 -> 52106 | N3: =IF((J3+K3)>0,L3/(J3+K3),"") -> 0.044878479
A4: 2012/13 | B4: 2120.08 | C4: =IF(N(B4)>0,E4/B4,"") -> 27.168786 | D4: 2238 | E4: 57600 | F4: 0 | G4: =D4+E4+F4 -> 59838 | H4: 19000 | I4: 1110 | J4: =H4+I4 -> 20110 | K4: 30660 | L4: 9068 | M4: =J4+K4+L4 -> 59838 | N4: =IF((J4+K4)>0,L4/(J4+K4),"") -> 0.17860942
A5: 2013/14 | B5: 2085.522 | C5: =IF(N(B5)>0,E5/B5,"") -> 27.427186 | D5: 9068 | E5: 57200 | F5: 34 | G5: =D5+E5+F5 -> 66302 | H5: 19130 | I5: 1080 | J5: =H5+I5 -> 20210 | K5: 34146 | L5: 11946 | M5: =J5+K5+L5 -> 66302 | N5: =IF((J5+K5)>0,L5/(J5+K5),"") -> 0.21977335
A6: 2014/15 | B6: 1997.827 | C6: =IF(N(B6)>0,E6/B6,"") -> 27.179531 | D6: 11946 | E6: 54300 | F6: 52 | G6: =D6+E6+F6 -> 66298 | H6: 19325 | I6: 1095 | J6: =H6+I6 -> 20420 | K6: 36573 | L6: 9305 | M6: =J6+K6+L6 -> 66298 | N6: =IF((J6+K6)>0,L6/(J6+K6),"") -> 0.16326566
A7: 2015/16 | B7: 1977.714 | C7: =IF(N(B7)>0,E7/B7,"") -> 24.978334 | D7: 9305 | E7: 49400 | F7: 65 | G7: =D7+E7+F7 -> 58770 | H7: 19750 | I7: 1105 | J7: =H7+I7 -> 20855 | K7: 35543 | L7: 2372 | M7: =J7+K7+L7 -> 58770 | N7: =IF((J7+K7)>0,L7/(J7+K7),"") -> 0.042058229
A8: 2016/17 | B8: 1996.604 | C8: =IF(N(B8)>0,E8/B8,"") -> 28.09771 | D8: 2372 | E8: 56100 | F8: 62 | G8: =D8+E8+F8 -> 58534 | H8: 20500 | I8: 1125 | J8: =H8+I8 -> 21625 | K8: 33081 | L8: 3828 | M8: =J8+K8+L8 -> 58534 | N8: =IF((J8+K8)>0,L8/(J8+K8),"") -> 0.069974043
A9: 2017/18 | B9: 1802.417 | C9: =IF(N(B9)>0,E9/B9,"") -> 28.905631 | D9: 3828 | E9: 52100 | F9: 61 | G9: =D9+E9+F9 -> 55989 | H9: 21275 | I9: 1145 | J9: =H9+I9 -> 22420 | K9: 30454 | L9: 3115 | M9: =J9+K9+L9 -> 55989 | N9: =IF((J9+K9)>0,L9/(J9+K9),"") -> 0.058913644
A10: 2018/19 | B10: 1863.966 | C10: =IF(N(B10)>0,E10/B10,"") -> 35.676616 | D10: 3115 | E10: 66500 | F10: 67 | G10: =D10+E10+F10 -> 69682 | H10: 22020 | I10: 1180 | J10: =H10+I10 -> 23200 | K10: 41426 | L10: 5056 | M10: =J10+K10+L10 -> 69682 | N10: =IF((J10+K10)>0,L10/(J10+K10),"") -> 0.078234766
A11: 2019/20 | B11: 1825.283 | C11: =IF(N(B11)>0,E11/B11,"") -> 33.145545 | D11: 5056 | E11: 60500 | F11: 67 | G11: =D11+E11+F11 -> 65623 | H11: 22065 | I11: 929 | J11: =H11+I11 -> 22994 | K11: 40256 | L11: 2373 | M11: =J11+K11+L11 -> 65623 | N11: =IF((J11+K11)>0,L11/(J11+K11),"") -> 0.037517787
A12: 2020/21 | B12: 1898.429 | C12: =IF(N(B12)>0,E12/B12,"") -> 36.819918 | D12: 2373 | E12: 69900 | F12: 72 | G12: =D12+E12+F12 -> 72345 | H12: 21350 | I12: 930 | J12: =H12+I12 -> 22280 | K12: 45675 | L12: 4390 | M12: =J12+K12+L12 -> 72345 | N12: =IF((J12+K12)>0,L12/(J12+K12),"") -> 0.064601575
A13: 2021/22 | B13: 1832.508 | C13: =IF(N(B13)>0,E13/B13,"") -> 31.705182 | D13: 4390 | E13: 58100 | F13: 75 | G13: =D13+E13+F13 -> 62565 | H13: 21400 | I13: 940 | J13: =H13+I13 -> 22340 | K13: 39685 | L13: 540 | M13: =J13+K13+L13 -> 62565 | N13: =IF((J13+K13)>0,L13/(J13+K13),"") -> 0.0087061669
... A19: 2026/27 (USDA Jun 2026) | B19: 1943.977 | C19: =IF(N(B19)>0,E19/B19,"") -> 36.986034 | D19: 3895 | E19: 71900 | F19: 90 | G19: =D19+E19+F19 -> 75885 | H19: 21400 | I19: 990 | J19: =H19+I19 -> 22390 | K19: 49070 | L19: 4425 | M19: =J19+K19+L19 -> 75885 | N19: =IF((J19+K19)>0,L19/(J19+K19),"") -> 0.061922754
A21: 2026/27 (USDA attaché, Jun 2026) | C21: =IF(N(B21)>0,E21/B21,"") | D21: 3895 | E21: 71900 | F21: 90 | G21: =D21+E21+F21 -> 75885 | H21: 21400 | I21: 990 | J21: =H21+I21 -> 22390 | K21: 49070 | L21: 4425 | M21: =J21+K21+L21 -> 75885 | N21: =IF((J21+K21)>0,L21/(J21+K21),"") -> 0.061922754
A23: 2026/27 My Estimate | B23: 1943.977 | C23: 36.986034 | D23: =L17 -> 3895 | E23: =B23*C23 -> 71900 | F23: 90 | G23: =D23+E23+F23 -> 75885 | H23: 21400 | I23: 990 | J23: =H23+I23 -> 22390 | K23: 49070 | L23: =G23-J23-K23 -> 4425 | M23: =J23+K23+L23 -> 75885 | N23: =IF((J23+K23)>0,L23/(J23+K23),"") -> 0.061922754
A25: Brazil: marketing year Jul-Jun.
A26: Units: 1,000 60-kg bags (green bean equivalent); area in 1,000 ha; yield = production / area harvested (bags/ha).
A27: Balance: USDA FAS PSD Online, coffee (update of July 2026; 2026/27 = USDA June 2026 forecast). Total Supply = Beginning Stocks + Production + Imports; Total Distribution = Consumption + Exports + Ending Stocks; Stocks/Use = Ending Stocks / (Consumption + Exports).
A28: Consumption columns: USDA roast & ground and soluble domestic consumption (the coffee counterparts of Feed & Residual and FSI in the corn sheet).
A29: Area harvested: FAOSTAT (item 656 Coffee, green; official national data compiled by FAO, bulk release Dec 2025): calendar year Y shown in MY Y/Y+1 (Mexico and Uganda: Y-1/Y). USDA's PSD has no coffee area. Grey italics = latest FAO value carried forward (FAO ends with 2024).
A30: 2026/27 My Estimate: yellow cells with blue figures are your inputs (start = USDA June values): area, yield, imports, consumption (roast & ground, soluble) and exports. Production = area x yield; beginning stocks = 2025/26 ending stocks; ending stocks = supply - consumption - exports. Black = formulas; green = links to another sheet.
A31: Area carried forward from the last FAO year for 2025/26, 2026/27.
A32: 2026/27 (USDA attaché): post estimate of the USDA GAIN Coffee Annual BR2026-0025 (Jun 2026); its area is the post's harvested area where the report gives one.

Sheet Vietnam
A1: Market Year | B1: Area Harvested (1,000 ha) | C1: Yield (bags/ha) | D1: Beginning Stocks | E1: Production | F1: MY Imports | G1: Total Supply (Official) | H1: Roast & Ground Consumption | I1: Soluble Consumption | J1: Total Consumption | K1: MY Exports | L1: Ending Stocks | M1: Total Distribution (Official) | N1: Stocks / Use Domestic + Exports
A2: 2010/11 | B2: 511.9 | C2: =IF(N(B2)>0,E2/B2,"") -> 37.92733 | D2: 1012 | E2: 19415 | F2: 350 | G2: =D2+E2+F2 -> 20777 | H2: 1200 | I2: 137 | J2: =H2+I2 -> 1337 | K2: 18640 | L2: 800 | M2: =J2+K2+L2 -> 20777 | N2: =IF((J2+K2)>0,L2/(J2+K2),"") -> 0.040046053
A3: 2011/12 | B3: 543.865 | C3: =IF(N(B3)>0,E3/B3,"") -> 47.805981 | D3: 800 | E3: 26000 | F3: 450 | G3: =D3+E3+F3 -> 27250 | H3: 1480 | I3: 185 | J3: =H3+I3 -> 1665 | K3: 24495 | L3: 1090 | M3: =J3+K3+L3 -> 27250 | N3: =IF((J3+K3)>0,L3/(J3+K3),"") -> 0.041666667
A4: 2012/13 | B4: 572.6 | C4: =IF(N(B4)>0,E4/B4,"") -> 46.280126 | D4: 1090 | E4: 26500 | F4: 824 | G4: =D4+E4+F4 -> 28414 | H4: 1625 | I4: 200 | J4: =H4+I4 -> 1825 | K4: 24643 | L4: 1946 | M4: =J4+K4+L4 -> 28414 | N4: =IF((J4+K4)>0,L4/(J4+K4),"") -> 0.073522744
A5: 2013/14 | B5: 581.381 | C5: =IF(N(B5)>0,E5/B5,"") -> 51.314026 | D5: 1946 | E5: 29833 | F5: 648 | G5: =D5+E5+F5 -> 32427 | H5: 1788 | I5: 220 | J5: =H5+I5 -> 2008 | K5: 28289 | L5: 2130 | M5: =J5+K5+L5 -> 32427 | N5: =IF((J5+K5)>0,L5/(J5+K5),"") -> 0.07030399
A6: 2014/15 | B6: 589.041 | C6: =IF(N(B6)>0,E6/B6,"") -> 46.516287 | D6: 2130 | E6: 27400 | F6: 590 | G6: =D6+E6+F6 -> 30120 | H6: 1917 | I6: 300 | J6: =H6+I6 -> 2217 | K6: 21567 | L6: 6336 | M6: =J6+K6+L6 -> 30120 | N6: =IF((J6+K6)>0,L6/(J6+K6),"") -> 0.26639758
A7: 2015/16 | B7: 593.8 | C7: =IF(N(B7)>0,E7/B7,"") -> 48.720108 | D7: 6336 | E7: 28930 | F7: 630 | G7: =D7+E7+F7 -> 35896 | H7: 2280 | I7: 350 | J7: =H7+I7 -> 2630 | K7: 29065 | L7: 4201 | M7: =J7+K7+L7 -> 35896 | N7: =IF((J7+K7)>0,L7/(J7+K7),"") -> 0.13254457
A8: 2016/17 | B8: 597.597 | C8: =IF(N(B8)>0,E8/B8,"") -> 44.678939 | D8: 4201 | E8: 26700 | F8: 1000 | G8: =D8+E8+F8 -> 31901 | H8: 2400 | I8: 370 | J8: =H8+I8 -> 2770 | K8: 26450 | L8: 2681 | M8: =J8+K8+L8 -> 31901 | N8: =IF((J8+K8)>0,L8/(J8+K8),"") -> 0.091752225
A9: 2017/18 | B9: 605.178 | C9: =IF(N(B9)>0,E9/B9,"") -> 48.415508 | D9: 2681 | E9: 29300 | F9: 1060 | G9: =D9+E9+F9 -> 33041 | H9: 2500 | I9: 380 | J9: =H9+I9 -> 2880 | K9: 29907 | L9: 254 | M9: =J9+K9+L9 -> 33041 | N9: =IF((J9+K9)>0,L9/(J9+K9),"") -> 0.0077469729
A10: 2018/19 | B10: 618.879 | C10: =IF(N(B10)>0,E10/B10,"") -> 49.121072 | D10: 254 | E10: 30400 | F10: 1160 | G10: =D10+E10+F10 -> 31814 | H10: 2550 | I10: 390 | J10: =H10+I10 -> 2940 | K10: 28318 | L10: 556 | M10: =J10+K10+L10 -> 31814 | N10: =IF((J10+K10)>0,L10/(J10+K10),"") -> 0.017787446
A11: 2019/20 | B11: 624.1 | C11: =IF(N(B11)>0,E11/B11,"") -> 50.152219 | D11: 556 | E11: 31300 | F11: 700 | G11: =D11+E11+F11 -> 32556 | H11: 2600 | I11: 500 | J11: =H11+I11 -> 3100 | K11: 27326 | L11: 2130 | M11: =J11+K11+L11 -> 32556 | N11: =IF((J11+K11)>0,L11/(J11+K11),"") -> 0.070005916
A12: 2020/21 | B12: 637.563 | C12: =IF(N(B12)>0,E12/B12,"") -> 45.485701 | D12: 2130 | E12: 29000 | F12: 550 | G12: =D12+E12+F12 -> 31680 | H12: 2220 | I12: 500 | J12: =H12+I12 -> 2720 | K12: 25300 | L12: 3660 | M12: =J12+K12+L12 -> 31680 | N12: =IF((J12+K12)>0,L12/(J12+K12),"") -> 0.13062099
A13: 2021/22 | B13: 653.192 | C13: =IF(N(B13)>0,E13/B13,"") -> 48.347193 | D13: 3660 | E13: 31580 | F13: 550 | G13: =D13+E13+F13 -> 35790 | H13: 2650 | I13: 550 | J13: =H13+I13 -> 3200 | K13: 29010 | L13: 3580 | M13: =J13+K13+L13 -> 35790 | N13: =IF((J13+K13)>0,L13/(J13+K13),"") -> 0.11114561
... A19: 2026/27 (USDA Jun 2026) | B19: 678.569 | C19: =IF(N(B19)>0,E19/B19,"") -> 47.894908 | D19: 689 | E19: 32500 | F19: 1250 | G19: =D19+E19+F19 -> 34439 | H19: 3450 | I19: 1550 | J19: =H19+I19 -> 5000 | K19: 28950 | L19: 489 | M19: =J19+K19+L19 -> 34439 | N19: =IF((J19+K19)>0,L19/(J19+K19),"") -> 0.014403535
A21: 2026/27 (USDA attaché, May 2026) | C21: =IF(N(B21)>0,E21/B21,"") | D21: 689 | E21: 32500 | F21: 1250 | G21: =D21+E21+F21 -> 34439 | H21: 3450 | I21: 1550 | J21: =H21+I21 -> 5000 | K21: 28950 | L21: 489 | M21: =J21+K21+L21 -> 34439 | N21: =IF((J21+K21)>0,L21/(J21+K21),"") -> 0.014403535
A23: 2026/27 My Estimate | B23: 678.569 | C23: 47.894908 | D23: =L17 -> 689 | E23: =B23*C23 -> 32500 | F23: 1250 | G23: =D23+E23+F23 -> 34439 | H23: 3450 | I23: 1550 | J23: =H23+I23 -> 5000 | K23: 28950 | L23: =G23-J23-K23 -> 489 | M23: =J23+K23+L23 -> 34439 | N23: =IF((J23+K23)>0,L23/(J23+K23),"") -> 0.014403535
A25: Vietnam: marketing year Oct-Sep.
A26: Units: 1,000 60-kg bags (green bean equivalent); area in 1,000 ha; yield = production / area harvested (bags/ha).
A27: Balance: USDA FAS PSD Online, coffee (update of July 2026; 2026/27 = USDA June 2026 forecast). Total Supply = Beginning Stocks + Production + Imports; Total Distribution = Consumption + Exports + Ending Stocks; Stocks/Use = Ending Stocks / (Consumption + Exports).
A28: Consumption columns: USDA roast & ground and soluble domestic consumption (the coffee counterparts of Feed & Residual and FSI in the corn sheet).
A29: Area harvested: FAOSTAT (item 656 Coffee, green; official national data compiled by FAO, bulk release Dec 2025): calendar year Y shown in MY Y/Y+1 (Mexico and Uganda: Y-1/Y). USDA's PSD has no coffee area. Grey italics = latest FAO value carried forward (FAO ends with 2024).
A30: 2026/27 My Estimate: yellow cells with blue figures are your inputs (start = USDA June values): area, yield, imports, consumption (roast & ground, soluble) and exports. Production = area x yield; beginning stocks = 2025/26 ending stocks; ending stocks = supply - consumption - exports. Black = formulas; green = links to another sheet.
A31: Area carried forward from the last FAO year for 2025/26, 2026/27.
A32: 2026/27 (USDA attaché): post estimate of the USDA GAIN Coffee Annual VM2026-0016 (May 2026); its area is the post's harvested area where the report gives one.

Sheet Colombia
A1: Market Year | B1: Area Harvested (1,000 ha) | C1: Yield (bags/ha) | D1: Beginning Stocks | E1: Production | F1: MY Imports | G1: Total Supply (Official) | H1: Roast & Ground Consumption | I1: Soluble Consumption | J1: Total Consumption | K1: MY Exports | L1: Ending Stocks | M1: Total Distribution (Official) | N1: Stocks / Use Domestic + Exports
A2: 2010/11 | B2: 778.052 | C2: =IF(N(B2)>0,E2/B2,"") -> 10.956851 | D2: 284 | E2: 8525 | F2: 795 | G2: =D2+E2+F2 -> 9604 | H2: 820 | I2: 300 | J2: =H2+I2 -> 1120 | K2: 8385 | L2: 99 | M2: =J2+K2+L2 -> 9604 | N2: =IF((J2+K2)>0,L2/(J2+K2),"") -> 0.010415571
A3: 2011/12 | B3: 723.921 | C3: =IF(N(B3)>0,E3/B3,"") -> 10.574358 | D3: 99 | E3: 7655 | F3: 1115 | G3: =D3+E3+F3 -> 8869 | H3: 960 | I3: 300 | J3: =H3+I3 -> 1260 | K3: 7360 | L3: 249 | M3: =J3+K3+L3 -> 8869 | N3: =IF((J3+K3)>0,L3/(J3+K3),"") -> 0.028886311
A4: 2012/13 | B4: 696.023 | C4: =IF(N(B4)>0,E4/B4,"") -> 14.26246 | D4: 249 | E4: 9927 | F4: 650 | G4: =D4+E4+F4 -> 10826 | H4: 900 | I4: 300 | J4: =H4+I4 -> 1200 | K4: 8855 | L4: 771 | M4: =J4+K4+L4 -> 10826 | N4: =IF((J4+K4)>0,L4/(J4+K4),"") -> 0.07667827
A5: 2013/14 | B5: 771.725 | C5: =IF(N(B5)>0,E5/B5,"") -> 15.646765 | D5: 771 | E5: 12075 | F5: 455 | G5: =D5+E5+F5 -> 13301 | H5: 1000 | I5: 300 | J5: =H5+I5 -> 1300 | K5: 11040 | L5: 961 | M5: =J5+K5+L5 -> 13301 | N5: =IF((J5+K5)>0,L5/(J5+K5),"") -> 0.077876823
A6: 2014/15 | B6: 795.563 | C6: =IF(N(B6)>0,E6/B6,"") -> 16.717721 | D6: 961 | E6: 13300 | F6: 230 | G6: =D6+E6+F6 -> 14491 | H6: 1100 | I6: 300 | J6: =H6+I6 -> 1400 | K6: 12420 | L6: 671 | M6: =J6+K6+L6 -> 14491 | N6: =IF((J6+K6)>0,L6/(J6+K6),"") -> 0.048552822
A7: 2015/16 | B7: 801.118 | C7: =IF(N(B7)>0,E7/B7,"") -> 17.475578 | D7: 671 | E7: 14000 | F7: 265 | G7: =D7+E7+F7 -> 14936 | H7: 1065 | I7: 350 | J7: =H7+I7 -> 1415 | K7: 12390 | L7: 1131 | M7: =J7+K7+L7 -> 14936 | N7: =IF((J7+K7)>0,L7/(J7+K7),"") -> 0.081926838
A8: 2016/17 | B8: 778.362 | C8: =IF(N(B8)>0,E8/B8,"") -> 18.757339 | D8: 1131 | E8: 14600 | F8: 360 | G8: =D8+E8+F8 -> 16091 | H8: 1060 | I8: 390 | J8: =H8+I8 -> 1450 | K8: 13755 | L8: 886 | M8: =J8+K8+L8 -> 16091 | N8: =IF((J8+K8)>0,L8/(J8+K8),"") -> 0.058270306
A9: 2017/18 | B9: 903.95 | C9: =IF(N(B9)>0,E9/B9,"") -> 15.293987 | D9: 886 | E9: 13825 | F9: 775 | G9: =D9+E9+F9 -> 15486 | H9: 1200 | I9: 450 | J9: =H9+I9 -> 1650 | K9: 12725 | L9: 1111 | M9: =J9+K9+L9 -> 15486 | N9: =IF((J9+K9)>0,L9/(J9+K9),"") -> 0.077286957
A10: 2018/19 | B10: 877.14 | C10: =IF(N(B10)>0,E10/B10,"") -> 15.812755 | D10: 1111 | E10: 13870 | F10: 1111 | G10: =D10+E10+F10 -> 16092 | H10: 1475 | I10: 450 | J10: =H10+I10 -> 1925 | K10: 13615 | L10: 552 | M10: =J10+K10+L10 -> 16092 | N10: =IF((J10+K10)>0,L10/(J10+K10),"") -> 0.035521236
A11: 2019/20 | B11: 853.698 | C11: =IF(N(B11)>0,E11/B11,"") -> 16.516379 | D11: 552 | E11: 14100 | F11: 980 | G11: =D11+E11+F11 -> 15632 | H11: 1275 | I11: 500 | J11: =H11+I11 -> 1775 | K11: 13005 | L11: 852 | M11: =J11+K11+L11 -> 15632 | N11: =IF((J11+K11)>0,L11/(J11+K11),"") -> 0.057645467
A12: 2020/21 | B12: 844.744 | C12: =IF(N(B12)>0,E12/B12,"") -> 15.862794 | D12: 852 | E12: 13400 | F12: 1818 | G12: =D12+E12+F12 -> 16070 | H12: 1480 | I12: 600 | J12: =H12+I12 -> 2080 | K12: 12755 | L12: 1235 | M12: =J12+K12+L12 -> 16070 | N12: =IF((J12+K12)>0,L12/(J12+K12),"") -> 0.083249073
A13: 2021/22 | B13: 840.112 | C13: =IF(N(B13)>0,E13/B13,"") -> 14.045746 | D13: 1235 | E13: 11800 | F13: 2235 | G13: =D13+E13+F13 -> 15270 | H13: 1545 | I13: 600 | J13: =H13+I13 -> 2145 | K13: 12365 | L13: 760 | M13: =J13+K13+L13 -> 15270 | N13: =IF((J13+K13)>0,L13/(J13+K13),"") -> 0.052377671
... A21: 2026/27 (USDA attaché, May 2026) | B21: 640 | C21: =IF(N(B21)>0,E21/B21,"") -> 20.9375 | D21: 866 | E21: 13400 | F21: 2004 | G21: =D21+E21+F21 -> 16270 | H21: 1600 | I21: 600 | J21: =H21+I21 -> 2200 | K21: 13400 | L21: 670 | M21: =J21+K21+L21 -> 16270 | N21: =IF((J21+K21)>0,L21/(J21+K21),"") -> 0.042948718
A23: 2026/27 My Estimate | B23: 837.685 | C23: 15.996466 | D23: =L17 -> 866 | E23: =B23*C23 -> 13400 | F23: 2004 | G23: =D23+E23+F23 -> 16270 | H23: 1600 | I23: 600 | J23: =H23+I23 -> 2200 | K23: 13400 | L23: =G23-J23-K23 -> 670 | M23: =J23+K23+L23 -> 16270 | N23: =IF((J23+K23)>0,L23/(J23+K23),"") -> 0.042948718
A25: Colombia: marketing year Oct-Sep.
A26: Units: 1,000 60-kg bags (green bean equivalent); area in 1,000 ha; yield = production / area harvested (bags/ha).
A27: Balance: USDA FAS PSD Online, coffee (update of July 2026; 2026/27 = USDA June 2026 forecast). Total Supply = Beginning Stocks + Production + Imports; Total Distribution = Consumption + Exports + Ending Stocks; Stocks/Use = Ending Stocks / (Consumption + Exports).
A28: Consumption columns: USDA roast & ground and soluble domestic consumption (the coffee counterparts of Feed & Residual and FSI in the corn sheet).
A29: Area harvested: FAOSTAT (item 656 Coffee, green; official national data compiled by FAO, bulk release Dec 2025): calendar year Y shown in MY Y/Y+1 (Mexico and Uganda: Y-1/Y). USDA's PSD has no coffee area. Grey italics = latest FAO value carried forward (FAO ends with 2024).
A30: 2026/27 My Estimate: yellow cells with blue figures are your inputs (start = USDA June values): area, yield, imports, consumption (roast & ground, soluble) and exports. Production = area x yield; beginning stocks = 2025/26 ending stocks; ending stocks = supply - consumption - exports. Black = formulas; green = links to another sheet.
A31: Area carried forward from the last FAO year for 2025/26, 2026/27.
A32: 2026/27 (USDA attaché): post estimate of the USDA GAIN Coffee Annual CO2026-0008 (May 2026); its area is the post's harvested area where the report gives one.

Sheet Ethiopia
A1: Market Year | B1: Area Harvested (1,000 ha) | C1: Yield (bags/ha) | D1: Beginning Stocks | E1: Production | F1: MY Imports | G1: Total Supply (Official) | H1: Roast & Ground Consumption | I1: Soluble Consumption | J1: Total Consumption | K1: MY Exports | L1: Ending Stocks | M1: Total Distribution (Official) | N1: Stocks / Use Domestic + Exports
A2: 2010/11 | B2: 498.618 | C2: =IF(N(B2)>0,E2/B2,"") -> 12.283953 | D2: 70 | E2: 6125 | F2: 0 | G2: =D2+E2+F2 -> 6195 | H2: 2860 | I2: 0 | J2: =H2+I2 -> 2860 | K2: 3235 | L2: 100 | M2: =J2+K2+L2 -> 6195 | N2: =IF((J2+K2)>0,L2/(J2+K2),"") -> 0.016406891
A3: 2011/12 | B3: 580.44 | C3: =IF(N(B3)>0,E3/B3,"") -> 10.888292 | D3: 100 | E3: 6320 | F3: 0 | G3: =D3+E3+F3 -> 6420 | H3: 3050 | I3: 0 | J3: =H3+I3 -> 3050 | K3: 3140 | L3: 230 | M3: =J3+K3+L3 -> 6420 | N3: =IF((J3+K3)>0,L3/(J3+K3),"") -> 0.037156704
A4: 2012/13 | B4: 600.53 | C4: =IF(N(B4)>0,E4/B4,"") -> 10.823772 | D4: 230 | E4: 6500 | F4: 0 | G4: =D4+E4+F4 -> 6730 | H4: 3130 | I4: 0 | J4: =H4+I4 -> 3130 | K4: 3500 | L4: 100 | M4: =J4+K4+L4 -> 6730 | N4: =IF((J4+K4)>0,L4/(J4+K4),"") -> 0.015082956
A5: 2013/14 | B5: 538.466 | C5: =IF(N(B5)>0,E5/B5,"") -> 11.783474 | D5: 100 | E5: 6345 | F5: 0 | G5: =D5+E5+F5 -> 6445 | H5: 3120 | I5: 0 | J5: =H5+I5 -> 3120 | K5: 3285 | L5: 40 | M5: =J5+K5+L5 -> 6445 | N5: =IF((J5+K5)>0,L5/(J5+K5),"") -> 0.006245121
A6: 2014/15 | B6: 626.82 | C6: =IF(N(B6)>0,E6/B6,"") -> 10.329919 | D6: 40 | E6: 6475 | F6: 0 | G6: =D6+E6+F6 -> 6515 | H6: 2985 | I6: 0 | J6: =H6+I6 -> 2985 | K6: 3500 | L6: 30 | M6: =J6+K6+L6 -> 6515 | N6: =IF((J6+K6)>0,L6/(J6+K6),"") -> 0.0046260601
A7: 2015/16 | B7: 653.94 | C7: =IF(N(B7)>0,E7/B7,"") -> 9.9550417 | D7: 30 | E7: 6510 | F7: 0 | G7: =D7+E7+F7 -> 6540 | H7: 3110 | I7: 0 | J7: =H7+I7 -> 3110 | K7: 3405 | L7: 25 | M7: =J7+K7+L7 -> 6540 | N7: =IF((J7+K7)>0,L7/(J7+K7),"") -> 0.0038372985
A8: 2016/17 | B8: 761.209 | C8: =IF(N(B8)>0,E8/B8,"") -> 9.1210167 | D8: 25 | E8: 6943 | F8: 0 | G8: =D8+E8+F8 -> 6968 | H8: 3100 | I8: 0 | J8: =H8+I8 -> 3100 | K8: 3853 | L8: 15 | M8: =J8+K8+L8 -> 6968 | N8: =IF((J8+K8)>0,L8/(J8+K8),"") -> 0.0021573422
A9: 2017/18 | B9: 808.022 | C9: =IF(N(B9)>0,E9/B9,"") -> 8.7311979 | D9: 15 | E9: 7055 | F9: 0 | G9: =D9+E9+F9 -> 7070 | H9: 3150 | I9: 0 | J9: =H9+I9 -> 3150 | K9: 3893 | L9: 27 | M9: =J9+K9+L9 -> 7070 | N9: =IF((J9+K9)>0,L9/(J9+K9),"") -> 0.0038335936
A10: 2018/19 | B10: 871.707 | C10: =IF(N(B10)>0,E10/B10,"") -> 8.4317322 | D10: 27 | E10: 7350 | F10: 0 | G10: =D10+E10+F10 -> 7377 | H10: 3193 | I10: 0 | J10: =H10+I10 -> 3193 | K10: 4174 | L10: 10 | M10: =J10+K10+L10 -> 7377 | N10: =IF((J10+K10)>0,L10/(J10+K10),"") -> 0.0013574046
A11: 2019/20 | B11: 871.38 | C11: =IF(N(B11)>0,E11/B11,"") -> 8.578347 | D11: 10 | E11: 7475 | F11: 0 | G11: =D11+E11+F11 -> 7485 | H11: 3140 | I11: 0 | J11: =H11+I11 -> 3140 | K11: 4135 | L11: 210 | M11: =J11+K11+L11 -> 7485 | N11: =IF((J11+K11)>0,L11/(J11+K11),"") -> 0.028865979
A12: 2020/21 | B12: 856.592 | C12: =IF(N(B12)>0,E12/B12,"") -> 8.8723686 | D12: 210 | E12: 7600 | F12: 0 | G12: =D12+E12+F12 -> 7810 | H12: 3000 | I12: 0 | J12: =H12+I12 -> 3000 | K12: 4675 | L12: 135 | M12: =J12+K12+L12 -> 7810 | N12: =IF((J12+K12)>0,L12/(J12+K12),"") -> 0.017589577
A13: 2021/22 | B13: 912.17 | C13: =IF(N(B13)>0,E13/B13,"") -> 8.934738 | D13: 135 | E13: 8150 | F13: 0 | G13: =D13+E13+F13 -> 8285 | H13: 3364 | I13: 0 | J13: =H13+I13 -> 3364 | K13: 4831 | L13: 90 | M13: =J13+K13+L13 -> 8285 | N13: =IF((J13+K13)>0,L13/(J13+K13),"") -> 0.010982306
... A21: 2026/27 (USDA attaché, May 2026) | B21: 800 | C21: =IF(N(B21)>0,E21/B21,"") -> 15.125 | D21: 175 | E21: 12100 | F21: 0 | G21: =D21+E21+F21 -> 12275 | H21: 5000 | I21: 0 | J21: =H21+I21 -> 5000 | K21: 7130 | L21: 145 | M21: =J21+K21+L21 -> 12275 | N21: =IF((J21+K21)>0,L21/(J21+K21),"") -> 0.011953833
A23: 2026/27 My Estimate | B23: 862.943 | C23: 14.021784 | D23: =L17 -> 175 | E23: =B23*C23 -> 12100 | F23: 0 | G23: =D23+E23+F23 -> 12275 | H23: 5000 | I23: 0 | J23: =H23+I23 -> 5000 | K23: 7130 | L23: =G23-J23-K23 -> 145 | M23: =J23+K23+L23 -> 12275 | N23: =IF((J23+K23)>0,L23/(J23+K23),"") -> 0.011953833
A25: Ethiopia: marketing year Oct-Sep.
A26: Units: 1,000 60-kg bags (green bean equivalent); area in 1,000 ha; yield = production / area harvested (bags/ha).
A27: Balance: USDA FAS PSD Online, coffee (update of July 2026; 2026/27 = USDA June 2026 forecast). Total Supply = Beginning Stocks + Production + Imports; Total Distribution = Consumption + Exports + Ending Stocks; Stocks/Use = Ending Stocks / (Consumption + Exports).
A28: Consumption columns: USDA roast & ground and soluble domestic consumption (the coffee counterparts of Feed & Residual and FSI in the corn sheet).
A29: Area harvested: FAOSTAT (item 656 Coffee, green; official national data compiled by FAO, bulk release Dec 2025): calendar year Y shown in MY Y/Y+1 (Mexico and Uganda: Y-1/Y). USDA's PSD has no coffee area. Grey italics = latest FAO value carried forward (FAO ends with 2024).
A30: 2026/27 My Estimate: yellow cells with blue figures are your inputs (start = USDA June values): area, yield, imports, consumption (roast & ground, soluble) and exports. Production = area x yield; beginning stocks = 2025/26 ending stocks; ending stocks = supply - consumption - exports. Black = formulas; green = links to another sheet.
A31: FAO area estimated or imputed by FAO (flags E/I) for 2011/12, 2012/13, 2014/15, 2015/16, 2019/20, 2021/22, 2023/24, 2024/25.
A32: Area carried forward from the last FAO year for 2025/26, 2026/27.
A33: 2026/27 (USDA attaché): post estimate of the USDA GAIN Coffee Annual ET2026-0005 (May 2026); its area is the post's harvested area where the report gives one.

Sheet Indonesia
A1: Market Year | B1: Area Harvested (1,000 ha) | C1: Yield (bags/ha) | D1: Beginning Stocks | E1: Production | F1: MY Imports | G1: Total Supply (Official) | H1: Roast & Ground Consumption | I1: Soluble Consumption | J1: Total Consumption | K1: MY Exports | L1: Ending Stocks | M1: Total Distribution (Official) | N1: Stocks / Use Domestic + Exports
A2: 2010/11 | B2: 1268.476 | C2: =IF(N(B2)>0,E2/B2,"") -> 7.3513413 | D2: 1603 | E2: 9325 | F2: 535 | G2: =D2+E2+F2 -> 11463 | H2: 1175 | I2: 475 | J2: =H2+I2 -> 1650 | K2: 9730 | L2: 83 | M2: =J2+K2+L2 -> 11463 | N2: =IF((J2+K2)>0,L2/(J2+K2),"") -> 0.0072934974
A3: 2011/12 | B3: 1293 | C3: =IF(N(B3)>0,E3/B3,"") -> 6.1639598 | D3: 83 | E3: 7970 | F3: 1305 | G3: =D3+E3+F3 -> 9358 | H3: 1655 | I3: 470 | J3: =H3+I3 -> 2125 | K3: 7145 | L3: 88 | M3: =J3+K3+L3 -> 9358 | N3: =IF((J3+K3)>0,L3/(J3+K3),"") -> 0.0094929881
A4: 2012/13 | B4: 1233.9 | C4: =IF(N(B4)>0,E4/B4,"") -> 9.6442175 | D4: 88 | E4: 11900 | F4: 1250 | G4: =D4+E4+F4 -> 13238 | H4: 2170 | I4: 645 | J4: =H4+I4 -> 2815 | K4: 10325 | L4: 98 | M4: =J4+K4+L4 -> 13238 | N4: =IF((J4+K4)>0,L4/(J4+K4),"") -> 0.0074581431
A5: 2013/14 | B5: 1241.7 | C5: =IF(N(B5)>0,E5/B5,"") -> 9.5836353 | D5: 98 | E5: 11900 | F5: 970 | G5: =D5+E5+F5 -> 12968 | H5: 1930 | I5: 610 | J5: =H5+I5 -> 2540 | K5: 10380 | L5: 48 | M5: =J5+K5+L5 -> 12968 | N5: =IF((J5+K5)>0,L5/(J5+K5),"") -> 0.0037151703
A6: 2014/15 | B6: 1230.5 | C6: =IF(N(B6)>0,E6/B6,"") -> 8.5087363 | D6: 48 | E6: 10470 | F6: 1155 | G6: =D6+E6+F6 -> 11673 | H6: 2125 | I6: 775 | J6: =H6+I6 -> 2900 | K6: 8720 | L6: 53 | M6: =J6+K6+L6 -> 11673 | N6: =IF((J6+K6)>0,L6/(J6+K6),"") -> 0.0045611015
A7: 2015/16 | B7: 1230.001 | C7: =IF(N(B7)>0,E7/B7,"") -> 9.8373904 | D7: 53 | E7: 12100 | F7: 964 | G7: =D7+E7+F7 -> 13117 | H7: 2375 | I7: 800 | J7: =H7+I7 -> 3175 | K7: 9896 | L7: 46 | M7: =J7+K7+L7 -> 13117 | N7: =IF((J7+K7)>0,L7/(J7+K7),"") -> 0.0035192411
A8: 2016/17 | B8: 1228.512 | C8: =IF(N(B8)>0,E8/B8,"") -> 8.6283243 | D8: 46 | E8: 10600 | F8: 743 | G8: =D8+E8+F8 -> 11389 | H8: 2393 | I8: 810 | J8: =H8+I8 -> 3203 | K8: 8174 | L8: 12 | M8: =J8+K8+L8 -> 11389 | N8: =IF((J8+K8)>0,L8/(J8+K8),"") -> 0.0010547596
A9: 2017/18 | B9: 1238.598 | C9: =IF(N(B9)>0,E9/B9,"") -> 8.3965903 | D9: 12 | E9: 10400 | F9: 1751 | G9: =D9+E9+F9 -> 12163 | H9: 2650 | I9: 910 | J9: =H9+I9 -> 3560 | K9: 8010 | L9: 593 | M9: =J9+K9+L9 -> 12163 | N9: =IF((J9+K9)>0,L9/(J9+K9),"") -> 0.051253241
A10: 2018/19 | B10: 1252.826 | C10: =IF(N(B10)>0,E10/B10,"") -> 8.4608717 | D10: 593 | E10: 10600 | F10: 1676 | G10: =D10+E10+F10 -> 12869 | H10: 3100 | I10: 1200 | J10: =H10+I10 -> 4300 | K10: 6150 | L10: 2419 | M10: =J10+K10+L10 -> 12869 | N10: =IF((J10+K10)>0,L10/(J10+K10),"") -> 0.23148325
A11: 2019/20 | B11: 1245.359 | C11: =IF(N(B11)>0,E11/B11,"") -> 8.5919 | D11: 2419 | E11: 10700 | F11: 1231 | G11: =D11+E11+F11 -> 14350 | H11: 3400 | I11: 1500 | J11: =H11+I11 -> 4900 | K11: 7152 | L11: 2298 | M11: =J11+K11+L11 -> 14350 | N11: =IF((J11+K11)>0,L11/(J11+K11),"") -> 0.19067375
A12: 2020/21 | B12: 1250.452 | C12: =IF(N(B12)>0,E12/B12,"") -> 8.5569058 | D12: 2298 | E12: 10700 | F12: 993 | G12: =D12+E12+F12 -> 13991 | H12: 3000 | I12: 1450 | J12: =H12+I12 -> 4450 | K12: 7872 | L12: 1669 | M12: =J12+K12+L12 -> 13991 | N12: =IF((J12+K12)>0,L12/(J12+K12),"") -> 0.13544879
A13: 2021/22 | B13: 1279.57 | C13: =IF(N(B13)>0,E13/B13,"") -> 8.2684027 | D13: 1669 | E13: 10580 | F13: 985 | G13: =D13+E13+F13 -> 13234 | H13: 3250 | I13: 1500 | J13: =H13+I13 -> 4750 | K13: 7428 | L13: 1056 | M13: =J13+K13+L13 -> 13234 | N13: =IF((J13+K13)>0,L13/(J13+K13),"") -> 0.086713746
... A19: 2026/27 (USDA Jun 2026) | B19: 1269.354 | C19: =IF(N(B19)>0,E19/B19,"") -> 8.9651902 | D19: 751 | E19: 11380 | F19: 1420 | G19: =D19+E19+F19 -> 13551 | H19: 3280 | I19: 1550 | J19: =H19+I19 -> 4830 | K19: 8050 | L19: 671 | M19: =J19+K19+L19 -> 13551 | N19: =IF((J19+K19)>0,L19/(J19+K19),"") -> 0.052096273
A21: 2026/27 (USDA attaché, May 2026) | C21: =IF(N(B21)>0,E21/B21,"") | D21: 751 | E21: 11380 | F21: 1420 | G21: =D21+E21+F21 -> 13551 | H21: 3280 | I21: 1550 | J21: =H21+I21 -> 4830 | K21: 8050 | L21: 671 | M21: =J21+K21+L21 -> 13551 | N21: =IF((J21+K21)>0,L21/(J21+K21),"") -> 0.052096273
A23: 2026/27 My Estimate | B23: 1269.354 | C23: 8.9651902 | D23: =L17 -> 751 | E23: =B23*C23 -> 11380 | F23: 1420 | G23: =D23+E23+F23 -> 13551 | H23: 3280 | I23: 1550 | J23: =H23+I23 -> 4830 | K23: 8050 | L23: =G23-J23-K23 -> 671 | M23: =J23+K23+L23 -> 13551 | N23: =IF((J23+K23)>0,L23/(J23+K23),"") -> 0.052096273
A25: Indonesia: marketing year Apr-Mar.
A26: Units: 1,000 60-kg bags (green bean equivalent); area in 1,000 ha; yield = production / area harvested (bags/ha).
A27: Balance: USDA FAS PSD Online, coffee (update of July 2026; 2026/27 = USDA June 2026 forecast). Total Supply = Beginning Stocks + Production + Imports; Total Distribution = Consumption + Exports + Ending Stocks; Stocks/Use = Ending Stocks / (Consumption + Exports).
A28: Consumption columns: USDA roast & ground and soluble domestic consumption (the coffee counterparts of Feed & Residual and FSI in the corn sheet).
A29: Area harvested: FAOSTAT (item 656 Coffee, green; official national data compiled by FAO, bulk release Dec 2025): calendar year Y shown in MY Y/Y+1 (Mexico and Uganda: Y-1/Y). USDA's PSD has no coffee area. Grey italics = latest FAO value carried forward (FAO ends with 2024).
A30: 2026/27 My Estimate: yellow cells with blue figures are your inputs (start = USDA June values): area, yield, imports, consumption (roast & ground, soluble) and exports. Production = area x yield; beginning stocks = 2025/26 ending stocks; ending stocks = supply - consumption - exports. Black = formulas; green = links to another sheet.
A31: Area carried forward from the last FAO year for 2025/26, 2026/27.
A32: 2026/27 (USDA attaché): post estimate of the USDA GAIN Coffee Annual ID2026-0021 (May 2026); its area is the post's harvested area where the report gives one.

Sheet Uganda
A1: Market Year | B1: Area Harvested (1,000 ha) | C1: Yield (bags/ha) | D1: Beginning Stocks | E1: Production | F1: MY Imports | G1: Total Supply (Official) | H1: Roast & Ground Consumption | I1: Soluble Consumption | J1: Total Consumption | K1: MY Exports | L1: Ending Stocks | M1: Total Distribution (Official) | N1: Stocks / Use Domestic + Exports
A2: 2010/11 | B2: 317.08 | C2: =IF(N(B2)>0,E2/B2,"") -> 10.129936 | D2: 701 | E2: 3212 | F2: 0 | G2: =D2+E2+F2 -> 3913 | H2: 150 | I2: 0 | J2: =H2+I2 -> 150 | K2: 3150 | L2: 613 | M2: =J2+K2+L2 -> 3913 | N2: =IF((J2+K2)>0,L2/(J2+K2),"") -> 0.18575758
A3: 2011/12 | B3: 316.923 | C3: =IF(N(B3)>0,E3/B3,"") -> 9.7026723 | D3: 613 | E3: 3075 | F3: 0 | G3: =D3+E3+F3 -> 3688 | H3: 150 | I3: 0 | J3: =H3+I3 -> 150 | K3: 3000 | L3: 538 | M3: =J3+K3+L3 -> 3688 | N3: =IF((J3+K3)>0,L3/(J3+K3),"") -> 0.17079365
A4: 2012/13 | B4: 387.263 | C4: =IF(N(B4)>0,E4/B4,"") -> 9.2960081 | D4: 538 | E4: 3600 | F4: 0 | G4: =D4+E4+F4 -> 4138 | H4: 200 | I4: 0 | J4: =H4+I4 -> 200 | K4: 3575 | L4: 363 | M4: =J4+K4+L4 -> 4138 | N4: =IF((J4+K4)>0,L4/(J4+K4),"") -> 0.09615894
A5: 2013/14 | B5: 377.526 | C5: =IF(N(B5)>0,E5/B5,"") -> 10.197973 | D5: 363 | E5: 3850 | F5: 0 | G5: =D5+E5+F5 -> 4213 | H5: 220 | I5: 0 | J5: =H5+I5 -> 220 | K5: 3600 | L5: 393 | M5: =J5+K5+L5 -> 4213 | N5: =IF((J5+K5)>0,L5/(J5+K5),"") -> 0.10287958
A6: 2014/15 | B6: 432 | C6: =IF(N(B6)>0,E6/B6,"") -> 8.1018519 | D6: 393 | E6: 3500 | F6: 0 | G6: =D6+E6+F6 -> 3893 | H6: 230 | I6: 0 | J6: =H6+I6 -> 230 | K6: 3350 | L6: 313 | M6: =J6+K6+L6 -> 3893 | N6: =IF((J6+K6)>0,L6/(J6+K6),"") -> 0.087430168
A7: 2015/16 | B7: 434.283 | C7: =IF(N(B7)>0,E7/B7,"") -> 8.1743932 | D7: 313 | E7: 3550 | F7: 0 | G7: =D7+E7+F7 -> 3863 | H7: 250 | I7: 0 | J7: =H7+I7 -> 250 | K7: 3300 | L7: 313 | M7: =J7+K7+L7 -> 3863 | N7: =IF((J7+K7)>0,L7/(J7+K7),"") -> 0.088169014
A8: 2016/17 | B8: 526.491 | C8: =IF(N(B8)>0,E8/B8,"") -> 9.2594175 | D8: 313 | E8: 4875 | F8: 0 | G8: =D8+E8+F8 -> 5188 | H8: 250 | I8: 0 | J8: =H8+I8 -> 250 | K8: 4600 | L8: 338 | M8: =J8+K8+L8 -> 5188 | N8: =IF((J8+K8)>0,L8/(J8+K8),"") -> 0.069690722
A9: 2017/18 | B9: 497.192 | C9: =IF(N(B9)>0,E9/B9,"") -> 9.251959 | D9: 338 | E9: 4600 | F9: 0 | G9: =D9+E9+F9 -> 4938 | H9: 250 | I9: 0 | J9: =H9+I9 -> 250 | K9: 4300 | L9: 388 | M9: =J9+K9+L9 -> 4938 | N9: =IF((J9+K9)>0,L9/(J9+K9),"") -> 0.085274725
A10: 2018/19 | B10: 541.495 | C10: =IF(N(B10)>0,E10/B10,"") -> 8.5873369 | D10: 388 | E10: 4650 | F10: 0 | G10: =D10+E10+F10 -> 5038 | H10: 250 | I10: 0 | J10: =H10+I10 -> 250 | K10: 4450 | L10: 338 | M10: =J10+K10+L10 -> 5038 | N10: =IF((J10+K10)>0,L10/(J10+K10),"") -> 0.071914894
A11: 2019/20 | B11: 632.691 | C11: =IF(N(B11)>0,E11/B11,"") -> 8.6535133 | D11: 338 | E11: 5475 | F11: 0 | G11: =D11+E11+F11 -> 5813 | H11: 100 | I11: 0 | J11: =H11+I11 -> 100 | K11: 5350 | L11: 363 | M11: =J11+K11+L11 -> 5813 | N11: =IF((J11+K11)>0,L11/(J11+K11),"") -> 0.066605505
A12: 2020/21 | B12: 737.884 | C12: =IF(N(B12)>0,E12/B12,"") -> 8.9851521 | D12: 363 | E12: 6630 | F12: 0 | G12: =D12+E12+F12 -> 6993 | H12: 100 | I12: 0 | J12: =H12+I12 -> 100 | K12: 6514 | L12: 379 | M12: =J12+K12+L12 -> 6993 | N12: =IF((J12+K12)>0,L12/(J12+K12),"") -> 0.057302691
A13: 2021/22 | B13: 912.315 | C13: =IF(N(B13)>0,E13/B13,"") -> 6.6314815 | D13: 379 | E13: 6050 | F13: 0 | G13: =D13+E13+F13 -> 6429 | H13: 125 | I13: 0 | J13: =H13+I13 -> 125 | K13: 5850 | L13: 454 | M13: =J13+K13+L13 -> 6429 | N13: =IF((J13+K13)>0,L13/(J13+K13),"") -> 0.075983264
... A21: 2026/27 (USDA attaché, May 2026) | B21: 580 | C21: =IF(N(B21)>0,E21/B21,"") -> 12.344828 | D21: 334 | E21: 7160 | F21: 0 | G21: =D21+E21+F21 -> 7494 | H21: 335 | I21: 0 | J21: =H21+I21 -> 335 | K21: 6830 | L21: 329 | M21: =J21+K21+L21 -> 7494 | N21: =IF((J21+K21)>0,L21/(J21+K21),"") -> 0.045917655
A23: 2026/27 My Estimate | B23: 736.547 | C23: 9.7210361 | D23: =L17 -> 334 | E23: =B23*C23 -> 7160 | F23: 0 | G23: =D23+E23+F23 -> 7494 | H23: 335 | I23: 0 | J23: =H23+I23 -> 335 | K23: 6830 | L23: =G23-J23-K23 -> 329 | M23: =J23+K23+L23 -> 7494 | N23: =IF((J23+K23)>0,L23/(J23+K23),"") -> 0.045917655
A25: Uganda: marketing year Oct-Sep.
A26: Units: 1,000 60-kg bags (green bean equivalent); area in 1,000 ha; yield = production / area harvested (bags/ha).
A27: Balance: USDA FAS PSD Online, coffee (update of July 2026; 2026/27 = USDA June 2026 forecast). Total Supply = Beginning Stocks + Production + Imports; Total Distribution = Consumption + Exports + Ending Stocks; Stocks/Use = Ending Stocks / (Consumption + Exports).
A28: Consumption columns: USDA roast & ground and soluble domestic consumption (the coffee counterparts of Feed & Residual and FSI in the corn sheet).
A29: Area harvested: FAOSTAT (item 656 Coffee, green; official national data compiled by FAO, bulk release Dec 2025): calendar year Y shown in MY Y/Y+1 (Mexico and Uganda: Y-1/Y). USDA's PSD has no coffee area. Grey italics = latest FAO value carried forward (FAO ends with 2024).
A30: 2026/27 My Estimate: yellow cells with blue figures are your inputs (start = USDA June values): area, yield, imports, consumption (roast & ground, soluble) and exports. Production = area x yield; beginning stocks = 2025/26 ending stocks; ending stocks = supply - consumption - exports. Black = formulas; green = links to another sheet.
A31: FAO area estimated or imputed by FAO (flags E/I) for 2010/11, 2011/12, 2012/13, 2013/14, 2014/15, 2015/16, 2016/17, 2017/18, 2018/19, 2019/20, 2020/21, 2021/22, 2022/23, 2023/24.
A32: Area carried forward from the last FAO year for 2024/25, 2025/26, 2026/27.
A33: 2026/27 (USDA attaché): post estimate of the USDA GAIN Coffee Annual UG2026-0001 (May 2026); its area is the post's harvested area where the report gives one.

Sheet Honduras
A1: Market Year | B1: Area Harvested (1,000 ha) | C1: Yield (bags/ha) | D1: Beginning Stocks | E1: Production | F1: MY Imports | G1: Total Supply (Official) | H1: Roast & Ground Consumption | I1: Soluble Consumption | J1: Total Consumption | K1: MY Exports | L1: Ending Stocks | M1: Total Distribution (Official) | N1: Stocks / Use Domestic + Exports
A2: 2010/11 | B2: 313.429 | C2: =IF(N(B2)>0,E2/B2,"") -> 12.682298 | D2: 218 | E2: 3975 | F2: 23 | G2: =D2+E2+F2 -> 4216 | H2: 271 | I2: 15 | J2: =H2+I2 -> 286 | K2: 3900 | L2: 30 | M2: =J2+K2+L2 -> 4216 | N2: =IF((J2+K2)>0,L2/(J2+K2),"") -> 0.0071667463
A3: 2011/12 | B3: 328.375 | C3: =IF(N(B3)>0,E3/B3,"") -> 17.053673 | D3: 30 | E3: 5600 | F3: 15 | G3: =D3+E3+F3 -> 5645 | H3: 250 | I3: 15 | J3: =H3+I3 -> 265 | K3: 5290 | L3: 90 | M3: =J3+K3+L3 -> 5645 | N3: =IF((J3+K3)>0,L3/(J3+K3),"") -> 0.01620162
A4: 2012/13 | B4: 347.065 | C4: =IF(N(B4)>0,E4/B4,"") -> 13.614164 | D4: 90 | E4: 4725 | F4: 15 | G4: =D4+E4+F4 -> 4830 | H4: 195 | I4: 15 | J4: =H4+I4 -> 210 | K4: 4480 | L4: 140 | M4: =J4+K4+L4 -> 4830 | N4: =IF((J4+K4)>0,L4/(J4+K4),"") -> 0.029850746
A5: 2013/14 | B5: 285.471 | C5: =IF(N(B5)>0,E5/B5,"") -> 15.413124 | D5: 140 | E5: 4400 | F5: 15 | G5: =D5+E5+F5 -> 4555 | H5: 300 | I5: 15 | J5: =H5+I5 -> 315 | K5: 3940 | L5: 300 | M5: =J5+K5+L5 -> 4555 | N5: =IF((J5+K5)>0,L5/(J5+K5),"") -> 0.070505288
A6: 2014/15 | B6: 270 | C6: =IF(N(B6)>0,E6/B6,"") -> 18.888889 | D6: 300 | E6: 5100 | F6: 20 | G6: =D6+E6+F6 -> 5420 | H6: 300 | I6: 20 | J6: =H6+I6 -> 320 | K6: 4760 | L6: 340 | M6: =J6+K6+L6 -> 5420 | N6: =IF((J6+K6)>0,L6/(J6+K6),"") -> 0.066929134
A7: 2015/16 | B7: 270 | C7: =IF(N(B7)>0,E7/B7,"") -> 19.62963 | D7: 340 | E7: 5300 | F7: 20 | G7: =D7+E7+F7 -> 5660 | H7: 325 | I7: 20 | J7: =H7+I7 -> 345 | K7: 5000 | L7: 315 | M7: =J7+K7+L7 -> 5660 | N7: =IF((J7+K7)>0,L7/(J7+K7),"") -> 0.058933583
A8: 2016/17 | B8: 309.806 | C8: =IF(N(B8)>0,E8/B8,"") -> 24.240977 | D8: 315 | E8: 7510 | F8: 25 | G8: =D8+E8+F8 -> 7850 | H8: 350 | I8: 25 | J8: =H8+I8 -> 375 | K8: 7175 | L8: 300 | M8: =J8+K8+L8 -> 7850 | N8: =IF((J8+K8)>0,L8/(J8+K8),"") -> 0.039735099
A9: 2017/18 | B9: 423.676 | C9: =IF(N(B9)>0,E9/B9,"") -> 17.938236 | D9: 300 | E9: 7600 | F9: 25 | G9: =D9+E9+F9 -> 7925 | H9: 350 | I9: 25 | J9: =H9+I9 -> 375 | K9: 7225 | L9: 325 | M9: =J9+K9+L9 -> 7925 | N9: =IF((J9+K9)>0,L9/(J9+K9),"") -> 0.042763158
A10: 2018/19 | B10: 431.122 | C10: =IF(N(B10)>0,E10/B10,"") -> 16.468656 | D10: 325 | E10: 7100 | F10: 12 | G10: =D10+E10+F10 -> 7437 | H10: 346 | I10: 19 | J10: =H10+I10 -> 365 | K10: 6910 | L10: 162 | M10: =J10+K10+L10 -> 7437 | N10: =IF((J10+K10)>0,L10/(J10+K10),"") -> 0.022268041
A11: 2019/20 | B11: 424.739 | C11: =IF(N(B11)>0,E11/B11,"") -> 12.242813 | D11: 162 | E11: 5200 | F11: 28 | G11: =D11+E11+F11 -> 5390 | H11: 346 | I11: 20 | J11: =H11+I11 -> 366 | K11: 4900 | L11: 124 | M11: =J11+K11+L11 -> 5390 | N11: =IF((J11+K11)>0,L11/(J11+K11),"") -> 0.023547284
A12: 2020/21 | B12: 323.457 | C12: =IF(N(B12)>0,E12/B12,"") -> 20.095407 | D12: 124 | E12: 6500 | F12: 24 | G12: =D12+E12+F12 -> 6648 | H12: 348 | I12: 21 | J12: =H12+I12 -> 369 | K12: 6010 | L12: 269 | M12: =J12+K12+L12 -> 6648 | N12: =IF((J12+K12)>0,L12/(J12+K12),"") -> 0.042169619
A13: 2021/22 | B13: 358.284 | C13: =IF(N(B13)>0,E13/B13,"") -> 13.397193 | D13: 269 | E13: 4800 | F13: 21 | G13: =D13+E13+F13 -> 5090 | H13: 351 | I13: 22 | J13: =H13+I13 -> 373 | K13: 4650 | L13: 67 | M13: =J13+K13+L13 -> 5090 | N13: =IF((J13+K13)>0,L13/(J13+K13),"") -> 0.013338642
... A21: 2026/27 (USDA attaché, Apr 2026) | B21: 330 | C21: =IF(N(B21)>0,E21/B21,"") -> 18.272727 | D21: 435 | E21: 6030 | F21: 160 | G21: =D21+E21+F21 -> 6625 | H21: 380 | I21: 35 | J21: =H21+I21 -> 415 | K21: 5503 | L21: 707 | M21: =J21+K21+L21 -> 6625 | N21: =IF((J21+K21)>0,L21/(J21+K21),"") -> 0.11946604
A23: 2026/27 My Estimate | B23: 266.728 | C23: 22.6073 | D23: =L17 -> 435 | E23: =B23*C23 -> 6030 | F23: 160 | G23: =D23+E23+F23 -> 6625 | H23: 380 | I23: 35 | J23: =H23+I23 -> 415 | K23: 5503 | L23: =G23-J23-K23 -> 707 | M23: =J23+K23+L23 -> 6625 | N23: =IF((J23+K23)>0,L23/(J23+K23),"") -> 0.11946604
A25: Honduras: marketing year Oct-Sep.
A26: Units: 1,000 60-kg bags (green bean equivalent); area in 1,000 ha; yield = production / area harvested (bags/ha).
A27: Balance: USDA FAS PSD Online, coffee (update of July 2026; 2026/27 = USDA June 2026 forecast). Total Supply = Beginning Stocks + Production + Imports; Total Distribution = Consumption + Exports + Ending Stocks; Stocks/Use = Ending Stocks / (Consumption + Exports).
A28: Consumption columns: USDA roast & ground and soluble domestic consumption (the coffee counterparts of Feed & Residual and FSI in the corn sheet).
A29: Area harvested: FAOSTAT (item 656 Coffee, green; official national data compiled by FAO, bulk release Dec 2025): calendar year Y shown in MY Y/Y+1 (Mexico and Uganda: Y-1/Y). USDA's PSD has no coffee area. Grey italics = latest FAO value carried forward (FAO ends with 2024).
A30: 2026/27 My Estimate: yellow cells with blue figures are your inputs (start = USDA June values): area, yield, imports, consumption (roast & ground, soluble) and exports. Production = area x yield; beginning stocks = 2025/26 ending stocks; ending stocks = supply - consumption - exports. Black = formulas; green = links to another sheet.
A31: FAO area estimated or imputed by FAO (flags E/I) for 2013/14, 2016/17, 2017/18, 2018/19, 2019/20, 2020/21, 2021/22, 2022/23, 2023/24, 2024/25.
A32: Area carried forward from the last FAO year for 2025/26, 2026/27.
A33: 2026/27 (USDA attaché): post estimate of the USDA GAIN Coffee Annual HO2026-0002 (Apr 2026); its area is the post's harvested area where the report gives one.

Sheet Others
A1: Market Year | B1: Area Harvested (1,000 ha) | C1: Yield (bags/ha) | D1: Beginning Stocks | E1: Production | F1: MY Imports | G1: Total Supply (Official) | H1: Roast & Ground Consumption | I1: Soluble Consumption | J1: Total Consumption | K1: MY Exports | L1: Ending Stocks | M1: Total Distribution (Official) | N1: Stocks / Use Domestic + Exports
A2: 2010/11 | B2: 4494.079 | C2: =IF(N(B2)>0,E2/B2,"") -> 8.0844151 | D2: 22121 | E2: 36332 | F2: 109163 | G2: =D2+E2+F2 -> 167616 | H2: 92398 | I2: 16287 | J2: =H2+I2 -> 108685 | K2: 34922 | L2: 24009 | M2: =J2+K2+L2 -> 167616 | N2: =IF((J2+K2)>0,L2/(J2+K2),"") -> 0.16718544
A3: 2011/12 | B3: 3882.53 | C3: =IF(N(B3)>0,E3/B3,"") -> 10.049375 | D3: 24009 | E3: 39017 | F3: 110248 | G3: =D3+E3+F3 -> 173274 | H3: 97808 | I3: 16483 | J3: =H3+I3 -> 114291 | K3: 37758 | L3: 21225 | M3: =J3+K3+L3 -> 173274 | N3: =IF((J3+K3)>0,L3/(J3+K3),"") -> 0.13959316
A4: 2012/13 | B4: 4306.336 | C4: =IF(N(B4)>0,E4/B4,"") -> 8.6537604 | D4: 21225 | E4: 37266 | F4: 115499 | G4: =D4+E4+F4 -> 173990 | H4: 96265 | I4: 17645 | J4: =H4+I4 -> 113910 | K4: 37201 | L4: 22879 | M4: =J4+K4+L4 -> 173990 | N4: =IF((J4+K4)>0,L4/(J4+K4),"") -> 0.15140526
A5: 2013/14 | B5: 4353.757 | C5: =IF(N(B5)>0,E5/B5,"") -> 7.9129359 | D5: 22879 | E5: 34451 | F5: 116780 | G5: =D5+E5+F5 -> 174110 | H5: 96997 | I5: 17167 | J5: =H5+I5 -> 114164 | K5: 34580 | L5: 25366 | M5: =J5+K5+L5 -> 174110 | N5: =IF((J5+K5)>0,L5/(J5+K5),"") -> 0.17053461
A6: 2014/15 | B6: 4336.003 | C6: =IF(N(B6)>0,E6/B6,"") -> 7.6685833 | D6: 25366 | E6: 33251 | F6: 117295 | G6: =D6+E6+F6 -> 175912 | H6: 99097 | I6: 17594 | J6: =H6+I6 -> 116691 | K6: 33137 | L6: 26084 | M6: =J6+K6+L6 -> 175912 | N6: =IF((J6+K6)>0,L6/(J6+K6),"") -> 0.17409296
A7: 2015/16 | B7: 4979.162 | C7: =IF(N(B7)>0,E7/B7,"") -> 6.5551191 | D7: 26084 | E7: 32639 | F7: 124477 | G7: =D7+E7+F7 -> 183200 | H7: 101043 | I7: 20363 | J7: =H7+I7 -> 121406 | K7: 35246 | L7: 26548 | M7: =J7+K7+L7 -> 183200 | N7: =IF((J7+K7)>0,L7/(J7+K7),"") -> 0.16947118
A8: 2016/17 | B8: 4890.804 | C8: =IF(N(B8)>0,E8/B8,"") -> 6.9009104 | D8: 26548 | E8: 33751 | F8: 126943 | G8: =D8+E8+F8 -> 187242 | H8: 100222 | I8: 22109 | J8: =H8+I8 -> 122331 | K8: 36518 | L8: 28393 | M8: =J8+K8+L8 -> 187242 | N8: =IF((J8+K8)>0,L8/(J8+K8),"") -> 0.17874208
A9: 2017/18 | B9: 4332.203 | C9: =IF(N(B9)>0,E9/B9,"") -> 8.0637957 | D9: 28393 | E9: 34934 | F9: 126813 | G9: =D9+E9+F9 -> 190140 | H9: 105417 | I9: 20925 | J9: =H9+I9 -> 126342 | K9: 37660 | L9: 26138 | M9: =J9+K9+L9 -> 190140 | N9: =IF((J9+K9)>0,L9/(J9+K9),"") -> 0.15937611
A10: 2018/19 | B10: 5395.507 | C10: =IF(N(B10)>0,E10/B10,"") -> 6.5584198 | D10: 26138 | E10: 35386 | F10: 134480 | G10: =D10+E10+F10 -> 196004 | H10: 108961 | I10: 20869 | J10: =H10+I10 -> 129830 | K10: 38321 | L10: 27853 | M10: =J10+K10+L10 -> 196004 | N10: =IF((J10+K10)>0,L10/(J10+K10),"") -> 0.16564279
A11: 2019/20 | B11: 4935.8 | C11: =IF(N(B11)>0,E11/B11,"") -> 6.9451761 | D11: 27853 | E11: 34280 | F11: 128182 | G11: =D11+E11+F11 -> 190315 | H11: 104344 | I11: 21636 | J11: =H11+I11 -> 125980 | K11: 36877 | L11: 27458 | M11: =J11+K11+L11 -> 190315 | N11: =IF((J11+K11)>0,L11/(J11+K11),"") -> 0.1686019
A12: 2020/21 | B12: 4702.924 | C12: =IF(N(B12)>0,E12/B12,"") -> 6.987993 | D12: 27458 | E12: 32864 | F12: 128669 | G12: =D12+E12+F12 -> 188991 | H12: 106218 | I12: 20876 | J12: =H12+I12 -> 127094 | K12: 36140 | L12: 25757 | M12: =J12+K12+L12 -> 188991 | N12: =IF((J12+K12)>0,L12/(J12+K12),"") -> 0.15779188
A13: 2021/22 | B13: 4684.185 | C13: =IF(N(B13)>0,E13/B13,"") -> 7.2550508 | D13: 25757 | E13: 33984 | F13: 136995 | G13: =D13+E13+F13 -> 196736 | H13: 108461 | I13: 23118 | J13: =H13+I13 -> 131579 | K13: 39764 | L13: 25393 | M13: =J13+K13+L13 -> 196736 | N13: =IF((J13+K13)>0,L13/(J13+K13),"") -> 0.14819981
... A19: 2026/27 (USDA Jun 2026) | B19: 4766.369 | C19: =IF(N(B19)>0,E19/B19,"") -> 7.3844472 | D19: 17225 | E19: 35197 | F19: 145932 | G19: =D19+E19+F19 -> 198354 | H19: 113831 | I19: 25735 | J19: =H19+I19 -> 139566 | K19: 39941 | L19: 18847 | M19: =J19+K19+L19 -> 198354 | N19: =IF((J19+K19)>0,L19/(J19+K19),"") -> 0.10499312
A23: 2026/27 My Estimate | B23: =World!D63-Brazil!B23-Vietnam!B23-Colombia!B23-Indonesia!B23-Ethiopia!B23-Uganda!B23-Honduras!B23 -> 4766.369 | C23: =IF(N(B23)>0,E23/B23,"") -> 7.3844472 | D23: =World!C63-Brazil!D23-Vietnam!D23-Colombia!D23-Indonesia!D23-Ethiopia!D23-Uganda!D23-Honduras!D23 -> 17225 | E23: =World!F63-Brazil!E23-Vietnam!E23-Colombia!E23-Indonesia!E23-Ethiopia!E23-Uganda!E23-Honduras!E23 -> 35197 | F23: =World!G63-Brazil!F23-Vietnam!F23-Colombia!F23-Indonesia!F23-Ethiopia!F23-Uganda!F23-Honduras!F23 -> 145932 | G23: =D23+E23+F23 -> 198354 | H23: =World!J63-Brazil!H23-Vietnam!H23-Colombia!H23-Indonesia!H23-Ethiopia!H23-Uganda!H23-Honduras!H23 -> 113831 | I23: =World!K63-Brazil!I23-Vietnam!I23-Colombia!I23-Indonesia!I23-Ethiopia!I23-Uganda!I23-Honduras!I23 -> 25735 | J23: =H23+I23 -> 139566 | K23: =World!I63-Brazil!K23-Vietnam!K23-Colombia!K23-Indonesia!K23-Ethiopia!K23-Uganda!K23-Honduras!K23 -> 39941 | L23: =World!M63-Brazil!L23-Vietnam!L23-Colombia!L23-Indonesia!L23-Ethiopia!L23-Uganda!L23-Honduras!L23 -> 18847 | M23: =J23+K23+L23 -> 198354 | N23: =IF((J23+K23)>0,L23/(J23+K23),"") -> 0.10499312
A25: Others: all USDA PSD countries except Brazil, Vietnam, Colombia, Indonesia, Ethiopia, Uganda and Honduras (= World - the seven countries); local marketing years.
A26: Units: 1,000 60-kg bags (green bean equivalent); area in 1,000 ha; yield = production / area harvested (bags/ha).
A27: Balance: USDA FAS PSD Online, coffee (update of July 2026; 2026/27 = USDA June 2026 forecast). Total Supply = Beginning Stocks + Production + Imports; Total Distribution = Consumption + Exports + Ending Stocks; Stocks/Use = Ending Stocks / (Consumption + Exports).
A28: Consumption columns: USDA roast & ground and soluble domestic consumption (the coffee counterparts of Feed & Residual and FSI in the corn sheet).
A29: Area harvested: FAOSTAT (item 656 Coffee, green; official national data compiled by FAO, bulk release Dec 2025): calendar year Y shown in MY Y/Y+1 (Mexico and Uganda: Y-1/Y). USDA's PSD has no coffee area. Grey italics = latest FAO value carried forward (FAO ends with 2024).
A30: 2026/27 My Estimate: yellow cells with blue figures are your inputs (start = USDA June values): area, yield, imports, consumption (roast & ground, soluble) and exports. Production = area x yield; beginning stocks = 2025/26 ending stocks; ending stocks = supply - consumption - exports. Black = formulas; green = links to another sheet.
A31: 2026/27 My Estimate for Others = World sheet estimate minus the seven country sheets (edit the Others / importer / China rows of the World sheet to change it).

Sheet World
A1: 市场年度 Market Year | B1: 区域 Region | C1: 期初库存 Beginning Stocks (1,000 60-kg bags) | D1: 收获面积 Area Harvested (1,000 ha) | E1: 单产 Yield (bags/ha) | F1: 产量 Production (1,000 60-kg bags) | G1: 市场年度进口 MY Imports (1,000 60-kg bags) | H1: 总供应 Total Supply (1,000 60-kg bags) | I1: 市场年度出口 MY Exports (1,000 60-kg bags) | J1: 烘焙及研磨咖啡消费 Roast & Ground Consumption (1,000 60-kg bags) | K1: 速溶咖啡消费 Soluble Consumption (1,000 60-kg bags) | L1: 国内消费 Domestic Consumption (1,000 60-kg bags) | M1: 期末库存 Ending Stocks (1,000 60-kg bags) | N1: 总分配 Total Distribution (1,000 60-kg bags) | O1: 库存使用比 Stocks / Use (Domestic + Exports)
A2: 2010/11 | B2: World | C2: 28845 | D2: 10341.419 | E2: =IF(N(D2)>0,F2/D2,"") -> 13.674042 | F2: 141409 | G2: 110866 | H2: =C2+F2+G2 -> 281120 | I2: 116972 | J2: 117204 | K2: 18304 | L2: =J2+K2 -> 135508 | M2: 28640 | N2: =I2+L2+M2 -> 281120 | O2: =IF((L2+I2)>0,M2/(L2+I2),"") -> 0.11343473
A3: 2011/12 | B3: World | C3: 28640 | D3: 9817.829 | E3: =IF(N(D3)>0,F3/D3,"") -> 14.752447 | F3: 144837 | G3: 113133 | H3: =C3+F3+G3 -> 286610 | I3: 118031 | J3: 124258 | K3: 18573 | L3: =J3+K3 -> 142831 | M3: 25748 | N3: =I3+L3+M3 -> 286610 | O3: =IF((L3+I3)>0,M3/(L3+I3),"") -> 0.098703529
A4: 2012/13 | B4: World | C4: 25748 | D4: 10263.797 | E4: =IF(N(D4)>0,F4/D4,"") -> 15.395667 | F4: 158018 | G4: 118238 | H4: =C4+F4+G4 -> 302004 | I4: 123239 | J4: 123485 | K4: 19915 | L4: =J4+K4 -> 143400 | M4: 35365 | N4: =I4+L4+M4 -> 302004 | O4: =IF((L4+I4)>0,M4/(L4+I4),"") -> 0.13263251
A5: 2013/14 | B5: World | C5: 35365 | D5: 10235.548 | E5: =IF(N(D5)>0,F5/D5,"") -> 15.637072 | F5: 160054 | G5: 118902 | H5: =C5+F5+G5 -> 314321 | I5: 129260 | J5: 124485 | K5: 19392 | L5: =J5+K5 -> 143877 | M5: 41184 | N5: =I5+L5+M5 -> 314321 | O5: =IF((L5+I5)>0,M5/(L5+I5),"") -> 0.15078148
A6: 2014/15 | B6: World | C6: 41184 | D6: 10277.754 | E6: =IF(N(D6)>0,F6/D6,"") -> 14.96397 | F6: 153796 | G6: 119342 | H6: =C6+F6+G6 -> 314322 | I6: 124027 | J6: 127079 | K6: 20084 | L6: =J6+K6 -> 147163 | M6: 43132 | N6: =I6+L6+M6 -> 314322 | O6: =IF((L6+I6)>0,M6/(L6+I6),"") -> 0.15904716
A7: 2015/16 | B7: World | C7: 43132 | D7: 10940.018 | E7: =IF(N(D7)>0,F7/D7,"") -> 13.933158 | F7: 152429 | G7: 126421 | H7: =C7+F7+G7 -> 321982 | I7: 133845 | J7: 130198 | K7: 22988 | L7: =J7+K7 -> 153186 | M7: 34951 | N7: =I7+L7+M7 -> 321982 | O7: =IF((L7+I7)>0,M7/(L7+I7),"") -> 0.12176734
A8: 2016/17 | B8: World | C8: 34951 | D8: 11089.385 | E8: =IF(N(D8)>0,F8/D8,"") -> 14.525512 | F8: 161079 | G8: 129133 | H8: =C8+F8+G8 -> 325163 | I8: 133606 | J8: 130275 | K8: 24829 | L8: =J8+K8 -> 155104 | M8: 36453 | N8: =I8+L8+M8 -> 325163 | O8: =IF((L8+I8)>0,M8/(L8+I8),"") -> 0.12626165
A9: 2017/18 | B9: World | C9: 36453 | D9: 10611.236 | E9: =IF(N(D9)>0,F9/D9,"") -> 15.060828 | F9: 159814 | G9: 130485 | H9: =C9+F9+G9 -> 326752 | I9: 134174 | J9: 136792 | K9: 23835 | L9: =J9+K9 -> 160627 | M9: 31951 | N9: =I9+L9+M9 -> 326752 | O9: =IF((L9+I9)>0,M9/(L9+I9),"") -> 0.10838159
A10: 2018/19 | B10: World | C10: 31951 | D10: 11852.642 | E10: =IF(N(D10)>0,F10/D10,"") -> 14.836861 | F10: 175856 | G10: 138506 | H10: =C10+F10+G10 -> 346313 | I10: 143364 | J10: 141895 | K10: 24108 | L10: =J10+K10 -> 166003 | M10: 36946 | N10: =I10+L10+M10 -> 346313 | O10: =IF((L10+I10)>0,M10/(L10+I10),"") -> 0.1194245
A11: 2019/20 | B11: World | C11: 36946 | D11: 11413.05 | E11: =IF(N(D11)>0,F11/D11,"") -> 14.810239 | F11: 169030 | G11: 131188 | H11: =C11+F11+G11 -> 337164 | I11: 139001 | J11: 137270 | K11: 25085 | L11: =J11+K11 -> 162355 | M11: 35808 | N11: =I11+L11+M11 -> 337164 | O11: =IF((L11+I11)>0,M11/(L11+I11),"") -> 0.11882292
A12: 2020/21 | B12: World | C12: 35808 | D12: 11252.045 | E12: =IF(N(D12)>0,F12/D12,"") -> 15.694392 | F12: 176594 | G12: 132126 | H12: =C12+F12+G12 -> 344528 | I12: 144941 | J12: 137716 | K12: 24377 | L12: =J12+K12 -> 162093 | M12: 37494 | N12: =I12+L12+M12 -> 344528 | O12: =IF((L12+I12)>0,M12/(L12+I12),"") -> 0.12211677
A13: 2021/22 | B13: World | C13: 37494 | D13: 11472.336 | E13: =IF(N(D13)>0,F13/D13,"") -> 14.386259 | F13: 165044 | G13: 140861 | H13: =C13+F13+G13 -> 343399 | I13: 143583 | J13: 141146 | K13: 26730 | L13: =J13+K13 -> 167876 | M13: 31940 | N13: =I13+L13+M13 -> 343399 | O13: =IF((L13+I13)>0,M13/(L13+I13),"") -> 0.10254961
... A16: 2024/25 | B16: World | C16: 23121 | D16: 11362.172 | E16: =IF(N(D16)>0,F16/D16,"") -> 15.561813 | F16: 176816 | G16: 141580 | H16: =C16+F16+G16 -> 341517 | I16: 147746 | J16: 143044 | K16: 28717 | L16: =J16+K16 -> 171761 | M16: 22010 | N16: =I16+L16+M16 -> 341517 | O16: =IF((L16+I16)>0,M16/(L16+I16),"") -> 0.06888738
A17: 2025/26 | B17: World | C17: =C19+C28+C38 -> 22010 | D17: =D19+D28+D38 -> 11362.172 | E17: =IF(N(D17)>0,F17/D17,"") -> 15.739068 | F17: =F19+F28+F38 -> 178830 | G17: =G19+G28+G38 -> 142931 | H17: =C17+F17+G17 -> 343771 | I17: =I19+I28+I38 -> 145942 | J17: =J19+J28+J38 -> 143882 | K17: =K19+K28+K38 -> 29577 | L17: =J17+K17 -> 173459 | M17: =M19+M28+M38 -> 24370 | N17: =I17+L17+M17 -> 343771 | O17: =IF((L17+I17)>0,M17/(L17+I17),"") -> 0.076299072
B18: Ex Brazil | C18: =C17-C20 -> 21055 | D18: =D17-D20 -> 9418.195 | E18: =IF(N(D18)>0,F18/D18,"") -> 12.298535 | F18: =F17-F20 -> 115830 | G18: =G17-G20 -> 142841 | H18: =C18+F18+G18 -> 279726 | I18: =I17-I20 -> 108072 | J18: =J17-J20 -> 122582 | K18: =K17-K20 -> 28597 | L18: =J18+K18 -> 151179 | M18: =M17-M20 -> 20475 | N18: =I18+L18+M18 -> 279726 | O18: =IF((L18+I18)>0,M18/(L18+I18),"") -> 0.078977516
B19: Major Exporters | C19: =C20+C21+C22+C23+C24+C25+C26+C27 -> 5172 | D19: =D20+D21+D22+D23+D24+D25+D26+D27 -> 11029.735 | E19: =IF(N(D19)>0,F19/D19,"") -> 15.861668 | F19: =F20+F21+F22+F23+F24+F25+F26+F27 -> 174950 | G19: =G20+G21+G22+G23+G24+G25+G26+G27 -> 12436 | H19: =C19+F19+G19 -> 192558 | I19: =I20+I21+I22+I23+I24+I25+I26+I27 -> 136282 | J19: =J20+J21+J22+J23+J24+J25+J26+J27 -> 38354 | K19: =K20+K21+K22+K23+K24+K25+K26+K27 -> 9652 | L19: =J19+K19 -> 48006 | M19: =M20+M21+M22+M23+M24+M25+M26+M27 -> 8270 | N19: =I19+L19+M19 -> 192558 | O19: =IF((L19+I19)>0,M19/(L19+I19),"") -> 0.044875412
B20: Brazil | C20: 955 | D20: 1943.977 | E20: =IF(N(D20)>0,F20/D20,"") -> 32.407791 | F20: 63000 | G20: 90 | H20: =C20+F20+G20 -> 64045 | I20: 37870 | J20: 21300 | K20: 980 | L20: =J20+K20 -> 22280 | M20: 3895 | N20: =I20+L20+M20 -> 64045 | O20: =IF((L20+I20)>0,M20/(L20+I20),"") -> 0.06475478
B21: Vietnam | C21: 1089 | D21: 678.569 | E21: =IF(N(D21)>0,F21/D21,"") -> 46.715957 | F21: 31700 | G21: 1300 | H21: =C21+F21+G21 -> 34089 | I21: 28500 | J21: 3400 | K21: 1500 | L21: =J21+K21 -> 4900 | M21: 689 | N21: =I21+L21+M21 -> 34089 | O21: =IF((L21+I21)>0,M21/(L21+I21),"") -> 0.020628743
B22: Colombia | C22: 922 | D22: 837.685 | E22: =IF(N(D22)>0,F22/D22,"") -> 14.922077 | F22: 12500 | G22: 2454 | H22: =C22+F22+G22 -> 15876 | I22: 12810 | J22: 1600 | K22: 600 | L22: =J22+K22 -> 2200 | M22: 866 | N22: =I22+L22+M22 -> 15876 | O22: =IF((L22+I22)>0,M22/(L22+I22),"") -> 0.05769487
B23: Indonesia | C23: 622 | D23: 1269.354 | E23: =IF(N(D23)>0,F23/D23,"") -> 9.7451144 | F23: 12370 | G23: 1411 | H23: =C23+F23+G23 -> 14403 | I23: 8842 | J23: 3270 | K23: 1540 | L23: =J23+K23 -> 4810 | M23: 751 | N23: =I23+L23+M23 -> 14403 | O23: =IF((L23+I23)>0,M23/(L23+I23),"") -> 0.055010255
B24: Ethiopia | C24: 80 | D24: 862.943 | E24: =IF(N(D24)>0,F24/D24,"") -> 13.396018 | F24: 11560 | G24: 0 | H24: =C24+F24+G24 -> 11640 | I24: 6965 | J24: 4500 | K24: 0 | L24: =J24+K24 -> 4500 | M24: 175 | N24: =I24+L24+M24 -> 11640 | O24: =IF((L24+I24)>0,M24/(L24+I24),"") -> 0.015263846
B25: Uganda | C25: 269 | D25: 736.547 | E25: =IF(N(D25)>0,F25/D25,"") -> 9.6327865 | F25: 7095 | G25: 0 | H25: =C25+F25+G25 -> 7364 | I25: 6700 | J25: 330 | K25: 0 | L25: =J25+K25 -> 330 | M25: 334 | N25: =I25+L25+M25 -> 7364 | O25: =IF((L25+I25)>0,M25/(L25+I25),"") -> 0.047510669
B26: Honduras | C26: 178 | D26: 266.728 | E26: =IF(N(D26)>0,F26/D26,"") -> 20.732731 | F26: 5530 | G26: 137 | H26: =C26+F26+G26 -> 5845 | I26: 5030 | J26: 350 | K26: 30 | L26: =J26+K26 -> 380 | M26: 435 | N26: =I26+L26+M26 -> 5845 | O26: =IF((L26+I26)>0,M26/(L26+I26),"") -> 0.080406654
B27: Others | C27: 1057 | D27: 4433.932 | E27: =IF(N(D27)>0,F27/D27,"") -> 7.0355161 | F27: 31195 | G27: 7044 | H27: =C27+F27+G27 -> 39296 | I27: 29565 | J27: 3604 | K27: 5002 | L27: =J27+K27 -> 8606 | M27: 1125 | N27: =I27+L27+M27 -> 39296 | O27: =IF((L27+I27)>0,M27/(L27+I27),"") -> 0.029472636
B28: Major Importers | C28: =C29+C30+C31+C32+C33+C34+C35+C36+C37 -> 16438 | D28: =D29+D30+D31+D32+D33+D34+D35+D36+D37 -> 332.437 | E28: =IF(N(D28)>0,F28/D28,"") -> 5.9560157 | F28: =F29+F30+F31+F32+F33+F34+F35+F36+F37 -> 1980 | G28: =G29+G30+G31+G32+G33+G34+G35+G36+G37 -> 124745 | H28: =C28+F28+G28 -> 143163 | I28: =I29+I30+I31+I32+I33+I34+I35+I36+I37 -> 8430 | J28: =J29+J30+J31+J32+J33+J34+J35+J36+J37 -> 101008 | K28: =K29+K30+K31+K32+K33+K34+K35+K36+K37 -> 18025 | L28: =J28+K28 -> 119033 | M28: =M29+M30+M31+M32+M33+M34+M35+M36+M37 -> 15700 | N28: =I28+L28+M28 -> 143163 | O28: =IF((L28+I28)>0,M28/(L28+I28),"") -> 0.123173
B29: European Union | C29: 8170 | E29: =IF(N(D29)>0,F29/D29,"") | F29: 0 | G29: 46500 | H29: =C29+F29+G29 -> 54670 | I29: 5600 | J29: 39170 | K29: 2400 | L29: =J29+K29 -> 41570 | M29: 7500 | N29: =I29+L29+M29 -> 54670 | O29: =IF((L29+I29)>0,M29/(L29+I29),"") -> 0.15899936
B30: United States | C30: 5700 | D30: 4.84 | E30: =IF(N(D30)>0,F30/D30,"") -> 10.330579 | F30: 50 | G30: 25500 | H30: =C30+F30+G30 -> 31250 | I30: 0 | J30: 24050 | K30: 1500 | L30: =J30+K30 -> 25550 | M30: 5700 | N30: =I30+L30+M30 -> 31250 | O30: =IF((L30+I30)>0,M30/(L30+I30),"") -> 0.22309198
B31: Japan | C31: 2268 | E31: =IF(N(D31)>0,F31/D31,"") | F31: 0 | G31: 6585 | H31: =C31+F31+G31 -> 8853 | I31: 0 | J31: 5968 | K31: 685 | L31: =J31+K31 -> 6653 | M31: 2200 | N31: =I31+L31+M31 -> 8853 | O31: =IF((L31+I31)>0,M31/(L31+I31),"") -> 0.33067789
B32: Philippines | C32: 300 | D32: 115.779 | E32: =IF(N(D32)>0,F32/D32,"") -> 3.8867152 | F32: 450 | G32: 6075 | H32: =C32+F32+G32 -> 6825 | I32: 0 | J32: 375 | K32: 6150 | L32: =J32+K32 -> 6525 | M32: 300 | N32: =I32+L32+M32 -> 6825 | O32: =IF((L32+I32)>0,M32/(L32+I32),"") -> 0.045977011
B33: Canada | C33: 0 | E33: =IF(N(D33)>0,F33/D33,"") | F33: 0 | G33: 5050 | H33: =C33+F33+G33 -> 5050 | I33: 0 | J33: 3450 | K33: 1600 | L33: =J33+K33 -> 5050 | M33: 0 | N33: =I33+L33+M33 -> 5050 | O33: =IF((L33+I33)>0,M33/(L33+I33),"") -> 0
B34: United Kingdom | C34: 0 | E34: =IF(N(D34)>0,F34/D34,"") | F34: 0 | G34: 4570 | H34: =C34+F34+G34 -> 4570 | I34: 0 | J34: 3130 | K34: 1440 | L34: =J34+K34 -> 4570 | M34: 0 | N34: =I34+L34+M34 -> 4570 | O34: =IF((L34+I34)>0,M34/(L34+I34),"") -> 0
B35: Russia | C35: 0 | E35: =IF(N(D35)>0,F35/D35,"") | F35: 0 | G35: 4575 | H35: =C35+F35+G35 -> 4575 | I35: 0 | J35: 4150 | K35: 425 | L35: =J35+K35 -> 4575 | M35: 0 | N35: =I35+L35+M35 -> 4575 | O35: =IF((L35+I35)>0,M35/(L35+I35),"") -> 0
B36: Korea | C36: 0 | E36: =IF(N(D36)>0,F36/D36,"") | F36: 0 | G36: 3200 | H36: =C36+F36+G36 -> 3200 | I36: 0 | J36: 3200 | K36: 0 | L36: =J36+K36 -> 3200 | M36: 0 | N36: =I36+L36+M36 -> 3200 | O36: =IF((L36+I36)>0,M36/(L36+I36),"") -> 0
B37: Others | C37: 0 | D37: 211.818 | E37: =IF(N(D37)>0,F37/D37,"") -> 6.9871305 | F37: 1480 | G37: 22690 | H37: =C37+F37+G37 -> 24170 | I37: 2830 | J37: 17515 | K37: 3825 | L37: =J37+K37 -> 21340 | M37: 0 | N37: =I37+L37+M37 -> 24170 | O37: =IF((L37+I37)>0,M37/(L37+I37),"") -> 0
B38: Selected Other | C38: =C39 -> 400 | D38: =D39 | E38: =IF(N(D38)>0,F38/D38,"") | F38: =F39 -> 1900 | G38: =G39 -> 5750 | H38: =C38+F38+G38 -> 8050 | I38: =I39 -> 1230 | J38: =J39 -> 4520 | K38: =K39 -> 1900 | L38: =J38+K38 -> 6420 | M38: =M39 -> 400 | N38: =I38+L38+M38 -> 8050 | O38: =IF((L38+I38)>0,M38/(L38+I38),"") -> 0.052287582
B39: China | C39: 400 | E39: =IF(N(D39)>0,F39/D39,"") | F39: 1900 | G39: 5750 | H39: =C39+F39+G39 -> 8050 | I39: 1230 | J39: 4520 | K39: 1900 | L39: =J39+K39 -> 6420 | M39: 400 | N39: =I39+L39+M39 -> 8050 | O39: =IF((L39+I39)>0,M39/(L39+I39),"") -> 0.052287582
