Workbook

Sheet README
A1: Espírito Santo (conilon) — météo par saison caféière (juillet → juin) et phase ENSO
A2: Fichier généré le 2026-09-27. Données mensuelles de juillet 2006 à August 2026 (mois complets uniquement).
A4: Zone
A5: Moyenne de 5 villes : Jaguaré, Vila Valério, Sooretama, Nova Venécia, São Mateus (principales communes du conilon ; altitude du modèle de terrain à 90 m).
A7: Sources retenues (les plus proches des vraies mesures)
A8: Chaque source a été comparée aux stations automatiques INMET de la région (A616, A614, A632, A631, mesures réelles 2007–2026) : voir l'onglet Validation.
A9: • Pluie : CHIRPS v3.0 (UCSB) — satellite + pluviomètres, grille 0,05° (~5 km).
A10: • Température moyenne et température minimale et humidité de l'air : Open-Meteo ERA5-Land (0,1°), corrigé à l'altitude de chaque ville.
A11: • Température maximale : Open-Meteo ERA5-Land + correction mensuelle mesurée sur les 4 stations INMET de la région (les modèles lissent les extrêmes du jour). Correction testée en excluant à chaque fois la station évaluée ; appliquée seulement là où elle réduit l'erreur (voir Validation).
A12: • Humidité du sol (0–100 cm et surface 0–7 cm) : Open-Meteo ERA5-Land, en % du volume de sol. Aucune station ne la mesure dans la région : c'est une estimation de modèle, non vérifiable localement.
A14: Phases ENSO
A15: Indice ONI de la NOAA pour décembre-janvier-février : ≥ +0,5 = El Niño, ≤ −0,5 = La Niña, sinon Neutre. Cette règle redonne exactement le classement du graphique de référence (2006/07–2024/25).
... A27: CHIRPS : Funk et al., Climate Hazards Center UCSB. Open-Meteo (CC BY 4.0) / ERA5-Land, Copernicus-ECMWF. NASA POWER, NASA Langley. INMET. NOAA CPC (ONI).

Sheet Charts
A1: Espírito Santo (conilon) | Temperature, rainfall, humidity and soil moisture by ENSO phase
A2: Coffee seasons Jul-Jun, 2006/07 to 2026/27. Dotted line = average of the phase. Best-validated source per variable (see Validation).

Sheet Monthly data
A1: Espírito Santo (conilon) — monthly data (average of the towns), best source per variable
A2: Towns: Jaguaré, Vila Valério, Sooretama, Nova Venécia, São Mateus. Complete months only.
D3: Source → Open-Meteo | E3: Open-Meteo | F3: Open-Meteo + INMET correction | G3: CHIRPS | H3: Open-Meteo | I3: Open-Meteo | J3: Open-Meteo
A4: Month | B4: Season | C4: ENSO phase | D4: Mean temperature (°C) | E4: Min temperature (°C) | F4: Max temperature (°C) | G4: Monthly rainfall (mm) | H4: Relative humidity (%) | I4: Soil moisture 0-100 cm (% vol.) | J4: Surface soil moisture 0-7 cm (% vol.)
A5: 38899 | B5: 2006/07 | C5: =INDEX(ENSO!$C$5:$C$25,MATCH(B5,ENSO!$A$5:$A$25,0)) -> El Niño | D5: 20.53 | E5: 16.55 | F5: 26.75 | G5: 56.48 | H5: 78.18 | I5: 26.67 | J5: 23.19
A6: 38930 | B6: 2006/07 | C6: =INDEX(ENSO!$C$5:$C$25,MATCH(B6,ENSO!$A$5:$A$25,0)) -> El Niño | D6: 21.87 | E6: 18.46 | F6: 27.58 | G6: 30.43 | H6: 77.8 | I6: 24.76 | J6: 22.39
A7: 38961 | B7: 2006/07 | C7: =INDEX(ENSO!$C$5:$C$25,MATCH(B7,ENSO!$A$5:$A$25,0)) -> El Niño | D7: 22.13 | E7: 18.72 | F7: 27.54 | G7: 87.11 | H7: 75.71 | I7: 24.37 | J7: 26.04
A8: 38991 | B8: 2006/07 | C8: =INDEX(ENSO!$C$5:$C$25,MATCH(B8,ENSO!$A$5:$A$25,0)) -> El Niño | D8: 23.24 | E8: 20.66 | F8: 27.5 | G8: 183.92 | H8: 80.61 | I8: 26.55 | J8: 33.23
A9: 39022 | B9: 2006/07 | C9: =INDEX(ENSO!$C$5:$C$25,MATCH(B9,ENSO!$A$5:$A$25,0)) -> El Niño | D9: 23.79 | E9: 21.34 | F9: 28.4 | G9: 313.24 | H9: 83.79 | I9: 34.52 | J9: 37.72
A10: 39052 | B10: 2006/07 | C10: =INDEX(ENSO!$C$5:$C$25,MATCH(B10,ENSO!$A$5:$A$25,0)) -> El Niño | D10: 24.6 | E10: 22.05 | F10: 29.73 | G10: 259.84 | H10: 83.86 | I10: 39.57 | J10: 37.83
A11: 39083 | B11: 2006/07 | C11: =INDEX(ENSO!$C$5:$C$25,MATCH(B11,ENSO!$A$5:$A$25,0)) -> El Niño | D11: 26.05 | E11: 23.12 | F11: 32.22 | G11: 124.89 | H11: 80.45 | I11: 35.84 | J11: 34.86
A12: 39114 | B12: 2006/07 | C12: =INDEX(ENSO!$C$5:$C$25,MATCH(B12,ENSO!$A$5:$A$25,0)) -> El Niño | D12: 24.92 | E12: 22.17 | F12: 30.62 | G12: 269.29 | H12: 84.9 | I12: 39.64 | J12: 39.53
A13: 39142 | B13: 2006/07 | C13: =INDEX(ENSO!$C$5:$C$25,MATCH(B13,ENSO!$A$5:$A$25,0)) -> El Niño | D13: 25.61 | E13: 22.33 | F13: 31.86 | G13: 29.84 | H13: 81.6 | I13: 34.98 | J13: 30.51
A14: 39173 | B14: 2006/07 | C14: =INDEX(ENSO!$C$5:$C$25,MATCH(B14,ENSO!$A$5:$A$25,0)) -> El Niño | D14: 24.67 | E14: 21.86 | F14: 30.73 | G14: 159.86 | H14: 84.31 | I14: 31.25 | J14: 32.87
A15: 39203 | B15: 2006/07 | C15: =INDEX(ENSO!$C$5:$C$25,MATCH(B15,ENSO!$A$5:$A$25,0)) -> El Niño | D15: 22.65 | E15: 19.45 | F15: 28.34 | G15: 21.76 | H15: 78.04 | I15: 28.78 | J15: 26.74
A16: 39234 | B16: 2006/07 | C16: =INDEX(ENSO!$C$5:$C$25,MATCH(B16,ENSO!$A$5:$A$25,0)) -> El Niño | D16: 21.54 | E16: 17.58 | F16: 27.81 | G16: 16.66 | H16: 78.54 | I16: 25.62 | J16: 20.51
... A246: 46235 | B246: 2026/27 | C246: =INDEX(ENSO!$C$5:$C$25,MATCH(B246,ENSO!$A$5:$A$25,0)) -> El Niño* | D246: 23.39 | E246: 19.78 | F246: 29.63 | G246: 31.47 | H246: 74.76 | I246: 23.33 | J246: 20.42

Sheet ENSO
A1: ENSO phase per coffee season (Jul-Jun)
A2: NOAA CPC Oceanic Niño Index (ONI). Rule: DJF ONI >= +0.5 El Niño, <= -0.5 La Niña, otherwise Neutral. * = season not finished, provisional.
A4: Season | B4: DJF ONI | C4: ENSO phase | D4: SON ONI | E4: NDJ ONI | F4: Note
A5: 2006/07 | B5: 0.62 | C5: El Niño | D5: 0.71 | E5: 0.88
A6: 2007/08 | B6: -1.76 | C6: La Niña | D6: -1.38 | E6: -1.72
A7: 2008/09 | B7: -0.89 | C7: La Niña | D7: -0.36 | E7: -0.79
A8: 2009/10 | B8: 1.47 | C8: El Niño | D8: 0.92 | E8: 1.5
A9: 2010/11 | B9: -1.29 | C9: La Niña | D9: -1.54 | E9: -1.48
A10: 2011/12 | B10: -0.71 | C10: La Niña | D10: -0.94 | E10: -0.92
A11: 2012/13 | B11: -0.24 | C11: Neutral | D11: 0.28 | E11: -0.03
A12: 2013/14 | B12: -0.24 | C12: Neutral | D12: -0.14 | E12: -0.11
A13: 2014/15 | B13: 0.73 | C13: El Niño | D13: 0.51 | E13: 0.8
A14: 2015/16 | B14: 2.5 | C14: El Niño | D14: 2.28 | E14: 2.59
A15: 2016/17 | B15: -0.08 | C15: Neutral | D15: -0.51 | E15: -0.37
A16: 2017/18 | B16: -0.71 | C16: La Niña | D16: -0.44 | E16: -0.76
... A24: 2025/26 | B24: -0.39 | C24: Neutral | D24: -0.57 | E24: -0.6
A25: 2026/27 | C25: El Niño* | F25: provisional: latest ONI JJA 2026 = +1.80
A27: Source: https://www.cpc.ncep.noaa.gov/data/indices/oni.ascii.txt

Sheet Mean temp
A1: Espírito Santo (conilon) — Mean temperature (°C) by coffee season
A2: Source: Open-Meteo, ERA5-Land 0.1° (models=era5_seamless), downscaled to town altitude. Values link to 'Monthly data'.
A4: Season | B4: ENSO phase | C4: Jul | D4: Aug | E4: Sep | F4: Oct | G4: Nov | H4: Dec | I4: Jan | J4: Feb | K4: Mar | L4: Apr | M4: May | N4: Jun | O4: Season mean
A5: 2006/07 | B5: =ENSO!C5 -> El Niño | C5: ='Monthly data'!D5 -> 20.53 | D5: ='Monthly data'!D6 -> 21.87 | E5: ='Monthly data'!D7 -> 22.13 | F5: ='Monthly data'!D8 -> 23.24 | G5: ='Monthly data'!D9 -> 23.79 | H5: ='Monthly data'!D10 -> 24.6 | I5: ='Monthly data'!D11 -> 26.05 | J5: ='Monthly data'!D12 -> 24.92 | K5: ='Monthly data'!D13 -> 25.61 | L5: ='Monthly data'!D14 -> 24.67 | M5: ='Monthly data'!D15 -> 22.65 | N5: ='Monthly data'!D16 -> 21.54 | O5: =IF(COUNT(C5:N5)=12,AVERAGE(C5:N5),"") -> 23.466667
A6: 2007/08 | B6: =ENSO!C6 -> La Niña | C6: ='Monthly data'!D17 -> 21.88 | D6: ='Monthly data'!D18 -> 21.24 | E6: ='Monthly data'!D19 -> 21.78 | F6: ='Monthly data'!D20 -> 23.89 | G6: ='Monthly data'!D21 -> 25.33 | H6: ='Monthly data'!D22 -> 25.35 | I6: ='Monthly data'!D23 -> 25.16 | J6: ='Monthly data'!D24 -> 25.75 | K6: ='Monthly data'!D25 -> 25.5 | L6: ='Monthly data'!D26 -> 25.51 | M6: ='Monthly data'!D27 -> 22.82 | N6: ='Monthly data'!D28 -> 21.9 | O6: =IF(COUNT(C6:N6)=12,AVERAGE(C6:N6),"") -> 23.8425
A7: 2008/09 | B7: =ENSO!C7 -> La Niña | C7: ='Monthly data'!D29 -> 20.73 | D7: ='Monthly data'!D30 -> 22.32 | E7: ='Monthly data'!D31 -> 22.84 | F7: ='Monthly data'!D32 -> 24.66 | G7: ='Monthly data'!D33 -> 24.12 | H7: ='Monthly data'!D34 -> 24.58 | I7: ='Monthly data'!D35 -> 25.58 | J7: ='Monthly data'!D36 -> 25.95 | K7: ='Monthly data'!D37 -> 26.34 | L7: ='Monthly data'!D38 -> 24.41 | M7: ='Monthly data'!D39 -> 22.6 | N7: ='Monthly data'!D40 -> 21.54 | O7: =IF(COUNT(C7:N7)=12,AVERAGE(C7:N7),"") -> 23.805833
A8: 2009/10 | B8: =ENSO!C8 -> El Niño | C8: ='Monthly data'!D41 -> 21.76 | D8: ='Monthly data'!D42 -> 22.06 | E8: ='Monthly data'!D43 -> 24.24 | F8: ='Monthly data'!D44 -> 24.52 | G8: ='Monthly data'!D45 -> 25.47 | H8: ='Monthly data'!D46 -> 26.4 | I8: ='Monthly data'!D47 -> 27.32 | J8: ='Monthly data'!D48 -> 27.59 | K8: ='Monthly data'!D49 -> 26.41 | L8: ='Monthly data'!D50 -> 24.22 | M8: ='Monthly data'!D51 -> 23.28 | N8: ='Monthly data'!D52 -> 21.39 | O8: =IF(COUNT(C8:N8)=12,AVERAGE(C8:N8),"") -> 24.555
A9: 2010/11 | B9: =ENSO!C9 -> La Niña | C9: ='Monthly data'!D53 -> 21.55 | D9: ='Monthly data'!D54 -> 21 | E9: ='Monthly data'!D55 -> 22.74 | F9: ='Monthly data'!D56 -> 24.04 | G9: ='Monthly data'!D57 -> 24.32 | H9: ='Monthly data'!D58 -> 25.68 | I9: ='Monthly data'!D59 -> 25.8 | J9: ='Monthly data'!D60 -> 26.31 | K9: ='Monthly data'!D61 -> 25.07 | L9: ='Monthly data'!D62 -> 24.12 | M9: ='Monthly data'!D63 -> 21.9 | N9: ='Monthly data'!D64 -> 21.34 | O9: =IF(COUNT(C9:N9)=12,AVERAGE(C9:N9),"") -> 23.655833
A10: 2011/12 | B10: =ENSO!C10 -> La Niña | C10: ='Monthly data'!D65 -> 20.89 | D10: ='Monthly data'!D66 -> 22.08 | E10: ='Monthly data'!D67 -> 21.71 | F10: ='Monthly data'!D68 -> 23.13 | G10: ='Monthly data'!D69 -> 22.65 | H10: ='Monthly data'!D70 -> 24.26 | I10: ='Monthly data'!D71 -> 24.85 | J10: ='Monthly data'!D72 -> 25.11 | K10: ='Monthly data'!D73 -> 25.29 | L10: ='Monthly data'!D74 -> 25.03 | M10: ='Monthly data'!D75 -> 22.47 | N10: ='Monthly data'!D76 -> 22.83 | O10: =IF(COUNT(C10:N10)=12,AVERAGE(C10:N10),"") -> 23.358333
A11: 2012/13 | B11: =ENSO!C11 -> Neutral | C11: ='Monthly data'!D77 -> 21.65 | D11: ='Monthly data'!D78 -> 21.04 | E11: ='Monthly data'!D79 -> 22.71 | F11: ='Monthly data'!D80 -> 24.08 | G11: ='Monthly data'!D81 -> 24.15 | H11: ='Monthly data'!D82 -> 26.5 | I11: ='Monthly data'!D83 -> 25.91 | J11: ='Monthly data'!D84 -> 26.16 | K11: ='Monthly data'!D85 -> 26.59 | L11: ='Monthly data'!D86 -> 23.95 | M11: ='Monthly data'!D87 -> 23.13 | N11: ='Monthly data'!D88 -> 22.67 | O11: =IF(COUNT(C11:N11)=12,AVERAGE(C11:N11),"") -> 24.045
A12: 2013/14 | B12: =ENSO!C12 -> Neutral | C12: ='Monthly data'!D89 -> 21.89 | D12: ='Monthly data'!D90 -> 21.74 | E12: ='Monthly data'!D91 -> 22.91 | F12: ='Monthly data'!D92 -> 23.36 | G12: ='Monthly data'!D93 -> 24.27 | H12: ='Monthly data'!D94 -> 25.08 | I12: ='Monthly data'!D95 -> 25.26 | J12: ='Monthly data'!D96 -> 25.48 | K12: ='Monthly data'!D97 -> 25.39 | L12: ='Monthly data'!D98 -> 24.55 | M12: ='Monthly data'!D99 -> 23.43 | N12: ='Monthly data'!D100 -> 21.68 | O12: =IF(COUNT(C12:N12)=12,AVERAGE(C12:N12),"") -> 23.753333
A13: 2014/15 | B13: =ENSO!C13 -> El Niño | C13: ='Monthly data'!D101 -> 21.03 | D13: ='Monthly data'!D102 -> 21.24 | E13: ='Monthly data'!D103 -> 23.02 | F13: ='Monthly data'!D104 -> 23.43 | G13: ='Monthly data'!D105 -> 23.95 | H13: ='Monthly data'!D106 -> 24.76 | I13: ='Monthly data'!D107 -> 26.43 | J13: ='Monthly data'!D108 -> 26.51 | K13: ='Monthly data'!D109 -> 25.89 | L13: ='Monthly data'!D110 -> 24.84 | M13: ='Monthly data'!D111 -> 23.12 | N13: ='Monthly data'!D112 -> 22.45 | O13: =IF(COUNT(C13:N13)=12,AVERAGE(C13:N13),"") -> 23.889167
A14: 2015/16 | B14: =ENSO!C14 -> El Niño | C14: ='Monthly data'!D113 -> 21.94 | D14: ='Monthly data'!D114 -> 22.03 | E14: ='Monthly data'!D115 -> 24.82 | F14: ='Monthly data'!D116 -> 25.48 | G14: ='Monthly data'!D117 -> 26.94 | H14: ='Monthly data'!D118 -> 27.51 | I14: ='Monthly data'!D119 -> 26.49 | J14: ='Monthly data'!D120 -> 27.18 | K14: ='Monthly data'!D121 -> 27.11 | L14: ='Monthly data'!D122 -> 26.38 | M14: ='Monthly data'!D123 -> 24.34 | N14: ='Monthly data'!D124 -> 22.5 | O14: =IF(COUNT(C14:N14)=12,AVERAGE(C14:N14),"") -> 25.226667
A15: 2016/17 | B15: =ENSO!C15 -> Neutral | C15: ='Monthly data'!D125 -> 21.96 | D15: ='Monthly data'!D126 -> 23.11 | E15: ='Monthly data'!D127 -> 23.8 | F15: ='Monthly data'!D128 -> 24.26 | G15: ='Monthly data'!D129 -> 24.46 | H15: ='Monthly data'!D130 -> 25.9 | I15: ='Monthly data'!D131 -> 26.94 | J15: ='Monthly data'!D132 -> 25.84 | K15: ='Monthly data'!D133 -> 26.33 | L15: ='Monthly data'!D134 -> 25.11 | M15: ='Monthly data'!D135 -> 23.16 | N15: ='Monthly data'!D136 -> 22.38 | O15: =IF(COUNT(C15:N15)=12,AVERAGE(C15:N15),"") -> 24.4375
A16: 2017/18 | B16: =ENSO!C16 -> La Niña | C16: ='Monthly data'!D137 -> 20.49 | D16: ='Monthly data'!D138 -> 21.16 | E16: ='Monthly data'!D139 -> 22 | F16: ='Monthly data'!D140 -> 24.91 | G16: ='Monthly data'!D141 -> 24.1 | H16: ='Monthly data'!D142 -> 24.94 | I16: ='Monthly data'!D143 -> 26.2 | J16: ='Monthly data'!D144 -> 25.29 | K16: ='Monthly data'!D145 -> 25.92 | L16: ='Monthly data'!D146 -> 23.79 | M16: ='Monthly data'!D147 -> 22.54 | N16: ='Monthly data'!D148 -> 22.16 | O16: =IF(COUNT(C16:N16)=12,AVERAGE(C16:N16),"") -> 23.625
A17: 2018/19 | B17: =ENSO!C17 -> El Niño | C17: ='Monthly data'!D149 -> 21.36 | D17: ='Monthly data'!D150 -> 22.15 | E17: ='Monthly data'!D151 -> 23.41 | F17: ='Monthly data'!D152 -> 24.64 | G17: ='Monthly data'!D153 -> 24.37 | H17: ='Monthly data'!D154 -> 25.14 | I17: ='Monthly data'!D155 -> 26.41 | J17: ='Monthly data'!D156 -> 27.81 | K17: ='Monthly data'!D157 -> 27.03 | L17: ='Monthly data'!D158 -> 26.2 | M17: ='Monthly data'!D159 -> 24.84 | N17: ='Monthly data'!D160 -> 22.8 | O17: =IF(COUNT(C17:N17)=12,AVERAGE(C17:N17),"") -> 24.68
A18: 2019/20 | B18: =ENSO!C18 -> El Niño | C18: ='Monthly data'!D161 -> 21.94 | D18: ='Monthly data'!D162 -> 21.86 | E18: ='Monthly data'!D163 -> 23.77 | F18: ='Monthly data'!D164 -> 24.52 | G18: ='Monthly data'!D165 -> 25.11 | H18: ='Monthly data'!D166 -> 25.43 | I18: ='Monthly data'!D167 -> 26.02 | J18: ='Monthly data'!D168 -> 26.56 | K18: ='Monthly data'!D169 -> 24.8 | L18: ='Monthly data'!D170 -> 24.32 | M18: ='Monthly data'!D171 -> 22.8 | N18: ='Monthly data'!D172 -> 22.58 | O18: =IF(COUNT(C18:N18)=12,AVERAGE(C18:N18),"") -> 24.1425
A19: 2020/21 | B19: =ENSO!C19 -> La Niña | C19: ='Monthly data'!D173 -> 21.76 | D19: ='Monthly data'!D174 -> 21.62 | E19: ='Monthly data'!D175 -> 23.68 | F19: ='Monthly data'!D176 -> 24.89 | G19: ='Monthly data'!D177 -> 24.18 | H19: ='Monthly data'!D178 -> 25.78 | I19: ='Monthly data'!D179 -> 26.22 | J19: ='Monthly data'!D180 -> 25.61 | K19: ='Monthly data'!D181 -> 25.94 | L19: ='Monthly data'!D182 -> 24.75 | M19: ='Monthly data'!D183 -> 23.76 | N19: ='Monthly data'!D184 -> 22.3 | O19: =IF(COUNT(C19:N19)=12,AVERAGE(C19:N19),"") -> 24.2075
A20: 2021/22 | B20: =ENSO!C20 -> La Niña | C20: ='Monthly data'!D185 -> 21.47 | D20: ='Monthly data'!D186 -> 21.8 | E20: ='Monthly data'!D187 -> 23.81 | F20: ='Monthly data'!D188 -> 24.03 | G20: ='Monthly data'!D189 -> 23.7 | H20: ='Monthly data'!D190 -> 24.37 | I20: ='Monthly data'!D191 -> 25.72 | J20: ='Monthly data'!D192 -> 25.61 | K20: ='Monthly data'!D193 -> 25.65 | L20: ='Monthly data'!D194 -> 25.34 | M20: ='Monthly data'!D195 -> 23.32 | N20: ='Monthly data'!D196 -> 21.88 | O20: =IF(COUNT(C20:N20)=12,AVERAGE(C20:N20),"") -> 23.891667
A21: 2022/23 | B21: =ENSO!C21 -> La Niña | C21: ='Monthly data'!D197 -> 21.62 | D21: ='Monthly data'!D198 -> 21.97 | E21: ='Monthly data'!D199 -> 22.69 | F21: ='Monthly data'!D200 -> 25.03 | G21: ='Monthly data'!D201 -> 23.52 | H21: ='Monthly data'!D202 -> 24.21 | I21: ='Monthly data'!D203 -> 25.31 | J21: ='Monthly data'!D204 -> 26.38 | K21: ='Monthly data'!D205 -> 26.04 | L21: ='Monthly data'!D206 -> 25.28 | M21: ='Monthly data'!D207 -> 22.83 | N21: ='Monthly data'!D208 -> 22.17 | O21: =IF(COUNT(C21:N21)=12,AVERAGE(C21:N21),"") -> 23.920833
A22: 2023/24 | B22: =ENSO!C22 -> El Niño | C22: ='Monthly data'!D209 -> 21.77 | D22: ='Monthly data'!D210 -> 22.95 | E22: ='Monthly data'!D211 -> 24.02 | F22: ='Monthly data'!D212 -> 25.67 | G22: ='Monthly data'!D213 -> 27.14 | H22: ='Monthly data'!D214 -> 27.59 | I22: ='Monthly data'!D215 -> 26.34 | J22: ='Monthly data'!D216 -> 26.31 | K22: ='Monthly data'!D217 -> 27.01 | L22: ='Monthly data'!D218 -> 25.82 | M22: ='Monthly data'!D219 -> 25.23 | N22: ='Monthly data'!D220 -> 23.3 | O22: =IF(COUNT(C22:N22)=12,AVERAGE(C22:N22),"") -> 25.2625
A23: 2024/25 | B23: =ENSO!C23 -> Neutral | C23: ='Monthly data'!D221 -> 22.85 | D23: ='Monthly data'!D222 -> 22.56 | E23: ='Monthly data'!D223 -> 24.51 | F23: ='Monthly data'!D224 -> 24.91 | G23: ='Monthly data'!D225 -> 24.6 | H23: ='Monthly data'!D226 -> 26.39 | I23: ='Monthly data'!D227 -> 25.99 | J23: ='Monthly data'!D228 -> 26.59 | K23: ='Monthly data'!D229 -> 26.22 | L23: ='Monthly data'!D230 -> 24.98 | M23: ='Monthly data'!D231 -> 22.92 | N23: ='Monthly data'!D232 -> 22.02 | O23: =IF(COUNT(C23:N23)=12,AVERAGE(C23:N23),"") -> 24.545
A24: 2025/26 | B24: =ENSO!C24 -> Neutral | C24: ='Monthly data'!D233 -> 21.01 | D24: ='Monthly data'!D234 -> 21.48 | E24: ='Monthly data'!D235 -> 22.44 | F24: ='Monthly data'!D236 -> 23.19 | G24: ='Monthly data'!D237 -> 24.77 | H24: ='Monthly data'!D238 -> 26.15 | I24: ='Monthly data'!D239 -> 25.94 | J24: ='Monthly data'!D240 -> 26.84 | K24: ='Monthly data'!D241 -> 25.39 | L24: ='Monthly data'!D242 -> 24.81 | M24: ='Monthly data'!D243 -> 23.79 | N24: ='Monthly data'!D244 -> 22.22 | O24: =IF(COUNT(C24:N24)=12,AVERAGE(C24:N24),"") -> 24.0025
A25: 2026/27 | B25: =ENSO!C25 -> El Niño* | C25: ='Monthly data'!D245 -> 22.17 | D25: ='Monthly data'!D246 -> 23.39 | O25: =IF(COUNT(C25:N25)=12,AVERAGE(C25:N25),"")
A27: Averages
A28: El Niño average (7 seasons) | C28: =AVERAGEIF($B$5:$B$25,"El Niño",C$5:C$25) -> 21.475714 | D28: =AVERAGEIF($B$5:$B$25,"El Niño",D$5:D$25) -> 22.022857 | E28: =AVERAGEIF($B$5:$B$25,"El Niño",E$5:E$25) -> 23.63 | F28: =AVERAGEIF($B$5:$B$25,"El Niño",F$5:F$25) -> 24.5 | G28: =AVERAGEIF($B$5:$B$25,"El Niño",G$5:G$25) -> 25.252857 | H28: =AVERAGEIF($B$5:$B$25,"El Niño",H$5:H$25) -> 25.918571 | I28: =AVERAGEIF($B$5:$B$25,"El Niño",I$5:I$25) -> 26.437143 | J28: =AVERAGEIF($B$5:$B$25,"El Niño",J$5:J$25) -> 26.697143 | ... O28: =AVERAGEIF($B$5:$B$25,"El Niño",O$5:O$25) -> 24.460357
A29: La Niña average (8 seasons) | C29: =AVERAGEIF($B$5:$B$25,"La Niña",C$5:C$25) -> 21.29875 | D29: =AVERAGEIF($B$5:$B$25,"La Niña",D$5:D$25) -> 21.64875 | E29: =AVERAGEIF($B$5:$B$25,"La Niña",E$5:E$25) -> 22.65625 | F29: =AVERAGEIF($B$5:$B$25,"La Niña",F$5:F$25) -> 24.3225 | G29: =AVERAGEIF($B$5:$B$25,"La Niña",G$5:G$25) -> 23.99 | H29: =AVERAGEIF($B$5:$B$25,"La Niña",H$5:H$25) -> 24.89625 | I29: =AVERAGEIF($B$5:$B$25,"La Niña",I$5:I$25) -> 25.605 | J29: =AVERAGEIF($B$5:$B$25,"La Niña",J$5:J$25) -> 25.75125 | ... O29: =AVERAGEIF($B$5:$B$25,"La Niña",O$5:O$25) -> 23.788438
A30: Neutral average (5 seasons) | C30: =AVERAGEIF($B$5:$B$25,"Neutral",C$5:C$25) -> 21.872 | D30: =AVERAGEIF($B$5:$B$25,"Neutral",D$5:D$25) -> 21.986 | E30: =AVERAGEIF($B$5:$B$25,"Neutral",E$5:E$25) -> 23.274 | F30: =AVERAGEIF($B$5:$B$25,"Neutral",F$5:F$25) -> 23.96 | G30: =AVERAGEIF($B$5:$B$25,"Neutral",G$5:G$25) -> 24.45 | H30: =AVERAGEIF($B$5:$B$25,"Neutral",H$5:H$25) -> 26.004 | I30: =AVERAGEIF($B$5:$B$25,"Neutral",I$5:I$25) -> 26.008 | J30: =AVERAGEIF($B$5:$B$25,"Neutral",J$5:J$25) -> 26.182 | ... O30: =AVERAGEIF($B$5:$B$25,"Neutral",O$5:O$25) -> 24.156667
A31: All complete seasons (20) | C31: =AVERAGE(C5:C24) -> 21.504 | D31: =AVERAGE(D5:D24) -> 21.864 | E31: =AVERAGE(E5:E24) -> 23.1515 | F31: =AVERAGE(F5:F24) -> 24.294 | G31: =AVERAGE(G5:G24) -> 24.547 | H31: =AVERAGE(H5:H24) -> 25.531 | I31: =AVERAGE(I5:I24) -> 25.997 | J31: =AVERAGE(J5:J24) -> 26.19 | ... O31: =AVERAGE(O5:O24) -> 24.115667
A33: * season not finished — ENSO phase provisional, not included in the phase averages.

Sheet Min temp
A1: Espírito Santo (conilon) — Min temperature (°C) by coffee season
A2: Source: Open-Meteo, ERA5-Land 0.1° (models=era5_seamless), downscaled to town altitude. Values link to 'Monthly data'.
A4: Season | B4: ENSO phase | C4: Jul | D4: Aug | E4: Sep | F4: Oct | G4: Nov | H4: Dec | I4: Jan | J4: Feb | K4: Mar | L4: Apr | M4: May | N4: Jun | O4: Season mean
A5: 2006/07 | B5: =ENSO!C5 -> El Niño | C5: ='Monthly data'!E5 -> 16.55 | D5: ='Monthly data'!E6 -> 18.46 | E5: ='Monthly data'!E7 -> 18.72 | F5: ='Monthly data'!E8 -> 20.66 | G5: ='Monthly data'!E9 -> 21.34 | H5: ='Monthly data'!E10 -> 22.05 | I5: ='Monthly data'!E11 -> 23.12 | J5: ='Monthly data'!E12 -> 22.17 | K5: ='Monthly data'!E13 -> 22.33 | L5: ='Monthly data'!E14 -> 21.86 | M5: ='Monthly data'!E15 -> 19.45 | N5: ='Monthly data'!E16 -> 17.58 | O5: =IF(COUNT(C5:N5)=12,AVERAGE(C5:N5),"") -> 20.3575
A6: 2007/08 | B6: =ENSO!C6 -> La Niña | C6: ='Monthly data'!E17 -> 18.41 | D6: ='Monthly data'!E18 -> 17.41 | E6: ='Monthly data'!E19 -> 18.14 | F6: ='Monthly data'!E20 -> 20.23 | G6: ='Monthly data'!E21 -> 21.87 | H6: ='Monthly data'!E22 -> 22.07 | I6: ='Monthly data'!E23 -> 22.13 | J6: ='Monthly data'!E24 -> 22.66 | K6: ='Monthly data'!E25 -> 22.51 | L6: ='Monthly data'!E26 -> 22.42 | M6: ='Monthly data'!E27 -> 19.49 | N6: ='Monthly data'!E28 -> 18.52 | O6: =IF(COUNT(C6:N6)=12,AVERAGE(C6:N6),"") -> 20.488333
A7: 2008/09 | B7: =ENSO!C7 -> La Niña | C7: ='Monthly data'!E29 -> 16.79 | D7: ='Monthly data'!E30 -> 18.4 | E7: ='Monthly data'!E31 -> 19.22 | F7: ='Monthly data'!E32 -> 21.01 | G7: ='Monthly data'!E33 -> 21.53 | H7: ='Monthly data'!E34 -> 21.77 | I7: ='Monthly data'!E35 -> 22.87 | J7: ='Monthly data'!E36 -> 22.8 | K7: ='Monthly data'!E37 -> 23.15 | L7: ='Monthly data'!E38 -> 21.65 | M7: ='Monthly data'!E39 -> 19.56 | N7: ='Monthly data'!E40 -> 18.61 | O7: =IF(COUNT(C7:N7)=12,AVERAGE(C7:N7),"") -> 20.613333
A8: 2009/10 | B8: =ENSO!C8 -> El Niño | C8: ='Monthly data'!E41 -> 18.37 | D8: ='Monthly data'!E42 -> 18.77 | E8: ='Monthly data'!E43 -> 20.66 | F8: ='Monthly data'!E44 -> 21.68 | G8: ='Monthly data'!E45 -> 22 | H8: ='Monthly data'!E46 -> 23.08 | I8: ='Monthly data'!E47 -> 23.65 | J8: ='Monthly data'!E48 -> 23.83 | K8: ='Monthly data'!E49 -> 23.54 | L8: ='Monthly data'!E50 -> 21.46 | M8: ='Monthly data'!E51 -> 20.13 | N8: ='Monthly data'!E52 -> 17.98 | O8: =IF(COUNT(C8:N8)=12,AVERAGE(C8:N8),"") -> 21.2625
A9: 2010/11 | B9: =ENSO!C9 -> La Niña | C9: ='Monthly data'!E53 -> 18.72 | D9: ='Monthly data'!E54 -> 16.98 | E9: ='Monthly data'!E55 -> 19.08 | F9: ='Monthly data'!E56 -> 20.84 | G9: ='Monthly data'!E57 -> 21.54 | H9: ='Monthly data'!E58 -> 22.62 | I9: ='Monthly data'!E59 -> 22.67 | J9: ='Monthly data'!E60 -> 22.68 | K9: ='Monthly data'!E61 -> 22.5 | L9: ='Monthly data'!E62 -> 21.64 | M9: ='Monthly data'!E63 -> 18.78 | N9: ='Monthly data'!E64 -> 18.01 | O9: =IF(COUNT(C9:N9)=12,AVERAGE(C9:N9),"") -> 20.505
A10: 2011/12 | B10: =ENSO!C10 -> La Niña | C10: ='Monthly data'!E65 -> 17.18 | D10: ='Monthly data'!E66 -> 18.18 | E10: ='Monthly data'!E67 -> 17.55 | F10: ='Monthly data'!E68 -> 20.49 | G10: ='Monthly data'!E69 -> 19.79 | H10: ='Monthly data'!E70 -> 21.58 | I10: ='Monthly data'!E71 -> 21.92 | J10: ='Monthly data'!E72 -> 21.69 | K10: ='Monthly data'!E73 -> 21.8 | L10: ='Monthly data'!E74 -> 21.75 | M10: ='Monthly data'!E75 -> 19.65 | N10: ='Monthly data'!E76 -> 19.77 | O10: =IF(COUNT(C10:N10)=12,AVERAGE(C10:N10),"") -> 20.1125
A11: 2012/13 | B11: =ENSO!C11 -> Neutral | C11: ='Monthly data'!E77 -> 17.81 | D11: ='Monthly data'!E78 -> 18.02 | E11: ='Monthly data'!E79 -> 19.14 | F11: ='Monthly data'!E80 -> 20.12 | G11: ='Monthly data'!E81 -> 21.66 | H11: ='Monthly data'!E82 -> 22.81 | I11: ='Monthly data'!E83 -> 22.88 | J11: ='Monthly data'!E84 -> 22.64 | K11: ='Monthly data'!E85 -> 23.27 | L11: ='Monthly data'!E86 -> 21.25 | M11: ='Monthly data'!E87 -> 19.85 | N11: ='Monthly data'!E88 -> 19.54 | O11: =IF(COUNT(C11:N11)=12,AVERAGE(C11:N11),"") -> 20.749167
A12: 2013/14 | B12: =ENSO!C12 -> Neutral | C12: ='Monthly data'!E89 -> 18.85 | D12: ='Monthly data'!E90 -> 18.07 | E12: ='Monthly data'!E91 -> 19.59 | F12: ='Monthly data'!E92 -> 20.09 | G12: ='Monthly data'!E93 -> 21.1 | H12: ='Monthly data'!E94 -> 22.48 | I12: ='Monthly data'!E95 -> 22 | J12: ='Monthly data'!E96 -> 21.96 | K12: ='Monthly data'!E97 -> 22.17 | L12: ='Monthly data'!E98 -> 21.45 | M12: ='Monthly data'!E99 -> 20.05 | N12: ='Monthly data'!E100 -> 18.77 | O12: =IF(COUNT(C12:N12)=12,AVERAGE(C12:N12),"") -> 20.548333
A13: 2014/15 | B13: =ENSO!C13 -> El Niño | C13: ='Monthly data'!E101 -> 18.29 | D13: ='Monthly data'!E102 -> 17.49 | E13: ='Monthly data'!E103 -> 19.09 | F13: ='Monthly data'!E104 -> 19.97 | G13: ='Monthly data'!E105 -> 20.98 | H13: ='Monthly data'!E106 -> 21.53 | I13: ='Monthly data'!E107 -> 22.61 | J13: ='Monthly data'!E108 -> 23.04 | K13: ='Monthly data'!E109 -> 22.6 | L13: ='Monthly data'!E110 -> 21.58 | M13: ='Monthly data'!E111 -> 20.13 | N13: ='Monthly data'!E112 -> 19.76 | O13: =IF(COUNT(C13:N13)=12,AVERAGE(C13:N13),"") -> 20.589167
A14: 2015/16 | B14: =ENSO!C14 -> El Niño | C14: ='Monthly data'!E113 -> 18.9 | D14: ='Monthly data'!E114 -> 18.35 | E14: ='Monthly data'!E115 -> 20.88 | F14: ='Monthly data'!E116 -> 21.8 | G14: ='Monthly data'!E117 -> 23.38 | H14: ='Monthly data'!E118 -> 23.65 | I14: ='Monthly data'!E119 -> 23.67 | J14: ='Monthly data'!E120 -> 23.41 | K14: ='Monthly data'!E121 -> 23.66 | L14: ='Monthly data'!E122 -> 22.71 | M14: ='Monthly data'!E123 -> 20.94 | N14: ='Monthly data'!E124 -> 19.01 | O14: =IF(COUNT(C14:N14)=12,AVERAGE(C14:N14),"") -> 21.696667
A15: 2016/17 | B15: =ENSO!C15 -> Neutral | C15: ='Monthly data'!E125 -> 18.33 | D15: ='Monthly data'!E126 -> 19.38 | E15: ='Monthly data'!E127 -> 20.28 | F15: ='Monthly data'!E128 -> 21.2 | G15: ='Monthly data'!E129 -> 21.54 | H15: ='Monthly data'!E130 -> 22.89 | I15: ='Monthly data'!E131 -> 23.37 | J15: ='Monthly data'!E132 -> 22.8 | K15: ='Monthly data'!E133 -> 22.77 | L15: ='Monthly data'!E134 -> 21.84 | M15: ='Monthly data'!E135 -> 20.27 | N15: ='Monthly data'!E136 -> 19.46 | O15: =IF(COUNT(C15:N15)=12,AVERAGE(C15:N15),"") -> 21.1775
A16: 2017/18 | B16: =ENSO!C16 -> La Niña | C16: ='Monthly data'!E137 -> 17.59 | D16: ='Monthly data'!E138 -> 17.26 | E16: ='Monthly data'!E139 -> 18.63 | F16: ='Monthly data'!E140 -> 21.25 | G16: ='Monthly data'!E141 -> 21.43 | H16: ='Monthly data'!E142 -> 22.27 | I16: ='Monthly data'!E143 -> 22.98 | J16: ='Monthly data'!E144 -> 22.65 | K16: ='Monthly data'!E145 -> 22.99 | L16: ='Monthly data'!E146 -> 21.31 | M16: ='Monthly data'!E147 -> 19.82 | N16: ='Monthly data'!E148 -> 19.3 | O16: =IF(COUNT(C16:N16)=12,AVERAGE(C16:N16),"") -> 20.623333
A17: 2018/19 | B17: =ENSO!C17 -> El Niño | C17: ='Monthly data'!E149 -> 17.71 | D17: ='Monthly data'!E150 -> 19.12 | E17: ='Monthly data'!E151 -> 20.13 | F17: ='Monthly data'!E152 -> 21.63 | G17: ='Monthly data'!E153 -> 21.61 | H17: ='Monthly data'!E154 -> 22.3 | I17: ='Monthly data'!E155 -> 23.02 | J17: ='Monthly data'!E156 -> 24.14 | K17: ='Monthly data'!E157 -> 23.67 | L17: ='Monthly data'!E158 -> 23.14 | M17: ='Monthly data'!E159 -> 21.86 | N17: ='Monthly data'!E160 -> 19.59 | O17: =IF(COUNT(C17:N17)=12,AVERAGE(C17:N17),"") -> 21.493333
A18: 2019/20 | B18: =ENSO!C18 -> El Niño | C18: ='Monthly data'!E161 -> 18.19 | D18: ='Monthly data'!E162 -> 18.64 | E18: ='Monthly data'!E163 -> 20.3 | F18: ='Monthly data'!E164 -> 21.24 | G18: ='Monthly data'!E165 -> 21.96 | H18: ='Monthly data'!E166 -> 22.41 | I18: ='Monthly data'!E167 -> 23.07 | J18: ='Monthly data'!E168 -> 23.61 | K18: ='Monthly data'!E169 -> 22.13 | L18: ='Monthly data'!E170 -> 21.49 | M18: ='Monthly data'!E171 -> 19.29 | N18: ='Monthly data'!E172 -> 19.14 | O18: =IF(COUNT(C18:N18)=12,AVERAGE(C18:N18),"") -> 20.955833
A19: 2020/21 | B19: =ENSO!C19 -> La Niña | C19: ='Monthly data'!E173 -> 18.12 | D19: ='Monthly data'!E174 -> 18.46 | E19: ='Monthly data'!E175 -> 19.69 | F19: ='Monthly data'!E176 -> 21.76 | G19: ='Monthly data'!E177 -> 21.51 | H19: ='Monthly data'!E178 -> 22.55 | I19: ='Monthly data'!E179 -> 22.55 | J19: ='Monthly data'!E180 -> 22.74 | K19: ='Monthly data'!E181 -> 22.25 | L19: ='Monthly data'!E182 -> 21.35 | M19: ='Monthly data'!E183 -> 19.96 | N19: ='Monthly data'!E184 -> 18.74 | O19: =IF(COUNT(C19:N19)=12,AVERAGE(C19:N19),"") -> 20.806667
A20: 2021/22 | B20: =ENSO!C20 -> La Niña | C20: ='Monthly data'!E185 -> 17.63 | D20: ='Monthly data'!E186 -> 18.34 | E20: ='Monthly data'!E187 -> 20.17 | F20: ='Monthly data'!E188 -> 21.41 | G20: ='Monthly data'!E189 -> 20.72 | H20: ='Monthly data'!E190 -> 21.73 | I20: ='Monthly data'!E191 -> 22.39 | J20: ='Monthly data'!E192 -> 22.71 | K20: ='Monthly data'!E193 -> 22.28 | L20: ='Monthly data'!E194 -> 21.75 | M20: ='Monthly data'!E195 -> 19.68 | N20: ='Monthly data'!E196 -> 18.1 | O20: =IF(COUNT(C20:N20)=12,AVERAGE(C20:N20),"") -> 20.575833
A21: 2022/23 | B21: =ENSO!C21 -> La Niña | C21: ='Monthly data'!E197 -> 18 | D21: ='Monthly data'!E198 -> 18.32 | E21: ='Monthly data'!E199 -> 19 | F21: ='Monthly data'!E200 -> 21.62 | G21: ='Monthly data'!E201 -> 20.86 | H21: ='Monthly data'!E202 -> 21.86 | I21: ='Monthly data'!E203 -> 22.51 | J21: ='Monthly data'!E204 -> 22.9 | K21: ='Monthly data'!E205 -> 22.41 | L21: ='Monthly data'!E206 -> 22.13 | M21: ='Monthly data'!E207 -> 19.61 | N21: ='Monthly data'!E208 -> 18.54 | O21: =IF(COUNT(C21:N21)=12,AVERAGE(C21:N21),"") -> 20.646667
A22: 2023/24 | B22: =ENSO!C22 -> El Niño | C22: ='Monthly data'!E209 -> 18.3 | D22: ='Monthly data'!E210 -> 19.39 | E22: ='Monthly data'!E211 -> 20.63 | F22: ='Monthly data'!E212 -> 22.32 | G22: ='Monthly data'!E213 -> 22.98 | H22: ='Monthly data'!E214 -> 23.68 | I22: ='Monthly data'!E215 -> 23.57 | J22: ='Monthly data'!E216 -> 23.23 | K22: ='Monthly data'!E217 -> 23.86 | L22: ='Monthly data'!E218 -> 22.65 | M22: ='Monthly data'!E219 -> 21.7 | N22: ='Monthly data'!E220 -> 19.7 | O22: =IF(COUNT(C22:N22)=12,AVERAGE(C22:N22),"") -> 21.834167
A23: 2024/25 | B23: =ENSO!C23 -> Neutral | C23: ='Monthly data'!E221 -> 18.95 | D23: ='Monthly data'!E222 -> 18.62 | E23: ='Monthly data'!E223 -> 20.4 | F23: ='Monthly data'!E224 -> 21.58 | G23: ='Monthly data'!E225 -> 21.47 | H23: ='Monthly data'!E226 -> 23.17 | I23: ='Monthly data'!E227 -> 23.21 | J23: ='Monthly data'!E228 -> 23.01 | K23: ='Monthly data'!E229 -> 22.88 | L23: ='Monthly data'!E230 -> 22.28 | M23: ='Monthly data'!E231 -> 20.24 | N23: ='Monthly data'!E232 -> 18.78 | O23: =IF(COUNT(C23:N23)=12,AVERAGE(C23:N23),"") -> 21.215833
A24: 2025/26 | B24: =ENSO!C24 -> Neutral | C24: ='Monthly data'!E233 -> 17.68 | D24: ='Monthly data'!E234 -> 17.79 | E24: ='Monthly data'!E235 -> 18.85 | F24: ='Monthly data'!E236 -> 20.15 | G24: ='Monthly data'!E237 -> 21.24 | H24: ='Monthly data'!E238 -> 22.81 | I24: ='Monthly data'!E239 -> 22.56 | J24: ='Monthly data'!E240 -> 23.61 | K24: ='Monthly data'!E241 -> 22.6 | L24: ='Monthly data'!E242 -> 21.62 | M24: ='Monthly data'!E243 -> 20.83 | N24: ='Monthly data'!E244 -> 18.64 | O24: =IF(COUNT(C24:N24)=12,AVERAGE(C24:N24),"") -> 20.698333
A25: 2026/27 | B25: =ENSO!C25 -> El Niño* | C25: ='Monthly data'!E245 -> 18.63 | D25: ='Monthly data'!E246 -> 19.78 | O25: =IF(COUNT(C25:N25)=12,AVERAGE(C25:N25),"")
A27: Averages
A28: El Niño average (7 seasons) | C28: =AVERAGEIF($B$5:$B$25,"El Niño",C$5:C$25) -> 18.044286 | D28: =AVERAGEIF($B$5:$B$25,"El Niño",D$5:D$25) -> 18.602857 | E28: =AVERAGEIF($B$5:$B$25,"El Niño",E$5:E$25) -> 20.058571 | F28: =AVERAGEIF($B$5:$B$25,"El Niño",F$5:F$25) -> 21.328571 | G28: =AVERAGEIF($B$5:$B$25,"El Niño",G$5:G$25) -> 22.035714 | H28: =AVERAGEIF($B$5:$B$25,"El Niño",H$5:H$25) -> 22.671429 | I28: =AVERAGEIF($B$5:$B$25,"El Niño",I$5:I$25) -> 23.244286 | J28: =AVERAGEIF($B$5:$B$25,"El Niño",J$5:J$25) -> 23.347143 | ... O28: =AVERAGEIF($B$5:$B$25,"El Niño",O$5:O$25) -> 21.169881
A29: La Niña average (8 seasons) | C29: =AVERAGEIF($B$5:$B$25,"La Niña",C$5:C$25) -> 17.805 | D29: =AVERAGEIF($B$5:$B$25,"La Niña",D$5:D$25) -> 17.91875 | E29: =AVERAGEIF($B$5:$B$25,"La Niña",E$5:E$25) -> 18.935 | F29: =AVERAGEIF($B$5:$B$25,"La Niña",F$5:F$25) -> 21.07625 | G29: =AVERAGEIF($B$5:$B$25,"La Niña",G$5:G$25) -> 21.15625 | H29: =AVERAGEIF($B$5:$B$25,"La Niña",H$5:H$25) -> 22.05625 | I29: =AVERAGEIF($B$5:$B$25,"La Niña",I$5:I$25) -> 22.5025 | J29: =AVERAGEIF($B$5:$B$25,"La Niña",J$5:J$25) -> 22.60375 | ... O29: =AVERAGEIF($B$5:$B$25,"La Niña",O$5:O$25) -> 20.546458
A30: Neutral average (5 seasons) | C30: =AVERAGEIF($B$5:$B$25,"Neutral",C$5:C$25) -> 18.324 | D30: =AVERAGEIF($B$5:$B$25,"Neutral",D$5:D$25) -> 18.376 | E30: =AVERAGEIF($B$5:$B$25,"Neutral",E$5:E$25) -> 19.652 | F30: =AVERAGEIF($B$5:$B$25,"Neutral",F$5:F$25) -> 20.628 | G30: =AVERAGEIF($B$5:$B$25,"Neutral",G$5:G$25) -> 21.402 | H30: =AVERAGEIF($B$5:$B$25,"Neutral",H$5:H$25) -> 22.832 | I30: =AVERAGEIF($B$5:$B$25,"Neutral",I$5:I$25) -> 22.804 | J30: =AVERAGEIF($B$5:$B$25,"Neutral",J$5:J$25) -> 22.804 | ... O30: =AVERAGEIF($B$5:$B$25,"Neutral",O$5:O$25) -> 20.877833
A31: All complete seasons (20) | C31: =AVERAGE(C5:C24) -> 18.0185 | D31: =AVERAGE(D5:D24) -> 18.2725 | E31: =AVERAGE(E5:E24) -> 19.5075 | F31: =AVERAGE(F5:F24) -> 21.0525 | G31: =AVERAGE(G5:G24) -> 21.5255 | H31: =AVERAGE(H5:H24) -> 22.4655 | I31: =AVERAGE(I5:I24) -> 22.8375 | J31: =AVERAGE(J5:J24) -> 22.914 | ... O31: =AVERAGE(O5:O24) -> 20.8475
A33: * season not finished — ENSO phase provisional, not included in the phase averages.

Sheet Max temp
A1: Espírito Santo (conilon) — Max temperature (°C) by coffee season
A2: Source: Open-Meteo ERA5-Land, altitude-downscaled, + monthly offsets measured at the INMET stations of the region (models smooth the daily extremes). Values link to 'Monthly data'.
A4: Season | B4: ENSO phase | C4: Jul | D4: Aug | E4: Sep | F4: Oct | G4: Nov | H4: Dec | I4: Jan | J4: Feb | K4: Mar | L4: Apr | M4: May | N4: Jun | O4: Season mean
A5: 2006/07 | B5: =ENSO!C5 -> El Niño | C5: ='Monthly data'!F5 -> 26.75 | D5: ='Monthly data'!F6 -> 27.58 | E5: ='Monthly data'!F7 -> 27.54 | F5: ='Monthly data'!F8 -> 27.5 | G5: ='Monthly data'!F9 -> 28.4 | H5: ='Monthly data'!F10 -> 29.73 | I5: ='Monthly data'!F11 -> 32.22 | J5: ='Monthly data'!F12 -> 30.62 | K5: ='Monthly data'!F13 -> 31.86 | L5: ='Monthly data'!F14 -> 30.73 | M5: ='Monthly data'!F15 -> 28.34 | N5: ='Monthly data'!F16 -> 27.81 | O5: =IF(COUNT(C5:N5)=12,AVERAGE(C5:N5),"") -> 29.09
A6: 2007/08 | B6: =ENSO!C6 -> La Niña | C6: ='Monthly data'!F17 -> 27.8 | D6: ='Monthly data'!F18 -> 27.26 | E6: ='Monthly data'!F19 -> 27.26 | F6: ='Monthly data'!F20 -> 29.72 | G6: ='Monthly data'!F21 -> 31.69 | H6: ='Monthly data'!F22 -> 31.38 | I6: ='Monthly data'!F23 -> 31.51 | J6: ='Monthly data'!F24 -> 32.17 | K6: ='Monthly data'!F25 -> 31.78 | L6: ='Monthly data'!F26 -> 31.67 | M6: ='Monthly data'!F27 -> 28.93 | N6: ='Monthly data'!F28 -> 28.02 | O6: =IF(COUNT(C6:N6)=12,AVERAGE(C6:N6),"") -> 29.9325
A7: 2008/09 | B7: =ENSO!C7 -> La Niña | C7: ='Monthly data'!F29 -> 27.03 | D7: ='Monthly data'!F30 -> 28.7 | E7: ='Monthly data'!F31 -> 28.89 | F7: ='Monthly data'!F32 -> 30.56 | G7: ='Monthly data'!F33 -> 29.21 | H7: ='Monthly data'!F34 -> 29.92 | I7: ='Monthly data'!F35 -> 31.57 | J7: ='Monthly data'!F36 -> 32.19 | K7: ='Monthly data'!F37 -> 32.94 | L7: ='Monthly data'!F38 -> 30.23 | M7: ='Monthly data'!F39 -> 28.04 | N7: ='Monthly data'!F40 -> 27.09 | O7: =IF(COUNT(C7:N7)=12,AVERAGE(C7:N7),"") -> 29.6975
A8: 2009/10 | B8: =ENSO!C8 -> El Niño | C8: ='Monthly data'!F41 -> 27.68 | D8: ='Monthly data'!F42 -> 27.61 | E8: ='Monthly data'!F43 -> 30.31 | F8: ='Monthly data'!F44 -> 29.43 | G8: ='Monthly data'!F45 -> 31.11 | H8: ='Monthly data'!F46 -> 32.66 | I8: ='Monthly data'!F47 -> 34.4 | J8: ='Monthly data'!F48 -> 34.96 | K8: ='Monthly data'!F49 -> 32.64 | L8: ='Monthly data'!F50 -> 30.07 | M8: ='Monthly data'!F51 -> 29.08 | N8: ='Monthly data'!F52 -> 27.42 | O8: =IF(COUNT(C8:N8)=12,AVERAGE(C8:N8),"") -> 30.614167
A9: 2010/11 | B9: =ENSO!C9 -> La Niña | C9: ='Monthly data'!F53 -> 26.79 | D9: ='Monthly data'!F54 -> 27.19 | E9: ='Monthly data'!F55 -> 28.79 | F9: ='Monthly data'!F56 -> 29.44 | G9: ='Monthly data'!F57 -> 29.28 | H9: ='Monthly data'!F58 -> 31.63 | I9: ='Monthly data'!F59 -> 32.18 | J9: ='Monthly data'!F60 -> 33.31 | K9: ='Monthly data'!F61 -> 30.88 | L9: ='Monthly data'!F62 -> 29.61 | M9: ='Monthly data'!F63 -> 27.6 | N9: ='Monthly data'!F64 -> 27.29 | O9: =IF(COUNT(C9:N9)=12,AVERAGE(C9:N9),"") -> 29.499167
A10: 2011/12 | B10: =ENSO!C10 -> La Niña | C10: ='Monthly data'!F65 -> 26.8 | D10: ='Monthly data'!F66 -> 28.48 | E10: ='Monthly data'!F67 -> 27.67 | F10: ='Monthly data'!F68 -> 27.58 | G10: ='Monthly data'!F69 -> 27.47 | H10: ='Monthly data'!F70 -> 29.55 | I10: ='Monthly data'!F71 -> 30.81 | J10: ='Monthly data'!F72 -> 31.58 | K10: ='Monthly data'!F73 -> 31.83 | L10: ='Monthly data'!F74 -> 31.62 | M10: ='Monthly data'!F75 -> 28.09 | N10: ='Monthly data'!F76 -> 28.97 | O10: =IF(COUNT(C10:N10)=12,AVERAGE(C10:N10),"") -> 29.204167
A11: 2012/13 | B11: =ENSO!C11 -> Neutral | C11: ='Monthly data'!F77 -> 27.98 | D11: ='Monthly data'!F78 -> 26.4 | E11: ='Monthly data'!F79 -> 28.73 | F11: ='Monthly data'!F80 -> 30.17 | G11: ='Monthly data'!F81 -> 28.97 | H11: ='Monthly data'!F82 -> 33.14 | I11: ='Monthly data'!F83 -> 32.24 | J11: ='Monthly data'!F84 -> 32.64 | K11: ='Monthly data'!F85 -> 33.6 | L11: ='Monthly data'!F86 -> 29.76 | M11: ='Monthly data'!F87 -> 29.09 | N11: ='Monthly data'!F88 -> 28.51 | O11: =IF(COUNT(C11:N11)=12,AVERAGE(C11:N11),"") -> 30.1025
A12: 2013/14 | B12: =ENSO!C12 -> Neutral | C12: ='Monthly data'!F89 -> 27.43 | D12: ='Monthly data'!F90 -> 27.73 | E12: ='Monthly data'!F91 -> 28.65 | F12: ='Monthly data'!F92 -> 28.63 | G12: ='Monthly data'!F93 -> 29.63 | H12: ='Monthly data'!F94 -> 30.42 | I12: ='Monthly data'!F95 -> 31.41 | J12: ='Monthly data'!F96 -> 31.9 | K12: ='Monthly data'!F97 -> 31.67 | L12: ='Monthly data'!F98 -> 30.62 | M12: ='Monthly data'!F99 -> 29.51 | N12: ='Monthly data'!F100 -> 27.1 | O12: =IF(COUNT(C12:N12)=12,AVERAGE(C12:N12),"") -> 29.558333
A13: 2014/15 | B13: =ENSO!C13 -> El Niño | C13: ='Monthly data'!F101 -> 26.23 | D13: ='Monthly data'!F102 -> 27.3 | E13: ='Monthly data'!F103 -> 29.2 | F13: ='Monthly data'!F104 -> 29.05 | G13: ='Monthly data'!F105 -> 28.98 | H13: ='Monthly data'!F106 -> 30.42 | I13: ='Monthly data'!F107 -> 33.73 | J13: ='Monthly data'!F108 -> 33.22 | K13: ='Monthly data'!F109 -> 32.51 | L13: ='Monthly data'!F110 -> 31.09 | M13: ='Monthly data'!F111 -> 28.85 | N13: ='Monthly data'!F112 -> 27.81 | O13: =IF(COUNT(C13:N13)=12,AVERAGE(C13:N13),"") -> 29.865833
A14: 2015/16 | B14: =ENSO!C14 -> El Niño | C14: ='Monthly data'!F113 -> 27.41 | D14: ='Monthly data'!F114 -> 27.95 | E14: ='Monthly data'!F115 -> 31.58 | F14: ='Monthly data'!F116 -> 31.73 | G14: ='Monthly data'!F117 -> 33.45 | H14: ='Monthly data'!F118 -> 34.65 | I14: ='Monthly data'!F119 -> 32.93 | J14: ='Monthly data'!F120 -> 34.37 | K14: ='Monthly data'!F121 -> 34 | L14: ='Monthly data'!F122 -> 33.24 | M14: ='Monthly data'!F123 -> 30.68 | N14: ='Monthly data'!F124 -> 28.89 | O14: =IF(COUNT(C14:N14)=12,AVERAGE(C14:N14),"") -> 31.74
A15: 2016/17 | B15: =ENSO!C15 -> Neutral | C15: ='Monthly data'!F125 -> 28.08 | D15: ='Monthly data'!F126 -> 29.6 | E15: ='Monthly data'!F127 -> 29.83 | F15: ='Monthly data'!F128 -> 29.47 | G15: ='Monthly data'!F129 -> 29.62 | H15: ='Monthly data'!F130 -> 31.86 | I15: ='Monthly data'!F131 -> 34.11 | J15: ='Monthly data'!F132 -> 32.04 | K15: ='Monthly data'!F133 -> 33.37 | L15: ='Monthly data'!F134 -> 31.34 | M15: ='Monthly data'!F135 -> 28.55 | N15: ='Monthly data'!F136 -> 28.24 | O15: =IF(COUNT(C15:N15)=12,AVERAGE(C15:N15),"") -> 30.509167
A16: 2017/18 | B16: =ENSO!C16 -> La Niña | C16: ='Monthly data'!F137 -> 25.95 | D16: ='Monthly data'!F138 -> 27.18 | E16: ='Monthly data'!F139 -> 27.34 | F16: ='Monthly data'!F140 -> 31.16 | G16: ='Monthly data'!F141 -> 28.96 | H16: ='Monthly data'!F142 -> 30.39 | I16: ='Monthly data'!F143 -> 32.72 | J16: ='Monthly data'!F144 -> 31.06 | K16: ='Monthly data'!F145 -> 32.04 | L16: ='Monthly data'!F146 -> 29.41 | M16: ='Monthly data'!F147 -> 27.94 | N16: ='Monthly data'!F148 -> 27.63 | O16: =IF(COUNT(C16:N16)=12,AVERAGE(C16:N16),"") -> 29.315
A17: 2018/19 | B17: =ENSO!C17 -> El Niño | C17: ='Monthly data'!F149 -> 27.36 | D17: ='Monthly data'!F150 -> 27.6 | E17: ='Monthly data'!F151 -> 29.14 | F17: ='Monthly data'!F152 -> 29.71 | G17: ='Monthly data'!F153 -> 29.25 | H17: ='Monthly data'!F154 -> 30.77 | I17: ='Monthly data'!F155 -> 33.03 | J17: ='Monthly data'!F156 -> 35.2 | K17: ='Monthly data'!F157 -> 33.66 | L17: ='Monthly data'!F158 -> 32.6 | M17: ='Monthly data'!F159 -> 30.61 | N17: ='Monthly data'!F160 -> 28.63 | O17: =IF(COUNT(C17:N17)=12,AVERAGE(C17:N17),"") -> 30.63
A18: 2019/20 | B18: =ENSO!C18 -> El Niño | C18: ='Monthly data'!F161 -> 28.11 | D18: ='Monthly data'!F162 -> 27.54 | E18: ='Monthly data'!F163 -> 29.83 | F18: ='Monthly data'!F164 -> 29.94 | G18: ='Monthly data'!F165 -> 30.7 | H18: ='Monthly data'!F166 -> 31.14 | I18: ='Monthly data'!F167 -> 32.29 | J18: ='Monthly data'!F168 -> 32.84 | K18: ='Monthly data'!F169 -> 30.24 | L18: ='Monthly data'!F170 -> 29.96 | M18: ='Monthly data'!F171 -> 28.94 | N18: ='Monthly data'!F172 -> 28.92 | O18: =IF(COUNT(C18:N18)=12,AVERAGE(C18:N18),"") -> 30.0375
A19: 2020/21 | B19: =ENSO!C19 -> La Niña | C19: ='Monthly data'!F173 -> 27.66 | D19: ='Monthly data'!F174 -> 27.21 | E19: ='Monthly data'!F175 -> 30.1 | F19: ='Monthly data'!F176 -> 30.34 | G19: ='Monthly data'!F177 -> 28.92 | H19: ='Monthly data'!F178 -> 31.75 | I19: ='Monthly data'!F179 -> 33.16 | J19: ='Monthly data'!F180 -> 31.51 | K19: ='Monthly data'!F181 -> 32.94 | L19: ='Monthly data'!F182 -> 31.32 | M19: ='Monthly data'!F183 -> 30.41 | N19: ='Monthly data'!F184 -> 28.58 | O19: =IF(COUNT(C19:N19)=12,AVERAGE(C19:N19),"") -> 30.325
A20: 2021/22 | B20: =ENSO!C20 -> La Niña | C20: ='Monthly data'!F185 -> 28.05 | D20: ='Monthly data'!F186 -> 27.63 | E20: ='Monthly data'!F187 -> 30.15 | F20: ='Monthly data'!F188 -> 28.74 | G20: ='Monthly data'!F189 -> 28.7 | H20: ='Monthly data'!F190 -> 29.65 | I20: ='Monthly data'!F191 -> 32.03 | J20: ='Monthly data'!F192 -> 31.54 | K20: ='Monthly data'!F193 -> 31.9 | L20: ='Monthly data'!F194 -> 32.09 | M20: ='Monthly data'!F195 -> 29.63 | N20: ='Monthly data'!F196 -> 28.47 | O20: =IF(COUNT(C20:N20)=12,AVERAGE(C20:N20),"") -> 29.881667
A21: 2022/23 | B21: =ENSO!C21 -> La Niña | C21: ='Monthly data'!F197 -> 27.53 | D21: ='Monthly data'!F198 -> 27.93 | E21: ='Monthly data'!F199 -> 28.7 | F21: ='Monthly data'!F200 -> 30.89 | G21: ='Monthly data'!F201 -> 28.64 | H21: ='Monthly data'!F202 -> 29.09 | I21: ='Monthly data'!F203 -> 31.19 | J21: ='Monthly data'!F204 -> 33.03 | K21: ='Monthly data'!F205 -> 32.68 | L21: ='Monthly data'!F206 -> 31.56 | M21: ='Monthly data'!F207 -> 28.71 | N21: ='Monthly data'!F208 -> 28.34 | O21: =IF(COUNT(C21:N21)=12,AVERAGE(C21:N21),"") -> 29.8575
A22: 2023/24 | B22: =ENSO!C22 -> El Niño | C22: ='Monthly data'!F209 -> 27.63 | D22: ='Monthly data'!F210 -> 28.96 | E22: ='Monthly data'!F211 -> 29.6 | F22: ='Monthly data'!F212 -> 31.37 | G22: ='Monthly data'!F213 -> 34.51 | H22: ='Monthly data'!F214 -> 34.7 | I22: ='Monthly data'!F215 -> 32.55 | J22: ='Monthly data'!F216 -> 32.46 | K22: ='Monthly data'!F217 -> 33.12 | L22: ='Monthly data'!F218 -> 31.87 | M22: ='Monthly data'!F219 -> 31.54 | N22: ='Monthly data'!F220 -> 29.53 | O22: =IF(COUNT(C22:N22)=12,AVERAGE(C22:N22),"") -> 31.486667
A23: 2024/25 | B23: =ENSO!C23 -> Neutral | C23: ='Monthly data'!F221 -> 29.14 | D23: ='Monthly data'!F222 -> 28.9 | E23: ='Monthly data'!F223 -> 31.16 | F23: ='Monthly data'!F224 -> 30.39 | G23: ='Monthly data'!F225 -> 29.66 | H23: ='Monthly data'!F226 -> 32.68 | I23: ='Monthly data'!F227 -> 31.9 | J23: ='Monthly data'!F228 -> 33.24 | K23: ='Monthly data'!F229 -> 32.77 | L23: ='Monthly data'!F230 -> 30.65 | M23: ='Monthly data'!F231 -> 28.08 | N23: ='Monthly data'!F232 -> 27.85 | O23: =IF(COUNT(C23:N23)=12,AVERAGE(C23:N23),"") -> 30.535
A24: 2025/26 | B24: =ENSO!C24 -> Neutral | C24: ='Monthly data'!F233 -> 27.03 | D24: ='Monthly data'!F234 -> 27.4 | E24: ='Monthly data'!F235 -> 28.05 | F24: ='Monthly data'!F236 -> 28.27 | G24: ='Monthly data'!F237 -> 30.65 | H24: ='Monthly data'!F238 -> 32.48 | I24: ='Monthly data'!F239 -> 32.39 | J24: ='Monthly data'!F240 -> 33.44 | K24: ='Monthly data'!F241 -> 31.25 | L24: ='Monthly data'!F242 -> 30.81 | M24: ='Monthly data'!F243 -> 29.26 | N24: ='Monthly data'!F244 -> 28.44 | O24: =IF(COUNT(C24:N24)=12,AVERAGE(C24:N24),"") -> 29.955833
A25: 2026/27 | B25: =ENSO!C25 -> El Niño* | C25: ='Monthly data'!F245 -> 28.15 | D25: ='Monthly data'!F246 -> 29.63 | O25: =IF(COUNT(C25:N25)=12,AVERAGE(C25:N25),"")
A27: Averages
A28: El Niño average (7 seasons) | C28: =AVERAGEIF($B$5:$B$25,"El Niño",C$5:C$25) -> 27.31 | D28: =AVERAGEIF($B$5:$B$25,"El Niño",D$5:D$25) -> 27.791429 | E28: =AVERAGEIF($B$5:$B$25,"El Niño",E$5:E$25) -> 29.6 | F28: =AVERAGEIF($B$5:$B$25,"El Niño",F$5:F$25) -> 29.818571 | G28: =AVERAGEIF($B$5:$B$25,"El Niño",G$5:G$25) -> 30.914286 | H28: =AVERAGEIF($B$5:$B$25,"El Niño",H$5:H$25) -> 32.01 | I28: =AVERAGEIF($B$5:$B$25,"El Niño",I$5:I$25) -> 33.021429 | J28: =AVERAGEIF($B$5:$B$25,"El Niño",J$5:J$25) -> 33.381429 | ... O28: =AVERAGEIF($B$5:$B$25,"El Niño",O$5:O$25) -> 30.494881
A29: La Niña average (8 seasons) | C29: =AVERAGEIF($B$5:$B$25,"La Niña",C$5:C$25) -> 27.20125 | D29: =AVERAGEIF($B$5:$B$25,"La Niña",D$5:D$25) -> 27.6975 | E29: =AVERAGEIF($B$5:$B$25,"La Niña",E$5:E$25) -> 28.6125 | F29: =AVERAGEIF($B$5:$B$25,"La Niña",F$5:F$25) -> 29.80375 | G29: =AVERAGEIF($B$5:$B$25,"La Niña",G$5:G$25) -> 29.10875 | H29: =AVERAGEIF($B$5:$B$25,"La Niña",H$5:H$25) -> 30.42 | I29: =AVERAGEIF($B$5:$B$25,"La Niña",I$5:I$25) -> 31.89625 | J29: =AVERAGEIF($B$5:$B$25,"La Niña",J$5:J$25) -> 32.04875 | ... O29: =AVERAGEIF($B$5:$B$25,"La Niña",O$5:O$25) -> 29.714063
A30: Neutral average (5 seasons) | C30: =AVERAGEIF($B$5:$B$25,"Neutral",C$5:C$25) -> 27.932 | D30: =AVERAGEIF($B$5:$B$25,"Neutral",D$5:D$25) -> 28.006 | E30: =AVERAGEIF($B$5:$B$25,"Neutral",E$5:E$25) -> 29.284 | F30: =AVERAGEIF($B$5:$B$25,"Neutral",F$5:F$25) -> 29.386 | G30: =AVERAGEIF($B$5:$B$25,"Neutral",G$5:G$25) -> 29.706 | H30: =AVERAGEIF($B$5:$B$25,"Neutral",H$5:H$25) -> 32.116 | I30: =AVERAGEIF($B$5:$B$25,"Neutral",I$5:I$25) -> 32.41 | J30: =AVERAGEIF($B$5:$B$25,"Neutral",J$5:J$25) -> 32.652 | ... O30: =AVERAGEIF($B$5:$B$25,"Neutral",O$5:O$25) -> 30.132167
A31: All complete seasons (20) | C31: =AVERAGE(C5:C24) -> 27.422 | D31: =AVERAGE(D5:D24) -> 27.8075 | E31: =AVERAGE(E5:E24) -> 29.126 | F31: =AVERAGE(F5:F24) -> 29.7045 | G31: =AVERAGE(G5:G24) -> 29.89 | H31: =AVERAGE(H5:H24) -> 31.4005 | I31: =AVERAGE(I5:I24) -> 32.4185 | J31: =AVERAGE(J5:J24) -> 32.666 | ... O31: =AVERAGE(O5:O24) -> 30.091875
A33: * season not finished — ENSO phase provisional, not included in the phase averages.

Sheet Rainfall
A1: Espírito Santo (conilon) — Monthly rainfall (mm) by coffee season
A2: Source: CHIRPS v3.0 (UCSB Climate Hazards Center), 0.05° satellite + rain gauges. Values link to 'Monthly data'.
A4: Season | B4: ENSO phase | C4: Jul | D4: Aug | E4: Sep | F4: Oct | G4: Nov | H4: Dec | I4: Jan | J4: Feb | K4: Mar | L4: Apr | M4: May | N4: Jun | O4: Season total
A5: 2006/07 | B5: =ENSO!C5 -> El Niño | C5: ='Monthly data'!G5 -> 56.48 | D5: ='Monthly data'!G6 -> 30.43 | E5: ='Monthly data'!G7 -> 87.11 | F5: ='Monthly data'!G8 -> 183.92 | G5: ='Monthly data'!G9 -> 313.24 | H5: ='Monthly data'!G10 -> 259.84 | I5: ='Monthly data'!G11 -> 124.89 | J5: ='Monthly data'!G12 -> 269.29 | K5: ='Monthly data'!G13 -> 29.84 | L5: ='Monthly data'!G14 -> 159.86 | M5: ='Monthly data'!G15 -> 21.76 | N5: ='Monthly data'!G16 -> 16.66 | O5: =IF(COUNT(C5:N5)=12,SUM(C5:N5),"") -> 1553.32
A6: 2007/08 | B6: =ENSO!C6 -> La Niña | C6: ='Monthly data'!G17 -> 18.98 | D6: ='Monthly data'!G18 -> 40.17 | E6: ='Monthly data'!G19 -> 48.62 | F6: ='Monthly data'!G20 -> 30.65 | G6: ='Monthly data'!G21 -> 118.59 | H6: ='Monthly data'!G22 -> 100.75 | I6: ='Monthly data'!G23 -> 162.86 | J6: ='Monthly data'!G24 -> 185.82 | K6: ='Monthly data'!G25 -> 154.92 | L6: ='Monthly data'!G26 -> 111.91 | M6: ='Monthly data'!G27 -> 27.54 | N6: ='Monthly data'!G28 -> 21.92 | O6: =IF(COUNT(C6:N6)=12,SUM(C6:N6),"") -> 1022.73
A7: 2008/09 | B7: =ENSO!C7 -> La Niña | C7: ='Monthly data'!G29 -> 34.08 | D7: ='Monthly data'!G30 -> 27.82 | E7: ='Monthly data'!G31 -> 42.51 | F7: ='Monthly data'!G32 -> 49.63 | G7: ='Monthly data'!G33 -> 391.44 | H7: ='Monthly data'!G34 -> 252.75 | I7: ='Monthly data'!G35 -> 322.08 | J7: ='Monthly data'!G36 -> 19.36 | K7: ='Monthly data'!G37 -> 173.14 | L7: ='Monthly data'!G38 -> 188.7 | M7: ='Monthly data'!G39 -> 23.39 | N7: ='Monthly data'!G40 -> 40.89 | O7: =IF(COUNT(C7:N7)=12,SUM(C7:N7),"") -> 1565.79
A8: 2009/10 | B8: =ENSO!C8 -> El Niño | C8: ='Monthly data'!G41 -> 41.5 | D8: ='Monthly data'!G42 -> 59.93 | E8: ='Monthly data'!G43 -> 42.01 | F8: ='Monthly data'!G44 -> 382.7 | G8: ='Monthly data'!G45 -> 139.48 | H8: ='Monthly data'!G46 -> 103.41 | I8: ='Monthly data'!G47 -> 11.69 | J8: ='Monthly data'!G48 -> 67.7 | K8: ='Monthly data'!G49 -> 155.46 | L8: ='Monthly data'!G50 -> 159.44 | M8: ='Monthly data'!G51 -> 42.32 | N8: ='Monthly data'!G52 -> 19.33 | O8: =IF(COUNT(C8:N8)=12,SUM(C8:N8),"") -> 1224.97
A9: 2010/11 | B9: =ENSO!C9 -> La Niña | C9: ='Monthly data'!G53 -> 78.85 | D9: ='Monthly data'!G54 -> 15.92 | E9: ='Monthly data'!G55 -> 36.29 | F9: ='Monthly data'!G56 -> 83.57 | G9: ='Monthly data'!G57 -> 243.66 | H9: ='Monthly data'!G58 -> 231.56 | I9: ='Monthly data'!G59 -> 90.68 | J9: ='Monthly data'!G60 -> 71.45 | K9: ='Monthly data'!G61 -> 282.31 | L9: ='Monthly data'!G62 -> 162.52 | M9: ='Monthly data'!G63 -> 20.67 | N9: ='Monthly data'!G64 -> 30.77 | O9: =IF(COUNT(C9:N9)=12,SUM(C9:N9),"") -> 1348.25
A10: 2011/12 | B10: =ENSO!C10 -> La Niña | C10: ='Monthly data'!G65 -> 59.3 | D10: ='Monthly data'!G66 -> 20.19 | E10: ='Monthly data'!G67 -> 25.62 | F10: ='Monthly data'!G68 -> 202.23 | G10: ='Monthly data'!G69 -> 224.24 | H10: ='Monthly data'!G70 -> 168.07 | I10: ='Monthly data'!G71 -> 160.27 | J10: ='Monthly data'!G72 -> 23.07 | K10: ='Monthly data'!G73 -> 43.93 | L10: ='Monthly data'!G74 -> 57.69 | M10: ='Monthly data'!G75 -> 59.91 | N10: ='Monthly data'!G76 -> 36.16 | O10: =IF(COUNT(C10:N10)=12,SUM(C10:N10),"") -> 1080.68
A11: 2012/13 | B11: =ENSO!C11 -> Neutral | C11: ='Monthly data'!G77 -> 66.75 | D11: ='Monthly data'!G78 -> 80.68 | E11: ='Monthly data'!G79 -> 48.72 | F11: ='Monthly data'!G80 -> 45.68 | G11: ='Monthly data'!G81 -> 272.43 | H11: ='Monthly data'!G82 -> 14.35 | I11: ='Monthly data'!G83 -> 205.24 | J11: ='Monthly data'!G84 -> 42.79 | K11: ='Monthly data'!G85 -> 62.2 | L11: ='Monthly data'!G86 -> 65.77 | M11: ='Monthly data'!G87 -> 39.75 | N11: ='Monthly data'!G88 -> 41.51 | O11: =IF(COUNT(C11:N11)=12,SUM(C11:N11),"") -> 985.87
A12: 2013/14 | B12: =ENSO!C12 -> Neutral | C12: ='Monthly data'!G89 -> 41.19 | D12: ='Monthly data'!G90 -> 48.28 | E12: ='Monthly data'!G91 -> 79.22 | F12: ='Monthly data'!G92 -> 143.16 | G12: ='Monthly data'!G93 -> 154.09 | H12: ='Monthly data'!G94 -> 591.91 | I12: ='Monthly data'!G95 -> 86.5 | J12: ='Monthly data'!G96 -> 43.72 | K12: ='Monthly data'!G97 -> 87.08 | L12: ='Monthly data'!G98 -> 66.83 | M12: ='Monthly data'!G99 -> 22.44 | N12: ='Monthly data'!G100 -> 57.14 | O12: =IF(COUNT(C12:N12)=12,SUM(C12:N12),"") -> 1421.56
A13: 2014/15 | B13: =ENSO!C13 -> El Niño | C13: ='Monthly data'!G101 -> 61.89 | D13: ='Monthly data'!G102 -> 99.79 | E13: ='Monthly data'!G103 -> 34.5 | F13: ='Monthly data'!G104 -> 175.12 | G13: ='Monthly data'!G105 -> 115.41 | H13: ='Monthly data'!G106 -> 86.45 | I13: ='Monthly data'!G107 -> 11.79 | J13: ='Monthly data'!G108 -> 123.47 | K13: ='Monthly data'!G109 -> 135.39 | L13: ='Monthly data'!G110 -> 44.82 | M13: ='Monthly data'!G111 -> 70.83 | N13: ='Monthly data'!G112 -> 53.51 | O13: =IF(COUNT(C13:N13)=12,SUM(C13:N13),"") -> 1012.97
A14: 2015/16 | B14: =ENSO!C14 -> El Niño | C14: ='Monthly data'!G113 -> 44.38 | D14: ='Monthly data'!G114 -> 37.13 | E14: ='Monthly data'!G115 -> 15.3 | F14: ='Monthly data'!G116 -> 29.72 | G14: ='Monthly data'!G117 -> 83.63 | H14: ='Monthly data'!G118 -> 90.56 | I14: ='Monthly data'!G119 -> 271.14 | J14: ='Monthly data'!G120 -> 11.27 | K14: ='Monthly data'!G121 -> 31.79 | L14: ='Monthly data'!G122 -> 39.73 | M14: ='Monthly data'!G123 -> 22.78 | N14: ='Monthly data'!G124 -> 34.89 | O14: =IF(COUNT(C14:N14)=12,SUM(C14:N14),"") -> 712.32
A15: 2016/17 | B15: =ENSO!C15 -> Neutral | C15: ='Monthly data'!G125 -> 41.97 | D15: ='Monthly data'!G126 -> 25.15 | E15: ='Monthly data'!G127 -> 35.2 | F15: ='Monthly data'!G128 -> 73.37 | G15: ='Monthly data'!G129 -> 237.23 | H15: ='Monthly data'!G130 -> 163.16 | I15: ='Monthly data'!G131 -> 31.32 | J15: ='Monthly data'!G132 -> 124.47 | K15: ='Monthly data'!G133 -> 74.13 | L15: ='Monthly data'!G134 -> 34.76 | M15: ='Monthly data'!G135 -> 86.96 | N15: ='Monthly data'!G136 -> 59.91 | O15: =IF(COUNT(C15:N15)=12,SUM(C15:N15),"") -> 987.63
A16: 2017/18 | B16: =ENSO!C16 -> La Niña | C16: ='Monthly data'!G137 -> 75.07 | D16: ='Monthly data'!G138 -> 25.88 | E16: ='Monthly data'!G139 -> 56.52 | F16: ='Monthly data'!G140 -> 49.92 | G16: ='Monthly data'!G141 -> 132.64 | H16: ='Monthly data'!G142 -> 310.14 | I16: ='Monthly data'!G143 -> 117.7 | J16: ='Monthly data'!G144 -> 234.6 | K16: ='Monthly data'!G145 -> 137.57 | L16: ='Monthly data'!G146 -> 123.36 | M16: ='Monthly data'!G147 -> 47.71 | N16: ='Monthly data'!G148 -> 39.99 | O16: =IF(COUNT(C16:N16)=12,SUM(C16:N16),"") -> 1351.1
A17: 2018/19 | B17: =ENSO!C17 -> El Niño | C17: ='Monthly data'!G149 -> 23.78 | D17: ='Monthly data'!G150 -> 89.43 | E17: ='Monthly data'!G151 -> 36.16 | F17: ='Monthly data'!G152 -> 194.22 | G17: ='Monthly data'!G153 -> 207.84 | H17: ='Monthly data'!G154 -> 340.65 | I17: ='Monthly data'!G155 -> 11.64 | J17: ='Monthly data'!G156 -> 107.63 | K17: ='Monthly data'!G157 -> 70.76 | L17: ='Monthly data'!G158 -> 100.28 | M17: ='Monthly data'!G159 -> 78.15 | N17: ='Monthly data'!G160 -> 48.35 | O17: =IF(COUNT(C17:N17)=12,SUM(C17:N17),"") -> 1308.89
A18: 2019/20 | B18: =ENSO!C18 -> El Niño | C18: ='Monthly data'!G161 -> 37.27 | D18: ='Monthly data'!G162 -> 78.47 | E18: ='Monthly data'!G163 -> 25.78 | F18: ='Monthly data'!G164 -> 128.84 | G18: ='Monthly data'!G165 -> 229.43 | H18: ='Monthly data'!G166 -> 138.51 | I18: ='Monthly data'!G167 -> 321.06 | J18: ='Monthly data'!G168 -> 104.25 | K18: ='Monthly data'!G169 -> 190.3 | L18: ='Monthly data'!G170 -> 53.03 | M18: ='Monthly data'!G171 -> 51.92 | N18: ='Monthly data'!G172 -> 36.93 | O18: =IF(COUNT(C18:N18)=12,SUM(C18:N18),"") -> 1395.79
A19: 2020/21 | B19: =ENSO!C19 -> La Niña | C19: ='Monthly data'!G173 -> 59.95 | D19: ='Monthly data'!G174 -> 38.73 | E19: ='Monthly data'!G175 -> 42.17 | F19: ='Monthly data'!G176 -> 207.82 | G19: ='Monthly data'!G177 -> 132.86 | H19: ='Monthly data'!G178 -> 50.53 | I19: ='Monthly data'!G179 -> 29.94 | J19: ='Monthly data'!G180 -> 206.93 | K19: ='Monthly data'!G181 -> 141.71 | L19: ='Monthly data'!G182 -> 57.14 | M19: ='Monthly data'!G183 -> 19.11 | N19: ='Monthly data'!G184 -> 23.83 | O19: =IF(COUNT(C19:N19)=12,SUM(C19:N19),"") -> 1010.72
A20: 2021/22 | B20: =ENSO!C20 -> La Niña | C20: ='Monthly data'!G185 -> 18.09 | D20: ='Monthly data'!G186 -> 39.14 | E20: ='Monthly data'!G187 -> 35 | F20: ='Monthly data'!G188 -> 175.89 | G20: ='Monthly data'!G189 -> 196.7 | H20: ='Monthly data'!G190 -> 331.34 | I20: ='Monthly data'!G191 -> 134.58 | J20: ='Monthly data'!G192 -> 216.52 | K20: ='Monthly data'!G193 -> 42.91 | L20: ='Monthly data'!G194 -> 38.11 | M20: ='Monthly data'!G195 -> 53.73 | N20: ='Monthly data'!G196 -> 15.18 | O20: =IF(COUNT(C20:N20)=12,SUM(C20:N20),"") -> 1297.19
A21: 2022/23 | B21: =ENSO!C21 -> La Niña | C21: ='Monthly data'!G197 -> 44.27 | D21: ='Monthly data'!G198 -> 18.25 | E21: ='Monthly data'!G199 -> 23.75 | F21: ='Monthly data'!G200 -> 113.35 | G21: ='Monthly data'!G201 -> 380.05 | H21: ='Monthly data'!G202 -> 466.18 | I21: ='Monthly data'!G203 -> 225.86 | J21: ='Monthly data'!G204 -> 35.52 | K21: ='Monthly data'!G205 -> 20.14 | L21: ='Monthly data'!G206 -> 89.43 | M21: ='Monthly data'!G207 -> 32.8 | N21: ='Monthly data'!G208 -> 31.34 | O21: =IF(COUNT(C21:N21)=12,SUM(C21:N21),"") -> 1480.94
A22: 2023/24 | B22: =ENSO!C22 -> El Niño | C22: ='Monthly data'!G209 -> 80.41 | D22: ='Monthly data'!G210 -> 79.32 | E22: ='Monthly data'!G211 -> 32.26 | F22: ='Monthly data'!G212 -> 83.85 | G22: ='Monthly data'!G213 -> 18.5 | H22: ='Monthly data'!G214 -> 97.7 | I22: ='Monthly data'!G215 -> 298.9 | J22: ='Monthly data'!G216 -> 188.74 | K22: ='Monthly data'!G217 -> 105.33 | L22: ='Monthly data'!G218 -> 40.3 | M22: ='Monthly data'!G219 -> 41.53 | N22: ='Monthly data'!G220 -> 25.79 | O22: =IF(COUNT(C22:N22)=12,SUM(C22:N22),"") -> 1092.63
A23: 2024/25 | B23: =ENSO!C23 -> Neutral | C23: ='Monthly data'!G221 -> 20.05 | D23: ='Monthly data'!G222 -> 47.45 | E23: ='Monthly data'!G223 -> 29.81 | F23: ='Monthly data'!G224 -> 219.6 | G23: ='Monthly data'!G225 -> 242.1 | H23: ='Monthly data'!G226 -> 152.38 | I23: ='Monthly data'!G227 -> 177.66 | J23: ='Monthly data'!G228 -> 12.13 | K23: ='Monthly data'!G229 -> 33.02 | L23: ='Monthly data'!G230 -> 117.18 | M23: ='Monthly data'!G231 -> 48.45 | N23: ='Monthly data'!G232 -> 39.13 | O23: =IF(COUNT(C23:N23)=12,SUM(C23:N23),"") -> 1138.96
A24: 2025/26 | B24: =ENSO!C24 -> Neutral | C24: ='Monthly data'!G233 -> 34.58 | D24: ='Monthly data'!G234 -> 26.8 | E24: ='Monthly data'!G235 -> 69.14 | F24: ='Monthly data'!G236 -> 96.11 | G24: ='Monthly data'!G237 -> 133.6 | H24: ='Monthly data'!G238 -> 145.13 | I24: ='Monthly data'!G239 -> 257.75 | J24: ='Monthly data'!G240 -> 181.87 | K24: ='Monthly data'!G241 -> 205.27 | L24: ='Monthly data'!G242 -> 59.85 | M24: ='Monthly data'!G243 -> 42.85 | N24: ='Monthly data'!G244 -> 34.72 | O24: =IF(COUNT(C24:N24)=12,SUM(C24:N24),"") -> 1287.67
A25: 2026/27 | B25: =ENSO!C25 -> El Niño* | C25: ='Monthly data'!G245 -> 38.39 | D25: ='Monthly data'!G246 -> 31.47 | O25: =IF(COUNT(C25:N25)=12,SUM(C25:N25),"")
A27: Averages
A28: El Niño average (7 seasons) | C28: =AVERAGEIF($B$5:$B$25,"El Niño",C$5:C$25) -> 49.387143 | D28: =AVERAGEIF($B$5:$B$25,"El Niño",D$5:D$25) -> 67.785714 | E28: =AVERAGEIF($B$5:$B$25,"El Niño",E$5:E$25) -> 39.017143 | F28: =AVERAGEIF($B$5:$B$25,"El Niño",F$5:F$25) -> 168.33857 | G28: =AVERAGEIF($B$5:$B$25,"El Niño",G$5:G$25) -> 158.21857 | H28: =AVERAGEIF($B$5:$B$25,"El Niño",H$5:H$25) -> 159.58857 | I28: =AVERAGEIF($B$5:$B$25,"El Niño",I$5:I$25) -> 150.15857 | J28: =AVERAGEIF($B$5:$B$25,"El Niño",J$5:J$25) -> 124.62143 | ... O28: =AVERAGEIF($B$5:$B$25,"El Niño",O$5:O$25) -> 1185.8414
A29: La Niña average (8 seasons) | C29: =AVERAGEIF($B$5:$B$25,"La Niña",C$5:C$25) -> 48.57375 | D29: =AVERAGEIF($B$5:$B$25,"La Niña",D$5:D$25) -> 28.2625 | E29: =AVERAGEIF($B$5:$B$25,"La Niña",E$5:E$25) -> 38.81 | F29: =AVERAGEIF($B$5:$B$25,"La Niña",F$5:F$25) -> 114.1325 | G29: =AVERAGEIF($B$5:$B$25,"La Niña",G$5:G$25) -> 227.5225 | H29: =AVERAGEIF($B$5:$B$25,"La Niña",H$5:H$25) -> 238.915 | I29: =AVERAGEIF($B$5:$B$25,"La Niña",I$5:I$25) -> 155.49625 | J29: =AVERAGEIF($B$5:$B$25,"La Niña",J$5:J$25) -> 124.15875 | ... O29: =AVERAGEIF($B$5:$B$25,"La Niña",O$5:O$25) -> 1269.675
A30: Neutral average (5 seasons) | C30: =AVERAGEIF($B$5:$B$25,"Neutral",C$5:C$25) -> 40.908 | D30: =AVERAGEIF($B$5:$B$25,"Neutral",D$5:D$25) -> 45.672 | E30: =AVERAGEIF($B$5:$B$25,"Neutral",E$5:E$25) -> 52.418 | F30: =AVERAGEIF($B$5:$B$25,"Neutral",F$5:F$25) -> 115.584 | G30: =AVERAGEIF($B$5:$B$25,"Neutral",G$5:G$25) -> 207.89 | H30: =AVERAGEIF($B$5:$B$25,"Neutral",H$5:H$25) -> 213.386 | I30: =AVERAGEIF($B$5:$B$25,"Neutral",I$5:I$25) -> 151.694 | J30: =AVERAGEIF($B$5:$B$25,"Neutral",J$5:J$25) -> 80.996 | ... O30: =AVERAGEIF($B$5:$B$25,"Neutral",O$5:O$25) -> 1164.338
A31: All complete seasons (20) | C31: =AVERAGE(C5:C24) -> 46.942 | D31: =AVERAGE(D5:D24) -> 46.448 | E31: =AVERAGE(E5:E24) -> 42.2845 | F31: =AVERAGE(F5:F24) -> 133.4675 | G31: =AVERAGE(G5:G24) -> 198.358 | H31: =AVERAGE(H5:H24) -> 204.7685 | I31: =AVERAGE(I5:I24) -> 152.6775 | J31: =AVERAGE(J5:J24) -> 113.53 | ... O31: =AVERAGE(O5:O24) -> 1213.999
